File: data/ReportRaw/Resin_CSV/V4_Resin_Green/Tensile_Test_01.csv
Time,Displacement,Force,Tensile strain (Strain 1),,Tensile stress
(s),(mm),(kN),(%),,(MPa)
0,0,0.0006,-6.7174,0,0.0565
0.22,0.0009,0.001,-6.7142,0.0032,0.0978
0.44,0.0054,0.0039,-6.6991,0.0183,0.38
0.66,0.0089,0.0058,-6.6864,0.031,0.5631
0.88,0.0126,0.0078,-6.6743,0.0431,0.7651
1.1,0.0164,0.0099,-6.6612,0.0562,0.9687
1.32,0.0198,0.0113,-6.6504,0.067,1.1017
1.54,0.0236,0.0133,-6.6377,0.0797,1.294
1.76,0.0273,0.015,-6.6259,0.0915,1.4657
1.98,0.0308,0.0165,-6.6148,0.1026,1.612
2.2,0.0347,0.0181,-6.6024,0.115,1.7654
2.42,0.0383,0.0197,-6.5917,0.1257,1.9241
2.64,0.0419,0.021,-6.5818,0.1356,2.0547
2.86,0.0458,0.0227,-6.5705,0.1469,2.2205
3.08,0.0493,0.0238,-6.5607,0.1567,2.3194
3.3,0.053,0.025,-6.551,0.1664,2.4458
3.52,0.057,0.0266,-6.5406,0.1768,2.5959
3.74,0.0603,0.0275,-6.532,0.1854,2.683
3.96,0.0642,0.0288,-6.5226,0.1948,2.8122
4.18,0.0682,0.0301,-6.512,0.2054,2.9403
4.4,0.0713,0.031,-6.5053,0.2121,3.0246
4.62,0.0754,0.0322,-6.4954,0.222,3.1438
4.84,0.0791,0.0334,-6.4863,0.2311,3.2615
5.06,0.0823,0.034,-6.4797,0.2377,3.3165
5.28,0.0864,0.0353,-6.47,0.2474,3.4474
5.5,0.0898,0.036,-6.4633,0.2541,3.5203
5.72,0.0933,0.0368,-6.4555,0.2619,3.5971
5.94,0.0973,0.0379,-6.4475,0.2699,3.7043
6.16,0.1005,0.0387,-6.4404,0.277,3.7794
6.38,0.1043,0.0395,-6.4332,0.2842,3.8527
6.6,0.1081,0.0405,-6.4246,0.2928,3.9506
6.82,0.1114,0.0411,-6.4187,0.2987,4.0148
7.04,0.1153,0.042,-6.4103,0.3071,4.1043
7.26,0.119,0.0429,-6.4037,0.3137,4.1931
7.48,0.1225,0.0434,-6.3972,0.3202,4.2415
7.7,0.1264,0.0443,-6.3905,0.3269,4.3251
7.92,0.13,0.0449,-6.3849,0.3325,4.3837
8.14,0.1336,0.0447,-6.3826,0.3348,4.3654
8.36,0.1376,0.0392,-6.4079,0.3095,3.8312
8.58,0.1409,0.0409,-6.4021,0.3153,3.9899
8.8,0.1447,0.0422,-6.3931,0.3243,4.1182
9.02,0.1488,0.0437,-6.3835,0.3339,4.2701
9.24,0.152,0.0443,-6.3769,0.3405,4.3303
9.46,0.1559,0.0456,-6.3685,0.3489,4.4535
9.68,0.1599,0.0467,-6.3604,0.357,4.5571
9.9,0.163,0.0472,-6.355,0.3624,4.6123
10.12,0.1671,0.0483,-6.3476,0.3698,4.7163
10.34,0.1707,0.049,-6.3403,0.3771,4.7839
10.56,0.174,0.0495,-6.3354,0.382,4.8348
10.78,0.1781,0.0504,-6.3272,0.3902,4.926
11,0.1813,0.051,-6.3221,0.3953,4.9763
11.22,0.1849,0.0517,-6.3161,0.4013,5.0472
11.44,0.1889,0.0526,-6.3092,0.4082,5.1385
11.66,0.1921,0.053,-6.3039,0.4135,5.1794
11.88,0.1959,0.0538,-6.2975,0.4199,5.2555
12.1,0.1997,0.0545,-6.2902,0.4272,5.3245
12.32,0.2031,0.055,-6.285,0.4324,5.3739
12.54,0.207,0.0558,-6.2782,0.4392,5.4471
12.76,0.2106,0.0567,-6.2714,0.446,5.5337
12.98,0.2142,0.0573,-6.2655,0.4519,5.5944
13.2,0.2181,0.0581,-6.2581,0.4593,5.6765
13.42,0.2216,0.059,-6.2522,0.4652,5.7594
13.64,0.2253,0.0595,-6.2452,0.4722,5.813
13.86,0.2294,0.0606,-6.2375,0.4799,5.9223
14.08,0.2326,0.0612,-6.2311,0.4863,5.979
14.3,0.2365,0.062,-6.2242,0.4932,6.0543
14.52,0.2405,0.0631,-6.2156,0.5018,6.1652
14.74,0.2436,0.0635,-6.2106,0.5068,6.1977
14.96,0.2477,0.0644,-6.2025,0.5149,6.2933
15.18,0.2515,0.0654,-6.1952,0.5222,6.3872
15.4,0.2546,0.0659,-6.1899,0.5275,6.4322
15.62,0.2587,0.0668,-6.182,0.5354,6.5209
15.84,0.2621,0.0674,-6.1756,0.5418,6.5838
16.06,0.2656,0.068,-6.1697,0.5477,6.6385
16.28,0.2696,0.0689,-6.1622,0.5552,6.7283
16.5,0.2729,0.0695,-6.1563,0.5611,6.7892
16.72,0.2766,0.0701,-6.1499,0.5675,6.8457
16.94,0.2804,0.0709,-6.1425,0.5749,6.9207
17.16,0.2838,0.0714,-6.1372,0.5802,6.9683
17.38,0.2876,0.0721,-6.1303,0.5871,7.0384
17.6,0.2914,0.073,-6.1237,0.5937,7.128
17.82,0.2948,0.0733,-6.1179,0.5995,7.1594
18.04,0.2987,0.0742,-6.1111,0.6063,7.2466
18.26,0.3023,0.0748,-6.1044,0.613,7.3049
18.48,0.3059,0.0754,-6.0991,0.6183,7.362
18.7,0.3098,0.0762,-6.092,0.6254,7.443
18.92,0.3133,0.0766,-6.0865,0.6309,7.4847
19.14,0.317,0.0775,-6.0795,0.6379,7.5644
19.36,0.3211,0.0783,-6.0725,0.6449,7.6443
19.58,0.3243,0.0788,-6.0671,0.6503,7.694
19.8,0.3282,0.0796,-6.06,0.6574,7.7757
20.02,0.3322,0.0805,-6.0521,0.6653,7.8627
20.24,0.3353,0.0811,-6.0469,0.6705,7.9166
20.46,0.3394,0.082,-6.0388,0.6786,8.0116
20.68,0.3431,0.0828,-6.0321,0.6853,8.0816
20.9,0.3463,0.0832,-6.0266,0.6908,8.1296
21.12,0.3504,0.0843,-6.0185,0.6989,8.2307
21.34,0.3538,0.0848,-6.0127,0.7047,8.2842
21.56,0.3573,0.0854,-6.0064,0.711,8.3435
21.78,0.3612,0.0863,-5.9992,0.7182,8.4315
22,0.3645,0.0866,-5.9933,0.7241,8.4609
22.22,0.3683,0.0875,-5.9869,0.7305,8.5419
22.44,0.372,0.088,-5.9798,0.7376,8.5982
22.66,0.3754,0.0886,-5.9747,0.7427,8.6496
22.88,0.3793,0.0894,-5.9669,0.7505,8.7288
23.1,0.383,0.0901,-5.9611,0.7563,8.8017
23.32,0.3864,0.0905,-5.9551,0.7623,8.8371
23.54,0.3904,0.0914,-5.9483,0.7691,8.9272
23.76,0.3939,0.0919,-5.9426,0.7748,8.97
23.98,0.3976,0.0925,-5.9367,0.7807,9.0297
24.2,0.4015,0.0932,-5.9293,0.7881,9.1
24.42,0.405,0.0938,-5.9247,0.7927,9.1571
24.64,0.4087,0.0942,-5.9184,0.799,9.2011
24.86,0.4128,0.095,-5.9114,0.806,9.2819
25.08,0.416,0.0954,-5.9066,0.8108,9.3142
25.3,0.4199,0.0961,-5.9,0.8174,9.3836
25.52,0.4239,0.0969,-5.8932,0.8242,9.4614
25.74,0.427,0.0972,-5.8891,0.8283,9.4874
25.96,0.4311,0.0979,-5.8826,0.8348,9.5591
26.18,0.4346,0.0984,-5.8765,0.8409,9.6051
26.4,0.438,0.0988,-5.8721,0.8453,9.6461
26.62,0.442,0.0996,-5.865,0.8524,9.7272
26.84,0.4454,0.0999,-5.86,0.8574,9.7576
27.06,0.4489,0.1004,-5.8548,0.8626,9.8084
27.28,0.4529,0.1012,-5.8482,0.8692,9.8857
27.5,0.4562,0.1015,-5.8436,0.8738,9.9105
27.72,0.46,0.1021,-5.8374,0.88,9.9661
27.94,0.4637,0.1027,-5.8318,0.8856,10.0333
28.16,0.4671,0.1031,-5.8265,0.8909,10.0671
28.38,0.471,0.1037,-5.8204,0.897,10.129
28.6,0.4746,0.1042,-5.8143,0.9031,10.1746
28.82,0.4782,0.1048,-5.8092,0.9082,10.2351
29.04,0.4821,0.1055,-5.8025,0.9149,10.3039
29.26,0.4856,0.106,-5.7974,0.92,10.3491
29.48,0.4893,0.1065,-5.7913,0.9261,10.4016
29.7,0.4933,0.1073,-5.7846,0.9328,10.4825
29.92,0.4966,0.1076,-5.7802,0.9372,10.5063
30.14,0.5005,0.1083,-5.7735,0.9439,10.5806
30.36,0.5045,0.109,-5.767,0.9504,10.6478
30.58,0.5077,0.1093,-5.7628,0.9546,10.6729
30.8,0.5117,0.1102,-5.7559,0.9615,10.7633
31.02,0.5155,0.1109,-5.7492,0.9682,10.8263
31.24,0.5186,0.111,-5.7458,0.9716,10.835
31.46,0.5228,0.1119,-5.7381,0.9793,10.9302
31.68,0.5262,0.1123,-5.7329,0.9845,10.9706
31.9,0.5296,0.1127,-5.728,0.9894,11.0015
32.12,0.5336,0.1134,-5.721,0.9964,11.0782
32.34,0.5369,0.1137,-5.7174,1,11.1044
32.56,0.5406,0.1143,-5.711,1.0064,11.1663
32.78,0.5444,0.115,-5.7047,1.0127,11.2258
33,0.5478,0.1153,-5.6996,1.0178,11.2639
33.22,0.5516,0.1159,-5.6937,1.0237,11.3209
33.44,0.5553,0.1167,-5.6877,1.0297,11.3918
33.66,0.5588,0.117,-5.6822,1.0352,11.4279
33.88,0.5627,0.1175,-5.676,1.0414,11.4723
34.1,0.5663,0.1182,-5.6703,1.0471,11.5451
34.32,0.5699,0.1187,-5.6647,1.0527,11.5869
34.54,0.5738,0.1194,-5.6583,1.0591,11.6574
34.76,0.5773,0.1198,-5.6529,1.0645,11.7023
34.98,0.581,0.1204,-5.647,1.0704,11.7585
35.2,0.5851,0.1211,-5.64,1.0774,11.8243
35.42,0.5883,0.1214,-5.6357,1.0817,11.8562
35.64,0.5923,0.1221,-5.6293,1.0881,11.9228
35.86,0.5962,0.1229,-5.6223,1.0951,12.0067
36.08,0.5993,0.1231,-5.618,1.0994,12.024
36.3,0.6034,0.1241,-5.6103,1.1071,12.1152
36.52,0.607,0.1247,-5.6042,1.1132,12.1756
36.74,0.6103,0.125,-5.5991,1.1183,12.2071
36.96,0.6144,0.1258,-5.5923,1.1251,12.2843
37.18,0.6177,0.1261,-5.5871,1.1303,12.3183
37.4,0.6213,0.1267,-5.5819,1.1355,12.3745
37.62,0.6252,0.1273,-5.5754,1.142,12.4363
37.84,0.6286,0.1276,-5.5711,1.1463,12.46
38.06,0.6323,0.1281,-5.5647,1.1527,12.5123
38.28,0.6361,0.1289,-5.5591,1.1583,12.5865
38.5,0.6395,0.129,-5.5542,1.1632,12.5998
38.72,0.6433,0.1297,-5.5485,1.1689,12.6656
38.94,0.647,0.1303,-5.5423,1.1751,12.7267
39.16,0.6505,0.1307,-5.5371,1.1803,12.7643
39.38,0.6544,0.1314,-5.5302,1.1872,12.8336
39.6,0.6579,0.1321,-5.5251,1.1923,12.8963
39.82,0.6616,0.1323,-5.5189,1.1985,12.9217
40.04,0.6656,0.1332,-5.5119,1.2055,13.0064
40.26,0.6689,0.1337,-5.5069,1.2105,13.0533
40.48,0.6727,0.1341,-5.5008,1.2166,13.0986
40.7,0.6768,0.135,-5.494,1.2234,13.1788
40.92,0.68,0.1352,-5.4892,1.2282,13.2063
41.14,0.6839,0.136,-5.4827,1.2347,13.2825
41.36,0.6879,0.1367,-5.4756,1.2418,13.3448
41.58,0.691,0.1369,-5.4716,1.2458,13.3726
41.8,0.6951,0.1377,-5.4643,1.2531,13.4489
42.02,0.6986,0.1382,-5.4584,1.259,13.4927
42.24,0.702,0.1385,-5.4534,1.264,13.5252
42.46,0.706,0.1396,-5.4463,1.2711,13.6303
42.68,0.7093,0.1397,-5.4417,1.2757,13.6391
42.9,0.713,0.1402,-5.436,1.2814,13.6902
43.12,0.7168,0.141,-5.4289,1.2885,13.7666
43.34,0.7201,0.1413,-5.4245,1.2929,13.7943
43.56,0.724,0.1419,-5.418,1.2994,13.8578
43.78,0.7277,0.1425,-5.4115,1.3059,13.9205
44,0.7311,0.1428,-5.4064,1.311,13.9441
44.22,0.735,0.1436,-5.3998,1.3176,14.0216
44.44,0.7386,0.1441,-5.394,1.3234,14.0719
44.66,0.7422,0.1445,-5.3878,1.3296,14.1065
44.88,0.7461,0.1454,-5.3812,1.3362,14.1996
45.1,0.7496,0.1457,-5.3757,1.3417,14.2322
45.32,0.7533,0.1463,-5.3698,1.3476,14.2837
45.54,0.7574,0.1471,-5.3621,1.3553,14.3626
45.76,0.7606,0.1474,-5.3576,1.3598,14.3945
45.98,0.7645,0.1481,-5.3511,1.3663,14.4637
46.2,0.7685,0.1488,-5.3436,1.3738,14.5311
46.42,0.7717,0.1491,-5.3394,1.378,14.5628
46.64,0.7757,0.1499,-5.3319,1.3855,14.6433
46.86,0.7794,0.1505,-5.3256,1.3918,14.6951
47.08,0.7826,0.1508,-5.3208,1.3966,14.7276
47.3,0.7868,0.1516,-5.3138,1.4036,14.8022
47.52,0.7901,0.1521,-5.3077,1.4097,14.8503
47.74,0.7936,0.1525,-5.3019,1.4155,14.8941
47.96,0.7976,0.1533,-5.2954,1.422,14.9666
48.18,0.8009,0.1535,-5.2899,1.4275,14.9924
48.4,0.8046,0.1542,-5.2835,1.4339,15.0543
48.62,0.8084,0.155,-5.2765,1.4409,15.1404
48.84,0.8118,0.1554,-5.2709,1.4465,15.1718
49.06,0.8156,0.1561,-5.2634,1.454,15.2457
49.28,0.8193,0.1567,-5.256,1.4614,15.3069
49.5,0.8228,0.1573,-5.2497,1.4677,15.3635
49.72,0.8267,0.1581,-5.2419,1.4755,15.4439
49.94,0.8303,0.1589,-5.2349,1.4825,15.5209
50.16,0.8339,0.1595,-5.2276,1.4898,15.5752
50.38,0.8379,0.1605,-5.2189,1.4985,15.6691
50.6,0.8413,0.1611,-5.2124,1.505,15.7368
50.82,0.845,0.1619,-5.2046,1.5128,15.815
51.04,0.8491,0.1628,-5.1959,1.5215,15.8993
51.26,0.8523,0.1634,-5.1898,1.5276,15.9528
51.48,0.8562,0.1641,-5.1812,1.5362,16.0268
51.7,0.8602,0.1651,-5.1731,1.5443,16.1189
51.92,0.8633,0.1654,-5.1671,1.5503,16.1486
52.14,0.8674,0.1664,-5.1584,1.559,16.25
52.36,0.8711,0.1672,-5.1507,1.5667,16.3243
52.58,0.8743,0.1675,-5.145,1.5724,16.3559
52.8,0.8784,0.1685,-5.1358,1.5816,16.4558
53.02,0.8818,0.1689,-5.1296,1.5878,16.496
53.24,0.8853,0.1695,-5.1223,1.5951,16.5503
53.46,0.8892,0.1704,-5.1145,1.6029,16.6393
53.68,0.8925,0.1708,-5.108,1.6094,16.6777
53.9,0.8963,0.1714,-5.1009,1.6165,16.7405
54.12,0.9,0.1722,-5.093,1.6244,16.8172
54.34,0.9034,0.1727,-5.0867,1.6307,16.8677
54.56,0.9073,0.1734,-5.079,1.6384,16.9318
54.78,0.911,0.1742,-5.0711,1.6463,17.0072
55,0.9145,0.1747,-5.0647,1.6527,17.0592
55.22,0.9184,0.1755,-5.0565,1.6609,17.1346
55.44,0.9219,0.176,-5.0499,1.6675,17.1856
55.66,0.9256,0.1766,-5.0423,1.6751,17.2453
55.88,0.9296,0.1775,-5.0343,1.6831,17.3332
56.1,0.9329,0.178,-5.0279,1.6895,17.3852
56.32,0.9368,0.1788,-5.0201,1.6973,17.4579
56.54,0.9408,0.1797,-5.0108,1.7066,17.551
56.76,0.944,0.18,-5.0056,1.7118,17.5744
56.98,0.948,0.1809,-4.9971,1.7203,17.6646
57.2,0.9518,0.1818,-4.989,1.7284,17.7518
57.42,0.955,0.1819,-4.9831,1.7343,17.7639
57.64,0.9591,0.1829,-4.9739,1.7435,17.8616
57.86,0.9626,0.1836,-4.9677,1.7497,17.9253
58.08,0.966,0.1838,-4.9611,1.7563,17.9521
58.3,0.97,0.1848,-4.9529,1.7645,18.0435
58.52,0.9733,0.1852,-4.947,1.7704,18.0857
58.74,0.9769,0.1858,-4.9398,1.7776,18.1463
58.96,0.9808,0.1865,-4.9315,1.7859,18.2117
59.18,0.9841,0.1871,-4.9256,1.7918,18.2688
59.4,0.988,0.1876,-4.9174,1.8,18.3172
59.62,0.9917,0.1884,-4.9106,1.8068,18.3993
59.84,0.9951,0.1888,-4.9031,1.8143,18.4372
60.06,0.999,0.1896,-4.8952,1.8222,18.5176
60.28,1.0026,0.1902,-4.8877,1.8297,18.5727
60.5,1.0062,0.1907,-4.8809,1.8365,18.619
60.72,1.0102,0.1915,-4.8723,1.8451,18.7028
60.94,1.0136,0.1922,-4.8652,1.8522,18.7735
61.16,1.0173,0.1928,-4.8578,1.8596,18.8291
61.38,1.0214,0.1937,-4.8488,1.8686,18.9142
61.6,1.0246,0.1942,-4.843,1.8744,18.9619
61.82,1.0286,0.1948,-4.8345,1.8829,19.0267
62.04,1.0325,0.1958,-4.8258,1.8916,19.1208
62.26,1.0356,0.196,-4.8198,1.8976,19.1373
62.48,1.0397,0.1969,-4.8113,1.9061,19.2334
62.7,1.0434,0.1976,-4.8034,1.914,19.2931
62.92,1.0466,0.1978,-4.7981,1.9193,19.3198
63.14,1.0507,0.1989,-4.7883,1.9291,19.4219
63.36,1.0541,0.1994,-4.7822,1.9352,19.4747
63.58,1.0576,0.1998,-4.7752,1.9422,19.5105
63.8,1.0616,0.2007,-4.7663,1.9511,19.5987
64.02,1.0649,0.2011,-4.7601,1.9573,19.6381
64.24,1.0686,0.2016,-4.7526,1.9648,19.6916
64.46,1.0724,0.2025,-4.7443,1.9731,19.7743
64.68,1.0758,0.2028,-4.7377,1.9797,19.8086
64.9,1.0796,0.2037,-4.73,1.9874,19.8884
65.12,1.0833,0.2042,-4.7218,1.9956,19.9429
65.34,1.0868,0.2046,-4.7152,2.0022,19.9849
65.56,1.0907,0.2055,-4.7063,2.0111,20.0693
65.78,1.0943,0.206,-4.6996,2.0178,20.1169
66,1.0979,0.2066,-4.692,2.0254,20.175
66.22,1.1019,0.2075,-4.6839,2.0335,20.2621
66.44,1.1053,0.208,-4.6764,2.041,20.312
66.66,1.109,0.2086,-4.6686,2.0488,20.374
66.88,1.1131,0.2094,-4.6596,2.0578,20.445
67.1,1.1163,0.2096,-4.654,2.0634,20.473
67.32,1.1203,0.2104,-4.6446,2.0728,20.551
67.54,1.1242,0.2114,-4.6365,2.0809,20.6454
67.76,1.1274,0.2116,-4.6308,2.0866,20.6658
67.98,1.1314,0.2125,-4.6216,2.0958,20.7516
68.2,1.1351,0.2131,-4.6134,2.104,20.8148
68.42,1.1383,0.2133,-4.6072,2.1102,20.8349
68.64,1.1424,0.2144,-4.5982,2.1192,20.9339
68.86,1.1457,0.2147,-4.5923,2.1251,20.97
69.08,1.1493,0.2152,-4.5846,2.1328,21.0148
69.3,1.1532,0.216,-4.5756,2.1418,21.0925
69.52,1.1565,0.2164,-4.5692,2.1482,21.1319
69.74,1.1603,0.217,-4.5612,2.1562,21.1896
69.96,1.1641,0.2177,-4.5532,2.1642,21.2605
70.18,1.1674,0.2181,-4.5461,2.1713,21.295
70.4,1.1713,0.2189,-4.5379,2.1795,21.3738
70.62,1.175,0.2195,-4.53,2.1874,21.4373
70.84,1.1785,0.22,-4.523,2.1944,21.4843
71.06,1.1824,0.2206,-4.5138,2.2036,21.5455
71.28,1.1859,0.2213,-4.5069,2.2105,21.6079
71.5,1.1896,0.2217,-4.4987,2.2187,21.6535
71.72,1.1936,0.2226,-4.4903,2.2271,21.7368
71.94,1.197,0.223,-4.4831,2.2343,21.7795
72.16,1.2008,0.2237,-4.4751,2.2423,21.8436
72.38,1.2048,0.2246,-4.4654,2.252,21.9329
72.6,1.208,0.2249,-4.4599,2.2575,21.9596
72.82,1.212,0.2258,-4.4503,2.2671,22.0461
73.04,1.2158,0.2264,-4.4418,2.2756,22.108
73.26,1.219,0.2266,-4.436,2.2814,22.1268
73.48,1.2231,0.2275,-4.4263,2.2911,22.2153
73.7,1.2265,0.228,-4.4195,2.2979,22.2701
73.92,1.2299,0.2284,-4.4122,2.3052,22.3035
74.14,1.2339,0.2291,-4.4035,2.3139,22.3778
74.36,1.2373,0.2296,-4.3962,2.3212,22.4202
74.58,1.2409,0.2302,-4.3884,2.329,22.4766
74.8,1.2448,0.2308,-4.3796,2.3378,22.5365
75.02,1.2482,0.2312,-4.3731,2.3443,22.5751
75.24,1.2519,0.2318,-4.3643,2.3531,22.6337
75.46,1.2557,0.2327,-4.3562,2.3612,22.7218
75.68,1.2591,0.2329,-4.349,2.3684,22.7435
75.9,1.263,0.2335,-4.3402,2.3772,22.8064
76.12,1.2667,0.2342,-4.3323,2.3851,22.8681
76.34,1.2702,0.2346,-4.3249,2.3925,22.9112
76.56,1.2742,0.2354,-4.3163,2.4011,22.9878
76.78,1.2776,0.2359,-4.3085,2.4089,23.0366
77,1.2813,0.2365,-4.3009,2.4165,23.0932
77.22,1.2854,0.2372,-4.2914,2.426,23.1686
77.44,1.2887,0.2375,-4.2849,2.4325,23.1949
77.66,1.2925,0.2381,-4.2767,2.4407,23.2531
77.88,1.2965,0.2386,-4.2688,2.4486,23.3008
78.1,1.2997,0.2387,-4.2647,2.4527,23.3064
78.32,1.3037,0.2391,-4.2566,2.4608,23.3498
78.54,1.3075,0.2396,-4.2501,2.4673,23.3978
78.76,1.3107,0.2396,-4.2448,2.4726,23.4027
78.98,1.3148,0.2404,-4.2363,2.4811,23.4778
79.2,1.3181,0.2408,-4.2295,2.4879,23.5112
79.42,1.3216,0.2411,-4.2232,2.4942,23.5407
79.64,1.3256,0.242,-4.2138,2.5036,23.6292
79.86,1.3289,0.2422,-4.2073,2.5101,23.6551
80.08,1.3326,0.243,-4.1985,2.5189,23.7267
80.3,1.3364,0.2437,-4.1898,2.5276,23.7946
80.52,1.3398,0.2439,-4.1824,2.535,23.8221
80.74,1.3437,0.2446,-4.1738,2.5436,23.889
80.96,1.3473,0.2453,-4.1649,2.5525,23.9591
81.18,1.3508,0.2458,-4.1579,2.5595,24.0032
81.4,1.3547,0.2466,-4.148,2.5694,24.0802
81.62,1.3583,0.247,-4.1398,2.5776,24.1252
81.84,1.3619,0.2476,-4.1314,2.586,24.1761
82.06,1.3659,0.2484,-4.1219,2.5955,24.2568
82.28,1.3693,0.2489,-4.1138,2.6036,24.3094
82.5,1.3731,0.2495,-4.1051,2.6123,24.3647
82.72,1.3771,0.2503,-4.0951,2.6223,24.4415
82.94,1.3803,0.2507,-4.0882,2.6292,24.4858
83.16,1.3842,0.2514,-4.0782,2.6392,24.5492
83.38,1.3882,0.2523,-4.0684,2.649,24.6369
83.6,1.3914,0.2524,-4.062,2.6554,24.6448
83.82,1.3954,0.2534,-4.0516,2.6658,24.7421
84.04,1.399,0.2539,-4.0437,2.6737,24.7956
84.26,1.4023,0.2541,-4.0362,2.6812,24.8181
84.48,1.4064,0.255,-4.0261,2.6913,24.9029
84.7,1.4097,0.2553,-4.0185,2.6989,24.933
84.92,1.4133,0.2558,-4.0105,2.7069,24.9782
85.14,1.4172,0.2564,-4.0009,2.7165,25.0433
85.36,1.4205,0.2569,-3.994,2.7234,25.0855
85.58,1.4243,0.2574,-3.9846,2.7328,25.1401
85.8,1.4281,0.258,-3.9765,2.7409,25.1931
86.02,1.4314,0.2583,-3.9689,2.7485,25.222
86.24,1.4353,0.2588,-3.9606,2.7568,25.2773
86.46,1.439,0.2593,-3.9526,2.7648,25.3218
86.68,1.4425,0.2595,-3.9449,2.7725,25.3444
86.9,1.4465,0.2602,-3.937,2.7804,25.4109
87.12,1.4499,0.2604,-3.9295,2.7879,25.432
87.34,1.4536,0.2607,-3.9216,2.7958,25.4605
87.56,1.4576,0.2614,-3.9132,2.8042,25.5235
87.78,1.4609,0.2616,-3.907,2.8104,25.5469
88,1.4648,0.2622,-3.898,2.8194,25.6077
88.22,1.4688,0.2629,-3.8895,2.8279,25.6698
88.44,1.472,0.263,-3.8832,2.8342,25.6865
88.66,1.476,0.2638,-3.8734,2.844,25.761
88.88,1.4798,0.2643,-3.8643,2.8531,25.8096
89.1,1.483,0.2646,-3.8579,2.8595,25.8372
89.32,1.4871,0.2654,-3.8475,2.8699,25.9213
89.54,1.4905,0.2658,-3.8397,2.8777,25.9572
89.76,1.4939,0.2662,-3.8317,2.8857,25.9997
89.98,1.4979,0.267,-3.821,2.8964,26.0736
90.2,1.5013,0.2673,-3.8134,2.904,26.1022
90.42,1.5049,0.2679,-3.8042,2.9132,26.164
90.64,1.5088,0.2687,-3.7945,2.9229,26.2381
90.86,1.5121,0.269,-3.7859,2.9315,26.2661
91.08,1.516,0.2697,-3.7762,2.9412,26.3409
91.3,1.5197,0.2704,-3.7667,2.9507,26.4043
91.52,1.5231,0.2709,-3.7579,2.9595,26.4564
91.74,1.527,0.2716,-3.7477,2.9697,26.5213
91.96,1.5307,0.272,-3.7381,2.9793,26.5624
92.18,1.5342,0.2726,-3.7295,2.9879,26.6187
92.4,1.5382,0.2732,-3.7182,2.9992,26.6838
92.62,1.5417,0.2738,-3.7098,3.0076,26.7404
92.84,1.5453,0.2745,-3.6995,3.0179,26.8035
93.06,1.5494,0.2753,-3.6889,3.0285,26.8823
93.28,1.5526,0.2755,-3.68,3.0374,26.9058
93.5,1.5566,0.2764,-3.6698,3.0476,26.9894
93.72,1.5605,0.277,-3.6588,3.0586,27.0545
93.94,1.5637,0.2774,-3.651,3.0664,27.0886
94.16,1.5678,0.2782,-3.6392,3.0782,27.1704
94.38,1.5714,0.2789,-3.6291,3.0883,27.2336
94.6,1.5747,0.2792,-3.6206,3.0968,27.2674
94.82,1.5787,0.2801,-3.6091,3.1083,27.3513
95.04,1.5821,0.2805,-3.6004,3.117,27.3961
95.26,1.5856,0.281,-3.59,3.1274,27.4408
95.48,1.5896,0.2818,-3.5796,3.1378,27.516
95.7,1.5929,0.2821,-3.5699,3.1475,27.545
95.92,1.5966,0.2826,-3.5593,3.1581,27.5989
96.14,1.6004,0.2835,-3.5486,3.1688,27.6807
96.36,1.6038,0.2839,-3.5395,3.1779,27.7244
96.58,1.6076,0.2846,-3.5281,3.1893,27.792
96.8,1.6113,0.2852,-3.5172,3.2002,27.8501
97.02,1.6148,0.2856,-3.5076,3.2098,27.8879
97.24,1.6187,0.2864,-3.4959,3.2215,27.9655
97.46,1.6223,0.287,-3.4857,3.2317,28.0241
97.68,1.6259,0.2874,-3.4748,3.2426,28.0675
97.9,1.6299,0.2884,-3.463,3.2544,28.1666
98.12,1.6333,0.2887,-3.4529,3.2645,28.198
98.34,1.637,0.2895,-3.4414,3.276,28.2717
98.56,1.6411,0.2906,-3.4285,3.2889,28.377
98.78,1.6443,0.2909,-3.4184,3.299,28.4115
99,1.6483,0.2918,-3.4053,3.3121,28.4999
99.22,1.6522,0.2928,-3.3925,3.3249,28.5953
99.44,1.6553,0.293,-3.3828,3.3346,28.6177
99.66,1.6594,0.294,-3.3689,3.3485,28.7143
99.88,1.663,0.2947,-3.3573,3.3601,28.7819
100.1,1.6663,0.2952,-3.3461,3.3713,28.825
100.32,1.6704,0.2962,-3.3325,3.3849,28.9213
100.54,1.6736,0.2965,-3.3216,3.3958,28.9553
100.76,1.6773,0.2972,-3.3092,3.4082,29.0216
100.98,1.6812,0.298,-3.2964,3.421,29.1006
101.2,1.6845,0.2986,-3.285,3.4324,29.1603
101.42,1.6883,0.2993,-3.2723,3.4451,29.2317
101.64,1.692,0.3,-3.2593,3.4581,29.2947
101.86,1.6955,0.3005,-3.2479,3.4695,29.3462
102.08,1.6993,0.3012,-3.2346,3.4828,29.4185
102.3,1.703,0.3019,-3.222,3.4954,29.4821
102.52,1.7065,0.3024,-3.21,3.5074,29.5345
102.74,1.7105,0.3034,-3.1962,3.5212,29.6264
102.96,1.714,0.304,-3.1846,3.5328,29.6868
103.18,1.7176,0.3045,-3.1715,3.5459,29.7332
103.4,1.7217,0.3053,-3.1578,3.5596,29.819
103.62,1.725,0.3058,-3.1462,3.5712,29.8633
103.84,1.7288,0.3064,-3.1326,3.5848,29.9199
104.06,1.7329,0.3073,-3.1183,3.5991,30.0127
104.28,1.736,0.3077,-3.1074,3.61,30.0488
104.5,1.74,0.3085,-3.0934,3.624,30.1239
104.72,1.7438,0.3092,-3.0797,3.6377,30.1932
104.94,1.747,0.3093,-3.0691,3.6483,30.2083
105.16,1.7511,0.3103,-3.0543,3.6631,30.3014
105.38,1.7545,0.3107,-3.0424,3.675,30.3381
105.6,1.7579,0.3111,-3.0307,3.6867,30.3809
105.82,1.7619,0.312,-3.016,3.7014,30.4715
106.04,1.7652,0.3123,-3.004,3.7134,30.4943
106.26,1.7689,0.3128,-2.9909,3.7265,30.5502
106.48,1.7728,0.3135,-2.9776,3.7398,30.6189
106.7,1.7761,0.314,-2.9655,3.7519,30.6622
106.92,1.78,0.3146,-2.9518,3.7656,30.719
107.14,1.7837,0.3151,-2.9378,3.7796,30.7752
107.36,1.7871,0.3156,-2.9263,3.7911,30.8184
107.58,1.7911,0.3162,-2.9113,3.8061,30.876
107.8,1.7946,0.3168,-2.8992,3.8182,30.935
108.02,1.7982,0.3173,-2.8854,3.832,30.9819
108.24,1.8022,0.318,-2.8709,3.8465,31.0503
108.46,1.8056,0.3183,-2.8587,3.8587,31.0824
108.68,1.8093,0.3189,-2.8448,3.8726,31.1435
108.9,1.8134,0.3198,-2.8298,3.8876,31.2269
109.12,1.8166,0.3199,-2.8177,3.8997,31.2402
109.34,1.8205,0.3206,-2.8034,3.914,31.3114
109.56,1.8245,0.3213,-2.788,3.9294,31.377
109.78,1.8277,0.3216,-2.7769,3.9405,31.4015
110,1.8317,0.3223,-2.7615,3.9559,31.4791
110.22,1.8354,0.3229,-2.748,3.9694,31.5338
110.44,1.8386,0.323,-2.7357,3.9817,31.5445
110.66,1.8427,0.3238,-2.7202,3.9972,31.62
110.88,1.8461,0.3241,-2.7076,4.0098,31.6542
111.1,1.8496,0.3244,-2.6943,4.0231,31.6835
111.32,1.8536,0.3252,-2.6791,4.0383,31.7553
111.54,1.8569,0.3255,-2.6662,4.0512,31.7846
111.76,1.8606,0.3259,-2.6525,4.0649,31.8304
111.98,1.8644,0.3265,-2.6376,4.0798,31.8888
112.2,1.8678,0.3267,-2.6246,4.0928,31.9086
112.42,1.8716,0.3274,-2.6095,4.1079,31.9685
112.64,1.8753,0.3278,-2.5959,4.1215,32.0148
112.86,1.8788,0.3281,-2.5821,4.1353,32.0442
113.08,1.8827,0.3287,-2.5669,4.1505,32.1011
113.3,1.8863,0.3293,-2.5527,4.1647,32.1602
113.52,1.8899,0.3296,-2.5392,4.1782,32.1859
113.74,1.8939,0.3303,-2.5231,4.1943,32.2586
113.96,1.8973,0.3306,-2.5095,4.2079,32.2879
114.18,1.9011,0.3311,-2.4943,4.2231,32.3308
114.4,1.9051,0.3319,-2.4782,4.2392,32.4115
114.62,1.9083,0.3318,-2.4657,4.2517,32.4055
114.84,1.9123,0.3326,-2.4491,4.2683,32.4824
115.06,1.9162,0.3332,-2.434,4.2834,32.5409
115.28,1.9193,0.3333,-2.4209,4.2965,32.5469
115.5,1.9234,0.334,-2.4047,4.3127,32.62
115.72,1.927,0.3344,-2.3897,4.3277,32.6524
115.94,1.9303,0.3344,-2.377,4.3404,32.6608
116.16,1.9343,0.3352,-2.36,4.3574,32.7354
116.38,1.9377,0.3354,-2.3465,4.3709,32.7512
116.6,1.9412,0.3358,-2.331,4.3864,32.7897
116.82,1.9451,0.3363,-2.3152,4.4022,32.8416
117.04,1.9485,0.3365,-2.301,4.4164,32.8596
117.26,1.9523,0.337,-2.2853,4.4321,32.9074
117.48,1.956,0.3374,-2.2697,4.4477,32.9521
117.7,1.9595,0.3377,-2.2554,4.462,32.9801
117.92,1.9634,0.3381,-2.2389,4.4785,33.0202
118.14,1.967,0.3385,-2.2236,4.4938,33.0548
118.36,1.9705,0.3388,-2.2087,4.5087,33.0872
118.58,1.9745,0.3393,-2.192,4.5254,33.1313
118.8,1.978,0.3396,-2.1774,4.54,33.1682
119.02,1.9816,0.3398,-2.1619,4.5555,33.1849
119.24,1.9857,0.3405,-2.1454,4.572,33.2485
119.46,1.989,0.3405,-2.1321,4.5853,33.2526
119.68,1.9928,0.3407,-2.1178,4.5996,33.2672
119.9,1.9968,0.3407,-2.1041,4.6133,33.2731
120.12,2,0.3395,-2.0989,4.6185,33.1585
120.34,2.004,0.3385,-2.0945,4.6229,33.0553
120.56,2.0078,0.3383,-2.0865,4.6309,33.0339
120.78,2.011,0.3381,-2.0763,4.6411,33.0223
121,2.0151,0.3386,-2.0613,4.6561,33.0704
121.22,2.0185,0.339,-2.0483,4.6691,33.1057
121.44,2.022,0.3392,-2.0343,4.6831,33.1289
121.66,2.0259,0.3398,-2.0177,4.6997,33.1813
121.88,2.0292,0.3401,-2.0036,4.7138,33.211
122.1,2.0329,0.3405,-1.9879,4.7295,33.2492
122.32,2.0368,0.341,-1.9711,4.7463,33.2984
122.54,2.0401,0.3412,-1.9564,4.761,33.3202
122.76,2.044,0.3417,-1.9396,4.7778,33.3725
122.98,2.0477,0.3422,-1.923,4.7944,33.4209
123.2,2.0511,0.3424,-1.9074,4.81,33.4327
123.42,2.055,0.3431,-1.8904,4.827,33.5011
123.64,2.0587,0.3433,-1.8738,4.8436,33.5275
123.86,2.0622,0.3436,-1.8576,4.8598,33.5554
124.08,2.0662,0.3442,-1.8396,4.8778,33.6136
124.3,2.0696,0.3446,-1.8236,4.8938,33.6498
124.52,2.0733,0.3449,-1.8061,4.9113,33.6827
124.74,2.0774,0.3456,-1.7883,4.9291,33.7453
124.96,2.0806,0.3457,-1.7721,4.9453,33.7563
125.18,2.0846,0.3462,-1.7545,4.9629,33.8106
125.4,2.0885,0.3468,-1.7361,4.9813,33.8626
125.62,2.0917,0.3468,-1.7211,4.9963,33.8677
125.84,2.0958,0.3475,-1.7021,5.0153,33.9307
126.06,2.0994,0.3478,-1.6851,5.0323,33.9649
126.28,2.1027,0.3478,-1.6686,5.0488,33.9623
126.5,2.1068,0.3485,-1.6495,5.0679,34.0361
126.72,2.1101,0.3486,-1.6333,5.0841,34.0458
126.94,2.1136,0.3488,-1.6164,5.101,34.0602
127.16,2.1175,0.3493,-1.5972,5.1202,34.1069
127.38,2.1209,0.3494,-1.5811,5.1363,34.1227
127.6,2.1246,0.3496,-1.5624,5.155,34.1449
127.82,2.1284,0.3502,-1.5442,5.1732,34.2004
128.04,2.1318,0.3503,-1.5271,5.1903,34.2125
128.26,2.1356,0.3508,-1.5083,5.2091,34.253
128.48,2.1393,0.3511,-1.4899,5.2275,34.2834
128.7,2.1428,0.3511,-1.4721,5.2453,34.2878
128.92,2.1468,0.3516,-1.453,5.2644,34.3387
129.14,2.1503,0.3518,-1.435,5.2824,34.3598
129.36,2.1539,0.3521,-1.4167,5.3007,34.3869
129.58,2.158,0.3528,-1.3965,5.3209,34.4491
129.8,2.1613,0.3528,-1.3791,5.3383,34.4537
130.02,2.1651,0.3531,-1.3601,5.3573,34.4827
130.24,2.1691,0.3537,-1.3396,5.3778,34.5386
130.46,2.1723,0.3535,-1.3231,5.3943,34.5216
130.68,2.1763,0.3541,-1.3022,5.4152,34.5808
130.9,2.1801,0.3544,-1.2831,5.4343,34.6049
131.12,2.1833,0.3543,-1.2659,5.4515,34.6032
131.34,2.1874,0.3549,-1.2459,5.4715,34.6538
131.56,2.1909,0.3548,-1.2276,5.4898,34.6514
131.78,2.1943,0.355,-1.2101,5.5073,34.6647
132,2.1983,0.3554,-1.19,5.5274,34.7035
132.22,2.2016,0.3552,-1.1733,5.5441,34.6907
132.44,2.2053,0.3553,-1.1546,5.5628,34.695
132.66,2.2091,0.3556,-1.1359,5.5815,34.7226
132.88,2.2125,0.3555,-1.1184,5.599,34.7127
133.1,2.2163,0.3558,-1.0992,5.6182,34.7457
133.32,2.2201,0.356,-1.0797,5.6377,34.7639
133.54,2.2235,0.356,-1.0613,5.6561,34.7646
133.76,2.2274,0.3563,-1.0412,5.6762,34.7923
133.98,2.231,0.3566,-1.0216,5.6958,34.8251
134.2,2.2345,0.3567,-1.0028,5.7146,34.8308
134.42,2.2385,0.3571,-0.9818,5.7356,34.8775
134.64,2.242,0.3572,-0.9628,5.7546,34.8844
134.86,2.2457,0.3574,-0.9419,5.7755,34.9016
135.08,2.2497,0.3578,-0.9207,5.7967,34.9424
135.3,2.253,0.3578,-0.9015,5.8159,34.9413
135.52,2.2568,0.3583,-0.8806,5.8368,34.9932
135.74,2.2608,0.3587,-0.8585,5.8589,35.0261
135.96,2.264,0.3586,-0.8397,5.8777,35.0185
136.18,2.268,0.359,-0.8172,5.9002,35.0605
136.4,2.2718,0.3593,-0.7964,5.921,35.0927
136.62,2.275,0.3592,-0.7771,5.9403,35.0813
136.84,2.2791,0.3597,-0.7545,5.9629,35.1273
137.06,2.2825,0.3597,-0.7342,5.9832,35.1282
137.28,2.286,0.3597,-0.714,6.0034,35.1305
137.5,2.2899,0.3603,-0.691,6.0264,35.19
137.72,2.2932,0.3602,-0.6713,6.0461,35.1731
137.94,2.2969,0.3604,-0.6495,6.0679,35.1926
138.16,2.3007,0.3608,-0.6273,6.0901,35.2331
138.38,2.3041,0.3607,-0.6066,6.1108,35.2238
138.6,2.308,0.361,-0.5843,6.1331,35.2556
138.82,2.3117,0.3613,-0.5624,6.155,35.2808
139.04,2.3151,0.3613,-0.5411,6.1763,35.2861
139.26,2.319,0.3615,-0.5179,6.1995,35.305
139.48,2.3226,0.3617,-0.4964,6.221,35.3235
139.7,2.3262,0.3618,-0.4742,6.2432,35.3357
139.92,2.3302,0.3622,-0.4511,6.2663,35.3681
140.14,2.3336,0.3622,-0.4295,6.2879,35.3696
140.36,2.3374,0.3624,-0.4064,6.311,35.3887
140.58,2.3414,0.3627,-0.3826,6.3348,35.4246
140.8,2.3446,0.3627,-0.3617,6.3557,35.4193
141.02,2.3486,0.363,-0.3381,6.3793,35.4495
141.24,2.3525,0.3634,-0.3135,6.4039,35.488
141.46,2.3557,0.3632,-0.293,6.4244,35.466
141.68,2.3597,0.3636,-0.2682,6.4492,35.503
141.9,2.3634,0.3639,-0.2455,6.4719,35.5343
142.12,2.3666,0.3637,-0.2237,6.4937,35.5209
142.34,2.3707,0.3641,-0.199,6.5184,35.5557
142.56,2.3741,0.364,-0.1771,6.5403,35.5464
142.78,2.3776,0.3639,-0.1545,6.5629,35.5377
143,2.3815,0.3644,-0.1294,6.588,35.5821
143.22,2.3849,0.3642,-0.1074,6.61,35.5689
143.44,2.3886,0.3644,-0.0839,6.6335,35.5818
143.66,2.3924,0.3645,-0.0595,6.6579,35.5996
143.88,2.3958,0.3645,-0.037,6.6804,35.591
144.1,2.3997,0.3647,-0.0118,6.7056,35.6196
144.32,2.4033,0.365,0.012,6.7294,35.6445
144.54,2.4068,0.3648,0.0356,6.753,35.6268
144.76,2.4108,0.3651,0.0602,6.7776,35.6538
144.98,2.4143,0.3651,0.0844,6.8018,35.656
145.2,2.4179,0.3651,0.1082,6.8256,35.6589
145.42,2.4219,0.3655,0.1346,6.852,35.6905
145.64,2.4253,0.3654,0.1567,6.8741,35.6859
145.86,2.4291,0.3656,0.1819,6.8993,35.6984
146.08,2.4331,0.3658,0.2078,6.9252,35.7265
146.3,2.4363,0.3656,0.2305,6.9479,35.7063
146.52,2.4403,0.366,0.2565,6.9739,35.7408
146.74,2.4441,0.3662,0.2821,6.9995,35.7663
146.96,2.4473,0.366,0.3051,7.0225,35.7434
147.18,2.4514,0.3662,0.3317,7.0491,35.7653
147.4,2.4549,0.3662,0.3559,7.0733,35.7626
147.62,2.4583,0.366,0.38,7.0974,35.7446
147.84,2.4623,0.3665,0.4069,7.1243,35.787
148.06,2.4656,0.3662,0.4305,7.1479,35.766
148.28,2.4693,0.3662,0.4558,7.1732,35.7656
148.5,2.4731,0.3665,0.4817,7.1991,35.7948
148.72,2.4765,0.3663,0.5059,7.2233,35.7669
148.94,2.4803,0.3666,0.5314,7.2488,35.797
149.16,2.484,0.3667,0.5579,7.2753,35.8132
149.38,2.4875,0.3665,0.5825,7.2999,35.7946
149.6,2.4913,0.3667,0.6098,7.3272,35.8132
149.82,2.495,0.3668,0.635,7.3524,35.8167
150.04,2.4985,0.3667,0.6604,7.3778,35.8115
150.26,2.5025,0.367,0.6874,7.4048,35.8378
150.48,2.506,0.3669,0.7132,7.4306,35.8262
150.7,2.5097,0.3669,0.7394,7.4568,35.8308
150.92,2.5137,0.3673,0.7669,7.4843,35.869
151.14,2.517,0.367,0.7918,7.5092,35.8434
151.36,2.5209,0.3671,0.8187,7.5361,35.8536
151.58,2.5249,0.3674,0.8468,7.5642,35.8825
151.8,2.528,0.3671,0.871,7.5884,35.8506
152.02,2.5321,0.3673,0.8994,7.6168,35.8693
152.24,2.5357,0.3675,0.926,7.6434,35.8846
152.46,2.539,0.3672,0.9505,7.6679,35.8571
152.68,2.543,0.3674,0.9795,7.6969,35.8749
152.9,2.5465,0.3673,1.0048,7.7222,35.8702
153.12,2.55,0.3673,1.0309,7.7483,35.8691
153.34,2.5539,0.3674,1.0589,7.7763,35.8767
153.56,2.5573,0.3672,1.0851,7.8025,35.8578
153.78,2.5609,0.3673,1.1119,7.8293,35.871
154,2.5648,0.3675,1.1395,7.8569,35.8844
154.22,2.5681,0.3672,1.1659,7.8833,35.855
154.44,2.572,0.3672,1.1941,7.9115,35.8621
154.66,2.5757,0.3673,1.2209,7.9383,35.8685
154.88,2.5791,0.3672,1.2479,7.9653,35.8599
155.1,2.583,0.3674,1.2764,7.9938,35.8753
155.32,2.5866,0.3672,1.3035,8.0209,35.8628
155.54,2.5902,0.3672,1.3309,8.0483,35.8587
155.76,2.5942,0.3674,1.3597,8.0771,35.8804
155.98,2.5976,0.3673,1.3864,8.1038,35.8676
156.2,2.6014,0.3674,1.414,8.1314,35.8759
156.42,2.6054,0.3675,1.4436,8.161,35.8896
156.64,2.6086,0.3673,1.4697,8.1871,35.868
156.86,2.6126,0.3673,1.4987,8.2161,35.8663
157.08,2.6165,0.3675,1.5282,8.2456,35.8908
157.3,2.6196,0.3672,1.5537,8.2711,35.8588
157.52,2.6237,0.3675,1.5833,8.3007,35.8886
157.74,2.6274,0.3675,1.6117,8.3291,35.8908
157.96,2.6306,0.3671,1.6382,8.3556,35.8504
158.18,2.6347,0.3674,1.6685,8.3859,35.8762
158.4,2.638,0.3672,1.695,8.4124,35.8614
158.62,2.6416,0.3671,1.7229,8.4403,35.851
158.84,2.6455,0.3673,1.7526,8.47,35.8658
159.06,2.6488,0.367,1.7798,8.4972,35.8392
159.28,2.6526,0.3671,1.8087,8.5261,35.8509
159.5,2.6564,0.367,1.8379,8.5553,35.8447
159.72,2.6598,0.3669,1.8654,8.5828,35.8333
159.94,2.6636,0.3669,1.8951,8.6125,35.8339
160.16,2.6673,0.3669,1.9241,8.6415,35.8299
160.38,2.6708,0.3668,1.9521,8.6695,35.8203
160.6,2.6748,0.367,1.9823,8.6997,35.8379
160.82,2.6783,0.3668,2.0101,8.7275,35.8249
161.04,2.682,0.3667,2.0392,8.7566,35.8103
161.26,2.686,0.3669,2.0694,8.7868,35.8314
161.48,2.6893,0.3667,2.097,8.8144,35.8095
161.7,2.6932,0.3668,2.1271,8.8445,35.8236
161.92,2.6972,0.3669,2.1576,8.875,35.8337
162.14,2.7003,0.3666,2.185,8.9024,35.8003
162.36,2.7043,0.3668,2.2158,8.9332,35.8216
162.58,2.7081,0.3668,2.2453,8.9627,35.8211
162.8,2.7113,0.3664,2.2727,8.9901,35.7846
163.02,2.7154,0.3666,2.3038,9.0212,35.7986
163.24,2.7188,0.3664,2.3321,9.0495,35.7788
163.46,2.7223,0.3662,2.3606,9.078,35.7613
163.68,2.7263,0.3665,2.3915,9.1089,35.7907
163.9,2.7296,0.3662,2.4198,9.1372,35.7619
164.12,2.7333,0.3661,2.4494,9.1668,35.7549
164.34,2.7371,0.3661,2.4797,9.1971,35.7568
164.56,2.7405,0.3659,2.5078,9.2252,35.7359
164.78,2.7443,0.3659,2.539,9.2564,35.7343
165,2.748,0.366,2.5686,9.286,35.7422
165.22,2.7515,0.3658,2.5976,9.315,35.7253
165.44,2.7554,0.366,2.6282,9.3456,35.7376
165.66,2.759,0.3658,2.6583,9.3757,35.7246
165.88,2.7625,0.3657,2.6878,9.4052,35.71
166.1,2.7665,0.3658,2.7192,9.4366,35.7181
166.32,2.77,0.3657,2.7484,9.4658,35.7129
166.54,2.7737,0.3656,2.7785,9.4959,35.7009
166.76,2.7777,0.3659,2.8105,9.5279,35.7298
166.98,2.781,0.3655,2.8387,9.5561,35.6974
167.2,2.7848,0.3654,2.8701,9.5875,35.6873
167.42,2.7888,0.3656,2.901,9.6184,35.7016
167.64,2.792,0.3653,2.93,9.6474,35.6774
167.86,2.796,0.3655,2.9616,9.679,35.6972
168.08,2.7998,0.3655,2.9923,9.7097,35.6887
168.3,2.803,0.3651,3.0204,9.7378,35.6513
168.52,2.8071,0.3654,3.053,9.7704,35.68
168.74,2.8105,0.3651,3.0821,9.7995,35.6501
168.96,2.814,0.365,3.1116,9.829,35.6406
169.18,2.8179,0.3651,3.1437,9.8611,35.6537
169.4,2.8213,0.3648,3.1722,9.8896,35.6266
169.62,2.8249,0.3647,3.2035,9.9209,35.6158
169.84,2.8287,0.3648,3.2346,9.952,35.6232
170.06,2.8321,0.3644,3.264,9.9814,35.5858
170.28,2.836,0.3644,3.2954,10.0128,35.5905
170.5,2.8397,0.3645,3.3262,10.0436,35.5976
170.72,2.8431,0.3644,3.3563,10.0737,35.5865
170.94,2.8471,0.3643,3.388,10.1054,35.5742
171.16,2.8506,0.3643,3.4184,10.1358,35.5734
171.38,2.8542,0.3641,3.4492,10.1666,35.556
171.6,2.8582,0.3642,3.4815,10.1989,35.5675
171.82,2.8616,0.364,3.5112,10.2286,35.5513
172.04,2.8654,0.364,3.5425,10.2599,35.5432
172.26,2.8694,0.3642,3.5749,10.2923,35.5702
172.48,2.8726,0.3639,3.6038,10.3212,35.5383
172.7,2.8766,0.3639,3.6362,10.3536,35.5359
172.92,2.8805,0.3641,3.6686,10.386,35.5586
173.14,2.8836,0.3637,3.697,10.4144,35.5208
173.36,2.8877,0.3638,3.7301,10.4475,35.5281
173.58,2.8913,0.3638,3.7609,10.4783,35.5298
173.8,2.8946,0.3634,3.7899,10.5073,35.4877
174.02,2.8987,0.3636,3.8228,10.5402,35.5076
174.24,2.902,0.3634,3.8524,10.5698,35.4838
174.46,2.9056,0.3633,3.884,10.6014,35.4788
174.68,2.9095,0.3633,3.9159,10.6333,35.4741
174.9,2.9128,0.3629,3.9458,10.6632,35.4408
175.12,2.9166,0.363,3.9774,10.6948,35.4466
175.34,2.9204,0.363,4.0095,10.7269,35.4501
175.56,2.9238,0.3627,4.0389,10.7563,35.4194
175.78,2.9277,0.3626,4.0721,10.7895,35.4141
176,2.9313,0.3627,4.1031,10.8205,35.4207
176.22,2.9348,0.3626,4.134,10.8514,35.4093
176.44,2.9388,0.3627,4.1667,10.8841,35.4177
176.66,2.9423,0.3625,4.1973,10.9147,35.4051
176.88,2.946,0.3624,4.229,10.9464,35.3917
177.1,2.95,0.3625,4.262,10.9794,35.4052
177.32,2.9533,0.3623,4.2921,11.0095,35.3829
177.54,2.9571,0.3622,4.324,11.0414,35.373
177.76,2.9612,0.3625,4.3574,11.0748,35.3991
177.98,2.9643,0.3622,4.3866,11.104,35.3666
178.2,2.9683,0.3622,4.4201,11.1375,35.3755
178.42,2.9721,0.3623,4.4519,11.1693,35.3772
178.64,2.9753,0.362,4.4816,11.199,35.3477
178.86,2.9794,0.3621,4.5152,11.2326,35.3574
179.08,2.9829,0.3619,4.5462,11.2636,35.3442
179.3,2.9863,0.3616,4.5764,11.2938,35.3095
179.52,2.9903,0.3618,4.6101,11.3275,35.3295
179.74,2.9936,0.3615,4.6398,11.3572,35.3008
179.96,2.9973,0.3615,4.6718,11.3892,35.2984
180.18,3.0011,0.3615,4.7041,11.4215,35.3035
180.4,3.0045,0.3612,4.7346,11.452,35.277
180.62,3.0083,0.3612,4.7672,11.4846,35.2772
180.84,3.012,0.3612,4.7991,11.5165,35.2772
181.06,3.0155,0.361,4.8306,11.548,35.258
181.28,3.0194,0.361,4.8632,11.5806,35.2558
181.5,3.023,0.361,4.895,11.6124,35.2518
181.72,3.0265,0.3608,4.926,11.6434,35.2371
181.94,3.0305,0.361,4.9599,11.6773,35.2522
182.16,3.0339,0.3607,4.9903,11.7077,35.2258
182.38,3.0377,0.3607,5.0224,11.7398,35.2278
182.6,3.0417,0.3608,5.0559,11.7733,35.2384
182.82,3.045,0.3606,5.0867,11.8041,35.2135
183.04,3.0489,0.3606,5.1192,11.8366,35.2105
183.26,3.0529,0.3607,5.1527,11.8701,35.2277
183.48,3.056,0.3603,5.1826,11.9,35.1867
183.7,3.0601,0.3606,5.2161,11.9335,35.2107
183.92,3.0638,0.3605,5.2483,11.9657,35.2065
184.14,3.067,0.3601,5.2784,11.9958,35.1657
184.36,3.0711,0.3604,5.3127,12.0301,35.1931
184.58,3.0745,0.3601,5.343,12.0604,35.1664
184.8,3.0779,0.3599,5.3747,12.0921,35.1436
185.02,3.0819,0.36,5.4075,12.1249,35.1583
185.24,3.0852,0.3598,5.4383,12.1557,35.1363
185.46,3.0889,0.3596,5.4705,12.1879,35.1152
185.68,3.0927,0.3597,5.5031,12.2205,35.1285
185.9,3.0961,0.3594,5.5336,12.251,35.0998
186.12,3.1,0.3595,5.5671,12.2845,35.1104
186.34,3.1037,0.3594,5.5991,12.3165,35.0975
186.56,3.1071,0.3593,5.6301,12.3475,35.0836
186.78,3.1111,0.3593,5.664,12.3814,35.0908
187,3.1146,0.3591,5.6953,12.4127,35.0724
187.22,3.1182,0.3591,5.7272,12.4446,35.0635
187.44,3.1223,0.3591,5.7611,12.4785,35.0727
187.66,3.1256,0.359,5.7919,12.5093,35.0594
187.88,3.1294,0.3589,5.8246,12.542,35.0453
188.1,3.1335,0.3593,5.8582,12.5756,35.0856
188.32,3.1366,0.3588,5.8879,12.6053,35.0423
188.54,3.1406,0.3589,5.922,12.6394,35.0505
188.76,3.1445,0.3589,5.9549,12.6723,35.0506
188.98,3.1476,0.3586,5.9848,12.7022,35.0192
189.2,3.1517,0.3588,6.0188,12.7362,35.0431
189.42,3.1552,0.3586,6.0505,12.7679,35.0236
189.64,3.1586,0.3584,6.0813,12.7987,34.9996
189.86,3.1626,0.3586,6.1152,12.8326,35.0216
190.08,3.166,0.3584,6.1457,12.8631,35.0034
190.3,3.1696,0.3582,6.1775,12.8949,34.9808
190.52,3.1735,0.3582,6.2107,12.9281,34.9853
190.74,3.1768,0.3581,6.2418,12.9592,34.9721
190.96,3.1806,0.3581,6.2746,12.992,34.9739
191.18,3.1844,0.3581,6.3075,13.0249,34.9709
191.4,3.1878,0.3578,6.3385,13.0559,34.946
191.62,3.1917,0.3579,6.3718,13.0892,34.9497
191.84,3.1953,0.3579,6.4037,13.1211,34.9498
192.06,3.1988,0.3576,6.4356,13.153,34.9245
192.28,3.2028,0.3579,6.4691,13.1865,34.9476
192.5,3.2063,0.3576,6.5009,13.2183,34.9259
192.72,3.21,0.3576,6.5331,13.2505,34.9212
192.94,3.214,0.3578,6.5669,13.2843,34.9377
193.16,3.2173,0.3575,6.5979,13.3153,34.9137
193.38,3.2212,0.3575,6.6305,13.3479,34.9074
193.6,3.2252,0.3578,6.6644,13.3818,34.9373
193.82,3.2284,0.3574,6.6952,13.4126,34.9018
194.04,3.2324,0.3576,6.7287,13.4461,34.922
194.26,3.2362,0.3575,6.7614,13.4788,34.9121
194.48,3.2393,0.3572,6.7914,13.5088,34.8786
194.7,3.2434,0.3573,6.8256,13.543,34.8919
194.92,3.2468,0.3571,6.8571,13.5745,34.8732
195.14,3.2503,0.357,6.8882,13.6056,34.8603
195.36,3.2543,0.3572,6.9224,13.6398,34.8814
195.58,3.2576,0.3569,6.953,13.6704,34.8579
195.8,3.2613,0.3568,6.9857,13.7031,34.8458
196.02,3.2651,0.3569,7.0184,13.7358,34.8487
196.24,3.2685,0.3567,7.0497,13.7671,34.8297
196.46,3.2723,0.3568,7.0829,13.8003,34.8404
196.68,3.276,0.3566,7.1155,13.8329,34.8203
196.9,3.2794,0.3566,7.1466,13.864,34.8211
197.12,3.2834,0.3565,7.1804,13.8978,34.8166
197.34,3.287,0.3564,7.2123,13.9297,34.8092
197.56,3.2905,0.3564,7.2442,13.9616,34.8071
197.78,3.2945,0.3565,7.278,13.9954,34.8144
198,3.298,0.3563,7.3094,14.0268,34.7965
198.22,3.3017,0.3563,7.3417,14.0591,34.7994
198.44,3.3057,0.3564,7.3761,14.0935,34.8075
198.66,3.309,0.3562,7.4062,14.1236,34.7859
198.88,3.3129,0.3563,7.4399,14.1573,34.7914
199.1,3.3169,0.3565,7.4736,14.191,34.8145
199.32,3.32,0.3562,7.5033,14.2207,34.7808
199.54,3.324,0.3562,7.5375,14.2549,34.7849
199.76,3.3277,0.3563,7.5693,14.2867,34.7903
199.98,3.331,0.3559,7.6003,14.3177,34.7532
200.2,3.3351,0.3561,7.6342,14.3516,34.7763
200.42,3.3384,0.356,7.6654,14.3828,34.7631
200.64,3.3419,0.3558,7.697,14.4144,34.75
200.86,3.3459,0.3559,7.731,14.4484,34.7552
201.08,3.3492,0.3557,7.7618,14.4792,34.7361
201.3,3.353,0.3556,7.7944,14.5118,34.725
201.52,3.3568,0.3556,7.827,14.5444,34.7287
201.74,3.3601,0.3554,7.8583,14.5757,34.7107
201.96,3.364,0.3554,7.8914,14.6088,34.705
202.18,3.3676,0.3553,7.9236,14.641,34.7019
202.4,3.3711,0.3552,7.9553,14.6727,34.6879
202.62,3.3751,0.3554,7.9888,14.7062,34.7118
202.84,3.3786,0.3553,8.0202,14.7376,34.697
203.06,3.3823,0.3552,8.0523,14.7697,34.6876
203.28,3.3862,0.3554,8.0868,14.8042,34.7028
203.5,3.3896,0.3552,8.1173,14.8347,34.6897
203.72,3.3934,0.3552,8.1504,14.8678,34.6878
203.94,3.3975,0.3555,8.1842,14.9016,34.7125
204.16,3.4007,0.3551,8.2143,14.9317,34.6798
204.38,3.4046,0.3552,8.2483,14.9657,34.6852
204.6,3.4085,0.3554,8.281,14.9984,34.7078
204.82,3.4116,0.3551,8.3116,15.029,34.6732
205.04,3.4158,0.3552,8.3452,15.0626,34.6899
205.26,3.4192,0.355,8.3773,15.0947,34.6722
205.48,3.4226,0.3549,8.4079,15.1253,34.66
205.7,3.4266,0.355,8.4415,15.1589,34.6719
205.92,3.43,0.3549,8.4724,15.1898,34.6545
206.14,3.4336,0.3548,8.5048,15.2222,34.6482
206.36,3.4375,0.3548,8.5379,15.2553,34.6531
206.58,3.4408,0.3546,8.5685,15.2859,34.6323
206.8,3.4446,0.3547,8.6015,15.3189,34.6363
207.02,3.4483,0.3547,8.6339,15.3513,34.6361
207.24,3.4518,0.3545,8.6654,15.3828,34.6177
207.46,3.4557,0.3546,8.6985,15.4159,34.6262
207.68,3.4593,0.3545,8.7302,15.4476,34.62
207.9,3.4629,0.3543,8.7621,15.4795,34.6044
208.12,3.4668,0.3546,8.7955,15.5129,34.6263
208.34,3.4703,0.3544,8.8273,15.5447,34.6101
208.56,3.474,0.3543,8.8593,15.5767,34.6035
208.78,3.478,0.3545,8.8934,15.6108,34.6178
209,3.4813,0.3544,8.9238,15.6412,34.6076
209.22,3.4852,0.3544,8.9569,15.6743,34.6094
209.44,3.4892,0.3546,8.9904,15.7078,34.6302
209.66,3.4923,0.3542,9.0199,15.7373,34.5908
209.88,3.4964,0.3543,9.054,15.7714,34.6007
210.1,3.5001,0.3545,9.0868,15.8042,34.6164
210.32,3.5033,0.3542,9.1163,15.8337,34.5913
210.54,3.5074,0.3544,9.1506,15.868,34.6088
210.76,3.5108,0.3542,9.1813,15.8987,34.591
210.98,3.5143,0.3541,9.2127,15.9301,34.5756
211.2,3.5182,0.3541,9.2461,15.9635,34.5839
211.42,3.5216,0.3541,9.2767,15.9941,34.5798
211.64,3.5253,0.3539,9.3086,16.026,34.5622
211.86,3.5291,0.354,9.3414,16.0588,34.5709
212.08,3.5325,0.3539,9.3727,16.0901,34.5614
212.3,3.5363,0.3539,9.405,16.1224,34.5612
212.52,3.54,0.3538,9.4377,16.1551,34.5556
212.74,3.5435,0.3537,9.4682,16.1856,34.542
212.96,3.5474,0.3538,9.5019,16.2193,34.5549
213.18,3.5509,0.3538,9.5334,16.2508,34.55
213.4,3.5545,0.3537,9.5652,16.2826,34.541
213.62,3.5585,0.3539,9.599,16.3164,34.56
213.84,3.5619,0.3536,9.6295,16.3469,34.5277
214.06,3.5657,0.3537,9.6618,16.3792,34.5418
214.28,3.5697,0.3539,9.6954,16.4128,34.556
214.5,3.573,0.3537,9.7256,16.443,34.5426
214.72,3.5769,0.3537,9.7585,16.4759,34.545
214.94,3.5809,0.354,9.7921,16.5095,34.5664
215.16,3.584,0.3536,9.8214,16.5388,34.5331
215.38,3.588,0.3537,9.8552,16.5726,34.5454
215.6,3.5917,0.3538,9.8875,16.6049,34.5469
215.82,3.595,0.3535,9.9173,16.6347,34.5239
216.04,3.5991,0.3537,9.9517,16.6691,34.5403
216.26,3.6024,0.3536,9.9822,16.6996,34.5353
216.48,3.6059,0.3533,10.0135,16.7309,34.5022
216.7,3.6099,0.3536,10.0463,16.7637,34.5306
216.92,3.6132,0.3534,10.0769,16.7943,34.5107
217.14,3.617,0.3534,10.1092,16.8266,34.5075
217.36,3.6207,0.3534,10.1415,16.8589,34.5097
217.58,3.6241,0.3532,10.1721,16.8895,34.495
217.8,3.628,0.3533,10.2053,16.9227,34.5066
218.02,3.6317,0.3533,10.2368,16.9542,34.5025
218.24,3.6351,0.3532,10.2679,16.9853,34.4924
218.46,3.6391,0.3533,10.3018,17.0192,34.5055
218.68,3.6426,0.3532,10.3327,17.0501,34.4917
218.9,3.6463,0.3532,10.3645,17.0819,34.4954
219.12,3.6503,0.3533,10.3982,17.1156,34.5049
219.34,3.6536,0.3531,10.4286,17.146,34.4844
219.56,3.6575,0.3532,10.4608,17.1782,34.4961
219.78,3.6615,0.3534,10.4947,17.2121,34.5072
220,3.6647,0.3531,10.5241,17.2415,34.4843
220.22,3.6687,0.3533,10.5576,17.275,34.5055
220.44,3.6725,0.3535,10.5897,17.3071,34.5176
220.66,3.6756,0.3531,10.6194,17.3368,34.4868
220.88,3.6797,0.3533,10.6536,17.371,34.5007
221.1,3.6832,0.3533,10.6843,17.4017,34.498
221.32,3.6866,0.3531,10.7152,17.4326,34.4776
221.54,3.6906,0.3531,10.7483,17.4657,34.4863
221.76,3.694,0.3531,10.779,17.4964,34.4836
221.98,3.6976,0.3529,10.8105,17.5279,34.465
222.2,3.7015,0.3532,10.8436,17.561,34.4899
222.42,3.7048,0.3529,10.8739,17.5913,34.4658
222.64,3.7086,0.3528,10.9066,17.624,34.4548
222.86,3.7124,0.353,10.9385,17.6559,34.4704
223.08,3.7158,0.3529,10.9694,17.6868,34.4599
223.3,3.7197,0.353,11.0028,17.7202,34.4752
223.52,3.7233,0.353,11.0338,17.7512,34.4737
223.74,3.7269,0.3529,11.0653,17.7827,34.46
223.96,3.7308,0.3531,11.0984,17.8158,34.4788
224.18,3.7343,0.3529,11.1297,17.8471,34.4656
224.4,3.738,0.353,11.1616,17.879,34.475
224.62,3.742,0.3531,11.1952,17.9126,34.4862
224.84,3.7453,0.353,11.2253,17.9427,34.4709
225.06,3.7492,0.3529,11.2576,17.975,34.4676
225.28,3.7532,0.3533,11.2919,18.0093,34.5002
225.5,3.7564,0.3529,11.3208,18.0382,34.4639
225.72,3.7603,0.3531,11.3544,18.0718,34.4846
225.94,3.7642,0.3532,11.3867,18.1041,34.496
226.16,3.7673,0.353,11.4163,18.1337,34.47
226.38,3.7714,0.3532,11.4503,18.1677,34.4897
226.6,3.7749,0.353,11.4805,18.1979,34.4765
226.82,3.7783,0.3528,11.5115,18.2289,34.4502
227.04,3.7823,0.3531,11.5443,18.2617,34.487
227.26,3.7856,0.3529,11.5749,18.2923,34.4601
227.48,3.7893,0.3529,11.6067,18.3241,34.4585
227.7,3.7931,0.3529,11.6392,18.3566,34.4596
227.92,3.7964,0.3527,11.6698,18.3872,34.44
228.14,3.8003,0.3528,11.7021,18.4195,34.45
228.36,3.804,0.3528,11.7338,18.4512,34.4525
228.58,3.8075,0.3526,11.7642,18.4816,34.437
228.8,3.8114,0.3528,11.7975,18.5149,34.4557
229.02,3.815,0.3527,11.8284,18.5458,34.4396
229.24,3.8185,0.3527,11.86,18.5774,34.4398
229.46,3.8225,0.3529,11.8931,18.6105,34.4603
229.68,3.826,0.3528,11.9241,18.6415,34.4508
229.9,3.8297,0.3528,11.9562,18.6736,34.4555
230.12,3.8338,0.353,11.9898,18.7072,34.4749
230.34,3.837,0.3529,12.019,18.7364,34.4581
230.56,3.8409,0.3528,12.0521,18.7695,34.4523
230.78,3.8449,0.3531,12.0854,18.8028,34.4831
231,3.848,0.3527,12.1143,18.8317,34.4436
231.22,3.8521,0.3531,12.148,18.8654,34.4804
231.44,3.8557,0.3529,12.1794,18.8968,34.4622
231.66,3.8589,0.3526,12.2091,18.9265,34.4366
231.88,3.863,0.353,12.2429,18.9603,34.4729
232.1,3.8664,0.3529,12.273,18.9904,34.4652
232.32,3.8699,0.3528,12.3042,19.0216,34.4507
232.54,3.8738,0.3529,12.3368,19.0542,34.4637
232.76,3.8772,0.3527,12.3676,19.085,34.4397
232.98,3.8809,0.3526,12.3992,19.1166,34.4335
233.2,3.8847,0.3528,12.4316,19.149,34.4519
233.42,3.8881,0.3527,12.4619,19.1793,34.4438
233.64,3.892,0.3526,12.495,19.2124,34.4336
233.86,3.8957,0.3528,12.5268,19.2442,34.449
234.08,3.8992,0.3526,12.5576,19.275,34.4311
234.3,3.9031,0.3528,12.5908,19.3082,34.4505
234.52,3.9067,0.3528,12.6219,19.3393,34.4496
234.74,3.9103,0.3527,12.6533,19.3707,34.4479
234.96,3.9143,0.3529,12.6866,19.404,34.4633
235.18,3.9177,0.3528,12.717,19.4344,34.4551
235.4,3.9215,0.3529,12.7498,19.4672,34.4599
235.62,3.9255,0.3531,12.7826,19.5,34.4787
235.84,3.9287,0.3528,12.8128,19.5302,34.4557
236.06,3.9327,0.353,12.8457,19.5631,34.4701
236.28,3.9365,0.353,12.8782,19.5956,34.4766
236.5,3.9396,0.3528,12.9075,19.6249,34.4486
236.72,3.9438,0.3529,12.9411,19.6585,34.4664
236.94,3.9473,0.353,12.9724,19.6898,34.471
237.16,3.9506,0.3528,13.0029,19.7203,34.4495
237.38,3.9546,0.353,13.0363,19.7537,34.4764
237.6,3.9579,0.3529,13.067,19.7844,34.4596
237.82,3.9616,0.3528,13.0988,19.8162,34.4541
238.04,3.9655,0.3529,13.1318,19.8492,34.4622
238.26,3.9688,0.3527,13.1623,19.8797,34.4416
238.48,3.9726,0.3528,13.195,19.9124,34.4567
238.7,3.9764,0.3529,13.2272,19.9446,34.4612
238.92,3.9798,0.3527,13.2584,19.9758,34.4452
239.14,3.9837,0.3529,13.2918,20.0092,34.4606
239.36,3.9873,0.3529,13.3234,20.0408,34.465
239.58,3.9908,0.3528,13.3552,20.0726,34.4525
239.8,3.9948,0.353,13.3891,20.1065,34.4697
240.02,3.9983,0.3528,13.4196,20.137,34.4572
240.24,4.002,0.3529,13.4519,20.1693,34.459
240.46,4.006,0.3531,13.4859,20.2033,34.4805
240.68,4.0093,0.353,13.5156,20.233,34.472
240.9,4.0132,0.353,13.5482,20.2656,34.4742
241.12,4.0172,0.3532,13.5802,20.2976,34.4928
241.34,4.0203,0.353,13.6087,20.3261,34.4717
241.56,4.0244,0.3531,13.6418,20.3592,34.4819
241.78,4.0282,0.3532,13.6734,20.3908,34.4929
242,4.0313,0.3529,13.7032,20.4206,34.4621
242.22,4.0354,0.3532,13.7365,20.4539,34.4913
242.44,4.0388,0.353,13.7667,20.4841,34.4765
242.66,4.0423,0.3529,13.7973,20.5147,34.4667
242.88,4.0463,0.3531,13.8301,20.5475,34.4779
243.1,4.0495,0.3529,13.8605,20.5779,34.4664
243.32,4.0532,0.353,13.8925,20.6099,34.4709
243.54,4.0571,0.3531,13.9257,20.6431,34.4795
243.76,4.0605,0.3529,13.9569,20.6743,34.4605
243.98,4.0643,0.353,13.9908,20.7082,34.4729
244.2,4.068,0.3529,14.024,20.7414,34.4629
244.42,4.0715,0.3527,14.0564,20.7738,34.4449
244.64,4.0754,0.2846,14.7088,21.4262,27.7928
244.655,4.0756,0.3677,15.2251,21.9425,35.9096