File: data/ReportRaw/Resin_CSV/V4_Resin_Green/Tensile_Test_03.csv
Time,Displacement,Force,Tensile strain (Strain 1),,Tensile stress
(s),(mm),(kN),(%),,(MPa)
0,0,0.0001,-8.6744,0,0.0118
0.3,0.0033,0.0024,-8.6633,0.0111,0.2329
0.6,0.0088,0.0027,-8.6576,0.0168,0.2677
0.9,0.0136,0.0027,-8.6577,0.0167,0.2601
1.2,0.0189,0.003,-8.6559,0.0185,0.2933
1.5,0.0236,0.0029,-8.6542,0.0202,0.287
1.8,0.0283,0.0031,-8.6533,0.0211,0.3064
2.1,0.0335,0.0036,-8.6494,0.025,0.3539
2.4,0.0388,0.004,-8.6459,0.0285,0.3911
2.7,0.0436,0.0046,-8.6415,0.0329,0.4454
3,0.0488,0.0057,-8.6341,0.0403,0.5611
3.3,0.0541,0.0072,-8.6261,0.0483,0.7013
3.6,0.0585,0.0083,-8.617,0.0574,0.8118
3.9,0.0634,0.0098,-8.6078,0.0666,0.9557
4.2,0.0686,0.0108,-8.5999,0.0745,1.052
4.5,0.0735,0.0115,-8.5937,0.0807,1.1216
4.8,0.0786,0.0129,-8.5845,0.0899,1.2575
5.1,0.084,0.0144,-8.5737,0.1007,1.4067
5.4,0.0889,0.0154,-8.5651,0.1093,1.501
5.7,0.0936,0.0166,-8.5576,0.1168,1.6185
6,0.0987,0.0177,-8.5489,0.1255,1.73
6.3,0.1036,0.0185,-8.5413,0.1331,1.8084
6.6,0.1084,0.0194,-8.5348,0.1396,1.8963
6.9,0.1135,0.0205,-8.5272,0.1472,2.002
7.2,0.1189,0.0213,-8.5198,0.1546,2.0818
7.5,0.1237,0.0221,-8.5136,0.1608,2.1566
7.8,0.1287,0.023,-8.5068,0.1676,2.2464
8.1,0.134,0.024,-8.5001,0.1743,2.3412
8.4,0.1385,0.0244,-8.4948,0.1796,2.3827
8.7,0.1433,0.0251,-8.4895,0.1849,2.4514
9,0.1486,0.0259,-8.4826,0.1918,2.527
9.3,0.1537,0.0265,-8.4772,0.1972,2.5859
9.6,0.1586,0.0271,-8.4719,0.2025,2.6487
9.9,0.1639,0.028,-8.4655,0.2089,2.7385
10.2,0.1691,0.0288,-8.4593,0.2151,2.8091
10.5,0.1735,0.0291,-8.4556,0.2188,2.8412
10.8,0.1784,0.0296,-8.451,0.2234,2.886
11.1,0.1836,0.0302,-8.4454,0.229,2.9515
11.4,0.1885,0.0306,-8.4415,0.2329,2.9916
11.7,0.1935,0.0312,-8.4366,0.2378,3.0503
12,0.199,0.0321,-8.4305,0.2439,3.1366
12.3,0.2039,0.0325,-8.4263,0.2481,3.1763
12.6,0.2086,0.0329,-8.4222,0.2522,3.2108
12.9,0.2137,0.0337,-8.4169,0.2575,3.2878
13.2,0.2186,0.034,-8.4128,0.2616,3.3222
13.5,0.2234,0.0344,-8.4088,0.2656,3.3618
13.8,0.2285,0.0351,-8.4033,0.2711,3.4294
14.1,0.2339,0.0356,-8.3979,0.2765,3.4803
14.4,0.2387,0.0361,-8.3936,0.2808,3.5227
14.7,0.2437,0.0368,-8.3887,0.2857,3.5961
15,0.2491,0.0376,-8.382,0.2924,3.6751
15.3,0.2535,0.0379,-8.378,0.2964,3.7024
15.6,0.2584,0.0387,-8.3722,0.3022,3.7755
15.9,0.2636,0.0396,-8.3654,0.309,3.8656
16.2,0.2686,0.0404,-8.3592,0.3152,3.9413
16.5,0.2736,0.0411,-8.3527,0.3217,4.0129
16.8,0.279,0.0426,-8.3436,0.3308,4.1557
17.1,0.2841,0.0435,-8.3351,0.3393,4.2448
17.4,0.2886,0.0442,-8.329,0.3454,4.3164
17.7,0.2935,0.045,-8.3221,0.3523,4.3922
18,0.2986,0.0457,-8.3161,0.3583,4.4587
18.3,0.3034,0.0463,-8.3104,0.364,4.5181
18.6,0.3085,0.0471,-8.304,0.3704,4.5984
18.9,0.314,0.0482,-8.2965,0.3779,4.7049
19.2,0.3188,0.0487,-8.2911,0.3833,4.7528
19.5,0.3236,0.0493,-8.2851,0.3893,4.8109
19.8,0.329,0.0502,-8.2778,0.3966,4.9048
20.1,0.3336,0.0506,-8.2727,0.4017,4.9393
20.4,0.3384,0.0513,-8.2676,0.4068,5.0065
20.7,0.3435,0.052,-8.2612,0.4132,5.0794
21,0.3487,0.0525,-8.2552,0.4192,5.1266
21.3,0.3536,0.0531,-8.2495,0.4249,5.1831
21.6,0.3588,0.054,-8.2426,0.4318,5.2736
21.9,0.3641,0.0547,-8.2359,0.4385,5.3414
22.2,0.3685,0.0551,-8.2318,0.4426,5.3805
22.5,0.3734,0.0556,-8.2259,0.4485,5.4297
22.8,0.3786,0.0563,-8.2199,0.4545,5.498
23.1,0.3835,0.0568,-8.2141,0.4603,5.5497
23.4,0.3885,0.0576,-8.2085,0.4659,5.624
23.7,0.394,0.0586,-8.2007,0.4737,5.7185
24,0.399,0.0591,-8.1955,0.4789,5.7741
24.3,0.4036,0.0595,-8.1902,0.4842,5.8077
24.6,0.4087,0.0602,-8.1833,0.4911,5.875
24.9,0.4135,0.061,-8.1776,0.4968,5.9532
25.2,0.4184,0.0615,-8.1705,0.5039,6.0062
25.5,0.4235,0.0625,-8.1634,0.511,6.0991
25.8,0.4289,0.0636,-8.1543,0.5201,6.2139
26.1,0.4337,0.0643,-8.1476,0.5268,6.2807
26.4,0.4386,0.0651,-8.1403,0.5341,6.3579
26.7,0.444,0.0661,-8.1321,0.5423,6.4554
27,0.4485,0.0666,-8.1261,0.5483,6.5017
27.3,0.4534,0.0672,-8.1196,0.5548,6.5656
27.6,0.4586,0.0681,-8.1117,0.5627,6.6529
27.9,0.4637,0.0689,-8.1041,0.5703,6.7306
28.2,0.4686,0.0697,-8.0973,0.5771,6.8024
28.5,0.4739,0.0706,-8.0895,0.5849,6.8911
28.8,0.4791,0.0714,-8.0823,0.5921,6.9717
29.1,0.4835,0.0718,-8.0764,0.598,7.0069
29.4,0.4885,0.0723,-8.0707,0.6037,7.0639
29.7,0.4935,0.0731,-8.0629,0.6115,7.1356
30,0.4985,0.074,-8.0555,0.6189,7.2292
30.3,0.5035,0.0749,-8.047,0.6274,7.3167
30.6,0.509,0.0762,-8.038,0.6364,7.4379
30.9,0.5139,0.0769,-8.0302,0.6442,7.5074
31.2,0.5186,0.0774,-8.0239,0.6505,7.5591
31.5,0.5237,0.0785,-8.0158,0.6586,7.6624
31.8,0.5286,0.0791,-8.0085,0.6659,7.7276
32.1,0.5334,0.0799,-8.0017,0.6727,7.7989
32.4,0.5385,0.0807,-7.9938,0.6806,7.885
32.7,0.5438,0.0817,-7.9857,0.6887,7.9832
33,0.5487,0.0825,-7.979,0.6954,8.056
33.3,0.5538,0.0833,-7.9708,0.7036,8.1301
33.6,0.5591,0.0844,-7.9627,0.7117,8.2433
33.9,0.5635,0.0845,-7.9576,0.7168,8.2563
34.2,0.5684,0.0853,-7.9504,0.724,8.329
34.5,0.5736,0.0862,-7.9429,0.7315,8.4191
34.8,0.5786,0.0868,-7.9355,0.7389,8.4814
35.1,0.5835,0.0877,-7.9287,0.7457,8.5626
35.4,0.589,0.0887,-7.9204,0.754,8.663
35.7,0.594,0.0894,-7.9131,0.7613,8.7288
36,0.5986,0.0899,-7.9075,0.7669,8.7811
36.3,0.6036,0.0907,-7.9001,0.7743,8.8618
36.6,0.6086,0.0914,-7.8935,0.7809,8.9272
36.9,0.6134,0.0921,-7.8869,0.7875,8.9926
37.2,0.6185,0.0927,-7.8803,0.7941,9.0513
37.5,0.624,0.0937,-7.8718,0.8026,9.1474
37.8,0.6288,0.0943,-7.8658,0.8086,9.2056
38.1,0.6336,0.095,-7.8591,0.8153,9.2725
38.4,0.6389,0.0959,-7.8519,0.8225,9.366
38.7,0.6435,0.0963,-7.8454,0.829,9.4
39,0.6483,0.0968,-7.8395,0.8349,9.4575
39.3,0.6535,0.0977,-7.8318,0.8426,9.5378
39.6,0.6588,0.0986,-7.8245,0.8499,9.6289
39.9,0.6636,0.0992,-7.8179,0.8565,9.6918
40.2,0.6688,0.1001,-7.8103,0.8641,9.779
40.5,0.6741,0.1011,-7.8022,0.8722,9.8694
40.8,0.6786,0.1015,-7.7973,0.8771,9.9076
41.1,0.6834,0.102,-7.7902,0.8842,9.9634
41.4,0.6886,0.1029,-7.7826,0.8918,10.0499
41.7,0.6935,0.1037,-7.7753,0.8991,10.1244
42,0.6985,0.1044,-7.7682,0.9062,10.1916
42.3,0.704,0.1055,-7.7596,0.9148,10.3027
42.6,0.709,0.1062,-7.7523,0.9221,10.3663
42.9,0.7136,0.1066,-7.7464,0.928,10.4093
43.2,0.7187,0.1075,-7.7389,0.9355,10.4963
43.5,0.7236,0.1081,-7.7328,0.9416,10.5591
43.8,0.7284,0.1086,-7.7266,0.9478,10.6054
44.1,0.7335,0.1093,-7.72,0.9544,10.6773
44.4,0.7389,0.1102,-7.7114,0.963,10.7659
44.7,0.7437,0.1109,-7.7052,0.9692,10.8292
45,0.7487,0.1115,-7.6986,0.9758,10.8914
45.3,0.754,0.1123,-7.6909,0.9835,10.9647
45.6,0.7585,0.1127,-7.6854,0.989,11.0099
45.9,0.7634,0.1133,-7.6797,0.9947,11.0637
46.2,0.7686,0.1141,-7.6723,1.0021,11.1399
46.5,0.7737,0.1148,-7.665,1.0094,11.2118
46.8,0.7786,0.1154,-7.6586,1.0158,11.2656
47.1,0.7839,0.1165,-7.65,1.0244,11.3738
47.4,0.7891,0.1173,-7.6425,1.0319,11.4544
47.7,0.7935,0.1176,-7.6366,1.0378,11.4851
48,0.7985,0.1185,-7.6294,1.045,11.5683
48.3,0.8036,0.1193,-7.6217,1.0527,11.6533
48.6,0.8085,0.1199,-7.6144,1.06,11.705
48.9,0.8135,0.1207,-7.6069,1.0675,11.7889
49.2,0.819,0.1218,-7.5977,1.0767,11.8962
49.5,0.8238,0.1225,-7.5914,1.083,11.9618
49.8,0.8286,0.1232,-7.584,1.0904,12.0306
50.1,0.8338,0.1241,-7.5754,1.099,12.1171
50.4,0.8385,0.1246,-7.5685,1.1059,12.1699
50.7,0.8433,0.1254,-7.5614,1.113,12.2462
51,0.8485,0.1263,-7.5535,1.1209,12.3302
51.3,0.8538,0.1271,-7.5441,1.1303,12.4131
51.6,0.8586,0.1277,-7.5374,1.137,12.4714
51.9,0.8638,0.1287,-7.5288,1.1456,12.5702
52.2,0.8691,0.1297,-7.5199,1.1545,12.6683
52.5,0.8735,0.1301,-7.5144,1.16,12.7055
52.8,0.8784,0.1308,-7.5069,1.1675,12.777
53.1,0.8836,0.1317,-7.4985,1.1759,12.8596
53.4,0.8886,0.1325,-7.4902,1.1842,12.9371
53.7,0.8935,0.1332,-7.4829,1.1915,13.0069
54,0.899,0.1344,-7.4732,1.2012,13.1298
54.3,0.904,0.135,-7.4659,1.2085,13.1855
54.6,0.9085,0.1355,-7.459,1.2154,13.2283
54.9,0.9136,0.1365,-7.4513,1.2231,13.329
55.2,0.9186,0.1371,-7.443,1.2314,13.3861
55.5,0.9234,0.1378,-7.4358,1.2386,13.4614
55.8,0.9285,0.1387,-7.4276,1.2468,13.5446
56.1,0.934,0.1398,-7.4181,1.2563,13.6545
56.4,0.9387,0.1403,-7.4108,1.2636,13.7018
56.7,0.9437,0.1412,-7.4027,1.2717,13.7861
57,0.9489,0.1421,-7.3938,1.2806,13.8805
57.3,0.9536,0.1427,-7.3864,1.288,13.9353
57.6,0.9583,0.1435,-7.379,1.2954,14.0136
57.9,0.9635,0.1443,-7.3699,1.3045,14.0928
58.2,0.9687,0.1453,-7.3605,1.3139,14.1856
58.5,0.9736,0.146,-7.3527,1.3217,14.2578
58.8,0.9789,0.1472,-7.3434,1.331,14.3773
59.1,0.9841,0.148,-7.3342,1.3402,14.4504
59.4,0.9886,0.1485,-7.3269,1.3475,14.5047
59.7,0.9934,0.1491,-7.3198,1.3546,14.563
60,0.9986,0.1501,-7.3106,1.3638,14.6605
60.3,1.0035,0.1509,-7.3026,1.3718,14.736
60.6,1.0085,0.1517,-7.2939,1.3805,14.812
60.9,1.014,0.1528,-7.2836,1.3908,14.9231
61.2,1.0189,0.1534,-7.2757,1.3987,14.9826
61.5,1.0236,0.1542,-7.2682,1.4062,15.0549
61.8,1.0287,0.155,-7.2597,1.4147,15.1396
62.1,1.0336,0.1557,-7.2509,1.4235,15.2024
62.4,1.0384,0.1565,-7.2429,1.4315,15.2814
62.7,1.0436,0.1576,-7.2327,1.4417,15.3933
63,1.0489,0.1587,-7.2226,1.4518,15.5005
63.3,1.0537,0.1595,-7.2137,1.4607,15.5752
63.6,1.0587,0.1605,-7.2038,1.4706,15.6769
63.9,1.0641,0.1617,-7.1934,1.481,15.7894
64.2,1.0685,0.1623,-7.1857,1.4887,15.8459
64.5,1.0733,0.163,-7.1774,1.497,15.9222
64.8,1.0786,0.164,-7.1666,1.5078,16.0134
65.1,1.0836,0.1649,-7.1576,1.5168,16.099
65.4,1.0885,0.1658,-7.1482,1.5262,16.1881
65.7,1.0939,0.1669,-7.1379,1.5365,16.3009
66,1.0991,0.1679,-7.1281,1.5463,16.3992
66.3,1.1035,0.1684,-7.1205,1.5539,16.4476
66.6,1.1085,0.1692,-7.1112,1.5632,16.5212
66.9,1.1136,0.1702,-7.1021,1.5723,16.6183
67.2,1.1184,0.1709,-7.0933,1.5811,16.6885
67.5,1.1235,0.1718,-7.0836,1.5908,16.7765
67.8,1.129,0.1729,-7.0726,1.6018,16.8852
68.1,1.1338,0.1737,-7.0644,1.61,16.9605
68.4,1.1386,0.1744,-7.0559,1.6185,17.0313
68.7,1.1438,0.1754,-7.0459,1.6285,17.1261
69,1.1485,0.1759,-7.0377,1.6367,17.174
69.3,1.1534,0.1766,-7.03,1.6444,17.2447
69.6,1.1585,0.1775,-7.02,1.6544,17.3314
69.9,1.1638,0.1785,-7.0102,1.6642,17.4296
70.2,1.1687,0.1791,-7.0024,1.672,17.4935
70.5,1.1738,0.1798,-6.9932,1.6812,17.5591
70.8,1.1791,0.1797,-6.9899,1.6845,17.5463
71.1,1.1836,0.1767,-7.0034,1.671,17.2607
71.4,1.1884,0.1778,-6.995,1.6794,17.3641
71.7,1.1936,0.1793,-6.9835,1.6909,17.5058
72,1.1986,0.1803,-6.9735,1.7009,17.6088
72.3,1.2035,0.1815,-6.9627,1.7117,17.7248
72.6,1.209,0.1829,-6.9509,1.7235,17.8565
72.9,1.214,0.1839,-6.9405,1.7339,17.9548
73.2,1.2186,0.1847,-6.931,1.7434,18.0331
73.5,1.2236,0.1857,-6.9206,1.7538,18.1343
73.8,1.2286,0.1866,-6.9106,1.7638,18.2272
74.1,1.2334,0.1874,-6.9012,1.7732,18.3041
74.4,1.2385,0.1885,-6.89,1.7844,18.408
74.7,1.2439,0.1898,-6.8782,1.7962,18.5332
75,1.2487,0.1905,-6.8684,1.806,18.6038
75.3,1.2536,0.1915,-6.8582,1.8162,18.6988
75.6,1.259,0.1926,-6.8467,1.8277,18.8058
75.9,1.2635,0.1932,-6.838,1.8364,18.8698
76.2,1.2684,0.1942,-6.8283,1.8461,18.9624
76.5,1.2736,0.195,-6.8167,1.8577,19.0463
76.8,1.2787,0.1962,-6.8065,1.8679,19.1612
77.1,1.2836,0.197,-6.7961,1.8783,19.2361
77.4,1.2889,0.1981,-6.7847,1.8897,19.349
77.7,1.2941,0.1992,-6.7737,1.9007,19.4494
78,1.2985,0.1997,-6.7651,1.9093,19.5053
78.3,1.3035,0.2005,-6.7547,1.9197,19.5843
78.6,1.3086,0.2015,-6.7439,1.9305,19.6761
78.9,1.3135,0.2022,-6.7344,1.94,19.7492
79.2,1.3185,0.2032,-6.7229,1.9515,19.8451
79.5,1.324,0.2044,-6.711,1.9634,19.9623
79.8,1.3289,0.2053,-6.7007,1.9737,20.0467
80.1,1.3336,0.206,-6.6914,1.983,20.116
80.4,1.3388,0.2071,-6.6799,1.9945,20.2262
80.7,1.3436,0.2077,-6.6702,2.0042,20.2831
81,1.3484,0.2085,-6.6598,2.0146,20.3618
81.3,1.3535,0.2095,-6.6486,2.0258,20.4612
81.6,1.3589,0.2105,-6.6372,2.0372,20.5598
81.9,1.3637,0.2112,-6.6267,2.0477,20.6248
82.2,1.3687,0.2122,-6.6165,2.0579,20.7248
82.5,1.3741,0.2133,-6.6042,2.0702,20.8286
82.8,1.3785,0.2138,-6.5961,2.0783,20.8778
83.1,1.3834,0.2145,-6.5853,2.0891,20.9505
83.4,1.3886,0.2154,-6.574,2.1004,21.0395
83.7,1.3936,0.2163,-6.5632,2.1112,21.1266
84,1.3986,0.217,-6.5523,2.1221,21.1931
84.3,1.4039,0.2182,-6.5403,2.1341,21.311
84.6,1.4091,0.2192,-6.5283,2.1461,21.4048
84.9,1.4136,0.2197,-6.5198,2.1546,21.4561
85.2,1.4185,0.2205,-6.5089,2.1655,21.531
85.5,1.4236,0.2213,-6.4982,2.1762,21.6132
85.8,1.4284,0.222,-6.4875,2.1869,21.6762
86.1,1.4335,0.2229,-6.4764,2.198,21.7694
86.4,1.439,0.2241,-6.4636,2.2108,21.8826
86.7,1.4438,0.2248,-6.4537,2.2207,21.9519
87,1.4486,0.2255,-6.4431,2.2313,22.0232
87.3,1.4539,0.2266,-6.4313,2.2431,22.1251
87.6,1.4585,0.2271,-6.4218,2.2526,22.1766
87.9,1.4634,0.2278,-6.411,2.2634,22.2447
88.2,1.4685,0.2287,-6.3995,2.2749,22.3307
88.5,1.4738,0.2297,-6.3875,2.2869,22.4344
88.8,1.4786,0.2304,-6.3773,2.2971,22.5036
89.1,1.4838,0.2312,-6.3653,2.3091,22.5784
89.4,1.4891,0.2323,-6.3534,2.321,22.6849
89.7,1.4935,0.2327,-6.3442,2.3302,22.7241
90,1.4984,0.2333,-6.3337,2.3407,22.7864
90.3,1.5036,0.2342,-6.3219,2.3525,22.8744
90.6,1.5085,0.235,-6.3112,2.3632,22.9447
90.9,1.5135,0.2359,-6.2998,2.3746,23.0386
91.2,1.519,0.237,-6.287,2.3874,23.1409
91.5,1.5239,0.2375,-6.2763,2.3981,23.197
91.8,1.5286,0.2382,-6.2659,2.4085,23.2574
92.1,1.5337,0.239,-6.2545,2.4199,23.3445
92.4,1.5386,0.2397,-6.2437,2.4307,23.4085
92.7,1.5434,0.2404,-6.2329,2.4415,23.4805
93,1.5485,0.2412,-6.2213,2.4531,23.5531
93.3,1.5539,0.2422,-6.2086,2.4658,23.6546
93.6,1.5587,0.2428,-6.1982,2.4762,23.7122
93.9,1.5637,0.2437,-6.1864,2.488,23.7948
94.2,1.569,0.2446,-6.1742,2.5002,23.8883
94.5,1.5735,0.245,-6.1646,2.5098,23.9259
94.8,1.5783,0.2456,-6.1532,2.5212,23.9857
95.1,1.5836,0.2465,-6.1414,2.533,24.0685
95.4,1.5887,0.2473,-6.1296,2.5448,24.1478
95.7,1.5936,0.248,-6.1183,2.5561,24.2178
96,1.599,0.2489,-6.1056,2.5688,24.3046
96.3,1.6041,0.2497,-6.0935,2.5809,24.3893
96.6,1.6085,0.25,-6.0845,2.5899,24.4178
96.9,1.6135,0.2506,-6.0738,2.6006,24.4755
97.2,1.6186,0.2512,-6.0632,2.6112,24.5356
97.5,1.6235,0.2508,-6.0581,2.6163,24.4888
97.8,1.6285,0.2439,-6.0943,2.5801,23.8167
98.1,1.634,0.2452,-6.0866,2.5878,23.9422
98.4,1.6389,0.2463,-6.0759,2.5985,24.0507
98.7,1.6436,0.2472,-6.0654,2.609,24.1445
99,1.6487,0.2485,-6.0519,2.6225,24.2635
99.3,1.6536,0.2493,-6.0404,2.634,24.3464
99.6,1.6584,0.2502,-6.0288,2.6456,24.4377
99.9,1.6635,0.2513,-6.0156,2.6588,24.5387
100.2,1.6689,0.2524,-6.0021,2.6723,24.652
100.5,1.6737,0.2533,-5.9897,2.6847,24.7393
100.8,1.6787,0.2544,-5.9765,2.6979,24.8402
101.1,1.6841,0.2555,-5.9625,2.7119,24.9491
101.4,1.6885,0.256,-5.951,2.7234,24.9995
101.7,1.6934,0.2569,-5.9394,2.735,25.0846
102,1.6985,0.2578,-5.9255,2.7489,25.176
102.3,1.7036,0.2587,-5.913,2.7614,25.2639
102.6,1.7086,0.2593,-5.8995,2.7749,25.3246
102.9,1.714,0.2608,-5.8855,2.7889,25.4641
103.2,1.7191,0.2615,-5.872,2.8024,25.5374
103.5,1.7235,0.262,-5.8606,2.8138,25.5878
103.8,1.7286,0.2628,-5.8473,2.8271,25.6668
104.1,1.7336,0.2638,-5.8339,2.8405,25.7581
104.4,1.7384,0.2645,-5.8213,2.8531,25.8268
104.7,1.7435,0.2654,-5.8077,2.8667,25.9228
105,1.7489,0.2665,-5.7925,2.8819,26.0287
105.3,1.7538,0.2672,-5.7802,2.8942,26.0896
105.6,1.7586,0.2681,-5.7672,2.9072,26.179
105.9,1.764,0.2691,-5.7525,2.9219,26.2806
106.2,1.7685,0.2695,-5.7406,2.9338,26.3145
106.5,1.7734,0.2702,-5.7278,2.9466,26.3859
106.8,1.7786,0.271,-5.7138,2.9606,26.4675
107.1,1.7837,0.2719,-5.6994,2.975,26.5565
107.4,1.7886,0.2726,-5.6862,2.9882,26.6257
107.7,1.7939,0.2736,-5.6712,3.0032,26.7192
108,1.7991,0.2745,-5.6568,3.0176,26.8094
108.3,1.8035,0.2748,-5.645,3.0294,26.8378
108.6,1.8084,0.2757,-5.6309,3.0435,26.9236
108.9,1.8136,0.2765,-5.6172,3.0572,26.9999
109.2,1.8185,0.2772,-5.603,3.0714,27.0715
109.5,1.8235,0.278,-5.5892,3.0852,27.1454
109.8,1.829,0.2791,-5.5734,3.101,27.2548
110.1,1.8339,0.2797,-5.5595,3.1149,27.3155
110.4,1.8386,0.2803,-5.5468,3.1276,27.3748
110.7,1.8437,0.2811,-5.5321,3.1423,27.4525
111,1.8486,0.2816,-5.5185,3.1559,27.5032
111.3,1.8534,0.2823,-5.5044,3.17,27.5635
111.6,1.8585,0.2831,-5.49,3.1844,27.6478
111.9,1.8639,0.2841,-5.4737,3.2007,27.7431
112.2,1.8687,0.2847,-5.4601,3.2143,27.8003
112.5,1.8737,0.2854,-5.4457,3.2287,27.873
112.8,1.879,0.2863,-5.43,3.2444,27.9593
113.1,1.8836,0.2868,-5.4167,3.2577,28.0045
113.4,1.8884,0.2873,-5.4025,3.2719,28.0528
113.7,1.8936,0.2881,-5.3878,3.2866,28.1342
114,1.8987,0.2889,-5.372,3.3024,28.2115
114.3,1.9036,0.2894,-5.3576,3.3168,28.2643
114.6,1.9089,0.2905,-5.3414,3.333,28.368
114.9,1.9141,0.2913,-5.3258,3.3486,28.4474
115.2,1.9185,0.2917,-5.312,3.3624,28.4819
115.5,1.9235,0.2922,-5.2976,3.3768,28.5342
115.8,1.9286,0.2929,-5.282,3.3924,28.6079
116.1,1.9335,0.2935,-5.2673,3.4071,28.6585
116.4,1.9385,0.2944,-5.2519,3.4225,28.7452
116.7,1.944,0.2952,-5.2344,3.44,28.8294
117,1.9488,0.2958,-5.2198,3.4546,28.8863
117.3,1.9536,0.2964,-5.2049,3.4695,28.9433
117.6,1.9588,0.297,-5.1887,3.4857,29.0078
117.9,1.9635,0.2976,-5.1739,3.5005,29.0633
118.2,1.9684,0.2981,-5.1586,3.5158,29.1126
118.5,1.9735,0.2989,-5.1422,3.5322,29.1879
118.8,1.9788,0.2998,-5.1252,3.5492,29.2756
119.1,1.9836,0.3003,-5.1102,3.5642,29.3223
119.4,1.9887,0.3009,-5.0935,3.5809,29.3878
119.7,1.9941,0.302,-5.0767,3.5977,29.4895
120,1.9985,0.302,-5.0624,3.612,29.4877
120.3,2.0034,0.3026,-5.0461,3.6283,29.5515
120.6,2.0086,0.3033,-5.0298,3.6446,29.6151
120.9,2.0136,0.3039,-5.0132,3.6612,29.676
121.2,2.0186,0.3044,-4.997,3.6774,29.7311
121.5,2.024,0.3054,-4.979,3.6954,29.8195
121.8,2.029,0.3059,-4.9622,3.7122,29.8741
122.1,2.0335,0.3063,-4.9472,3.7272,29.9119
122.4,2.0386,0.307,-4.9301,3.7443,29.9769
122.7,2.0436,0.3076,-4.9136,3.7608,30.0407
123,2.0484,0.3079,-4.897,3.7774,30.0732
123.3,2.0535,0.3087,-4.8792,3.7952,30.1447
123.6,2.0589,0.3095,-4.8612,3.8132,30.2232
123.9,2.0638,0.31,-4.8442,3.8302,30.2758
124.2,2.0687,0.3105,-4.8277,3.8467,30.3232
124.5,2.074,0.3113,-4.8087,3.8657,30.4002
124.8,2.0785,0.3116,-4.7931,3.8813,30.4255
125.1,2.0834,0.3121,-4.7761,3.8983,30.4813
125.4,2.0886,0.3128,-4.757,3.9174,30.5468
125.7,2.0937,0.3134,-4.7388,3.9356,30.608
126,2.0986,0.3139,-4.7212,3.9532,30.6536
126.3,2.1039,0.3146,-4.7027,3.9717,30.724
126.6,2.1091,0.3153,-4.6832,3.9912,30.7868
126.9,2.1135,0.3154,-4.6673,4.0071,30.8043
127.2,2.1184,0.3158,-4.6498,4.0246,30.8436
127.5,2.1236,0.3167,-4.6305,4.0439,30.924
127.8,2.1285,0.3171,-4.6122,4.0622,30.9683
128.1,2.1335,0.3177,-4.5937,4.0807,31.0229
128.4,2.139,0.3184,-4.5735,4.1009,31.0982
128.7,2.1439,0.3189,-4.5551,4.1193,31.1413
129,2.1486,0.3193,-4.5374,4.137,31.1832
129.3,2.1537,0.3199,-4.5178,4.1566,31.2414
129.6,2.1585,0.3202,-4.4998,4.1746,31.2707
129.9,2.1634,0.3205,-4.4813,4.1931,31.3027
130.2,2.1685,0.3212,-4.4616,4.2128,31.3674
130.5,2.1739,0.3219,-4.4406,4.2338,31.4322
130.8,2.1787,0.3222,-4.4221,4.2523,31.4675
131.1,2.1837,0.3229,-4.4025,4.2719,31.5298
131.4,2.189,0.3234,-4.3816,4.2928,31.5852
131.7,2.1936,0.3236,-4.3641,4.3103,31.6034
132,2.1983,0.3239,-4.3451,4.3293,31.6324
132.3,2.2036,0.3246,-4.3248,4.3496,31.6979
132.6,2.2086,0.325,-4.3041,4.3703,31.7409
132.9,2.2136,0.3254,-4.2849,4.3895,31.7786
133.2,2.2189,0.3262,-4.263,4.4114,31.8521
133.5,2.2241,0.3267,-4.2424,4.432,31.9029
133.8,2.2285,0.3268,-4.2238,4.4506,31.9168
134.1,2.2335,0.3274,-4.2036,4.4708,31.971
134.4,2.2386,0.3277,-4.1827,4.4917,32.0018
134.7,2.2434,0.3281,-4.163,4.5114,32.0413
135,2.2485,0.3285,-4.142,4.5324,32.0759
135.3,2.254,0.3291,-4.1192,4.5552,32.1406
135.6,2.2588,0.3294,-4.0995,4.5749,32.1672
135.9,2.2636,0.3297,-4.0788,4.5956,32.1987
136.2,2.2689,0.3303,-4.057,4.6174,32.2582
136.5,2.2735,0.3305,-4.0374,4.637,32.272
136.8,2.2784,0.3308,-4.0167,4.6577,32.3067
137.1,2.2835,0.3313,-3.9943,4.6801,32.3517
137.4,2.2888,0.3319,-3.9723,4.7021,32.4099
137.7,2.2936,0.332,-3.9511,4.7233,32.4238
138,2.2988,0.3325,-3.9292,4.7452,32.4751
138.3,2.3041,0.3331,-3.906,4.7684,32.5278
138.6,2.3086,0.3331,-3.8864,4.788,32.5338
138.9,2.3134,0.3333,-3.8649,4.8095,32.548
139.2,2.3186,0.3338,-3.8426,4.8318,32.6005
139.5,2.3235,0.3341,-3.8202,4.8542,32.6262
139.8,2.3286,0.3344,-3.7981,4.8763,32.6586
140.1,2.334,0.3351,-3.774,4.9004,32.7275
140.4,2.339,0.3354,-3.7514,4.923,32.7559
140.7,2.3436,0.3355,-3.7305,4.9439,32.7636
141,2.3486,0.3359,-3.7076,4.9668,32.8029
141.3,2.3536,0.3361,-3.6853,4.9891,32.8231
141.6,2.3584,0.3363,-3.6625,5.0119,32.8423
141.9,2.3635,0.3367,-3.6395,5.0349,32.8768
142.2,2.369,0.3372,-3.6145,5.0599,32.9322
142.5,2.3738,0.3374,-3.5922,5.0822,32.9466
142.8,2.3787,0.3377,-3.5687,5.1057,32.9759
143.1,2.384,0.3382,-3.5446,5.1298,33.0232
143.4,2.3886,0.3382,-3.5222,5.1522,33.0286
143.7,2.3934,0.3383,-3.4999,5.1745,33.0355
144,2.3985,0.3387,-3.4747,5.1997,33.0803
144.3,2.4037,0.3391,-3.4511,5.2233,33.1178
144.6,2.4086,0.3393,-3.427,5.2474,33.1308
144.9,2.4138,0.3398,-3.4024,5.272,33.1814
145.2,2.4191,0.3401,-3.3769,5.2975,33.2163
145.5,2.4236,0.3401,-3.355,5.3194,33.2097
145.8,2.4285,0.3402,-3.3306,5.3438,33.2212
146.1,2.4336,0.3406,-3.3055,5.3689,33.2583
146.4,2.4385,0.3406,-3.2815,5.3929,33.2655
146.7,2.4435,0.341,-3.2565,5.4179,33.2998
147,2.449,0.3416,-3.2298,5.4446,33.3575
147.3,2.4539,0.3417,-3.2051,5.4693,33.3663
147.6,2.4586,0.3418,-3.1813,5.4931,33.3818
147.9,2.4637,0.3422,-3.1554,5.519,33.4191
148.2,2.4686,0.3422,-3.131,5.5434,33.4164
148.5,2.4734,0.3422,-3.1065,5.5679,33.4191
148.8,2.4785,0.3426,-3.0797,5.5947,33.4551
149.1,2.4838,0.3429,-3.0529,5.6215,33.4846
149.4,2.4887,0.343,-3.0276,5.6468,33.4983
149.7,2.4937,0.3433,-3.0018,5.6726,33.5224
150,2.4991,0.3438,-2.9738,5.7006,33.571
150.3,2.5036,0.3436,-2.9503,5.7241,33.5522
150.6,2.5084,0.3435,-2.9244,5.75,33.5496
150.9,2.5136,0.3439,-2.8978,5.7766,33.5887
151.2,2.5186,0.3441,-2.8709,5.8035,33.6003
151.5,2.5236,0.3443,-2.845,5.8294,33.6186
151.8,2.5289,0.3447,-2.8172,5.8572,33.6661
152.1,2.534,0.3449,-2.7897,5.8847,33.6826
152.4,2.5385,0.3447,-2.7647,5.9097,33.6662
152.7,2.5436,0.345,-2.7381,5.9363,33.6878
153,2.5486,0.3451,-2.7107,5.9637,33.6999
153.3,2.5534,0.345,-2.6843,5.9901,33.6962
153.6,2.5585,0.3454,-2.6566,6.0178,33.7286
153.9,2.564,0.3458,-2.6279,6.0465,33.766
154.2,2.5688,0.3458,-2.6006,6.0738,33.7683
154.5,2.5736,0.3458,-2.5745,6.0999,33.7741
154.8,2.5789,0.3462,-2.5456,6.1288,33.8065
155.1,2.5835,0.346,-2.5193,6.1551,33.7848
155.4,2.5884,0.346,-2.4921,6.1823,33.786
155.7,2.5935,0.3462,-2.4635,6.2109,33.8057
156,2.5988,0.3465,-2.4342,6.2402,33.8352
156.3,2.6036,0.3465,-2.4067,6.2677,33.8367
156.6,2.6088,0.3467,-2.3784,6.296,33.8561
156.9,2.6141,0.3471,-2.3482,6.3262,33.8988
157.2,2.6186,0.3467,-2.322,6.3524,33.8586
157.5,2.6234,0.3467,-2.2945,6.3799,33.8578
157.8,2.6286,0.3469,-2.2654,6.409,33.8781
158.1,2.6335,0.3469,-2.2369,6.4375,33.8796
158.4,2.6386,0.3471,-2.208,6.4664,33.8942
158.7,2.644,0.3475,-2.178,6.4964,33.9357
159,2.649,0.3474,-2.1486,6.5258,33.9274
159.3,2.6536,0.3472,-2.1216,6.5528,33.9103
159.6,2.6587,0.3474,-2.0922,6.5822,33.9217
159.9,2.6635,0.3474,-2.0634,6.611,33.9291
160.2,2.6684,0.3474,-2.0343,6.6401,33.9275
160.5,2.6735,0.3475,-2.0043,6.6701,33.9312
160.8,2.6789,0.3478,-1.9731,6.7013,33.9649
161.1,2.6837,0.3477,-1.9445,6.7299,33.9582
161.4,2.6887,0.3479,-1.9148,6.7596,33.9773
161.7,2.694,0.3481,-1.8841,6.7903,33.9934
162,2.6985,0.3478,-1.8555,6.8189,33.963
162.3,2.7034,0.3477,-1.8268,6.8476,33.9585
162.6,2.7086,0.348,-1.7956,6.8788,33.9844
162.9,2.7137,0.348,-1.7649,6.9095,33.981
163.2,2.7186,0.348,-1.7345,6.9399,33.9837
163.5,2.7239,0.3483,-1.7031,6.9713,34.0168
163.8,2.7291,0.3484,-1.6716,7.0028,34.0203
164.1,2.7335,0.3482,-1.6429,7.0315,33.9994
164.4,2.7385,0.3482,-1.6125,7.0619,34.0043
164.7,2.7436,0.3482,-1.5809,7.0935,34.0012
165,2.7485,0.3481,-1.5507,7.1237,33.994
165.3,2.7535,0.3482,-1.5194,7.155,34.0044
165.6,2.759,0.3486,-1.4862,7.1882,34.0432
165.9,2.7638,0.3484,-1.4552,7.2192,34.0219
166.2,2.7686,0.3485,-1.425,7.2494,34.0286
166.5,2.7738,0.3486,-1.3926,7.2818,34.0465
166.8,2.7785,0.3484,-1.3622,7.3122,34.0283
167.1,2.7834,0.3484,-1.3306,7.3438,34.0199
167.4,2.7885,0.3484,-1.2988,7.3756,34.0198
167.7,2.7938,0.3486,-1.2652,7.4092,34.045
168,2.7987,0.3485,-1.234,7.4404,34.0361
168.3,2.8038,0.3487,-1.2015,7.4729,34.0564
168.6,2.8091,0.3489,-1.1679,7.5065,34.0688
168.9,2.8135,0.3485,-1.1376,7.5368,34.035
169.2,2.8184,0.3484,-1.1061,7.5683,34.028
169.5,2.8235,0.3486,-1.0722,7.6022,34.0392
169.8,2.8286,0.3486,-1.04,7.6344,34.0434
170.1,2.8335,0.3486,-1.0069,7.6675,34.0432
170.4,2.8389,0.3488,-0.973,7.7014,34.0621
170.7,2.844,0.3489,-0.9392,7.7352,34.069
171,2.8486,0.3487,-0.9088,7.7656,34.0497
171.3,2.8535,0.3486,-0.8753,7.7991,34.0445
171.6,2.8586,0.3486,-0.8422,7.8322,34.0459
171.9,2.8634,0.3485,-0.8087,7.8657,34.0339
172.2,2.8685,0.3485,-0.7756,7.8988,34.034
172.5,2.874,0.3488,-0.74,7.9344,34.0646
172.8,2.8788,0.3487,-0.7072,7.9672,34.0568
173.1,2.8836,0.3487,-0.6744,8,34.0506
173.4,2.8889,0.3488,-0.6398,8.0346,34.0592
173.7,2.8936,0.3486,-0.6069,8.0675,34.0419
174,2.8984,0.3485,-0.5743,8.1001,34.0289
174.3,2.9035,0.3485,-0.5393,8.1351,34.0349
174.6,2.9087,0.3486,-0.5041,8.1703,34.0383
174.9,2.9136,0.3486,-0.4705,8.2039,34.0397
175.2,2.9188,0.3488,-0.4353,8.2391,34.0599
175.5,2.9241,0.3488,-0.3994,8.275,34.0643
175.8,2.9285,0.3486,-0.3679,8.3065,34.039
176.1,2.9334,0.3484,-0.3335,8.3409,34.0277
176.4,2.9386,0.3485,-0.2988,8.3756,34.0297
176.7,2.9435,0.3483,-0.2641,8.4103,34.0154
177,2.9485,0.3484,-0.2292,8.4452,34.0202
177.3,2.954,0.3486,-0.1929,8.4815,34.0418
177.6,2.9589,0.3485,-0.1578,8.5166,34.0312
177.9,2.9636,0.3482,-0.1249,8.5495,34.0001
178.2,2.9687,0.3484,-0.0891,8.5853,34.0197
178.5,2.9736,0.3484,-0.0543,8.6201,34.0208
178.8,2.9784,0.3482,-0.0198,8.6546,34.0022
179.1,2.9835,0.3482,0.0157,8.6901,34.0016
179.4,2.9889,0.3483,0.0532,8.7276,34.0094
179.7,2.9937,0.3481,0.0875,8.7619,33.9946
180,2.9987,0.3481,0.1234,8.7978,33.9939
180.3,3.004,0.3483,0.1595,8.8339,34.0178
180.6,3.0085,0.348,0.1932,8.8676,33.9799
180.9,3.0134,0.3478,0.2281,8.9025,33.9612
181.2,3.0185,0.3478,0.265,8.9394,33.9672
181.5,3.0236,0.3478,0.3012,8.9756,33.9661
181.8,3.0286,0.3477,0.3367,9.0111,33.959
182.1,3.0339,0.348,0.3738,9.0482,33.9804
182.4,3.0391,0.348,0.4108,9.0852,33.9861
182.7,3.0436,0.3476,0.4452,9.1196,33.9453
183,3.0485,0.3476,0.4805,9.1549,33.9423
183.3,3.0536,0.3474,0.5172,9.1916,33.9304
183.6,3.0585,0.3475,0.5533,9.2277,33.9307
183.9,3.0635,0.3475,0.5895,9.2639,33.9309
184.2,3.069,0.3476,0.6284,9.3028,33.9448
184.5,3.0738,0.3475,0.6639,9.3383,33.9363
184.8,3.0786,0.3473,0.6996,9.374,33.9122
185.1,3.0838,0.3473,0.7371,9.4115,33.9194
185.4,3.0886,0.3471,0.7727,9.4471,33.8964
185.7,3.0934,0.347,0.8087,9.4831,33.8862
186,3.0985,0.347,0.846,9.5204,33.8838
186.3,3.1038,0.3472,0.8843,9.5587,33.9016
186.6,3.1086,0.347,0.9202,9.5946,33.8871
186.9,3.1138,0.347,0.9579,9.6323,33.8879
187.2,3.1191,0.3472,0.9961,9.6705,33.9087
187.5,3.1236,0.3468,1.0313,9.7057,33.868
187.8,3.1284,0.3467,1.0672,9.7416,33.8561
188.1,3.1336,0.3466,1.1055,9.7799,33.8429
188.4,3.1386,0.3465,1.1433,9.8177,33.8333
188.7,3.1436,0.3465,1.1805,9.8549,33.8417
189,3.149,0.3467,1.2194,9.8938,33.8564
189.3,3.154,0.3467,1.257,9.9314,33.8602
189.6,3.1586,0.3463,1.2926,9.967,33.8205
189.9,3.1636,0.3464,1.3304,10.0048,33.8298
190.2,3.1686,0.3462,1.3682,10.0426,33.8112
190.5,3.1734,0.3461,1.4048,10.0792,33.798
190.8,3.1785,0.3462,1.4435,10.1179,33.8085
191.1,3.184,0.3464,1.4825,10.1569,33.8266
191.4,3.1888,0.3461,1.5198,10.1942,33.8022
191.7,3.1936,0.3461,1.5568,10.2312,33.8013
192,3.199,0.3462,1.5963,10.2707,33.8066
192.3,3.2035,0.3458,1.6325,10.3069,33.7696
192.6,3.2084,0.3457,1.6698,10.3442,33.7646
192.9,3.2135,0.3457,1.7088,10.3832,33.7568
193.2,3.2187,0.3458,1.7474,10.4218,33.7663
193.5,3.2236,0.3456,1.7854,10.4598,33.7539
193.8,3.2289,0.3457,1.8243,10.4987,33.7631
194.1,3.2341,0.3458,1.8638,10.5382,33.7732
194.4,3.2385,0.3455,1.8998,10.5742,33.7396
194.7,3.2434,0.3453,1.9372,10.6116,33.7231
195,3.2486,0.3453,1.9764,10.6508,33.7167
195.3,3.2535,0.3453,2.0146,10.689,33.717
195.6,3.2585,0.3452,2.053,10.7274,33.7122
195.9,3.264,0.3454,2.0934,10.7678,33.726
196.2,3.2689,0.3452,2.1317,10.8061,33.7132
196.5,3.2736,0.3451,2.1686,10.843,33.6975
196.8,3.2788,0.3451,2.2079,10.8823,33.7037
197.1,3.2835,0.3449,2.2456,10.92,33.6802
197.4,3.2884,0.3447,2.2834,10.9578,33.6606
197.7,3.2935,0.3446,2.3224,10.9968,33.6565
198,3.2989,0.3448,2.3631,11.0375,33.6726
198.3,3.3037,0.3448,2.4006,11.075,33.6706
198.6,3.3087,0.3446,2.4397,11.1141,33.6539
198.9,3.314,0.3448,2.4791,11.1535,33.6712
199.2,3.3185,0.3445,2.5161,11.1905,33.645
199.5,3.3234,0.3442,2.5545,11.2289,33.615
199.8,3.3285,0.3444,2.5944,11.2688,33.6324
200.1,3.3337,0.3444,2.6336,11.308,33.6292
200.4,3.3386,0.3442,2.6725,11.3469,33.6118
200.7,3.3439,0.3443,2.7127,11.3871,33.6239
201,3.349,0.3443,2.7526,11.427,33.6245
201.3,3.3536,0.344,2.7898,11.4642,33.5943
201.6,3.3585,0.3439,2.8281,11.5025,33.5848
201.9,3.3636,0.3439,2.8675,11.5419,33.5814
202.2,3.3685,0.3437,2.9064,11.5808,33.5693
202.5,3.3735,0.3438,2.9456,11.62,33.5755
202.8,3.379,0.344,2.9866,11.661,33.5922
203.1,3.3838,0.3438,3.0253,11.6997,33.5701
203.4,3.3886,0.3437,3.0636,11.738,33.5639
203.7,3.3938,0.3438,3.1036,11.778,33.5773
204,3.3986,0.3435,3.142,11.8164,33.5446
204.3,3.4033,0.3434,3.1803,11.8547,33.5336
204.6,3.4086,0.3434,3.2207,11.8951,33.5333
204.9,3.4138,0.3436,3.2608,11.9352,33.5547
205.2,3.4186,0.3433,3.2997,11.9741,33.5233
205.5,3.4238,0.3434,3.3392,12.0136,33.5365
205.8,3.4291,0.3435,3.3806,12.055,33.5409
206.1,3.4335,0.3431,3.4175,12.0919,33.5032
206.4,3.4384,0.3432,3.4564,12.1308,33.5121
206.7,3.4436,0.343,3.4972,12.1716,33.493
207,3.4485,0.343,3.5363,12.2107,33.4947
207.3,3.4536,0.3428,3.5759,12.2503,33.4802
207.6,3.459,0.343,3.6177,12.2921,33.4993
207.9,3.464,0.343,3.6563,12.3307,33.4944
208.2,3.4686,0.3428,3.6946,12.369,33.4796
208.5,3.4737,0.3429,3.7347,12.4091,33.4833
208.8,3.4786,0.3427,3.7738,12.4482,33.4635
209.1,3.4834,0.3426,3.813,12.4874,33.4602
209.4,3.4885,0.3426,3.8527,12.5271,33.4598
209.7,3.4939,0.3427,3.8941,12.5685,33.4712
210,3.4987,0.3426,3.9327,12.6071,33.4605
210.3,3.5037,0.3425,3.9726,12.647,33.4521
210.6,3.509,0.3427,4.0129,12.6873,33.4655
210.9,3.5135,0.3423,4.051,12.7254,33.4306
211.2,3.5184,0.3422,4.0899,12.7643,33.4197
211.5,3.5235,0.3423,4.1305,12.8049,33.425
211.8,3.5287,0.3422,4.1708,12.8452,33.4226
212.1,3.5336,0.3423,4.2102,12.8846,33.4235
212.4,3.5389,0.3422,4.2509,12.9253,33.4216
212.7,3.5441,0.3423,4.2916,12.966,33.4311
213,3.5485,0.3419,4.3286,13.003,33.3894
213.3,3.5535,0.3421,4.3681,13.0425,33.4041
213.6,3.5585,0.342,4.4086,13.083,33.3939
213.9,3.5635,0.3418,4.4483,13.1227,33.3798
214.2,3.5685,0.3417,4.4877,13.1621,33.3722
214.5,3.574,0.3421,4.5299,13.2043,33.4114
214.8,3.5789,0.342,4.5697,13.2441,33.4001
215.1,3.5836,0.3417,4.6077,13.2821,33.3703
215.4,3.5887,0.3418,4.6482,13.3226,33.3828
215.7,3.5936,0.3416,4.6876,13.362,33.3628
216,3.5984,0.3415,4.7264,13.4008,33.349
216.3,3.6035,0.3416,4.7676,13.442,33.3603
216.6,3.6088,0.3416,4.8085,13.4829,33.3618
216.9,3.6137,0.3414,4.8481,13.5225,33.3435
217.2,3.6187,0.3417,4.888,13.5624,33.3644
217.5,3.6241,0.3418,4.9295,13.6039,33.3773
217.8,3.6286,0.3414,4.9672,13.6416,33.3429
218.1,3.6334,0.3412,5.0065,13.6809,33.3187
218.4,3.6386,0.3413,5.0476,13.722,33.3324
218.7,3.6436,0.3413,5.0877,13.7621,33.3264
219,3.6486,0.3412,5.1275,13.8019,33.3188
219.3,3.654,0.3415,5.1689,13.8433,33.3491
219.6,3.6591,0.3414,5.2099,13.8843,33.3446
219.9,3.6636,0.3411,5.2475,13.9219,33.306
220.2,3.6685,0.341,5.2873,13.9617,33.3023
220.5,3.6736,0.3411,5.3275,14.0019,33.3113
220.8,3.6784,0.3408,5.3677,14.0421,33.2808
221.1,3.6835,0.341,5.408,14.0824,33.3004
221.4,3.689,0.3411,5.45,14.1244,33.3135
221.7,3.6938,0.341,5.4891,14.1635,33.2999
222,3.6986,0.3409,5.5287,14.2031,33.2936
222.3,3.7039,0.3411,5.57,14.2444,33.3131
222.6,3.7085,0.3408,5.6085,14.2829,33.28
222.9,3.7134,0.3407,5.6477,14.3221,33.2715
223.2,3.7186,0.3407,5.6883,14.3627,33.2729
223.5,3.7238,0.3407,5.7294,14.4038,33.2683
223.8,3.7286,0.3406,5.769,14.4434,33.2654
224.1,3.7339,0.3408,5.8098,14.4842,33.2794
224.4,3.7391,0.341,5.8517,14.5261,33.3049
224.7,3.7435,0.3405,5.8888,14.5632,33.2544
225,3.7484,0.3406,5.9282,14.6026,33.259
225.3,3.7536,0.3404,5.9689,14.6433,33.2467
225.6,3.7585,0.3403,6.0094,14.6838,33.2368
225.9,3.7636,0.3405,6.0493,14.7237,33.2495
226.2,3.7691,0.3407,6.0916,14.766,33.268
226.5,3.774,0.3405,6.1315,14.8059,33.2568
226.8,3.7786,0.3404,6.17,14.8444,33.2426
227.1,3.7836,0.3404,6.2101,14.8845,33.243
227.4,3.7885,0.3402,6.2496,14.924,33.2267
227.7,3.7934,0.3402,6.2897,14.9641,33.2205
228,3.7985,0.3403,6.3301,15.0045,33.2345
228.3,3.8039,0.3405,6.3725,15.0469,33.252
228.6,3.8087,0.3403,6.4116,15.086,33.233
228.9,3.8137,0.3403,6.4513,15.1257,33.2285
229.2,3.819,0.3403,6.4925,15.1669,33.2366
229.5,3.8235,0.3401,6.531,15.2054,33.2088
229.8,3.8284,0.34,6.5705,15.2449,33.2036
230.1,3.8335,0.3401,6.6111,15.2855,33.2136
230.4,3.8387,0.3402,6.6524,15.3268,33.2195
230.7,3.8436,0.34,6.6915,15.3659,33.2031
231,3.8489,0.3402,6.7336,15.408,33.2209
231.3,3.8541,0.3403,6.7743,15.4487,33.2344
231.6,3.8585,0.34,6.8121,15.4865,33.2045
231.9,3.8635,0.34,6.8518,15.5262,33.2009
232.2,3.8685,0.34,6.8925,15.5669,33.1983
232.5,3.8735,0.3398,6.9327,15.6071,33.1872
232.8,3.8785,0.3398,6.9728,15.6472,33.1856
233.1,3.884,0.3402,7.0149,15.6893,33.2212
233.4,3.8889,0.3401,7.0548,15.7292,33.2131
233.7,3.8936,0.3399,7.0937,15.7681,33.1936
234,3.8988,0.3398,7.1346,15.809,33.1853
234.3,3.9035,0.3399,7.1735,15.8479,33.1939
234.6,3.9084,0.3396,7.2134,15.8878,33.1664
234.9,3.9135,0.3398,7.254,15.9284,33.1844
235.2,3.9188,0.3399,7.2958,15.9702,33.1928
235.5,3.9237,0.3398,7.3351,16.0095,33.1823
235.8,3.9287,0.3399,7.3758,16.0502,33.1908
236.1,3.9341,0.3402,7.4173,16.0917,33.2194
236.4,3.9385,0.3397,7.455,16.1294,33.1752
236.7,3.9434,0.3396,7.4946,16.169,33.1686
237,3.9486,0.3397,7.5355,16.2099,33.1774
237.3,3.9536,0.3398,7.5759,16.2503,33.1791
237.6,3.9585,0.3397,7.6153,16.2897,33.1765
237.9,3.964,0.34,7.6579,16.3323,33.2005
238.2,3.969,0.3399,7.6981,16.3725,33.1978
238.5,3.9735,0.3397,7.7364,16.4108,33.1726
238.8,3.9786,0.3399,7.7762,16.4506,33.1888
239.1,3.9836,0.3395,7.8167,16.4911,33.1582
239.4,3.9884,0.3396,7.8559,16.5303,33.1613
239.7,3.9935,0.3395,7.8964,16.5708,33.1583
240,3.9989,0.3398,7.9384,16.6128,33.1816
240.3,4.0038,0.3397,7.9781,16.6525,33.1692
240.6,4.0087,0.3397,8.017,16.6914,33.1748
240.9,4.0139,0.3398,8.0582,16.7326,33.1834
241.2,4.0185,0.3396,8.0969,16.7713,33.1631
241.5,4.0234,0.3395,8.1362,16.8106,33.1557
241.8,4.0285,0.3396,8.1766,16.851,33.1685
242.1,4.0338,0.3397,8.2181,16.8925,33.1705
242.4,4.0386,0.3396,8.2577,16.9321,33.1634
242.7,4.0438,0.3397,8.2986,16.973,33.1757
243,4.0491,0.3399,8.3399,17.0143,33.191
243.3,4.0535,0.3395,8.3772,17.0516,33.1588
243.6,4.0584,0.3395,8.4165,17.0909,33.1519
243.9,4.0636,0.3395,8.457,17.1314,33.1516
244.2,4.0685,0.3396,8.4975,17.1719,33.1607
244.5,4.0735,0.3396,8.5369,17.2113,33.1596
244.8,4.079,0.3397,8.5791,17.2535,33.1761
245.1,4.084,0.3398,8.6189,17.2933,33.1832
245.4,4.0886,0.3395,8.6567,17.3311,33.1521
245.7,4.0936,0.3397,8.697,17.3714,33.1722
246,4.0985,0.3396,8.7365,17.4109,33.1626
246.3,4.1034,0.3394,8.7759,17.4503,33.1488
246.6,4.1085,0.3395,8.816,17.4904,33.1529
246.9,4.1139,0.3397,8.8578,17.5322,33.1775
247.2,4.1187,0.3395,8.8967,17.5711,33.1546
247.5,4.1237,0.3397,8.9364,17.6108,33.1718
247.8,4.1291,0.3398,8.9772,17.6516,33.1794
248.1,4.1335,0.3396,9.015,17.6894,33.1614
248.4,4.1384,0.3394,9.0545,17.7289,33.1465
248.7,4.1435,0.3395,9.095,17.7694,33.1563
249,4.1487,0.3395,9.1354,17.8098,33.1574
249.3,4.1536,0.3395,9.1747,17.8491,33.1575
249.6,4.1589,0.3398,9.2161,17.8905,33.1851
249.9,4.1641,0.3399,9.2561,17.9305,33.1924
250.2,4.1685,0.3395,9.2934,17.9678,33.1526
250.5,4.1735,0.3396,9.3335,18.0079,33.1634
250.8,4.1786,0.3396,9.3732,18.0476,33.1675
251.1,4.1835,0.3394,9.4123,18.0867,33.1483
251.4,4.1885,0.3395,9.4515,18.1259,33.1541
251.7,4.194,0.3399,9.4938,18.1682,33.1921
252,4.1988,0.3396,9.5327,18.2071,33.1628
252.3,4.2036,0.3397,9.5711,18.2455,33.1713
252.6,4.2088,0.3398,9.6114,18.2858,33.1878
252.9,4.2135,0.3396,9.6498,18.3242,33.1632
253.2,4.2184,0.3395,9.6883,18.3627,33.1556
253.5,4.2235,0.3397,9.7288,18.4032,33.1696
253.8,4.2288,0.3397,9.7696,18.444,33.1772
254.1,4.2336,0.3397,9.8084,18.4828,33.173
254.4,4.2388,0.3398,9.8486,18.523,33.181
254.7,4.2441,0.3399,9.8891,18.5635,33.1933
255,4.2485,0.3396,9.9266,18.601,33.165
255.3,4.2534,0.3396,9.9651,18.6395,33.1624
255.6,4.2586,0.3397,10.0056,18.68,33.1721
255.9,4.2636,0.3396,10.045,18.7194,33.1648
256.2,4.2685,0.3396,10.0841,18.7585,33.1598
256.5,4.274,0.3399,10.1252,18.7996,33.1961
256.8,4.279,0.3399,10.1649,18.8393,33.1964
257.1,4.2836,0.3397,10.2019,18.8763,33.1765
257.4,4.2886,0.3398,10.2417,18.9161,33.1803
257.7,4.2936,0.3398,10.2818,18.9562,33.1799
258,4.2984,0.3397,10.32,18.9944,33.1738
258.3,4.3035,0.3397,10.3594,19.0338,33.1753
258.6,4.309,0.3399,10.4009,19.0753,33.1962
258.9,4.3138,0.3398,10.4396,19.114,33.1866
259.2,4.3187,0.3398,10.4783,19.1527,33.188
259.5,4.3239,0.3401,10.5189,19.1933,33.2087
259.8,4.3285,0.3397,10.5563,19.2307,33.1763
260.1,4.3334,0.3397,10.5949,19.2693,33.1747
260.4,4.3385,0.3399,10.635,19.3094,33.1906
260.7,4.3437,0.3399,10.6751,19.3495,33.1968
261,4.3486,0.3399,10.7139,19.3883,33.1919
261.3,4.3538,0.3401,10.7544,19.4288,33.2108
261.6,4.3591,0.3402,10.7946,19.469,33.2257
261.9,4.3636,0.34,10.8314,19.5058,33.2037
262.2,4.3684,0.3399,10.8706,19.545,33.1935
262.5,4.3736,0.34,10.9104,19.5848,33.2057
262.8,4.3785,0.3398,10.9496,19.624,33.1858
263.1,4.3835,0.3399,10.9885,19.6629,33.1982
263.4,4.389,0.3404,11.03,19.7044,33.2385
263.7,4.3939,0.3402,11.0689,19.7433,33.2217
264,4.3986,0.3401,11.1062,19.7806,33.2087
264.3,4.4037,0.3402,11.1458,19.8202,33.2256
264.6,4.4085,0.3401,11.1845,19.8589,33.2132
264.9,4.4134,0.34,11.2227,19.8971,33.204
265.2,4.4185,0.3401,11.2621,19.9365,33.2113
265.5,4.4239,0.3403,11.3031,19.9775,33.2316
265.8,4.4287,0.3402,11.3409,20.0153,33.2195
266.1,4.4337,0.3402,11.3804,20.0548,33.2228
266.4,4.4391,0.3404,11.421,20.0954,33.2434
266.7,4.4435,0.3402,11.4574,20.1318,33.2213
267,4.4484,0.34,11.4955,20.1699,33.2045
267.3,4.4536,0.3403,11.5359,20.2103,33.2337
267.6,4.4586,0.3402,11.5746,20.249,33.2223
267.9,4.4635,0.3403,11.6139,20.2883,33.2353
268.2,4.4689,0.3406,11.654,20.3284,33.2648
268.5,4.4741,0.3405,11.6934,20.3678,33.254
268.8,4.4786,0.3403,11.73,20.4044,33.2332
269.1,4.4836,0.3403,11.7691,20.4435,33.2367
269.4,4.4885,0.3402,11.8076,20.482,33.2222
269.7,4.4934,0.3403,11.8462,20.5206,33.2327
270,4.4985,0.3404,11.8858,20.5602,33.2469
270.3,4.504,0.3406,11.9264,20.6008,33.2588
270.6,4.5088,0.3406,11.9645,20.6389,33.2625
270.9,4.5136,0.3405,12.0021,20.6765,33.2543
271.2,4.5189,0.3407,12.0424,20.7168,33.2716
271.5,4.5235,0.3405,12.0792,20.7536,33.2513
271.8,4.5284,0.3406,12.1179,20.7923,33.2571
272.1,4.5335,0.3404,12.1571,20.8315,33.2398
272.4,4.5388,0.3408,12.1974,20.8718,33.2826
272.7,4.5437,0.3406,12.2355,20.9099,33.2603
273,4.5488,0.3407,12.275,20.9494,33.2737
273.3,4.5541,0.341,12.3147,20.9891,33.296
273.6,4.5586,0.3407,12.3514,21.0258,33.2738
273.9,4.5634,0.3407,12.3893,21.0637,33.2707
274.2,4.5686,0.3407,12.4286,21.103,33.2695
274.5,4.5736,0.3408,12.4673,21.1417,33.2798
274.8,4.5785,0.3407,12.5056,21.18,33.2742
275.1,4.5839,0.341,12.5464,21.2208,33.3036
275.4,4.589,0.341,12.5848,21.2592,33.3003
275.7,4.5936,0.3408,12.6219,21.2963,33.2809
276,4.5987,0.341,12.6605,21.3349,33.298
276.3,4.6036,0.3409,12.6989,21.3733,33.2941
276.6,4.6084,0.3407,12.7367,21.4111,33.2742
276.9,4.6135,0.341,12.7756,21.45,33.3042
277.2,4.6189,0.3412,12.8164,21.4908,33.3187
277.5,4.6237,0.3411,12.8539,21.5283,33.3063
277.8,4.6286,0.3411,12.892,21.5664,33.3102
278.1,4.6339,0.3414,12.9315,21.6059,33.3388
278.4,4.6385,0.3411,12.9684,21.6428,33.3154
278.7,4.6434,0.3411,13.0065,21.6809,33.3063
279,4.6485,0.3411,13.0453,21.7197,33.3115
279.3,4.6537,0.3411,13.0842,21.7586,33.3153
279.6,4.6586,0.3412,13.1218,21.7962,33.3174
279.9,4.6639,0.3415,13.1619,21.8363,33.3479
280.2,4.6691,0.3416,13.2008,21.8752,33.3606
280.5,4.6735,0.3413,13.2372,21.9116,33.3294
280.8,4.6785,0.3413,13.2749,21.9493,33.3279
281.1,4.6836,0.3413,13.3139,21.9883,33.3319
281.4,4.6885,0.3414,13.352,22.0264,33.3357
281.7,4.6935,0.3414,13.3903,22.0647,33.3414
282,4.699,0.3417,13.4302,22.1046,33.3669
282.3,4.7039,0.3417,13.4679,22.1423,33.3686
282.6,4.7086,0.3416,13.5053,22.1797,33.3572
282.9,4.7138,0.3417,13.5437,22.2181,33.3645
283.2,4.7185,0.3416,13.5812,22.2556,33.3554
283.5,4.7234,0.3415,13.6185,22.2929,33.3516
283.8,4.7285,0.3416,13.6572,22.3316,33.3584
284.1,4.7339,0.3418,13.6967,22.3711,33.3798
284.4,4.7387,0.3417,13.7346,22.409,33.3726
284.7,4.7438,0.3417,13.7724,22.4468,33.3706
285,4.7491,0.342,13.8117,22.4861,33.394
285.3,4.7535,0.3418,13.8469,22.5213,33.3772
285.6,4.7584,0.3417,13.8847,22.5591,33.3691
285.9,4.7635,0.3418,13.9234,22.5978,33.382
286.2,4.7686,0.3418,13.9622,22.6366,33.3791
286.5,4.7736,0.3419,13.9996,22.674,33.3877
286.8,4.779,0.3422,14.0389,22.7133,33.4175
287.1,4.7841,0.3423,14.0781,22.7525,33.4232
287.4,4.7886,0.3421,14.1131,22.7875,33.4066
287.7,4.7935,0.3421,14.151,22.8254,33.4082
288,4.7986,0.3421,14.1889,22.8633,33.4125
288.3,4.8034,0.3421,14.2261,22.9005,33.4046
288.6,4.8085,0.3421,14.2649,22.9393,33.4125
288.9,4.814,0.3425,14.3045,22.9789,33.449
289.2,4.8188,0.3425,14.3415,23.0159,33.4436
289.5,4.8236,0.3423,14.3785,23.0529,33.4296
289.8,4.8289,0.3425,14.4174,23.0918,33.4507
290.1,4.8335,0.3423,14.4537,23.1281,33.4301
290.4,4.8384,0.3423,14.4908,23.1652,33.4262
290.7,4.8435,0.3425,14.5296,23.204,33.4503
291,4.8488,0.3426,14.5679,23.2423,33.4575
291.3,4.8536,0.3425,14.605,23.2794,33.4511
291.6,4.8588,0.3428,14.6436,23.318,33.4747
291.9,4.8641,0.3429,14.6827,23.3571,33.4829
292.2,4.8685,0.3426,14.7176,23.392,33.4595
292.5,4.8734,0.3426,14.7547,23.4291,33.4605
292.8,4.8786,0.3427,14.7924,23.4668,33.4683
293.1,4.8835,0.3428,14.8301,23.5045,33.4745
293.4,4.8885,0.3428,14.8676,23.542,33.4793
293.7,4.894,0.3429,14.9073,23.5817,33.4907
294,4.8989,0.3431,14.9449,23.6193,33.5082
294.3,4.9036,0.343,14.9803,23.6547,33.4966
294.6,4.9087,0.3432,15.0185,23.6929,33.5121
294.9,4.9136,0.343,15.0554,23.7298,33.4958
295.2,4.9184,0.3429,15.0918,23.7662,33.4878
295.5,4.9235,0.343,15.1297,23.8041,33.498
295.8,4.9289,0.3433,15.1685,23.8429,33.5208
296.1,4.9337,0.3433,15.2055,23.8799,33.5236
296.4,4.9387,0.3432,15.2422,23.9166,33.5183
296.7,4.944,0.3436,15.2812,23.9556,33.5543
297,4.9485,0.3432,15.3165,23.9909,33.5204
297.3,4.9534,0.3432,15.353,24.0274,33.5166
297.6,4.9585,0.3434,15.3908,24.0652,33.5376
297.9,4.9637,0.3435,15.4289,24.1033,33.5427
298.2,4.9686,0.3433,15.4658,24.1402,33.5298
298.5,4.9739,0.3437,15.5038,24.1782,33.5664
298.8,4.9791,0.3439,15.5423,24.2167,33.5815
299.1,4.9835,0.3435,15.5769,24.2513,33.5464
299.4,4.9885,0.3436,15.6138,24.2882,33.5528
299.7,4.9935,0.3437,15.6511,24.3255,33.5634
300,4.9985,0.3436,15.6883,24.3627,33.5553
300.3,5.0035,0.3437,15.7255,24.3999,33.5669
300.6,5.009,0.344,15.7643,24.4387,33.5981
300.9,5.0139,0.344,15.8011,24.4755,33.5953
301.2,5.0186,0.3439,15.8366,24.511,33.5804
301.5,5.0238,0.3441,15.8745,24.5489,33.6018
301.8,5.0286,0.344,15.9103,24.5847,33.5909
302.1,5.0334,0.3439,15.9468,24.6212,33.5885
302.4,5.0385,0.3441,15.9842,24.6586,33.6017
302.7,5.0438,0.3443,16.0229,24.6973,33.6188
303,5.0487,0.3442,16.0589,24.7333,33.6115
303.3,5.0538,0.3443,16.0965,24.7709,33.6199
303.6,5.0591,0.3446,16.1344,24.8088,33.6563
303.9,5.0635,0.3443,16.169,24.8434,33.6226
304.2,5.0684,0.3442,16.2051,24.8795,33.6099
304.5,5.0735,0.3444,16.2426,24.917,33.6314
304.8,5.0786,0.3445,16.2798,24.9542,33.6411
305.1,5.0835,0.3443,16.3163,24.9907,33.6242
305.4,5.089,0.3448,16.3551,25.0295,33.6763
305.7,5.094,0.3448,16.3923,25.0667,33.6673
306,5.0986,0.3445,16.4269,25.1013,33.6457
306.3,5.1036,0.3447,16.4636,25.138,33.6634
306.6,5.1086,0.3446,16.5001,25.1745,33.6535
306.9,5.1134,0.3447,16.5361,25.2105,33.6588
307.2,5.1185,0.3447,16.5733,25.2477,33.666
307.5,5.1239,0.3451,16.6116,25.286,33.7012
307.8,5.1288,0.345,16.6476,25.322,33.6868
308.1,5.1336,0.345,16.6836,25.358,33.6929
308.4,5.139,0.3453,16.7215,25.3959,33.7177
308.7,5.1436,0.345,16.7565,25.4309,33.6918
309,5.1484,0.3449,16.7921,25.4665,33.6826
309.3,5.1536,0.3451,16.8292,25.5036,33.701
309.6,5.1587,0.3452,16.8667,25.5411,33.7124
309.9,5.1636,0.3451,16.9022,25.5766,33.6987
310.2,5.1689,0.3454,16.9402,25.6146,33.7348
310.5,5.1741,0.3456,16.9776,25.652,33.7518
310.8,5.1785,0.3452,17.0113,25.6857,33.7138
311.1,5.1834,0.3453,17.0471,25.7215,33.7191
311.4,5.1886,0.3455,17.0843,25.7587,33.7354
311.7,5.1935,0.3455,17.1202,25.7946,33.7359
312,5.1985,0.3455,17.1564,25.8308,33.737
312.3,5.204,0.3458,17.1948,25.8692,33.7691
312.6,5.2089,0.3458,17.2308,25.9052,33.7725
312.9,5.2136,0.3456,17.2656,25.94,33.7518
313.2,5.2186,0.3458,17.3022,25.9766,33.7725
313.5,5.2235,0.3458,17.3379,26.0123,33.7703
313.8,5.2284,0.3456,17.373,26.0474,33.7474
314.1,5.2335,0.3458,17.41,26.0844,33.7705
314.4,5.2389,0.346,17.4477,26.1221,33.7924
314.7,5.2437,0.346,17.4825,26.1569,33.7851
315,5.2487,0.346,17.5186,26.193,33.7924
315.3,5.254,0.3462,17.5558,26.2302,33.8105
315.6,5.2585,0.3461,17.5902,26.2646,33.7984
315.9,5.2634,0.346,17.625,26.2994,33.7852
316.2,5.2685,0.3462,17.6618,26.3362,33.8108
316.5,5.2737,0.3464,17.6988,26.3732,33.8235
316.8,5.2786,0.3463,17.7343,26.4087,33.8155
317.1,5.2839,0.3466,17.7714,26.4458,33.8518
317.4,5.2891,0.3466,17.8081,26.4825,33.8505
317.7,5.2936,0.3465,17.8417,26.5161,33.8369
318,5.2985,0.3465,17.8772,26.5516,33.837
318.3,5.3035,0.3466,17.9135,26.5879,33.8458
318.6,5.3085,0.3466,17.949,26.6234,33.8519
318.9,5.3135,0.3466,17.9851,26.6595,33.8509
319.2,5.319,0.347,18.0227,26.6971,33.883
319.5,5.3238,0.3469,18.0582,26.7326,33.8728
319.8,5.3286,0.3468,18.0923,26.7667,33.8719
320.1,5.3338,0.347,18.1292,26.8036,33.8825
320.4,5.3386,0.3469,18.1638,26.8382,33.879
320.7,5.3434,0.3468,18.1986,26.873,33.8648
321,5.3485,0.347,18.2349,26.9093,33.8873
321.3,5.3538,0.3472,18.2721,26.9465,33.9058
321.6,5.3586,0.3472,18.3071,26.9815,33.9035
321.9,5.3638,0.3474,18.3428,27.0172,33.9274
322.2,5.3691,0.3476,18.3799,27.0543,33.9473
322.5,5.3735,0.3474,18.4127,27.0871,33.921
322.8,5.3784,0.3473,18.448,27.1224,33.9153
323.1,5.3836,0.3474,18.4844,27.1588,33.927
323.4,5.3886,0.3474,18.5197,27.1941,33.9269
323.7,5.3936,0.3475,18.5553,27.2297,33.9376
324,5.399,0.3478,18.5928,27.2672,33.9645
324.3,5.404,0.3478,18.6281,27.3025,33.9656
324.6,5.4085,0.3477,18.6616,27.336,33.953
324.9,5.4136,0.3477,18.6974,27.3718,33.9573
325.2,5.4186,0.3479,18.7324,27.4068,33.9717
325.5,5.4234,0.3477,18.7675,27.4419,33.9542
325.8,5.4285,0.3479,18.8032,27.4776,33.976
326.1,5.4339,0.3481,18.8398,27.5142,33.9946
326.4,5.4388,0.348,18.8748,27.5492,33.9884
326.7,5.4437,0.3481,18.9099,27.5843,33.9928
327,5.449,0.3484,18.9464,27.6208,34.021
327.3,5.4535,0.3482,18.9795,27.6539,33.9998
327.6,5.4584,0.3481,19.0142,27.6886,33.9909
327.9,5.4636,0.3483,19.0505,27.7249,34.0107
328.2,5.4687,0.3483,19.0863,27.7607,34.0144
328.5,5.4736,0.3484,19.1206,27.795,34.0273
328.8,5.4789,0.3485,19.157,27.8314,34.0377
329.1,5.4841,0.3488,19.1933,27.8677,34.0647
329.4,5.4885,0.3486,19.226,27.9004,34.0449
329.7,5.4934,0.3486,19.2608,27.9352,34.0401
330,5.4986,0.3486,19.2965,27.9709,34.0459
330.3,5.5035,0.3486,19.3312,28.0056,34.0396
330.6,5.5085,0.3487,19.3659,28.0403,34.0508
330.9,5.514,0.3489,19.4034,28.0778,34.0738
331.2,5.5189,0.3489,19.4381,28.1125,34.073
331.5,5.5236,0.349,19.4718,28.1462,34.0818
331.8,5.5287,0.3491,19.5072,28.1816,34.0884
332.1,5.5336,0.3489,19.5414,28.2158,34.0749
332.4,5.5384,0.3489,19.5761,28.2505,34.0746
332.7,5.5435,0.349,19.6111,28.2855,34.0843
333,5.5489,0.3493,19.6481,28.3225,34.1103
333.3,5.5537,0.3493,19.6817,28.3561,34.1075
333.6,5.5587,0.3494,19.7172,28.3916,34.1183
333.9,5.564,0.3495,19.7536,28.428,34.1355
334.2,5.5686,0.3494,19.7866,28.461,34.1237
334.5,5.5733,0.3494,19.8206,28.495,34.1236
334.8,5.5786,0.3495,19.8564,28.5308,34.1309
335.1,5.5836,0.3496,19.8922,28.5666,34.1421
335.4,5.5886,0.3495,19.9268,28.6012,34.1324
335.7,5.5939,0.3499,19.9634,28.6378,34.1701
336,5.5991,0.35,19.999,28.6734,34.184
336.3,5.6035,0.3497,20.0317,28.7061,34.1513
336.6,5.6085,0.3498,20.0666,28.741,34.161
336.9,5.6136,0.3499,20.1022,28.7766,34.1696
337.2,5.6184,0.3499,20.1372,28.8116,34.1654
337.5,5.6235,0.3498,20.1726,28.847,34.1649
337.8,5.629,0.3503,20.2104,28.8848,34.2046
338.1,5.6338,0.3502,20.245,28.9194,34.1958
338.4,5.6386,0.3501,20.2799,28.9543,34.1927
338.7,5.6439,0.3504,20.3166,28.991,34.2226
339,5.6485,0.3502,20.3508,29.0252,34.2034
339.3,5.6533,0.3502,20.3862,29.0606,34.2004
339.6,5.6585,0.3504,20.4239,29.0983,34.2155
339.9,5.6638,0.3504,20.4621,29.1365,34.216
340.2,5.6686,0.3503,20.5009,29.1753,34.2137
340.295,5.6701,0.3507,22.4383,31.1127,34.2473