File: data/ReportRaw/Resin_CSV/V4_Resin_Green/Tensile_Test_02.csv
Time,Displacement,Force,Tensile strain (Strain 1),,Tensile stress
(s),(mm),(kN),(%),,(MPa)
0,0,0.0003,-1.2125,0,0.031
0.24,0.0014,0.0011,-1.2068,0.0057,0.1031
0.48,0.007,0.0044,-1.1872,0.0253,0.4304
0.72,0.0111,0.0064,-1.1734,0.0391,0.6212
0.96,0.0146,0.0078,-1.1623,0.0502,0.76
1.2,0.0188,0.0096,-1.1501,0.0624,0.942
1.44,0.023,0.0113,-1.1381,0.0744,1.1024
1.68,0.0266,0.0125,-1.1278,0.0847,1.2164
1.92,0.0306,0.0137,-1.1176,0.0949,1.3392
2.16,0.0348,0.0149,-1.1086,0.1039,1.4556
2.4,0.0385,0.0145,-1.1082,0.1043,1.4113
2.64,0.0425,0.0147,-1.1041,0.1084,1.4342
2.88,0.0466,0.0162,-1.0936,0.1189,1.5803
3.12,0.0506,0.0177,-1.0831,0.1294,1.7238
3.36,0.0544,0.0189,-1.0736,0.1389,1.842
3.6,0.0586,0.0201,-1.0637,0.1488,1.9604
3.84,0.0626,0.0212,-1.0533,0.1592,2.0689
4.08,0.0664,0.0221,-1.045,0.1675,2.1605
4.32,0.0706,0.0232,-1.0362,0.1763,2.265
4.56,0.0748,0.0243,-1.0277,0.1848,2.3741
4.8,0.0787,0.0251,-1.0204,0.1921,2.4504
5.04,0.0826,0.0256,-1.0132,0.1993,2.5001
5.28,0.087,0.0268,-1.0046,0.2079,2.614
5.52,0.091,0.0274,-0.9972,0.2153,2.6789
5.76,0.0946,0.0278,-0.9921,0.2204,2.7172
6,0.0989,0.0287,-0.9849,0.2276,2.8041
6.24,0.1031,0.0294,-0.9776,0.2349,2.867
6.48,0.1066,0.0298,-0.9732,0.2393,2.9078
6.72,0.1107,0.0303,-0.967,0.2455,2.9632
6.96,0.1149,0.0312,-0.9601,0.2524,3.0422
7.2,0.1185,0.0314,-0.9548,0.2577,3.0689
7.44,0.1225,0.0321,-0.9488,0.2637,3.1321
7.68,0.1267,0.0327,-0.9426,0.2699,3.1944
7.92,0.1305,0.0334,-0.9366,0.2759,3.258
8.16,0.1344,0.0338,-0.9308,0.2817,3.3047
8.4,0.1386,0.0345,-0.9237,0.2888,3.3661
8.64,0.1426,0.0353,-0.9172,0.2953,3.4452
8.88,0.1464,0.0357,-0.9113,0.3012,3.4905
9.12,0.1506,0.0365,-0.904,0.3085,3.5651
9.36,0.1547,0.0373,-0.8967,0.3158,3.6423
9.6,0.1584,0.0379,-0.8909,0.3216,3.7009
9.84,0.1626,0.0386,-0.8842,0.3283,3.7672
10.08,0.1669,0.0394,-0.8765,0.336,3.85
10.32,0.1707,0.0399,-0.8703,0.3422,3.8948
10.56,0.1745,0.0404,-0.8644,0.3481,3.9425
10.8,0.179,0.0412,-0.8565,0.356,4.0273
11.04,0.183,0.0419,-0.8497,0.3628,4.0953
11.28,0.1866,0.0423,-0.8452,0.3673,4.127
11.52,0.1909,0.0431,-0.8376,0.3749,4.2111
11.76,0.1951,0.0438,-0.8301,0.3824,4.2815
12,0.1986,0.0441,-0.8249,0.3876,4.3099
12.24,0.2027,0.0447,-0.8185,0.394,4.3694
12.48,0.2069,0.0455,-0.8117,0.4008,4.4451
12.72,0.2106,0.046,-0.8059,0.4066,4.4899
12.96,0.2145,0.0465,-0.7995,0.413,4.5427
13.2,0.2187,0.0472,-0.7924,0.4201,4.6113
13.44,0.2226,0.048,-0.7855,0.427,4.6856
13.68,0.2264,0.0483,-0.7801,0.4324,4.719
13.92,0.2306,0.0491,-0.7728,0.4397,4.7947
14.16,0.2346,0.0497,-0.7656,0.4469,4.8563
14.4,0.2384,0.0503,-0.76,0.4525,4.9088
14.64,0.2425,0.051,-0.7531,0.4594,4.9792
14.88,0.2467,0.0518,-0.7456,0.4669,5.0542
15.12,0.2505,0.0523,-0.7391,0.4734,5.1033
15.36,0.2545,0.0529,-0.7322,0.4803,5.1646
15.6,0.259,0.0539,-0.7236,0.4889,5.2597
15.84,0.2628,0.0545,-0.7172,0.4953,5.3206
16.08,0.2666,0.055,-0.7109,0.5016,5.3717
16.32,0.271,0.0559,-0.7027,0.5098,5.4561
16.56,0.2751,0.0566,-0.6954,0.5171,5.5318
16.8,0.2786,0.0569,-0.6901,0.5224,5.559
17.04,0.2828,0.0577,-0.6828,0.5297,5.634
17.28,0.2871,0.0585,-0.6756,0.5369,5.7098
17.52,0.2906,0.0589,-0.6701,0.5424,5.7503
17.76,0.2946,0.0594,-0.6634,0.5491,5.7967
18,0.2988,0.0601,-0.6559,0.5566,5.8668
18.24,0.3026,0.0607,-0.65,0.5625,5.9268
18.48,0.3064,0.0611,-0.6439,0.5686,5.965
18.72,0.3106,0.0618,-0.6364,0.5761,6.0329
18.96,0.3145,0.0625,-0.6303,0.5822,6.1006
19.2,0.3183,0.0628,-0.6245,0.588,6.1328
19.44,0.3226,0.0637,-0.6175,0.595,6.2184
19.68,0.3266,0.0643,-0.6105,0.602,6.2799
19.92,0.3304,0.0647,-0.6049,0.6076,6.3204
20.16,0.3345,0.0654,-0.5978,0.6147,6.3888
20.4,0.3388,0.0661,-0.5909,0.6216,6.4588
20.64,0.3426,0.0666,-0.5849,0.6276,6.5032
20.88,0.3466,0.0671,-0.5794,0.6331,6.5559
21.12,0.351,0.0679,-0.5711,0.6414,6.6266
21.36,0.355,0.0685,-0.5646,0.6479,6.6925
21.6,0.3586,0.0687,-0.5599,0.6526,6.711
21.84,0.3629,0.0693,-0.553,0.6595,6.7721
22.08,0.3671,0.07,-0.546,0.6665,6.8376
22.32,0.3706,0.0702,-0.5414,0.6711,6.8591
22.56,0.3747,0.0708,-0.5352,0.6773,6.9097
22.8,0.379,0.0715,-0.5286,0.6839,6.9839
23.04,0.3825,0.0718,-0.5235,0.689,7.0122
23.28,0.3865,0.0724,-0.5173,0.6952,7.0725
23.52,0.3908,0.0729,-0.5107,0.7018,7.1164
23.76,0.3945,0.0734,-0.5055,0.707,7.1674
24,0.3984,0.0738,-0.4997,0.7128,7.2059
24.24,0.4026,0.0745,-0.493,0.7195,7.2734
24.48,0.4066,0.075,-0.4868,0.7257,7.325
24.72,0.4104,0.0755,-0.4813,0.7312,7.3695
24.96,0.4145,0.0761,-0.4752,0.7373,7.4289
25.2,0.4187,0.0767,-0.468,0.7445,7.4933
25.44,0.4224,0.0771,-0.4629,0.7496,7.5309
25.68,0.4265,0.0776,-0.4564,0.7561,7.5829
25.92,0.4309,0.0785,-0.4495,0.763,7.6654
26.16,0.4346,0.0788,-0.444,0.7685,7.6911
26.4,0.4386,0.0792,-0.438,0.7745,7.7391
26.64,0.443,0.08,-0.4302,0.7823,7.816
26.88,0.447,0.0807,-0.4242,0.7883,7.8839
27.12,0.4506,0.0808,-0.4199,0.7926,7.8923
27.36,0.4549,0.0816,-0.4123,0.8002,7.9714
27.6,0.4591,0.0823,-0.4058,0.8067,8.0371
27.84,0.4626,0.0825,-0.4015,0.811,8.0527
28.08,0.4667,0.083,-0.3945,0.818,8.1031
28.32,0.4709,0.0837,-0.3881,0.8244,8.1705
28.56,0.4746,0.0841,-0.3834,0.8291,8.2119
28.8,0.4785,0.0845,-0.3774,0.8351,8.2481
29.04,0.4827,0.085,-0.3702,0.8423,8.3032
29.28,0.4865,0.0857,-0.3645,0.848,8.3651
29.52,0.4904,0.086,-0.3586,0.8539,8.3993
29.76,0.4946,0.0866,-0.3522,0.8603,8.4586
30,0.4986,0.0873,-0.3448,0.8677,8.5258
30.24,0.5024,0.0879,-0.3391,0.8734,8.5798
30.48,0.5065,0.0886,-0.332,0.8805,8.6504
30.72,0.5108,0.0893,-0.3249,0.8876,8.7198
30.96,0.5145,0.0897,-0.3197,0.8928,8.7602
31.2,0.5186,0.0904,-0.313,0.8995,8.8291
31.44,0.523,0.0912,-0.305,0.9075,8.9064
31.68,0.5268,0.0918,-0.2983,0.9142,8.9681
31.92,0.5306,0.0922,-0.2927,0.9198,9.0004
32.16,0.535,0.093,-0.2849,0.9276,9.0861
32.4,0.5391,0.0937,-0.2778,0.9347,9.1485
32.64,0.5426,0.0939,-0.2726,0.9399,9.1702
32.88,0.5468,0.0947,-0.2654,0.9471,9.2505
33.12,0.551,0.0953,-0.2585,0.954,9.3096
33.36,0.5545,0.0956,-0.253,0.9595,9.3353
33.6,0.5586,0.0962,-0.2464,0.9661,9.3982
33.84,0.5628,0.097,-0.2391,0.9734,9.4727
34.08,0.5665,0.0974,-0.2335,0.979,9.5127
34.32,0.5704,0.0979,-0.2273,0.9852,9.5642
34.56,0.5746,0.0987,-0.2203,0.9922,9.6362
34.8,0.5785,0.0992,-0.2134,0.9991,9.6908
35.04,0.5824,0.0997,-0.2077,1.0048,9.7317
35.28,0.5865,0.1004,-0.2004,1.0121,9.8051
35.52,0.5906,0.101,-0.1935,1.019,9.8679
35.76,0.5944,0.1014,-0.1877,1.0248,9.905
36,0.5985,0.102,-0.1809,1.0316,9.9611
36.24,0.6028,0.103,-0.1734,1.0391,10.0555
36.48,0.6066,0.1033,-0.1675,1.045,10.0887
36.72,0.6106,0.1039,-0.1612,1.0513,10.1439
36.96,0.615,0.1046,-0.1532,1.0593,10.2195
37.2,0.619,0.1053,-0.147,1.0655,10.2808
37.44,0.6226,0.1056,-0.1415,1.071,10.3173
37.68,0.627,0.1065,-0.1337,1.0788,10.3973
37.92,0.6311,0.1072,-0.126,1.0865,10.4686
38.16,0.6346,0.1073,-0.122,1.0905,10.4777
38.4,0.6388,0.108,-0.1152,1.0973,10.5486
38.64,0.643,0.1087,-0.1073,1.1052,10.6135
38.88,0.6466,0.109,-0.102,1.1105,10.646
39.12,0.6506,0.1095,-0.0956,1.1169,10.6936
39.36,0.6548,0.1102,-0.0885,1.124,10.7628
39.6,0.6585,0.1107,-0.0827,1.1298,10.8079
39.84,0.6624,0.1111,-0.0762,1.1363,10.8537
40.08,0.6666,0.1118,-0.069,1.1435,10.9168
40.32,0.6706,0.1124,-0.0624,1.1501,10.9748
40.56,0.6744,0.1129,-0.0571,1.1554,11.0278
40.8,0.6786,0.1136,-0.0502,1.1623,11.0893
41.04,0.6827,0.1142,-0.0427,1.1698,11.1513
41.28,0.6864,0.1146,-0.0369,1.1756,11.1888
41.52,0.6905,0.1152,-0.03,1.1825,11.247
41.76,0.6949,0.1161,-0.0227,1.1898,11.3347
42,0.6987,0.1164,-0.0166,1.1959,11.3704
42.24,0.7026,0.117,-0.01,1.2025,11.4218
42.48,0.707,0.1177,-0.0025,1.21,11.4969
42.72,0.711,0.1184,0.0041,1.2166,11.5644
42.96,0.7146,0.1186,0.0094,1.2219,11.5864
43.2,0.7189,0.1194,0.0172,1.2297,11.6619
43.44,0.7231,0.1202,0.0248,1.2373,11.7346
43.68,0.7266,0.1204,0.0293,1.2418,11.7576
43.92,0.7307,0.1211,0.0361,1.2486,11.8297
44.16,0.7349,0.1218,0.0439,1.2564,11.891
44.4,0.7386,0.1222,0.0492,1.2617,11.9355
44.64,0.7425,0.1226,0.0552,1.2677,11.9723
44.88,0.7467,0.1232,0.0625,1.275,12.03
45.12,0.7506,0.1239,0.0691,1.2816,12.0958
45.36,0.7544,0.1242,0.0754,1.2879,12.1332
45.6,0.7586,0.1249,0.0823,1.2948,12.1974
45.84,0.7626,0.1255,0.0891,1.3016,12.26
46.08,0.7664,0.1258,0.0952,1.3077,12.2892
46.32,0.7705,0.1266,0.1023,1.3148,12.36
46.56,0.7747,0.1273,0.1097,1.3222,12.4343
46.8,0.7785,0.1279,0.1162,1.3287,12.4881
47.04,0.7826,0.1286,0.1236,1.3361,12.5542
47.28,0.7869,0.1296,0.1324,1.3449,12.6532
47.52,0.7908,0.13,0.1394,1.3519,12.6995
47.76,0.7946,0.1306,0.146,1.3585,12.7533
48,0.799,0.1315,0.1545,1.367,12.846
48.24,0.8031,0.1322,0.1621,1.3746,12.9113
48.48,0.8066,0.1326,0.1679,1.3804,12.9522
48.72,0.8108,0.1335,0.1762,1.3887,13.0347
48.96,0.815,0.1344,0.1844,1.3969,13.1292
49.2,0.8186,0.1345,0.1902,1.4027,13.1358
49.44,0.8226,0.1352,0.1976,1.4101,13.2045
49.68,0.8268,0.136,0.2059,1.4184,13.2772
49.92,0.8305,0.1365,0.2125,1.425,13.3285
50.16,0.8344,0.1371,0.2197,1.4322,13.3855
50.4,0.8387,0.138,0.228,1.4405,13.473
50.64,0.8425,0.1387,0.2355,1.448,13.542
50.88,0.8464,0.1391,0.2428,1.4553,13.5801
51.12,0.8505,0.1399,0.2509,1.4634,13.6614
51.36,0.8546,0.1406,0.259,1.4715,13.735
51.6,0.8584,0.1413,0.2659,1.4784,13.7941
51.84,0.8625,0.142,0.2741,1.4866,13.8703
52.08,0.8668,0.1429,0.2828,1.4953,13.956
52.32,0.8706,0.1434,0.2888,1.5013,14.0013
52.56,0.8746,0.1439,0.2969,1.5094,14.0553
52.8,0.879,0.145,0.306,1.5185,14.1631
53.04,0.8829,0.1456,0.3131,1.5256,14.2213
53.28,0.8866,0.146,0.3192,1.5317,14.2587
53.52,0.891,0.1469,0.3282,1.5407,14.3414
53.76,0.8951,0.1477,0.3367,1.5492,14.4282
54,0.8985,0.1479,0.342,1.5545,14.4412
54.24,0.9028,0.1486,0.3499,1.5624,14.5138
54.48,0.907,0.1494,0.3584,1.5709,14.5881
54.72,0.9105,0.1497,0.3643,1.5768,14.6211
54.96,0.9146,0.1503,0.3719,1.5844,14.6771
55.2,0.9188,0.1512,0.3801,1.5926,14.7643
55.44,0.9226,0.1517,0.3865,1.599,14.81
55.68,0.9264,0.1521,0.3933,1.6058,14.8546
55.92,0.9306,0.1529,0.4018,1.6143,14.9336
56.16,0.9346,0.1536,0.4092,1.6217,14.9999
56.4,0.9384,0.1542,0.4159,1.6284,15.0548
56.64,0.9425,0.155,0.4243,1.6368,15.1406
56.88,0.9467,0.1559,0.4335,1.646,15.2262
57.12,0.9504,0.1565,0.441,1.6535,15.2811
57.36,0.9545,0.1573,0.4499,1.6624,15.3591
57.6,0.9589,0.1583,0.4598,1.6723,15.4602
57.84,0.9626,0.159,0.4672,1.6797,15.5304
58.08,0.9666,0.1597,0.4757,1.6882,15.5935
58.32,0.971,0.1606,0.4853,1.6978,15.6806
58.56,0.975,0.1614,0.4936,1.7061,15.7627
58.8,0.9785,0.1618,0.4997,1.7122,15.7983
59.04,0.9829,0.1627,0.5092,1.7217,15.8852
59.28,0.9871,0.1635,0.518,1.7305,15.9663
59.52,0.9906,0.1638,0.5241,1.7366,15.9987
59.76,0.9947,0.1644,0.5318,1.7443,16.0542
60,0.999,0.1651,0.5401,1.7526,16.1258
60.24,1.0025,0.1654,0.5456,1.7581,16.1512
60.48,1.0065,0.1658,0.552,1.7645,16.1934
60.72,1.0107,0.1662,0.5579,1.7704,16.2265
60.96,1.0145,0.1658,0.5602,1.7727,16.1888
61.2,1.0184,0.1619,0.5413,1.7538,15.8148
61.44,1.0226,0.1617,0.5415,1.754,15.7918
61.68,1.0266,0.1615,0.5418,1.7543,15.769
61.92,1.0304,0.1618,0.5448,1.7573,15.8022
62.16,1.0346,0.1625,0.5514,1.7639,15.8653
62.4,1.0387,0.1634,0.5592,1.7717,15.9613
62.64,1.0425,0.1641,0.5662,1.7787,16.0293
62.88,1.0466,0.1648,0.5739,1.7864,16.0955
63.12,1.051,0.166,0.583,1.7955,16.2156
63.36,1.0548,0.1666,0.5901,1.8026,16.2721
63.6,1.0586,0.1671,0.597,1.8095,16.3179
63.84,1.063,0.1682,0.6069,1.8194,16.4245
64.08,1.0671,0.169,0.6148,1.8273,16.5049
64.32,1.0706,0.1693,0.6209,1.8334,16.5363
64.56,1.0748,0.1702,0.6294,1.8419,16.6243
64.8,1.0791,0.1712,0.6387,1.8512,16.7167
65.04,1.0826,0.1716,0.6453,1.8578,16.755
65.28,1.0866,0.1724,0.6534,1.8659,16.8356
65.52,1.0908,0.1732,0.6625,1.875,16.9124
65.76,1.0945,0.1738,0.6695,1.882,16.9715
66,1.0985,0.1745,0.678,1.8905,17.0422
66.24,1.1027,0.1753,0.6866,1.8991,17.1232
66.48,1.1066,0.1761,0.6945,1.907,17.1926
66.72,1.1104,0.1766,0.7026,1.9151,17.2465
66.96,1.1146,0.1774,0.7116,1.9241,17.3289
67.2,1.1186,0.1782,0.7206,1.9331,17.4052
67.44,1.1224,0.179,0.7282,1.9407,17.4785
67.68,1.1265,0.1798,0.737,1.9495,17.5559
67.92,1.1308,0.1807,0.7464,1.9589,17.6471
68.16,1.1346,0.1813,0.7541,1.9666,17.7063
68.4,1.1385,0.182,0.7632,1.9757,17.7767
68.64,1.143,0.1832,0.7739,1.9864,17.8915
68.88,1.1469,0.1839,0.7822,1.9947,17.9595
69.12,1.1506,0.1844,0.79,2.0025,18.0112
69.36,1.155,0.1856,0.8005,2.013,18.1241
69.6,1.1591,0.1863,0.8101,2.0226,18.1968
69.84,1.1626,0.1867,0.817,2.0295,18.2366
70.08,1.1668,0.1877,0.8273,2.0398,18.3326
70.32,1.171,0.1888,0.8372,2.0497,18.4344
70.56,1.1745,0.1891,0.8451,2.0576,18.4682
70.8,1.1786,0.19,0.8547,2.0672,18.5517
71.04,1.1828,0.1909,0.8644,2.0769,18.644
71.28,1.1866,0.1917,0.8729,2.0854,18.7183
71.52,1.1904,0.1923,0.8817,2.0942,18.7759
71.76,1.1946,0.1932,0.8921,2.1046,18.865
72,1.1986,0.194,0.9013,2.1138,18.9461
72.24,1.2024,0.1947,0.9096,2.1221,19.012
72.48,1.2065,0.1955,0.9197,2.1322,19.0958
72.72,1.2106,0.1965,0.9297,2.1422,19.1889
72.96,1.2144,0.1971,0.9386,2.1511,19.2447
73.2,1.2185,0.1979,0.9482,2.1607,19.3232
73.44,1.2229,0.199,0.9586,2.1711,19.433
73.68,1.2267,0.1996,0.9676,2.1801,19.4911
73.92,1.2305,0.2003,0.9763,2.1888,19.5557
74.16,1.2351,0.2013,0.9879,2.2004,19.6617
74.4,1.239,0.2021,0.9968,2.2093,19.7371
74.64,1.2426,0.2025,1.0047,2.2172,19.7786
74.88,1.247,0.2036,1.0155,2.228,19.8799
75.12,1.2511,0.2045,1.0254,2.2379,19.9671
75.36,1.2546,0.2048,1.0331,2.2456,20.004
75.6,1.2587,0.2057,1.0433,2.2558,20.0906
75.84,1.263,0.2065,1.0532,2.2657,20.1681
76.08,1.2665,0.2069,1.0612,2.2737,20.2073
76.32,1.2705,0.2077,1.0701,2.2826,20.285
76.56,1.2747,0.2085,1.0801,2.2926,20.3613
76.8,1.2785,0.2091,1.0887,2.3012,20.4245
77.04,1.2824,0.2097,1.0977,2.3102,20.4787
77.28,1.2866,0.2106,1.108,2.3205,20.5708
77.52,1.2906,0.2113,1.1168,2.3293,20.6358
77.76,1.2944,0.2119,1.1257,2.3382,20.6948
78,1.2985,0.2127,1.1356,2.3481,20.7725
78.24,1.3027,0.2136,1.1461,2.3586,20.863
78.48,1.3065,0.2142,1.1547,2.3672,20.9223
78.72,1.3105,0.2148,1.1636,2.3761,20.9768
78.96,1.315,0.2159,1.1747,2.3872,21.0849
79.2,1.3188,0.2164,1.1836,2.3961,21.1349
79.44,1.3226,0.217,1.1925,2.405,21.1878
79.68,1.327,0.218,1.2033,2.4158,21.2852
79.92,1.3311,0.2188,1.2126,2.4251,21.3637
80.16,1.3346,0.219,1.2205,2.433,21.389
80.4,1.3388,0.22,1.2309,2.4434,21.4813
80.64,1.3431,0.2208,1.2416,2.4541,21.56
80.88,1.3465,0.2213,1.2488,2.4613,21.6068
81.12,1.3506,0.2219,1.2585,2.471,21.6685
81.36,1.3549,0.2227,1.2698,2.4823,21.7455
81.6,1.3585,0.2232,1.2777,2.4902,21.7947
81.84,1.3625,0.2239,1.2868,2.4993,21.8676
82.08,1.3667,0.2247,1.297,2.5095,21.943
82.32,1.3705,0.2254,1.3061,2.5186,22.0101
82.56,1.3744,0.2259,1.3154,2.5279,22.0568
82.8,1.3786,0.2268,1.3256,2.5381,22.1473
83.04,1.3826,0.2275,1.3353,2.5478,22.2134
83.28,1.3864,0.228,1.3446,2.5571,22.2612
83.52,1.3905,0.2287,1.3546,2.5671,22.3377
83.76,1.3947,0.2296,1.3651,2.5776,22.4249
84,1.3985,0.2302,1.3736,2.5861,22.4794
84.24,1.4025,0.2309,1.3833,2.5958,22.5457
84.48,1.4069,0.2318,1.3944,2.6069,22.637
84.72,1.4108,0.2324,1.4039,2.6164,22.7001
84.96,1.4146,0.2329,1.4125,2.625,22.7439
85.2,1.419,0.2338,1.4239,2.6364,22.8341
85.44,1.4231,0.2347,1.4338,2.6463,22.9166
85.68,1.4266,0.2349,1.4418,2.6543,22.9357
85.92,1.4308,0.2357,1.4527,2.6652,23.0157
86.16,1.435,0.2367,1.463,2.6755,23.1109
86.4,1.4385,0.2368,1.4707,2.6832,23.1265
86.64,1.4426,0.2374,1.4812,2.6937,23.1878
86.88,1.4468,0.2384,1.4918,2.7043,23.2775
87.12,1.4506,0.2388,1.5006,2.7131,23.3205
87.36,1.4544,0.2394,1.5098,2.7223,23.3743
87.6,1.4586,0.2402,1.5205,2.733,23.4538
87.84,1.4626,0.2409,1.5301,2.7426,23.5206
88.08,1.4664,0.2414,1.5394,2.7519,23.5726
88.32,1.4705,0.2421,1.5496,2.7621,23.6433
88.56,1.4747,0.2429,1.5599,2.7724,23.7178
88.8,1.4784,0.2433,1.5694,2.7819,23.7618
89.04,1.4825,0.244,1.5796,2.7921,23.8302
89.28,1.4869,0.245,1.5907,2.8032,23.9264
89.52,1.4906,0.2455,1.5995,2.812,23.9724
89.76,1.4946,0.246,1.6095,2.822,24.0221
90,1.499,0.247,1.621,2.8335,24.1162
90.24,1.5029,0.2476,1.631,2.8435,24.1795
90.48,1.5066,0.248,1.6401,2.8526,24.2168
90.72,1.5109,0.2489,1.6515,2.864,24.3049
90.96,1.5151,0.2497,1.6621,2.8746,24.3816
91.2,1.5186,0.25,1.6697,2.8822,24.4185
91.44,1.5227,0.2507,1.6812,2.8937,24.4794
91.68,1.5269,0.2515,1.6926,2.9051,24.5597
91.92,1.5306,0.2519,1.7015,2.914,24.6013
92.16,1.5345,0.2525,1.711,2.9235,24.6593
92.4,1.5387,0.2533,1.7227,2.9352,24.7326
92.64,1.5425,0.2538,1.7322,2.9447,24.7892
92.88,1.5464,0.2544,1.7425,2.955,24.8439
93.12,1.5506,0.2551,1.7533,2.9658,24.9152
93.36,1.5546,0.2558,1.7638,2.9763,24.9852
93.6,1.5584,0.2563,1.7733,2.9858,25.0267
93.84,1.5625,0.2571,1.7848,2.9973,25.104
94.08,1.5667,0.2578,1.7961,3.0086,25.1793
94.32,1.5705,0.2584,1.8053,3.0178,25.23
94.56,1.5745,0.2589,1.8162,3.0287,25.2865
94.8,1.5789,0.26,1.8279,3.0404,25.3902
95.04,1.5828,0.2604,1.8386,3.0511,25.4332
95.28,1.5865,0.2609,1.8484,3.0609,25.4826
95.52,1.591,0.2618,1.8609,3.0734,25.5687
95.76,1.5951,0.2626,1.8714,3.0839,25.6457
96,1.5986,0.2628,1.8802,3.0927,25.6599
96.24,1.6029,0.2637,1.8925,3.105,25.7507
96.48,1.6071,0.2644,1.9042,3.1167,25.8252
96.72,1.6105,0.2648,1.9126,3.1251,25.8572
96.96,1.6147,0.2653,1.9241,3.1366,25.9119
97.2,1.6189,0.2661,1.936,3.1485,25.9912
97.44,1.6225,0.2666,1.9454,3.1579,26.0392
97.68,1.6265,0.2672,1.9559,3.1684,26.0912
97.92,1.6307,0.268,1.9678,3.1803,26.1682
98.16,1.6346,0.2685,1.9782,3.1907,26.2226
98.4,1.6384,0.269,1.9885,3.201,26.2693
98.64,1.6426,0.2697,2.0001,3.2126,26.3397
98.88,1.6466,0.2704,2.0118,3.2243,26.4073
99.12,1.6504,0.2709,2.022,3.2345,26.4524
99.36,1.6545,0.2714,2.0332,3.2457,26.5026
99.6,1.6587,0.2724,2.0451,3.2576,26.6023
99.84,1.6625,0.2728,2.0555,3.268,26.6409
100.08,1.6665,0.2735,2.0669,3.2794,26.7071
100.32,1.671,0.2744,2.0799,3.2924,26.7973
100.56,1.6748,0.2749,2.0907,3.3032,26.8433
100.8,1.6786,0.2753,2.1007,3.3132,26.8805
101.04,1.683,0.2761,2.1138,3.3263,26.9623
101.28,1.6871,0.2768,2.1257,3.3382,27.0316
101.52,1.6906,0.2771,2.1349,3.3474,27.0562
101.76,1.6948,0.2778,2.1474,3.3599,27.1317
102,1.6991,0.2786,2.1592,3.3717,27.2114
102.24,1.7026,0.2788,2.1688,3.3813,27.2277
102.48,1.7066,0.2793,2.1808,3.3933,27.2777
102.72,1.7108,0.2801,2.1932,3.4057,27.3582
102.96,1.7146,0.2807,2.2034,3.4159,27.409
103.2,1.7184,0.2811,2.2143,3.4268,27.4478
103.44,1.7227,0.2816,2.227,3.4395,27.5008
103.68,1.7265,0.2823,2.2381,3.4506,27.565
103.92,1.7304,0.2827,2.2485,3.461,27.608
104.16,1.7346,0.2834,2.2609,3.4734,27.6779
104.4,1.7386,0.284,2.273,3.4855,27.7315
104.64,1.7424,0.2845,2.2839,3.4964,27.7857
104.88,1.7465,0.2851,2.2962,3.5087,27.8449
105.12,1.7508,0.2859,2.3086,3.5211,27.92
105.36,1.7546,0.2863,2.3196,3.5321,27.9609
105.6,1.7586,0.2868,2.3314,3.5439,28.0048
105.84,1.763,0.2877,2.3448,3.5573,28.0991
106.08,1.767,0.2882,2.3567,3.5692,28.149
106.32,1.7706,0.2886,2.3668,3.5793,28.1831
106.56,1.775,0.2893,2.3805,3.593,28.2564
106.8,1.7791,0.2901,2.3932,3.6057,28.3274
107.04,1.7826,0.2902,2.4029,3.6154,28.3368
107.28,1.7867,0.291,2.4155,3.628,28.4135
107.52,1.7909,0.2916,2.4286,3.6411,28.4744
107.76,1.7945,0.2919,2.4389,3.6514,28.5063
108,1.7985,0.2924,2.4511,3.6636,28.5525
108.24,1.8027,0.2931,2.464,3.6765,28.6276
108.48,1.8065,0.2935,2.4757,3.6882,28.6617
108.72,1.8104,0.2939,2.4874,3.6999,28.7059
108.96,1.8146,0.2946,2.5,3.7125,28.7711
109.2,1.8186,0.2953,2.5126,3.7251,28.8367
109.44,1.8224,0.2956,2.5242,3.7367,28.8666
109.68,1.8265,0.2961,2.5372,3.7497,28.9207
109.92,1.8307,0.2968,2.5503,3.7628,28.9862
110.16,1.8345,0.2974,2.5623,3.7748,29.0411
110.4,1.8385,0.2979,2.575,3.7875,29.0871
110.64,1.8429,0.2987,2.5889,3.8014,29.1722
110.88,1.8467,0.299,2.6004,3.8129,29.2004
111.12,1.8506,0.2995,2.6126,3.8251,29.2437
111.36,1.855,0.3002,2.6271,3.8396,29.3132
111.6,1.859,0.3008,2.64,3.8525,29.3763
111.84,1.8626,0.3008,2.6502,3.8627,29.3781
112.08,1.8669,0.3017,2.6643,3.8768,29.4599
112.32,1.8711,0.3023,2.6778,3.8903,29.5212
112.56,1.8745,0.3024,2.6881,3.9006,29.5313
112.8,1.8787,0.3029,2.7014,3.9139,29.5811
113.04,1.8829,0.3036,2.7146,3.9271,29.6458
113.28,1.8866,0.3038,2.7261,3.9386,29.6699
113.52,1.8905,0.3041,2.738,3.9505,29.6945
113.76,1.8947,0.3047,2.751,3.9635,29.7528
114,1.8986,0.3049,2.7621,3.9746,29.7761
114.24,1.9024,0.3051,2.7727,3.9852,29.7946
114.48,1.9066,0.3053,2.7844,3.9969,29.8136
114.72,1.9106,0.3056,2.7942,4.0067,29.8437
114.96,1.9144,0.303,2.7888,4.0013,29.5857
115.2,1.9185,0.2996,2.7699,3.9824,29.2616
115.44,1.9227,0.3005,2.7796,3.9921,29.3457
115.68,1.9265,0.3011,2.7904,4.0029,29.4026
115.92,1.9305,0.3017,2.8023,4.0148,29.4602
116.16,1.9349,0.3029,2.8171,4.0296,29.5803
116.4,1.9388,0.3036,2.8308,4.0433,29.6527
116.64,1.9425,0.3041,2.8431,4.0556,29.7007
116.88,1.947,0.3052,2.8584,4.0709,29.8048
117.12,1.9511,0.3058,2.8725,4.085,29.8614
117.36,1.9546,0.3062,2.8844,4.0969,29.9066
117.6,1.9588,0.307,2.8998,4.1123,29.9796
117.84,1.9631,0.3079,2.9145,4.127,30.0639
118.08,1.9666,0.3081,2.9261,4.1386,30.0845
118.32,1.9706,0.3088,2.9408,4.1533,30.1535
118.56,1.9748,0.3095,2.9556,4.1681,30.228
118.8,1.9785,0.31,2.9691,4.1816,30.2725
119.04,1.9825,0.3105,2.9821,4.1946,30.3259
119.28,1.9866,0.3112,2.9976,4.2101,30.3893
119.52,1.9906,0.3117,3.0116,4.2241,30.4436
119.76,1.9944,0.3121,3.0254,4.2379,30.4808
120,1.9986,0.3129,3.0404,4.2529,30.5556
120.24,2.0026,0.3135,3.0549,4.2674,30.6125
120.48,2.0064,0.3139,3.0685,4.281,30.6528
120.72,2.0106,0.3145,3.0841,4.2966,30.7135
120.96,2.0148,0.3151,3.0999,4.3124,30.7688
121.2,2.0186,0.3158,3.1139,4.3264,30.8388
121.44,2.0226,0.3163,3.1281,4.3406,30.8862
121.68,2.027,0.3171,3.1444,4.3569,30.9629
121.92,2.031,0.3175,3.1598,4.3723,31.0056
122.16,2.0346,0.3178,3.1731,4.3856,31.0327
122.4,2.039,0.3186,3.1899,4.4024,31.1113
122.64,2.0431,0.3192,3.2054,4.4179,31.1736
122.88,2.0466,0.3193,3.2185,4.431,31.181
123.12,2.0507,0.32,3.2339,4.4464,31.2504
123.36,2.055,0.3207,3.2511,4.4636,31.3157
123.6,2.0585,0.3209,3.2645,4.477,31.3378
123.84,2.0625,0.3214,3.2799,4.4924,31.382
124.08,2.0668,0.322,3.296,4.5085,31.4416
124.32,2.0706,0.3226,3.311,4.5235,31.5052
124.56,2.0744,0.323,3.3265,4.539,31.5406
124.8,2.0786,0.3235,3.3431,4.5556,31.5879
125.04,2.0826,0.324,3.3584,4.5709,31.6397
125.28,2.0864,0.3244,3.3736,4.5861,31.6775
125.52,2.0906,0.3249,3.3899,4.6024,31.7274
125.76,2.0947,0.3255,3.4066,4.6191,31.7862
126,2.0984,0.3259,3.4219,4.6344,31.8306
126.24,2.1025,0.3263,3.4385,4.651,31.8645
126.48,2.1069,0.327,3.456,4.6685,31.9364
126.72,2.1107,0.3274,3.4716,4.6841,31.9742
126.96,2.1145,0.3278,3.4875,4.7,32.0115
127.2,2.119,0.3284,3.5059,4.7184,32.0742
127.44,2.123,0.329,3.5221,4.7346,32.1282
127.68,2.1266,0.3291,3.5371,4.7496,32.1431
127.92,2.1309,0.3298,3.555,4.7675,32.2044
128.16,2.1351,0.3304,3.5731,4.7856,32.2674
128.4,2.1386,0.3305,3.5873,4.7998,32.2769
128.64,2.1427,0.331,3.6047,4.8172,32.3264
128.88,2.1469,0.3316,3.6227,4.8352,32.3859
129.12,2.1506,0.3318,3.638,4.8505,32.4058
129.36,2.1545,0.3324,3.6547,4.8672,32.4571
129.6,2.1587,0.3328,3.6731,4.8856,32.5016
129.84,2.1626,0.3332,3.69,4.9025,32.5365
130.08,2.1664,0.3335,3.7062,4.9187,32.5698
130.32,2.1706,0.334,3.7244,4.9369,32.6135
130.56,2.1746,0.3345,3.7423,4.9548,32.662
130.8,2.1784,0.3347,3.7589,4.9714,32.6885
131.04,2.1825,0.3351,3.7769,4.9894,32.7259
131.28,2.1867,0.3358,3.7959,5.0084,32.7904
131.52,2.1905,0.3361,3.8138,5.0263,32.8246
131.76,2.1945,0.3367,3.8319,5.0444,32.8774
132,2.1989,0.3373,3.852,5.0645,32.9394
132.24,2.2028,0.3376,3.8694,5.0819,32.9692
132.48,2.2066,0.3379,3.8871,5.0996,33.0011
132.72,2.211,0.3385,3.9075,5.12,33.0606
132.96,2.2151,0.3391,3.9268,5.1393,33.1156
133.2,2.2185,0.3392,3.9429,5.1554,33.1205
133.44,2.2229,0.3396,3.9631,5.1756,33.1676
133.68,2.2271,0.3403,3.9829,5.1954,33.232
133.92,2.2305,0.3403,4,5.2125,33.2277
134.16,2.2346,0.3407,4.0193,5.2318,33.2754
134.4,2.2388,0.3413,4.0395,5.252,33.3325
134.64,2.2425,0.3415,4.0576,5.2701,33.3527
134.88,2.2464,0.3418,4.0766,5.2891,33.3779
135.12,2.2507,0.3422,4.0972,5.3097,33.4223
135.36,2.2546,0.3427,4.1158,5.3283,33.4621
135.6,2.2584,0.3429,4.1344,5.3469,33.4839
135.84,2.2626,0.3434,4.155,5.3675,33.5382
136.08,2.2666,0.3439,4.1755,5.388,33.5846
136.32,2.2704,0.344,4.1944,5.4069,33.5916
136.56,2.2745,0.3444,4.215,5.4275,33.6334
136.8,2.2788,0.345,4.2361,5.4486,33.6921
137.04,2.2826,0.3452,4.255,5.4675,33.7066
137.28,2.2865,0.3455,4.2754,5.4879,33.7382
137.52,2.291,0.3461,4.2977,5.5102,33.7997
137.76,2.2949,0.3465,4.3175,5.53,33.8373
138,2.2986,0.3464,4.3365,5.549,33.8275
138.24,2.303,0.3471,4.3584,5.5709,33.8946
138.48,2.3071,0.3475,4.3802,5.5927,33.9322
138.72,2.3106,0.3475,4.399,5.6115,33.9403
138.96,2.3147,0.3478,4.42,5.6325,33.9613
139.2,2.319,0.3483,4.4421,5.6546,34.0102
139.44,2.3225,0.3483,4.4613,5.6738,34.0088
139.68,2.3265,0.3486,4.4825,5.695,34.0394
139.92,2.3308,0.349,4.5048,5.7173,34.0835
140.16,2.3346,0.3493,4.5249,5.7374,34.1078
140.4,2.3384,0.3493,4.546,5.7585,34.1123
140.64,2.3426,0.3498,4.5686,5.7811,34.1594
140.88,2.3466,0.35,4.59,5.8025,34.1828
141.12,2.3504,0.3502,4.6101,5.8226,34.1976
141.36,2.3545,0.3506,4.6327,5.8452,34.2367
141.6,2.3587,0.3509,4.6553,5.8678,34.2706
141.84,2.3624,0.3511,4.677,5.8895,34.2874
142.08,2.3665,0.3514,4.699,5.9115,34.3136
142.32,2.3708,0.3518,4.7223,5.9348,34.3586
142.56,2.3746,0.352,4.7438,5.9563,34.3741
142.8,2.3785,0.3522,4.7661,5.9786,34.3922
143.04,2.383,0.3528,4.7905,6.003,34.4521
143.28,2.387,0.353,4.8128,6.0253,34.4708
143.52,2.3906,0.3529,4.8334,6.0459,34.4638
143.76,2.3949,0.3533,4.8578,6.0703,34.5022
144,2.3991,0.3537,4.8814,6.0939,34.5455
144.24,2.4026,0.3536,4.9016,6.1141,34.5303
144.48,2.4067,0.3538,4.925,6.1375,34.5553
144.72,2.4109,0.3542,4.95,6.1625,34.5897
144.96,2.4145,0.3543,4.9711,6.1836,34.6045
145.2,2.4185,0.3544,4.9945,6.207,34.6139
145.44,2.4227,0.3547,5.0185,6.231,34.6411
145.68,2.4266,0.355,5.0416,6.2541,34.6664
145.92,2.4304,0.355,5.0649,6.2774,34.6687
146.16,2.4346,0.3554,5.0889,6.3014,34.7039
146.4,2.4386,0.3555,5.1127,6.3252,34.7153
146.64,2.4424,0.3554,5.1354,6.3479,34.711
146.88,2.4466,0.356,5.1606,6.3731,34.7641
147.12,2.4507,0.3561,5.1853,6.3978,34.7773
147.36,2.4545,0.3562,5.2084,6.4209,34.7816
147.6,2.4585,0.3564,5.2327,6.4452,34.8084
147.84,2.4629,0.3568,5.2587,6.4712,34.8441
148.08,2.4668,0.357,5.2823,6.4948,34.8625
148.32,2.4706,0.3569,5.3065,6.519,34.8569
148.56,2.475,0.3574,5.3328,6.5453,34.9036
148.8,2.4791,0.3575,5.3577,6.5702,34.9165
149.04,2.4826,0.3574,5.3806,6.5931,34.9005
149.28,2.4868,0.3578,5.4065,6.619,34.9423
149.52,2.4911,0.3579,5.4327,6.6452,34.9545
149.76,2.4945,0.3579,5.4554,6.6679,34.9492
150,2.4986,0.358,5.4811,6.6936,34.9589
150.24,2.5028,0.3583,5.5071,6.7196,34.986
150.48,2.5065,0.3582,5.5311,6.7436,34.9853
150.72,2.5105,0.3583,5.5567,6.7692,34.986
150.96,2.5146,0.3585,5.5829,6.7954,35.0126
151.2,2.5186,0.3586,5.6079,6.8204,35.0238
151.44,2.5224,0.3587,5.6329,6.8454,35.0249
151.68,2.5266,0.3588,5.6597,6.8722,35.0412
151.92,2.5306,0.359,5.6859,6.8984,35.0633
152.16,2.5344,0.3591,5.7107,6.9232,35.0646
152.4,2.5385,0.3591,5.7372,6.9497,35.0666
152.64,2.5428,0.3595,5.7645,6.977,35.1049
152.88,2.5466,0.3595,5.7901,7.0026,35.1036
153.12,2.5505,0.3595,5.8162,7.0287,35.1064
153.36,2.555,0.36,5.8443,7.0568,35.1516
153.6,2.5589,0.36,5.8704,7.0829,35.1608
153.84,2.5626,0.3597,5.8957,7.1082,35.1257
154.08,2.567,0.3601,5.9243,7.1368,35.167
154.32,2.5711,0.3604,5.9516,7.1641,35.1917
154.56,2.5746,0.36,5.976,7.1885,35.161
154.8,2.5788,0.3602,6.0039,7.2164,35.1768
155.04,2.583,0.3605,6.0318,7.2443,35.2085
155.28,2.5865,0.3603,6.057,7.2695,35.1889
155.52,2.5906,0.3603,6.0846,7.2971,35.1845
155.76,2.5948,0.3606,6.1127,7.3252,35.2105
156,2.5985,0.3605,6.1391,7.3516,35.2013
156.24,2.6024,0.3606,6.1659,7.3784,35.2121
156.48,2.6066,0.3607,6.1942,7.4067,35.2225
156.72,2.6106,0.3607,6.2217,7.4342,35.224
156.96,2.6144,0.3606,6.2487,7.4612,35.2144
157.2,2.6186,0.3608,6.2773,7.4898,35.2339
157.44,2.6227,0.3608,6.3056,7.5181,35.2373
157.68,2.6264,0.3608,6.3327,7.5452,35.235
157.92,2.6305,0.3609,6.3612,7.5737,35.2402
158.16,2.6348,0.3612,6.3906,7.6031,35.2696
158.4,2.6386,0.3611,6.4178,7.6303,35.2605
158.64,2.6425,0.361,6.4461,7.6586,35.2521
158.88,2.647,0.3614,6.4766,7.6891,35.2948
159.12,2.6509,0.3614,6.5049,7.7174,35.2978
159.36,2.6546,0.3612,6.5315,7.744,35.2712
159.6,2.6589,0.3615,6.562,7.7745,35.3024
159.84,2.6631,0.3615,6.5911,7.8036,35.3053
160.08,2.6666,0.3613,6.6179,7.8304,35.2796
160.32,2.6707,0.3613,6.6473,7.8598,35.2873
160.56,2.6749,0.3615,6.677,7.8895,35.2998
160.8,2.6786,0.3614,6.7042,7.9167,35.2882
161.04,2.6825,0.3613,6.7333,7.9458,35.2821
161.28,2.6867,0.3615,6.7639,7.9764,35.2985
161.52,2.6906,0.3613,6.7924,8.0049,35.2868
161.76,2.6944,0.3612,6.8209,8.0334,35.2761
162,2.6986,0.3613,6.8508,8.0633,35.287
162.24,2.7026,0.3613,6.8806,8.0931,35.2875
162.48,2.7064,0.3613,6.9092,8.1217,35.2786
162.72,2.7105,0.3614,6.9391,8.1516,35.2951
162.96,2.7147,0.3613,6.9693,8.1818,35.2868
163.2,2.7185,0.3614,6.9983,8.2108,35.2946
163.44,2.7225,0.3614,7.0286,8.2411,35.2942
163.68,2.7269,0.3616,7.0601,8.2726,35.3116
163.92,2.7308,0.3616,7.0894,8.3019,35.3096
164.16,2.7346,0.3614,7.1185,8.331,35.2956
164.4,2.739,0.3616,7.1509,8.3634,35.3136
164.64,2.7431,0.3616,7.1813,8.3938,35.316
164.88,2.7466,0.3613,7.2091,8.4216,35.2822
165.12,2.7509,0.3614,7.2404,8.4529,35.2978
165.36,2.7551,0.3615,7.2715,8.484,35.3044
165.6,2.7585,0.3611,7.2997,8.5122,35.2667
165.84,2.7626,0.3612,7.3306,8.5431,35.2765
166.08,2.7668,0.3613,7.3618,8.5743,35.2794
166.32,2.7705,0.3611,7.3905,8.603,35.2653
166.56,2.7744,0.361,7.4214,8.6339,35.2548
166.8,2.7787,0.3611,7.4529,8.6654,35.2652
167.04,2.7826,0.3611,7.4832,8.6957,35.2626
167.28,2.7864,0.3609,7.513,8.7255,35.2404
167.52,2.7906,0.3608,7.5444,8.7569,35.2351
167.76,2.7947,0.361,7.5759,8.7884,35.2525
168,2.7984,0.3608,7.6058,8.8183,35.2304
168.24,2.8025,0.3608,7.6373,8.8498,35.235
168.48,2.8068,0.361,7.6695,8.882,35.2512
168.72,2.8105,0.3608,7.6995,8.912,35.2365
168.96,2.8145,0.3606,7.7304,8.9429,35.2169
169.2,2.819,0.3609,7.764,8.9765,35.2407
169.44,2.8229,0.3609,7.7945,9.007,35.24
169.68,2.8265,0.3606,7.8245,9.037,35.2112
169.92,2.831,0.3608,7.8579,9.0704,35.2317
170.16,2.8351,0.361,7.8899,9.1024,35.2498
170.4,2.8386,0.3604,7.919,9.1315,35.1949
170.64,2.8428,0.3605,7.9516,9.1641,35.2044
170.88,2.847,0.3606,7.9838,9.1963,35.2146
171.12,2.8506,0.3603,8.0138,9.2263,35.1833
171.36,2.8546,0.3602,8.0455,9.258,35.1737
171.6,2.8588,0.3604,8.0781,9.2906,35.1958
171.84,2.8626,0.3601,8.1084,9.3209,35.1683
172.08,2.8664,0.3601,8.1401,9.3526,35.1638
172.32,2.8706,0.3601,8.1724,9.3849,35.1644
172.56,2.8746,0.3599,8.2043,9.4168,35.1477
172.8,2.8784,0.3597,8.235,9.4475,35.1316
173.04,2.8826,0.3598,8.2676,9.4801,35.1395
173.28,2.8867,0.3598,8.3002,9.5127,35.1397
173.52,2.8904,0.3596,8.3312,9.5437,35.1202
173.76,2.8945,0.3595,8.3639,9.5764,35.1084
174,2.8988,0.3596,8.3965,9.609,35.1213
174.24,2.9026,0.3595,8.4285,9.641,35.1085
174.48,2.9065,0.3593,8.4599,9.6724,35.0864
174.72,2.911,0.3596,8.4947,9.7072,35.1206
174.96,2.915,0.3596,8.5266,9.7391,35.1183
175.2,2.9186,0.3592,8.5568,9.7693,35.0815
175.44,2.923,0.3593,8.5913,9.8038,35.0905
175.68,2.9271,0.3594,8.6237,9.8362,35.1012
175.92,2.9306,0.359,8.6539,9.8664,35.058
176.16,2.9347,0.3591,8.6869,9.8994,35.0655
176.4,2.939,0.3592,8.7203,9.9328,35.0795
176.64,2.9425,0.3588,8.7507,9.9632,35.0411
176.88,2.9465,0.3587,8.7834,9.9959,35.0244
177.12,2.9507,0.3586,8.8166,10.0291,35.023
177.36,2.9545,0.3586,8.8482,10.0607,35.0172
177.6,2.9584,0.3584,8.8803,10.0928,34.9954
177.84,2.9626,0.3583,8.914,10.1265,34.995
178.08,2.9666,0.3584,8.946,10.1585,34.9998
178.32,2.9704,0.3581,8.9774,10.1899,34.9723
178.56,2.9745,0.3582,9.011,10.2235,34.9807
178.8,2.9787,0.3583,9.0442,10.2567,34.9878
179.04,2.9825,0.358,9.0764,10.2889,34.9578
179.28,2.9865,0.358,9.1092,10.3217,34.9604
179.52,2.9909,0.3581,9.1432,10.3557,34.9734
179.76,2.9948,0.3579,9.175,10.3875,34.9551
180,2.9986,0.3578,9.2073,10.4198,34.9379
180.24,3.003,0.3579,9.242,10.4545,34.9518
180.48,3.0071,0.3579,9.2752,10.4877,34.9509
180.72,3.0106,0.3575,9.3057,10.5182,34.9094
180.96,3.0148,0.3575,9.3397,10.5522,34.9138
181.2,3.0191,0.3576,9.3734,10.5859,34.9172
181.44,3.0225,0.3573,9.4038,10.6163,34.8902
181.68,3.0266,0.3572,9.4372,10.6497,34.8823
181.92,3.0309,0.3573,9.4708,10.6833,34.8929
182.16,3.0345,0.357,9.5023,10.7148,34.8594
182.4,3.0385,0.3568,9.5345,10.747,34.8483
182.64,3.0427,0.3569,9.569,10.7815,34.8559
182.88,3.0466,0.3567,9.6011,10.8136,34.8351
183.12,3.0504,0.3565,9.6329,10.8454,34.8192
183.36,3.0546,0.3565,9.6667,10.8792,34.8157
183.6,3.0586,0.3565,9.7001,10.9126,34.8157
183.84,3.0624,0.3562,9.7318,10.9443,34.7861
184.08,3.0666,0.3562,9.7653,10.9778,34.7894
184.32,3.0708,0.3564,9.7992,11.0117,34.8027
184.56,3.0745,0.3562,9.8311,11.0436,34.781
184.8,3.0785,0.3561,9.8645,11.077,34.7745
185.04,3.0829,0.3563,9.8994,11.1119,34.7914
185.28,3.0868,0.356,9.9316,11.1441,34.7631
185.52,3.0905,0.3557,9.9635,11.176,34.7411
185.76,3.095,0.356,9.9988,11.2113,34.7628
186,3.0991,0.3561,10.0319,11.2444,34.7722
186.24,3.1026,0.3556,10.0629,11.2754,34.7298
186.48,3.1068,0.3556,10.0971,11.3096,34.7314
186.72,3.1111,0.3557,10.1311,11.3436,34.7376
186.96,3.1146,0.3554,10.1619,11.3744,34.7043
187.2,3.1186,0.3552,10.1958,11.4083,34.6846
187.44,3.1228,0.3552,10.2295,11.442,34.685
187.68,3.1266,0.355,10.2615,11.474,34.6713
187.92,3.1304,0.3548,10.2939,11.5064,34.6442
188.16,3.1346,0.355,10.3279,11.5404,34.667
188.4,3.1386,0.3548,10.3609,11.5734,34.6487
188.64,3.1424,0.3546,10.3926,11.6051,34.6262
188.88,3.1465,0.3546,10.4268,11.6393,34.629
189.12,3.1506,0.3547,10.4605,11.673,34.64
189.36,3.1544,0.3544,10.493,11.7055,34.613
189.6,3.1585,0.3544,10.526,11.7385,34.6093
189.84,3.1628,0.3545,10.5602,11.7727,34.6202
190.08,3.1666,0.3543,10.5931,11.8056,34.5973
190.32,3.1705,0.3541,10.6257,11.8382,34.5821
190.56,3.175,0.3543,10.6612,11.8737,34.5972
190.8,3.1789,0.3543,10.6938,11.9063,34.5953
191.04,3.1826,0.354,10.7251,11.9376,34.5695
191.28,3.187,0.3541,10.7605,11.973,34.5783
191.52,3.1911,0.3541,10.7939,12.0064,34.5801
191.76,3.1946,0.3536,10.8243,12.0368,34.536
192,3.1987,0.3536,10.8582,12.0707,34.5341
192.24,3.2029,0.3537,10.8923,12.1048,34.5377
192.48,3.2065,0.3533,10.9239,12.1364,34.5049
192.72,3.2105,0.3534,10.957,12.1695,34.5086
192.96,3.2147,0.3533,10.9909,12.2034,34.4993
193.2,3.2185,0.3532,11.0233,12.2358,34.4939
193.44,3.2224,0.353,11.0551,12.2676,34.4755
193.68,3.2266,0.3531,11.0894,12.3019,34.4785
193.92,3.2306,0.353,11.1228,12.3353,34.4694
194.16,3.2344,0.3528,11.1547,12.3672,34.4512
194.4,3.2385,0.3527,11.1882,12.4007,34.4458
194.64,3.2427,0.3528,11.2213,12.4338,34.4519
194.88,3.2465,0.3526,11.2536,12.4661,34.4366
195.12,3.2505,0.3525,11.2873,12.4998,34.4243
195.36,3.2549,0.3526,11.3216,12.5341,34.4366
195.6,3.2587,0.3525,11.3538,12.5663,34.419
195.84,3.2625,0.3524,11.3857,12.5982,34.4093
196.08,3.267,0.3524,11.4207,12.6332,34.4169
196.32,3.271,0.3524,11.4537,12.6662,34.4111
196.56,3.2746,0.3521,11.4844,12.6969,34.3893
196.8,3.2789,0.3522,11.5188,12.7313,34.3918
197.04,3.2831,0.3522,11.5526,12.7651,34.3982
197.28,3.2866,0.3518,11.5831,12.7956,34.3544
197.52,3.2906,0.3518,11.616,12.8285,34.3518
197.76,3.2949,0.3518,11.6499,12.8624,34.354
198,3.2985,0.3515,11.6812,12.8937,34.327
198.24,3.3025,0.3514,11.7135,12.926,34.3212
198.48,3.3067,0.3515,11.7471,12.9596,34.3217
198.72,3.3105,0.3513,11.7797,12.9922,34.3108
198.96,3.3144,0.3513,11.8117,13.0242,34.3024
199.2,3.3186,0.3513,11.8454,13.0579,34.306
199.44,3.3226,0.3511,11.8779,13.0904,34.2866
199.68,3.3264,0.3511,11.9092,13.1217,34.2902
199.92,3.3305,0.351,11.9426,13.1551,34.2821
200.16,3.3347,0.3511,11.9761,13.1886,34.2842
200.4,3.3385,0.3509,12.0082,13.2207,34.2721
200.64,3.3425,0.3509,12.0411,13.2536,34.2652
200.88,3.3469,0.351,12.075,13.2875,34.2805
201.12,3.3508,0.3509,12.1073,13.3198,34.2662
201.36,3.3546,0.3507,12.1392,13.3517,34.2527
201.6,3.359,0.3508,12.1738,13.3863,34.2607
201.84,3.3631,0.3508,12.2067,13.4192,34.2541
202.08,3.3666,0.3504,12.2366,13.4491,34.2139
202.32,3.3708,0.3504,12.2708,13.4833,34.2166
202.56,3.3751,0.3505,12.3044,13.5169,34.2306
202.8,3.3786,0.3502,12.3354,13.5479,34.2008
203.04,3.3826,0.3502,12.3682,13.5807,34.1976
203.28,3.3868,0.3503,12.4016,13.6141,34.2062
203.52,3.3906,0.35,12.4332,13.6457,34.1796
203.76,3.3944,0.3499,12.4657,13.6782,34.1722
204,3.3986,0.3499,12.499,13.7115,34.1685
204.24,3.4026,0.3498,12.5321,13.7446,34.1603
204.48,3.4064,0.3497,12.5634,13.7759,34.151
204.72,3.4106,0.3497,12.597,13.8095,34.1533
204.96,3.4147,0.3497,12.6303,13.8428,34.1528
205.2,3.4184,0.3495,12.6624,13.8749,34.1297
205.44,3.4225,0.3495,12.6959,13.9084,34.1326
205.68,3.4268,0.3496,12.7298,13.9423,34.1384
205.92,3.4306,0.3495,12.7615,13.974,34.128
206.16,3.4345,0.3493,12.7948,14.0073,34.1068
206.4,3.439,0.3496,12.8296,14.0421,34.1361
206.64,3.4429,0.3495,12.8619,14.0744,34.1328
206.88,3.4466,0.3491,12.8936,14.1061,34.0908
207.12,3.451,0.3493,12.9285,14.141,34.1121
207.36,3.4551,0.3493,12.9623,14.1748,34.1143
207.6,3.4586,0.3489,12.9925,14.205,34.0766
207.84,3.4627,0.3489,13.0261,14.2386,34.0727
208.08,3.4669,0.349,13.0606,14.2731,34.0802
208.32,3.4705,0.3488,13.0915,14.304,34.0605
208.56,3.4745,0.3487,13.1244,14.3369,34.0493
208.8,3.4787,0.3487,13.1583,14.3708,34.0574
209.04,3.4825,0.3486,13.1908,14.4033,34.0405
209.28,3.4864,0.3484,13.2235,14.436,34.0201
209.52,3.4906,0.3485,13.2576,14.4701,34.032
209.76,3.4946,0.3485,13.2902,14.5027,34.0347
210,3.4984,0.3483,13.3226,14.5351,34.0147
210.24,3.5025,0.3483,13.3564,14.5689,34.0185
210.48,3.5067,0.3484,13.3905,14.603,34.0231
210.72,3.5105,0.3482,13.4221,14.6346,34.003
210.96,3.5145,0.3482,13.4561,14.6686,34.0085
211.2,3.5189,0.3484,13.4906,14.7031,34.0264
211.44,3.5227,0.3483,13.5229,14.7354,34.01
211.68,3.5265,0.348,13.5555,14.768,33.9843
211.92,3.531,0.3483,13.5906,14.8031,34.0152
212.16,3.535,0.3482,13.624,14.8365,34.0001
212.4,3.5386,0.3479,13.6551,14.8676,33.9755
212.64,3.5429,0.3481,13.6898,14.9023,33.9902
212.88,3.5471,0.348,13.7244,14.9369,33.9856
213.12,3.5505,0.3477,13.7547,14.9672,33.9555
213.36,3.5547,0.3478,13.7887,15.0012,33.9668
213.6,3.5589,0.3478,13.823,15.0355,33.9677
213.84,3.5625,0.3475,13.8539,15.0664,33.9354
214.08,3.5665,0.3475,13.8873,15.0998,33.9341
214.32,3.5707,0.3475,13.9221,15.1346,33.9397
214.56,3.5746,0.3474,13.9545,15.167,33.9241
214.8,3.5784,0.3473,13.9867,15.1992,33.9171
215.04,3.5826,0.3474,14.0212,15.2337,33.922
215.28,3.5866,0.3475,14.0544,15.2669,33.9337
215.52,3.5904,0.3473,14.0868,15.2993,33.9113
215.76,3.5945,0.3471,14.1206,15.3331,33.8977
216,3.5987,0.3473,14.1553,15.3678,33.9194
216.24,3.6025,0.3472,14.187,15.3995,33.9049
216.48,3.6065,0.347,14.2206,15.4331,33.8895
216.72,3.6109,0.3473,14.2556,15.4681,33.919
216.96,3.6148,0.3471,14.2886,15.5011,33.9
217.2,3.6185,0.347,14.3212,15.5337,33.8851
217.44,3.623,0.3471,14.3565,15.569,33.898
217.68,3.6271,0.3472,14.3903,15.6028,33.9111
217.92,3.6306,0.347,14.422,15.6345,33.8865
218.16,3.6348,0.347,14.4565,15.669,33.8882
218.4,3.639,0.347,14.4907,15.7032,33.8834
218.64,3.6426,0.3468,14.5216,15.7341,33.8719
218.88,3.6466,0.3467,14.5554,15.7679,33.8535
219.12,3.6508,0.3468,14.5907,15.8032,33.8704
219.36,3.6546,0.3468,14.6219,15.8344,33.8652
219.6,3.6585,0.3465,14.6554,15.8679,33.8358
219.84,3.6627,0.3466,14.6899,15.9024,33.8475
220.08,3.6666,0.3467,14.7228,15.9353,33.8539
220.32,3.6704,0.3464,14.7555,15.968,33.8246
220.56,3.6746,0.3465,14.79,16.0025,33.8413
220.8,3.6786,0.3465,14.8235,16.036,33.8361
221.04,3.6824,0.3464,14.8561,16.0686,33.8319
221.28,3.6865,0.3465,14.8901,16.1026,33.8337
221.52,3.6908,0.3465,14.9245,16.137,33.836
221.76,3.6946,0.3464,14.9572,16.1697,33.8274
222,3.6986,0.3463,14.9906,16.2031,33.8221
222.24,3.703,0.3465,15.026,16.2385,33.8393
222.48,3.707,0.3465,15.0592,16.2717,33.8356
222.72,3.7106,0.3462,15.091,16.3035,33.8103
222.96,3.715,0.3464,15.1267,16.3392,33.8245
223.2,3.7191,0.3464,15.161,16.3735,33.8274
223.44,3.7226,0.3461,15.192,16.4045,33.8022
223.68,3.7267,0.3461,15.2262,16.4387,33.8009
223.92,3.731,0.3462,15.2607,16.4732,33.8094
224.16,3.7345,0.3459,15.2921,16.5046,33.7801
224.4,3.7385,0.3458,15.3258,16.5383,33.7733
224.64,3.7427,0.346,15.3608,16.5733,33.7937
224.88,3.7465,0.3459,15.3928,16.6053,33.7782
225.12,3.7504,0.3459,15.4257,16.6382,33.7787
225.36,3.7546,0.346,15.4604,16.6729,33.7874
225.6,3.7586,0.3459,15.4944,16.7069,33.7746
225.84,3.7624,0.3457,15.5264,16.7389,33.7643
226.08,3.7665,0.3459,15.5608,16.7733,33.7773
226.32,3.7707,0.3459,15.5953,16.8078,33.7781
226.56,3.7744,0.3457,15.6277,16.8402,33.7564
226.8,3.7785,0.3457,15.6618,16.8743,33.7641
227.04,3.7829,0.3458,15.6969,16.9094,33.7744
227.28,3.7867,0.3457,15.73,16.9425,33.7636
227.52,3.7905,0.3456,15.7625,16.975,33.7487
227.76,3.795,0.3458,15.799,17.0115,33.7728
228,3.799,0.3458,15.8321,17.0446,33.7649
228.24,3.8026,0.3456,15.8642,17.0767,33.7493
228.48,3.8069,0.3458,15.8996,17.1121,33.772
228.72,3.8111,0.3458,15.9341,17.1466,33.7724
228.96,3.8146,0.3456,15.9652,17.1777,33.7457
229.2,3.8187,0.3455,15.9996,17.2121,33.7447
229.44,3.823,0.3456,16.0341,17.2466,33.7472
229.68,3.8266,0.3455,16.0658,17.2783,33.7385
229.92,3.8305,0.3454,16.1,17.3125,33.7257
230.16,3.8347,0.3455,16.1342,17.3467,33.7425
230.4,3.8386,0.3454,16.1674,17.3799,33.7343
230.64,3.8424,0.3453,16.2008,17.4133,33.7162
230.88,3.8466,0.3454,16.2353,17.4478,33.7296
231.12,3.8506,0.3454,16.2692,17.4817,33.7348
231.36,3.8544,0.3452,16.3021,17.5146,33.7061
231.6,3.8585,0.3453,16.3359,17.5484,33.7194
231.84,3.8627,0.3454,16.3705,17.583,33.7327
232.08,3.8665,0.3452,16.4034,17.6159,33.7116
232.32,3.8705,0.3452,16.4371,17.6496,33.7061
232.56,3.8749,0.3454,16.473,17.6855,33.7332
232.8,3.8788,0.3453,16.5058,17.7183,33.7161
233.04,3.8826,0.3452,16.5387,17.7512,33.7133
233.28,3.887,0.3455,16.5745,17.787,33.7366
233.52,3.8911,0.3455,16.6084,17.8209,33.7373
233.76,3.8946,0.3452,16.6399,17.8524,33.7154
234,3.8989,0.3453,16.675,17.8875,33.7202
234.24,3.9031,0.3454,16.71,17.9225,33.7285
234.48,3.9066,0.3451,16.741,17.9535,33.7046
234.72,3.9106,0.3451,16.7751,17.9876,33.7012
234.96,3.9148,0.3453,16.8098,18.0223,33.7189
235.2,3.9185,0.345,16.842,18.0545,33.6962
235.44,3.9224,0.345,16.875,18.0875,33.6938
235.68,3.9267,0.3451,16.9096,18.1221,33.701
235.92,3.9305,0.3451,16.9428,18.1553,33.7027
236.16,3.9344,0.345,16.9757,18.1882,33.6952
236.4,3.9386,0.345,17.0102,18.2227,33.6928
236.64,3.9426,0.3451,17.044,18.2565,33.699
236.88,3.9464,0.3449,17.0764,18.2889,33.6823
237.12,3.9505,0.3449,17.1106,18.3231,33.6817
237.36,3.9548,0.3451,17.145,18.3575,33.705
237.6,3.9586,0.3451,17.1779,18.3904,33.7021
237.84,3.9626,0.3449,17.2109,18.4234,33.6847
238.08,3.967,0.3453,17.2466,18.4591,33.7227
238.32,3.9709,0.3453,17.2795,18.492,33.7231
238.56,3.9746,0.3451,17.3117,18.5242,33.6982
238.8,3.9789,0.3451,17.3466,18.5591,33.7019
239.04,3.9831,0.3453,17.3808,18.5933,33.7208
239.28,3.9866,0.3449,17.4113,18.6238,33.6857
239.52,3.9908,0.3451,17.4453,18.6578,33.6985
239.76,3.995,0.3452,17.4802,18.6927,33.707
240,3.9986,0.345,17.511,18.7235,33.6867
240.24,4.0025,0.3448,17.5444,18.7569,33.6731
240.48,4.0068,0.345,17.5784,18.7909,33.6929
240.72,4.0105,0.3448,17.6109,18.8234,33.6745
240.96,4.0144,0.3448,17.6432,18.8557,33.6737
241.2,4.0186,0.3449,17.6776,18.8901,33.6788
241.44,4.0226,0.3449,17.7104,18.9229,33.6819
241.68,4.0264,0.3447,17.7424,18.9549,33.6636
241.92,4.0305,0.3448,17.7767,18.9892,33.6728
242.16,4.0347,0.3449,17.8103,19.0228,33.685
242.4,4.0384,0.3448,17.8424,19.0549,33.6681
242.64,4.0425,0.3449,17.8756,19.0881,33.6768
242.88,4.0468,0.345,17.91,19.1225,33.6958
243.12,4.0506,0.3449,17.9421,19.1546,33.6782
243.36,4.0545,0.3449,17.975,19.1875,33.6846
243.6,4.059,0.3452,18.01,19.2225,33.7074
243.84,4.063,0.3452,18.0432,19.2557,33.7135
244.08,4.0666,0.3448,18.0742,19.2867,33.6711
244.32,4.0709,0.345,18.1088,19.3213,33.6911
244.56,4.0751,0.3451,18.1425,19.355,33.706
244.8,4.0786,0.3448,18.1731,19.3856,33.6719
245.04,4.0827,0.345,18.2064,19.4189,33.6886
245.28,4.0869,0.3451,18.2402,19.4527,33.701
245.52,4.0906,0.3449,18.271,19.4835,33.6783
245.76,4.0945,0.3448,18.3036,19.5161,33.6714
246,4.0987,0.3449,18.3378,19.5503,33.6838
246.24,4.1025,0.3449,18.3695,19.582,33.6831
246.48,4.1064,0.3448,18.4014,19.6139,33.6758
246.72,4.1106,0.3448,18.435,19.6475,33.6709
246.96,4.1146,0.3449,18.4674,19.6799,33.6831
247.2,4.1184,0.3447,18.4993,19.7118,33.6659
247.44,4.1225,0.3448,18.5324,19.7449,33.6716
247.68,4.1267,0.3451,18.5659,19.7784,33.6965
247.92,4.1305,0.3448,18.5971,19.8096,33.6754
248.16,4.1346,0.3449,18.6302,19.8427,33.6856
248.4,4.1389,0.3451,18.6646,19.8771,33.7027
248.64,4.1428,0.3451,18.6963,19.9088,33.7001
248.88,4.1465,0.345,18.7274,19.9399,33.6888
249.12,4.151,0.3452,18.7618,19.9743,33.7112
249.36,4.155,0.3453,18.7943,20.0068,33.7186
249.6,4.1586,0.345,18.8244,20.0369,33.688
249.84,4.1628,0.3451,18.8575,20.07,33.6996
250.08,4.1671,0.345,18.8911,20.1036,33.6958
250.32,4.1706,0.3449,18.9206,20.1331,33.6858
250.56,4.1746,0.345,18.9535,20.166,33.6896
250.8,4.1788,0.3451,18.9865,20.199,33.7
251.04,4.1825,0.3449,19.0166,20.2291,33.6836
251.28,4.1865,0.3448,19.0485,20.261,33.6747
251.52,4.1906,0.3451,19.0808,20.2933,33.6963
251.76,4.1946,0.3451,19.1126,20.3251,33.7051
252,4.1984,0.3449,19.1436,20.3561,33.6771
252.24,4.2026,0.345,19.1762,20.3887,33.6922
252.48,4.2066,0.3451,19.2081,20.4206,33.6975
252.72,4.2104,0.3449,19.2387,20.4512,33.6815
252.96,4.2145,0.3451,19.2705,20.483,33.6999
253.2,4.2188,0.3453,19.3037,20.5162,33.7163
253.44,4.2226,0.3451,19.3333,20.5458,33.6964
253.68,4.2265,0.3451,19.3651,20.5776,33.6999
253.92,4.231,0.3453,19.3983,20.6108,33.7233
254.16,4.2349,0.3453,19.4294,20.6419,33.7221
254.4,4.2385,0.3451,19.4587,20.6712,33.6968
254.64,4.243,0.3453,19.4917,20.7042,33.7226
254.88,4.2471,0.3454,19.5238,20.7363,33.7347
255.12,4.2506,0.3452,19.5523,20.7648,33.7081
255.36,4.2548,0.3452,19.5843,20.7968,33.7082
255.6,4.2591,0.3455,19.6165,20.829,33.74
255.84,4.2626,0.3451,19.6446,20.8571,33.6989
256.08,4.2666,0.3452,19.6755,20.888,33.7119
256.32,4.2708,0.3453,19.7071,20.9196,33.7187
256.56,4.2745,0.3453,19.7369,20.9494,33.7176
256.8,4.2784,0.3451,19.7669,20.9794,33.7037
257.04,4.2826,0.3453,19.7982,21.0107,33.7167
257.28,4.2866,0.3453,19.8285,21.041,33.7162
257.52,4.2904,0.3451,19.858,21.0705,33.7057
257.76,4.2945,0.3452,19.889,21.1015,33.712
258,4.2986,0.3453,19.9202,21.1327,33.7252
258.24,4.3024,0.3452,19.949,21.1615,33.7093
258.48,4.3065,0.3452,19.9801,21.1926,33.7138
258.72,4.3108,0.3455,20.0117,21.2242,33.7372
258.96,4.3146,0.3454,20.0405,21.253,33.7317
259.2,4.3185,0.3453,20.0703,21.2828,33.7237
259.44,4.323,0.3456,20.1029,21.3154,33.7532
259.68,4.3269,0.3457,20.1327,21.3452,33.7591
259.92,4.3306,0.3455,20.1606,21.3731,33.7411
260.16,4.3349,0.3457,20.1924,21.4049,33.7587
260.4,4.3391,0.3458,20.2234,21.4359,33.7715
260.64,4.3426,0.3455,20.2507,21.4632,33.7436
260.88,4.3467,0.3456,20.2814,21.4939,33.7508
261.12,4.351,0.3458,20.3118,21.5243,33.7691
261.36,4.3546,0.3456,20.3398,21.5523,33.7538
261.6,4.3585,0.3455,20.3695,21.582,33.7426
261.84,4.3627,0.3457,20.3995,21.612,33.7594
262.08,4.3666,0.3457,20.4282,21.6407,33.7556
262.32,4.3704,0.3456,20.4568,21.6693,33.7454
262.56,4.3746,0.3458,20.4873,21.6998,33.7664
262.8,4.3786,0.3457,20.5161,21.7286,33.7604
263.04,4.3824,0.3457,20.5442,21.7567,33.7557
263.28,4.3865,0.3459,20.5735,21.786,33.7772
263.52,4.3907,0.3459,20.603,21.8155,33.7775
263.76,4.3945,0.3459,20.631,21.8435,33.7782
264,4.3985,0.3458,20.6595,21.872,33.7706
264.24,4.4029,0.3461,20.6894,21.9019,33.7989
264.48,4.4068,0.3461,20.7167,21.9292,33.801
264.72,4.4106,0.3459,20.7432,21.9557,33.782
264.96,4.415,0.3462,20.7724,21.9849,33.8127
265.2,4.4191,0.3463,20.7998,22.0123,33.8152
265.44,4.4226,0.346,20.8246,22.0371,33.7892
265.68,4.4269,0.3462,20.8525,22.065,33.8075
265.92,4.4311,0.3463,20.88,22.0925,33.823
266.16,4.4346,0.346,20.9033,22.1158,33.7939
266.4,4.4387,0.3461,20.9296,22.1421,33.7982
266.64,4.4428,0.3463,20.9561,22.1686,33.8187
266.88,4.4465,0.3462,20.9795,22.192,33.8086
267.12,4.4505,0.346,21.0036,22.2161,33.7934
267.36,4.4547,0.3462,21.0281,22.2406,33.8083
267.6,4.4585,0.3464,21.0506,22.2631,33.8242
267.84,4.4624,0.3462,21.0725,22.285,33.8094
268.08,4.4666,0.3463,21.0953,22.3078,33.8166
268.32,4.4706,0.3465,21.1159,22.3284,33.836
268.56,4.4744,0.3463,21.1355,22.348,33.8161
268.8,4.4785,0.3463,21.1556,22.3681,33.8135
269.04,4.4828,0.3465,21.1765,22.389,33.8354
269.28,4.4866,0.3464,21.1937,22.4062,33.8277
269.52,4.4905,0.3465,21.2096,22.4221,33.8393
269.76,4.495,0.3467,21.2271,22.4396,33.8542
270,4.4988,0.3467,21.2406,22.4531,33.8597
270.24,4.5026,0.3465,21.2538,22.4663,33.8334
270.48,4.507,0.3468,21.2705,22.483,33.8629
270.72,4.5111,0.3468,21.285,22.4975,33.8685
270.96,4.5145,0.3466,21.3,22.5125,33.8454
271.115,4.5174,0.3619,21.9833,23.1958,35.3377