File: data/ReportRaw/Resin_CSV/V4_Resin_HT/Tensile_Test_05.csv
Time,Displacement,Force,Tensile strain (Strain 1),,,,Tensile stress
(s),(mm),(kN),(%),,,,(MPa)
0,0,-0.0568,-6.8748,0,0,0,-5.6897
0.24,0.0019,-0.0546,-6.8691,0.0057,0.216580034,0.2221,-5.4676
0.48,0.0067,-0.0496,-6.8542,0.0206,0.709321553,0.7274,-4.9623
0.72,0.0106,-0.0458,-6.8425,0.0323,1.076561719,1.104,-4.5857
0.96,0.0148,-0.0416,-6.8297,0.0451,1.486805845,1.5247,-4.165
1.2,0.0187,-0.038,-6.8186,0.0562,1.840491475,1.8874,-3.8023
1.44,0.0225,-0.0341,-6.807,0.0678,2.214460151,2.2709,-3.4188
1.68,0.0267,-0.0304,-6.7943,0.0805,2.574776777,2.6404,-3.0493
1.92,0.0308,-0.0267,-6.7831,0.0917,2.936458608,3.0113,-2.6784
2.16,0.0346,-0.0234,-6.7721,0.1027,3.268008413,3.3513,-2.3384
2.4,0.0387,-0.0197,-6.7603,0.1145,3.620816411,3.7131,-1.9766
2.64,0.0429,-0.0159,-6.748,0.1268,3.9942,4.096,-1.5937
2.88,0.0467,-0.0127,-6.7373,0.1375,4.305466758,4.4152,-1.2745
3.12,0.0507,-0.0092,-6.7258,0.149,4.646280454,4.7647,-0.925
3.36,0.0551,-0.0054,-6.7136,0.1612,5.021614336,5.1496,-0.5401
3.6,0.0591,-0.0021,-6.7019,0.1729,5.345753027,5.482,-0.2077
3.84,0.0627,0.0009,-6.6923,0.1825,5.633128696,5.7767,0.087
4.08,0.0671,0.0046,-6.6798,0.195,5.994615498,6.1474,0.4577
4.32,0.0713,0.008,-6.668,0.2068,6.328895713,6.4902,0.8005
4.56,0.0747,0.0108,-6.6589,0.2159,6.599011289,6.7672,1.0775
4.8,0.0789,0.014,-6.6473,0.2275,6.916323955,7.0926,1.4029
5.04,0.0831,0.0176,-6.6361,0.2387,7.264256221,7.4494,1.7597
5.28,0.0867,0.0202,-6.627,0.2478,7.517599277,7.7092,2.0195
5.52,0.0907,0.0234,-6.616,0.2588,7.828671006,8.0282,2.3385
5.76,0.0949,0.0267,-6.6048,0.27,8.157782944,8.3657,2.676
6,0.0987,0.0294,-6.5949,0.2799,8.422145156,8.6368,2.9471
6.24,0.1026,0.0325,-6.5846,0.2902,8.721125068,8.9434,3.2537
6.48,0.1067,0.0356,-6.574,0.3008,9.027808638,9.2579,3.5682
6.72,0.1107,0.0386,-6.5634,0.3114,9.316842056,9.5543,3.8646
6.96,0.1145,0.0412,-6.5546,0.3202,9.567454702,9.8113,4.1216
7.2,0.1187,0.0441,-6.5442,0.3306,9.85522043,10.1064,4.4167
7.44,0.1229,0.0473,-6.5333,0.3415,10.16502447,10.4241,4.7344
7.68,0.1266,0.0497,-6.5246,0.3502,10.40208258,10.6672,4.9775
7.92,0.1307,0.0525,-6.5148,0.36,10.677854,10.95,5.2603
8.16,0.1351,0.0556,-6.5039,0.3709,10.97810161,11.2579,5.5682
8.4,0.1388,0.058,-6.4961,0.3787,11.20882126,11.4945,5.8048
8.64,0.1427,0.0603,-6.4867,0.3881,11.43866329,11.7302,6.0405
8.88,0.1471,0.0632,-6.4769,0.3979,11.72135826,12.0201,6.3304
9.12,0.1512,0.0658,-6.4675,0.4073,11.97479883,12.28,6.5903
9.36,0.1547,0.0677,-6.4605,0.4143,12.1583214,12.4682,6.7785
9.6,0.1591,0.0704,-6.4514,0.4234,12.42307367,12.7397,7.05
9.84,0.1632,0.0728,-6.4418,0.433,12.66100941,12.9837,7.294
10.08,0.1667,0.0744,-6.4357,0.4391,12.81859308,13.1453,7.4556
10.32,0.1709,0.0767,-6.4274,0.4474,13.03848861,13.3708,7.6811
10.56,0.1751,0.079,-6.4186,0.4562,13.26764804,13.6058,7.9161
10.8,0.1787,0.0808,-6.4126,0.4622,13.43556826,13.778,8.0883
11.04,0.1827,0.0827,-6.4051,0.4697,13.62523425,13.9725,8.2828
11.28,0.1869,0.0848,-6.3977,0.4771,13.83352554,14.1861,8.4964
11.52,0.1907,0.0866,-6.391,0.4838,14.00846682,14.3655,8.6758
11.76,0.1946,0.0884,-6.3846,0.4902,14.17619202,14.5375,8.8478
12,0.1987,0.0902,-6.3775,0.4973,14.35786181,14.7238,9.0341
12.24,0.2028,0.0922,-6.3702,0.5046,14.55123335,14.9221,9.2324
12.48,0.2065,0.0934,-6.3652,0.5096,14.67254158,15.0465,9.3568
12.72,0.2107,0.0952,-6.3581,0.5167,14.84923812,15.2277,9.538
12.96,0.2149,0.0971,-6.3515,0.5233,15.02964022,15.4127,9.723
13.2,0.2186,0.0983,-6.3465,0.5283,15.14773046,15.5338,9.8441
13.44,0.2227,0.0999,-6.3408,0.534,15.30492407,15.695,10.0053
13.68,0.227,0.1016,-6.3341,0.5407,15.47372193,15.8681,10.1784
13.92,0.2309,0.1028,-6.3288,0.546,15.58752152,15.9848,10.2951
14.16,0.2347,0.1038,-6.3252,0.5496,15.68640138,16.0862,10.3965
14.4,0.2392,0.1055,-6.3186,0.5562,15.85168871,16.2557,10.566
14.64,0.2432,0.1065,-6.3143,0.5605,15.95212879,16.3587,10.669
14.88,0.2468,0.107,-6.312,0.5628,15.99425512,16.4019,10.7122
15.12,0.251,0.1078,-6.3084,0.5664,16.07450968,16.4842,10.7945
15.36,0.2552,0.1084,-6.3056,0.5692,16.13672402,16.548,10.8583
15.6,0.2587,0.108,-6.3063,0.5685,16.09430515,16.5045,10.8148
15.84,0.2628,0.1076,-6.3067,0.5681,16.05383657,16.463,10.7733
16.08,0.267,0.1066,-6.3087,0.5661,15.96090511,16.3677,10.678
16.32,0.2707,0.1074,-6.3062,0.5686,16.03228583,16.4409,10.7512
16.56,0.2746,0.1081,-6.3035,0.5713,16.10776217,16.5183,10.8286
16.8,0.2788,0.1093,-6.2987,0.5761,16.21834378,16.6317,10.942
17.04,0.2827,0.1104,-6.2949,0.5799,16.32570741,16.7418,11.0521
17.28,0.2865,0.1113,-6.2911,0.5837,16.41493332,16.8333,11.1436
17.52,0.2907,0.1127,-6.286,0.5888,16.55389169,16.9758,11.2861
17.76,0.2947,0.114,-6.2813,0.5935,16.68290357,17.1081,11.4184
18,0.2985,0.115,-6.2769,0.5979,16.77749278,17.2051,11.5154
18.24,0.3027,0.1162,-6.2724,0.6024,16.89928857,17.33,11.6403
18.48,0.307,0.1177,-6.2668,0.608,17.04419534,17.4786,11.7889
18.72,0.3108,0.118,-6.2628,0.612,17.07325471,17.5084,11.8187
18.96,0.3147,0.1119,-6.2766,0.5982,16.47900044,16.899,11.2093
19.2,0.3191,0.1155,-6.2652,0.6096,16.83200347,17.261,11.5713
19.44,0.3231,0.1184,-6.2558,0.619,17.10835998,17.5444,11.8547
19.68,0.3267,0.1206,-6.2476,0.6272,17.32279469,17.7643,12.0746
19.92,0.3311,0.1235,-6.2378,0.637,17.60734244,18.0561,12.3664
20.16,0.3353,0.1259,-6.2293,0.6455,17.83932979,18.294,12.6043
20.4,0.3387,0.1276,-6.2227,0.6521,18.00822516,18.4672,12.7775
20.64,0.3429,0.1297,-6.2146,0.6602,18.21505373,18.6793,12.9896
20.88,0.3471,0.1321,-6.2059,0.6689,18.44957646,18.9198,13.2301
21.12,0.3507,0.1336,-6.2002,0.6746,18.59818878,19.0722,13.3825
21.36,0.3547,0.1355,-6.1931,0.6817,18.77907845,19.2577,13.568
21.6,0.3589,0.1377,-6.1847,0.6901,18.99692618,19.4811,13.7914
21.84,0.3627,0.1394,-6.1785,0.6963,19.16036073,19.6487,13.959
22.08,0.3666,0.1411,-6.1716,0.7032,19.32935361,19.822,14.1323
22.32,0.3708,0.1432,-6.1642,0.7106,19.53393935,20.0318,14.3421
22.56,0.3747,0.1451,-6.1568,0.718,19.7213625,20.224,14.5343
22.8,0.3785,0.1467,-6.1505,0.7243,19.87494807,20.3815,14.6918
23.04,0.3827,0.1487,-6.1431,0.7317,20.07212269,20.5837,14.894
23.28,0.3868,0.1508,-6.135,0.7398,20.27943883,20.7963,15.1066
23.52,0.3906,0.1525,-6.1289,0.7459,20.43799765,20.9589,15.2692
23.76,0.3947,0.1544,-6.1212,0.7536,20.62610341,21.1518,15.4621
24,0.399,0.1565,-6.1132,0.7616,20.83566239,21.3667,15.677
24.24,0.4028,0.1584,-6.1067,0.7681,21.01830732,21.554,15.8643
24.48,0.4067,0.1602,-6.0998,0.775,21.18817784,21.7282,16.0385
24.72,0.4112,0.1623,-6.0914,0.7834,21.40163741,21.9471,16.2574
24.96,0.4151,0.164,-6.0846,0.7902,21.5646819,22.1143,16.4246
25.2,0.4187,0.1654,-6.0788,0.796,21.69876454,22.2518,16.5621
25.44,0.4231,0.1675,-6.0707,0.8041,21.90325276,22.4615,16.7718
25.68,0.4273,0.1695,-6.0633,0.8115,22.10091495,22.6642,16.9745
25.92,0.4307,0.1705,-6.058,0.8168,22.19920972,22.765,17.0753
26.16,0.4349,0.1724,-6.051,0.8238,22.38448755,22.955,17.2653
26.4,0.4391,0.1743,-6.0439,0.8309,22.56723,23.1424,17.4527
26.64,0.4427,0.1757,-6.0384,0.8364,22.70843121,23.2872,17.5975
26.88,0.4467,0.1772,-6.0324,0.8424,22.85772614,23.4403,17.7506
27.12,0.4509,0.179,-6.0252,0.8496,23.03237487,23.6194,17.9297
27.36,0.4547,0.1805,-6.0193,0.8555,23.17494129,23.7656,18.0759
27.6,0.4585,0.1819,-6.0128,0.862,23.31380215,23.908,18.2183
27.84,0.4627,0.1838,-6.0059,0.8689,23.49381419,24.0926,18.4029
28.08,0.4667,0.1853,-5.9994,0.8754,23.64067125,24.2432,18.5535
28.32,0.4705,0.1868,-5.994,0.8808,23.78645565,24.3927,18.703
28.56,0.4747,0.1885,-5.9876,0.8872,23.95164546,24.5621,18.8724
28.8,0.4789,0.1902,-5.9805,0.8943,24.12473396,24.7396,19.0499
29.04,0.4827,0.1914,-5.9753,0.8995,24.24253166,24.8604,19.1707
29.28,0.4867,0.193,-5.9685,0.9063,24.39845758,25.0203,19.3306
29.52,0.4911,0.195,-5.9612,0.9136,24.58948878,25.2162,19.5265
29.76,0.4949,0.1963,-5.956,0.9188,24.7207435,25.3508,19.6611
30,0.4988,0.1975,-5.9504,0.9244,24.8365909,25.4696,19.7799
30.24,0.5032,0.1993,-5.9432,0.9316,25.01260484,25.6501,19.9604
30.48,0.5072,0.201,-5.9367,0.9381,25.17750211,25.8192,20.1295
30.72,0.5107,0.2019,-5.9327,0.9421,25.26282743,25.9067,20.217
30.96,0.515,0.2036,-5.9259,0.9489,25.42957748,26.0777,20.388
31.2,0.5192,0.2051,-5.9192,0.9556,25.57662957,26.2285,20.5388
31.44,0.5227,0.2061,-5.9152,0.9596,25.67960503,26.3341,20.6444
31.68,0.5268,0.2074,-5.9091,0.9657,25.80647159,26.4642,20.7745
31.92,0.531,0.209,-5.903,0.9718,25.96064225,26.6223,20.9326
32.16,0.5346,0.2102,-5.898,0.9768,26.07619711,26.7408,21.0511
32.4,0.5386,0.2114,-5.8927,0.9821,26.19243457,26.86,21.1703
32.64,0.5428,0.2129,-5.8866,0.9882,26.34319222,27.0146,21.3249
32.88,0.5467,0.2142,-5.8807,0.9941,26.47005877,27.1447,21.455
33.12,0.5505,0.2154,-5.8764,0.9984,26.58210311,27.2596,21.5699
33.36,0.5547,0.2169,-5.8694,1.0054,26.73178809,27.4131,21.7234
33.6,0.5588,0.2185,-5.8637,1.0111,26.88264325,27.5678,21.8781
33.84,0.5626,0.2196,-5.8587,1.0161,26.99195717,27.6799,21.9902
34.08,0.5667,0.2209,-5.8532,1.0216,27.12408952,27.8154,22.1257
34.32,0.571,0.2226,-5.8462,1.0286,27.28849922,27.984,22.2943
34.56,0.5747,0.2235,-5.842,1.0328,27.37509223,28.0728,22.3831
34.8,0.5787,0.2249,-5.8362,1.0386,27.50800469,28.2091,22.5194
35.04,0.5831,0.2265,-5.8295,1.0453,27.67036658,28.3756,22.6859
35.28,0.587,0.2278,-5.8245,1.0503,27.79352758,28.5019,22.8122
35.52,0.5907,0.2287,-5.8197,1.0551,27.88665407,28.5974,22.9077
35.76,0.5951,0.2303,-5.8139,1.0609,28.03672912,28.7513,23.0616
36,0.5993,0.2318,-5.8075,1.0673,28.18319612,28.9015,23.2118
36.24,0.6027,0.2325,-5.804,1.0708,28.24950608,28.9695,23.2798
36.48,0.6069,0.2339,-5.7981,1.0767,28.39099983,29.1146,23.4249
36.72,0.6112,0.2354,-5.7921,1.0827,28.53561406,29.2629,23.5732
36.96,0.6147,0.2363,-5.788,1.0868,28.62220707,29.3517,23.662
37.2,0.6187,0.2375,-5.7823,1.0925,28.74332026,29.4759,23.7862
37.44,0.623,0.2389,-5.7764,1.0984,28.88023083,29.6163,23.9266
37.68,0.6267,0.2399,-5.7718,1.103,28.97842808,29.717,24.0273
37.92,0.6306,0.241,-5.7668,1.108,29.08140354,29.8226,24.1329
38.16,0.6348,0.2425,-5.7608,1.114,29.2295283,29.9745,24.2848
38.4,0.6387,0.2437,-5.7553,1.1195,29.34947131,30.0975,24.4078
38.64,0.6425,0.2446,-5.751,1.1238,29.43889225,30.1892,24.4995
38.88,0.6467,0.2461,-5.7447,1.1301,29.58555428,30.3396,24.6499
39.12,0.6508,0.2476,-5.7393,1.1355,29.72490271,30.4825,24.7928
39.36,0.6546,0.2484,-5.7344,1.1404,29.80876531,30.5685,24.8788
39.6,0.6587,0.2498,-5.7288,1.146,29.9385573,30.7016,25.0119
39.84,0.663,0.2513,-5.723,1.1518,30.08950998,30.8564,25.1667
40.08,0.6668,0.2522,-5.7176,1.1572,30.17893091,30.9481,25.2584
40.32,0.6707,0.2534,-5.7129,1.1619,30.29624104,31.0684,25.3787
40.56,0.6752,0.2552,-5.7062,1.1686,30.46630658,31.2428,25.5531
40.8,0.6791,0.2562,-5.7011,1.1737,30.56967211,31.3488,25.6591
41.04,0.6827,0.2571,-5.6973,1.1775,30.65597257,31.4373,25.7476
41.28,0.6871,0.2587,-5.6905,1.1843,30.8132637,31.5986,25.9089
41.52,0.6913,0.2601,-5.6845,1.1903,30.94646871,31.7352,26.0455
41.76,0.6947,0.2607,-5.6808,1.194,31.00848803,31.7988,26.1091
42,0.6989,0.262,-5.6748,1.2,31.13788997,31.9315,26.2418
42.24,0.7031,0.2636,-5.6694,1.2054,31.2899153,32.0874,26.3977
42.48,0.7067,0.2643,-5.6648,1.21,31.36334383,32.1627,26.473
42.72,0.7107,0.2655,-5.6597,1.2151,31.47733846,32.2796,26.5899
42.96,0.7149,0.267,-5.6535,1.2213,31.62156262,32.4275,26.7378
43.2,0.7187,0.2681,-5.6485,1.2263,31.72736602,32.536,26.8463
43.44,0.7225,0.2691,-5.6438,1.231,31.82517321,32.6363,26.9466
43.68,0.7267,0.2705,-5.6374,1.2374,31.95954839,32.7741,27.0844
43.92,0.7308,0.2717,-5.6324,1.2424,32.07705354,32.8946,27.2049
44.16,0.7345,0.2726,-5.6274,1.2474,32.1733005,32.9933,27.3036
44.4,0.7387,0.274,-5.6213,1.2535,32.306408,33.1298,27.4401
44.64,0.7429,0.2755,-5.6153,1.2595,32.4488769,33.2759,27.5862
44.88,0.7466,0.2765,-5.6103,1.2645,32.54648906,33.376,27.6863
45.12,0.7507,0.2777,-5.6051,1.2697,32.67208793,33.5048,27.8151
45.36,0.7551,0.2792,-5.5982,1.2766,32.81114382,33.6474,27.9577
45.6,0.7589,0.2804,-5.5933,1.2815,32.928844,33.7681,28.0784
45.84,0.7627,0.2814,-5.5886,1.2862,33.03298964,33.8749,28.1852
46.08,0.7671,0.2831,-5.5811,1.2937,33.19398633,34.04,28.3503
46.32,0.7712,0.2845,-5.5759,1.2989,33.32943417,34.1789,28.4892
46.56,0.7747,0.2851,-5.5719,1.3029,33.3901858,34.2412,28.5515
46.8,0.779,0.2866,-5.5654,1.3094,33.53733541,34.3921,28.7024
47.04,0.7832,0.2879,-5.5593,1.3155,33.66751746,34.5256,28.8359
47.28,0.7867,0.2888,-5.5545,1.3203,33.75459804,34.6149,28.9252
47.52,0.7908,0.2901,-5.5484,1.3264,33.88312235,34.7467,29.057
47.76,0.795,0.2919,-5.5418,1.333,34.05153015,34.9194,29.2297
48,0.7987,0.2927,-5.5374,1.3374,34.13558777,35.0056,29.3159
48.24,0.8026,0.2939,-5.5315,1.3433,34.24597436,35.1188,29.4291
48.48,0.8068,0.2953,-5.5252,1.3496,34.38590788,35.2623,29.5726
48.72,0.8107,0.2964,-5.5199,1.3549,34.49678203,35.376,29.6863
48.96,0.8145,0.2974,-5.5145,1.3603,34.58893337,35.4705,29.7808
49.2,0.8187,0.2987,-5.509,1.3658,34.71853034,35.6034,29.9137
49.44,0.8228,0.3001,-5.5025,1.3723,34.85787877,35.7463,30.0566
49.68,0.8265,0.301,-5.4983,1.3765,34.93842587,35.8289,30.1392
49.92,0.8307,0.3023,-5.4923,1.3825,35.07260603,35.9665,30.2768
50.16,0.8349,0.3036,-5.4853,1.3895,35.19976513,36.0969,30.4072
50.4,0.8387,0.3047,-5.4808,1.394,35.30547101,36.2053,30.5156
50.64,0.8427,0.3058,-5.4756,1.3992,35.41449239,36.3171,30.6274
50.88,0.8471,0.3074,-5.4689,1.4059,35.5663227,36.4728,30.7831
51.12,0.851,0.3086,-5.4629,1.4119,35.68226761,36.5917,30.902
51.36,0.8547,0.3094,-5.4586,1.4162,35.75949921,36.6709,30.9812
51.6,0.8592,0.3111,-5.4514,1.4234,35.92624926,36.8419,31.1522
51.84,0.8633,0.3124,-5.4453,1.4295,36.05301831,36.9719,31.2822
52.08,0.8667,0.3131,-5.4414,1.4334,36.12361891,37.0443,31.3546
52.32,0.8709,0.3145,-5.4347,1.4401,36.2579941,37.1821,31.4924
52.56,0.8752,0.3159,-5.4289,1.4459,36.39636738,37.324,31.6343
52.8,0.8787,0.3167,-5.4241,1.4507,36.47652442,37.4062,31.7165
53.04,0.8827,0.3178,-5.4183,1.4565,36.5855458,37.518,31.8283
53.28,0.8869,0.3192,-5.4118,1.463,36.72294394,37.6589,31.9692
53.52,0.8907,0.3202,-5.4068,1.468,36.82260391,37.7611,32.0714
53.76,0.8946,0.3214,-5.4015,1.4733,36.93162529,37.8729,32.1832
54,0.8988,0.3227,-5.3948,1.48,37.06541539,38.0101,32.3204
54.24,0.9027,0.324,-5.3898,1.485,37.18565095,38.1334,32.4437
54.48,0.9065,0.3249,-5.3845,1.4903,37.28063021,38.2308,32.5411
54.72,0.9107,0.3264,-5.3777,1.4971,37.42144137,38.3752,32.6855
54.96,0.9148,0.3278,-5.3718,1.503,37.55727927,38.5145,32.8248
55.2,0.9186,0.3289,-5.3657,1.5091,37.66786088,38.6279,32.9382
55.44,0.9227,0.3302,-5.3601,1.5147,37.79238709,38.7556,33.0659
55.68,0.927,0.3318,-5.3524,1.5224,37.95231111,38.9196,33.2299
55.92,0.9307,0.3329,-5.347,1.5278,38.06055237,39.0306,33.3409
56.16,0.9347,0.3341,-5.3413,1.5335,38.17747244,39.1505,33.4608
56.4,0.9391,0.3358,-5.3333,1.5415,38.34412497,39.3214,33.6317
56.64,0.9431,0.3373,-5.3273,1.5475,38.48425352,39.4651,33.7754
56.88,0.9467,0.3381,-5.3218,1.553,38.57016393,39.5532,33.8635
57.12,0.9511,0.3399,-5.3145,1.5603,38.73964438,39.727,34.0373
57.36,0.9553,0.3415,-5.3069,1.5679,38.89654545,39.8879,34.1982
57.6,0.9587,0.3421,-5.3026,1.5722,38.95797968,39.9509,34.2612
57.84,0.9629,0.3436,-5.2961,1.5787,39.09966847,40.0962,34.4065
58.08,0.9671,0.3451,-5.2886,1.5862,39.24915842,40.2495,34.5598
58.32,0.9707,0.346,-5.2843,1.5905,39.33935947,40.342,34.6523
58.56,0.9747,0.3473,-5.2779,1.5969,39.46193539,40.4677,34.778
58.8,0.9789,0.3487,-5.271,1.6038,39.60528192,40.6147,34.925
59.04,0.9827,0.3498,-5.265,1.6098,39.70757479,40.7196,35.0299
59.28,0.9866,0.351,-5.2594,1.6154,39.82127687,40.8362,35.1465
59.52,0.9907,0.3524,-5.2526,1.6222,39.96491594,40.9835,35.2938
59.76,0.9947,0.3536,-5.2462,1.6286,40.08407884,41.1057,35.416
60,0.9985,0.3548,-5.2412,1.6336,40.19446542,41.2189,35.5292
60.24,1.0027,0.3562,-5.2341,1.6407,40.33157102,41.3595,35.6698
60.48,1.0068,0.3577,-5.2277,1.6471,40.47745293,41.5091,35.8194
60.72,1.0106,0.3586,-5.2218,1.653,40.56892167,41.6029,35.9132
60.96,1.0147,0.36,-5.2153,1.6595,40.70349189,41.7409,36.0512
61.2,1.019,0.3615,-5.2083,1.6665,40.85229924,41.8935,36.2038
61.44,1.0229,0.3628,-5.2016,1.6732,40.97887326,42.0233,36.3336
61.68,1.0267,0.3639,-5.196,1.6788,41.0823363,42.1294,36.4397
61.92,1.0312,0.3657,-5.1881,1.6867,41.25639995,42.3079,36.6182
62.16,1.0352,0.367,-5.1813,1.6935,41.38355905,42.4383,36.7486
62.4,1.0387,0.368,-5.1762,1.6986,41.48165878,42.5389,36.8492
62.64,1.043,0.3695,-5.1685,1.7063,41.63329406,42.6944,37.0047
62.88,1.0472,0.371,-5.1613,1.7135,41.77937101,42.8442,37.1545
63.12,1.0507,0.3719,-5.1563,1.7185,41.86615904,42.9332,37.2435
63.36,1.0548,0.3732,-5.1494,1.7254,41.99185542,43.0621,37.3724
63.6,1.059,0.3748,-5.142,1.7328,42.14622111,43.2204,37.5307
63.84,1.0627,0.3758,-5.1366,1.7382,42.24812392,43.3249,37.6352
64.08,1.0666,0.377,-5.1299,1.7449,42.36065583,43.4403,37.7506
64.32,1.0708,0.3786,-5.1227,1.7521,42.52145748,43.6052,37.9155
64.56,1.0747,0.3799,-5.1165,1.7583,42.64549611,43.7324,38.0427
64.8,1.0785,0.3809,-5.1102,1.7646,42.74837407,43.8379,38.1482
65.04,1.0827,0.3823,-5.1032,1.7716,42.88713741,43.9802,38.2905
65.28,1.0868,0.3837,-5.0959,1.7789,43.01663687,44.113,38.4233
65.52,1.0906,0.3849,-5.0898,1.785,43.13687243,44.2363,38.5466
65.76,1.0947,0.3862,-5.0828,1.792,43.26598182,44.3687,38.679
66,1.0989,0.3879,-5.0748,1.8,43.4289288,44.5358,38.8461
66.24,1.1027,0.389,-5.0694,1.8054,43.53599988,44.6456,38.9559
66.48,1.1067,0.3902,-5.0621,1.8127,43.65623544,44.7689,39.0792
66.72,1.1111,0.392,-5.0542,1.8206,43.82600845,44.943,39.2533
66.96,1.115,0.3932,-5.0479,1.8269,43.942831,45.0628,39.3731
67.2,1.1187,0.3941,-5.0423,1.8325,44.03010661,45.1523,39.4626
67.44,1.1231,0.3957,-5.0339,1.8409,44.1945163,45.3209,39.6312
67.68,1.1272,0.3971,-5.0271,1.8477,44.33240202,45.4623,39.7726
67.92,1.1307,0.398,-5.0222,1.8526,44.41129137,45.5432,39.8535
68.16,1.135,0.3994,-5.0146,1.8602,44.55346772,45.689,39.9993
68.4,1.1392,0.4009,-5.0077,1.8671,44.69798443,45.8372,40.1475
68.64,1.1427,0.4017,-5.0019,1.8729,44.77268065,45.9138,40.2241
68.88,1.1468,0.4029,-4.9954,1.8794,44.88979575,46.0339,40.3442
69.12,1.151,0.4044,-4.9881,1.8867,45.03606772,46.1839,40.4942
69.36,1.1547,0.4054,-4.9825,1.8923,45.13338734,46.2837,40.594
69.6,1.1586,0.4065,-4.9761,1.8987,45.2449441,46.3981,40.7084
69.84,1.1628,0.4079,-4.9685,1.9063,45.38204969,46.5387,40.849
70.08,1.1668,0.4091,-4.9623,1.9125,45.50248028,46.6622,40.9725
70.32,1.1705,0.4102,-4.9562,1.9186,45.60994143,46.7724,41.0827
70.56,1.1747,0.4116,-4.9492,1.9256,45.74392655,46.9098,41.2201
70.8,1.1788,0.413,-4.9417,1.9331,45.88220232,47.0516,41.3619
71.04,1.1826,0.414,-4.9359,1.9389,45.97776668,47.1496,41.4599
71.28,1.1867,0.4153,-4.9284,1.9464,46.10892388,47.2841,41.5944
71.52,1.1909,0.4169,-4.9207,1.9541,46.26075419,47.4398,41.7501
71.76,1.1948,0.418,-4.9144,1.9604,46.36548492,47.5472,41.8575
72,1.1987,0.4191,-4.9079,1.9669,46.479187,47.6638,41.9741
72.24,1.2032,0.4207,-4.8995,1.9753,46.63618559,47.8248,42.1351
72.48,1.2071,0.4221,-4.8926,1.9822,46.76666019,47.9586,42.2689
72.72,1.2108,0.4229,-4.8872,1.9876,46.85023024,48.0443,42.3546
72.96,1.2151,0.4244,-4.8788,1.996,46.99786742,48.1957,42.506
73.2,1.2193,0.4259,-4.871,2.0038,47.14228661,48.3438,42.6541
73.44,1.2228,0.4267,-4.8659,2.0089,47.21688532,48.4203,42.7306
73.68,1.2269,0.428,-4.858,2.0168,47.34999281,48.5568,42.8671
73.92,1.2311,0.4296,-4.8505,2.0243,47.49977531,48.7104,43.0207
74.16,1.2347,0.4305,-4.8444,2.0304,47.58666086,48.7995,43.1098
74.4,1.2387,0.4316,-4.8378,2.037,47.69987537,48.9156,43.2259
74.64,1.2429,0.4331,-4.83,2.0448,47.84595231,49.0654,43.3757
74.88,1.2467,0.4341,-4.8235,2.0513,47.94483217,49.1668,43.4771
75.12,1.2506,0.4353,-4.8165,2.0583,48.05950939,49.2844,43.5947
75.36,1.2548,0.4369,-4.809,2.0658,48.21007201,49.4388,43.7491
75.6,1.2587,0.4381,-4.8018,2.073,48.33108769,49.5629,43.8732
75.84,1.2625,0.4392,-4.7948,2.08,48.43757369,49.6721,43.9824
76.08,1.2667,0.4406,-4.7872,2.0876,48.57926247,49.8174,44.1277
76.32,1.2708,0.442,-4.7796,2.0952,48.71597801,49.9576,44.2679
76.56,1.2746,0.4431,-4.7733,2.1015,48.81622307,50.0604,44.3707
76.8,1.2787,0.4443,-4.7656,2.1092,48.93304562,50.1802,44.4905
77.04,1.283,0.4459,-4.7572,2.1176,49.09121438,50.3424,44.6527
77.28,1.2869,0.4471,-4.7499,2.1249,49.21037728,50.4646,44.7749
77.52,1.2907,0.4481,-4.7439,2.1309,49.30876956,50.5655,44.8758
77.76,1.2952,0.4499,-4.7348,2.14,49.4807854,50.7419,45.0522
78,1.2992,0.4511,-4.7271,2.1477,49.59955824,50.8637,45.174
78.24,1.3028,0.452,-4.7217,2.1531,49.69034438,50.9568,45.2671
78.48,1.307,0.4534,-4.7129,2.1619,49.827645,51.0976,45.4079
78.72,1.3112,0.455,-4.7051,2.1697,49.9800604,51.2539,45.5642
78.96,1.3147,0.4557,-4.6989,2.1759,50.04978337,51.3254,45.6357
79.2,1.3188,0.4569,-4.6919,2.1829,50.16787361,51.4465,45.7568
79.44,1.323,0.4585,-4.6832,2.1916,50.32038652,51.6029,45.9132
79.68,1.3267,0.4593,-4.6771,2.1977,50.40190876,51.6865,45.9968
79.92,1.3306,0.4605,-4.6697,2.2051,50.5186338,51.8062,46.1165
80.16,1.3348,0.462,-4.6614,2.2134,50.66480826,51.9561,46.2664
80.4,1.3387,0.4631,-4.654,2.2208,50.7696365,52.0636,46.3739
80.64,1.3425,0.4641,-4.6474,2.2274,50.86666358,52.1631,46.4734
80.88,1.3468,0.4656,-4.6389,2.2359,51.0172262,52.3175,46.6278
81.12,1.3508,0.4669,-4.6311,2.2437,51.13941205,52.4428,46.7531
81.36,1.3545,0.4679,-4.6247,2.2501,51.2456055,52.5517,46.862
81.6,1.3587,0.4692,-4.6165,2.2583,51.37149691,52.6808,46.9911
81.84,1.3629,0.4707,-4.6084,2.2664,51.51776889,52.8308,47.1411
82.08,1.3667,0.4718,-4.6012,2.2736,51.62318222,52.9389,47.2492
82.32,1.3707,0.473,-4.5937,2.2811,51.73571413,53.0543,47.3646
82.56,1.3751,0.4747,-4.5847,2.2901,51.90782748,53.2308,47.5411
82.8,1.3789,0.4758,-4.5771,2.2977,52.01333833,53.339,47.6493
83.04,1.3827,0.4766,-4.5704,2.3044,52.0896923,53.4173,47.7276
83.28,1.3871,0.4783,-4.5609,2.3139,52.2620982,53.5941,47.9044
83.52,1.3912,0.4798,-4.5534,2.3214,52.40037397,53.7359,48.0462
83.76,1.3947,0.4804,-4.5472,2.3276,52.46600133,53.8032,48.1135
84,1.399,0.4819,-4.5385,2.3363,52.60778763,53.9486,48.2589
84.24,1.4032,0.4833,-4.5295,2.3453,52.74557583,54.0899,48.4002
84.48,1.4067,0.4842,-4.5233,2.3515,52.83499676,54.1816,48.4919
84.72,1.4108,0.4855,-4.5156,2.3592,52.96127823,54.3111,48.6214
84.96,1.415,0.4869,-4.5062,2.3686,53.09614099,54.4494,48.7597
85.2,1.4187,0.4879,-4.4994,2.3754,53.19823882,54.5541,48.8644
85.44,1.4226,0.4891,-4.4917,2.3831,53.31184339,54.6706,48.9809
85.68,1.4268,0.4907,-4.4824,2.3924,53.4643563,54.827,49.1373
85.92,1.4307,0.4919,-4.4741,2.4007,53.58429932,54.95,49.2603
86.16,1.4345,0.493,-4.4659,2.4089,53.69283312,55.0613,49.3716
86.4,1.4387,0.4946,-4.4571,2.4177,53.84836898,55.2208,49.5311
86.64,1.4428,0.4961,-4.448,2.4268,53.99083789,55.3669,49.6772
86.88,1.4466,0.497,-4.4401,2.4347,54.08552461,55.464,49.7743
87.12,1.4507,0.4985,-4.4315,2.4433,54.22955375,55.6117,49.922
87.36,1.455,0.5001,-4.421,2.4538,54.38655233,55.7727,50.083
87.6,1.4587,0.5012,-4.4138,2.461,54.48982034,55.8786,50.1889
87.84,1.4627,0.5024,-4.4053,2.4695,54.60966584,56.0015,50.3118
88.08,1.4671,0.5041,-4.395,2.4798,54.77573329,56.1718,50.4821
88.32,1.4711,0.5054,-4.3869,2.4879,54.90747558,56.3069,50.6172
88.56,1.4747,0.5063,-4.379,2.4958,54.99592137,56.3976,50.7079
88.8,1.4791,0.508,-4.3691,2.5057,55.15409013,56.5598,50.8701
89.04,1.4832,0.5094,-4.3595,2.5153,55.29626648,56.7056,51.0159
89.28,1.4867,0.5102,-4.3526,2.5222,55.37496081,56.7863,51.0966
89.52,1.4909,0.5115,-4.3438,2.531,55.50085222,56.9154,51.2257
89.76,1.4951,0.5131,-4.3338,2.541,55.65765577,57.0762,51.3865
90,1.4987,0.5139,-4.3265,2.5483,55.7343998,57.1549,51.4652
90.24,1.5027,0.5152,-4.3176,2.5572,55.86506943,57.2889,51.5992
90.48,1.5069,0.5166,-4.3084,2.5664,55.99993219,57.4272,51.7375
90.72,1.5107,0.5178,-4.3,2.5748,56.11938763,57.5497,51.86
90.96,1.5146,0.5189,-4.2917,2.5831,56.22294819,57.6559,51.9662
91.2,1.5187,0.5204,-4.2822,2.5926,56.36580715,57.8024,52.1127
91.44,1.5228,0.5216,-4.2727,2.6021,56.48614022,57.9258,52.2361
91.68,1.5265,0.5227,-4.2648,2.61,56.59603923,58.0385,52.3488
91.92,1.5307,0.5241,-4.2552,2.6196,56.72953679,58.1754,52.4857
92.16,1.5348,0.5255,-4.2457,2.6291,56.86459458,58.3139,52.6242
92.4,1.5386,0.5265,-4.2375,2.6373,56.96269431,58.4145,52.7248
92.64,1.5427,0.5278,-4.2281,2.6467,57.08965838,58.5447,52.855
92.88,1.547,0.5294,-4.2175,2.6573,57.25211779,58.7113,53.0216
93.12,1.5509,0.5306,-4.2089,2.6659,57.36279691,58.8248,53.1351
93.36,1.5547,0.5315,-4.2007,2.6741,57.45660601,58.921,53.2313
93.6,1.5591,0.5333,-4.1899,2.6849,57.62520883,59.0939,53.4042
93.84,1.5632,0.5345,-4.1804,2.6944,57.74427422,59.216,53.5263
94.08,1.5667,0.5351,-4.1725,2.7023,57.80580596,59.2791,53.5894
94.32,1.571,0.5368,-4.1621,2.7127,57.9665101,59.4439,53.7542
94.56,1.5753,0.5383,-4.1521,2.7227,58.11521994,59.5964,53.9067
94.8,1.5787,0.539,-4.1448,2.73,58.18387025,59.6668,53.9771
95.04,1.5828,0.5404,-4.1347,2.7401,58.32107336,59.8075,54.1178
95.28,1.5871,0.5418,-4.1243,2.7505,58.45808145,59.948,54.2583
95.52,1.5907,0.5428,-4.116,2.7588,58.55930165,60.0518,54.3621
95.76,1.5946,0.5437,-4.1069,2.7679,58.64862507,60.1434,54.4537
96,1.5989,0.5453,-4.0966,2.7782,58.79557964,60.2941,54.6044
96.24,1.6027,0.5464,-4.0878,2.787,58.90557617,60.4069,54.7172
96.48,1.6065,0.5473,-4.0788,2.796,58.99860514,60.5023,54.8126
96.72,1.6107,0.5487,-4.0683,2.8065,59.13473559,60.6419,54.9522
96.96,1.6147,0.5499,-4.059,2.8158,59.25419104,60.7644,55.0747
97.2,1.6185,0.5511,-4.0499,2.8249,59.36535773,60.8784,55.1887
97.44,1.6227,0.5524,-4.0396,2.8352,59.48929885,61.0055,55.3158
97.68,1.6268,0.5537,-4.0295,2.8453,59.61918836,61.1387,55.449
97.92,1.6306,0.5547,-4.0203,2.8545,59.72177377,61.2439,55.5542
98.16,1.6347,0.556,-4.0105,2.8643,59.84386211,61.3691,55.6794
98.4,1.6391,0.5575,-3.9992,2.8756,59.99110923,61.5201,55.8304
98.64,1.6429,0.5586,-3.9902,2.8846,60.0980828,61.6298,55.9401
98.88,1.6467,0.5595,-3.9807,2.8941,60.18769876,61.7217,56.032
99.12,1.6512,0.5612,-3.9691,2.9057,60.35298609,61.8912,56.2015
99.36,1.6552,0.5624,-3.959,2.9158,60.4688335,62.01,56.3203
99.6,1.6587,0.5632,-3.9508,2.924,60.54889302,62.0921,56.4024
99.84,1.663,0.5644,-3.94,2.9348,60.67029876,62.2166,56.5269
100.08,1.6672,0.566,-3.9288,2.946,60.81774091,62.3678,56.6781
100.32,1.6707,0.5666,-3.921,2.9538,60.87878508,62.4304,56.7407
100.56,1.6748,0.5679,-3.9102,2.9646,61.004774,62.5596,56.8699
100.8,1.679,0.5692,-3.8995,2.9753,61.13261571,62.6907,57.001
101.04,1.6827,0.5703,-3.8905,2.9843,61.23832159,62.7991,57.1094
101.28,1.6866,0.5713,-3.8806,2.9942,61.33710393,62.9004,57.2107
101.52,1.6908,0.5725,-3.87,3.0048,61.45480411,63.0211,57.3314
101.76,1.6948,0.5737,-3.8596,3.0152,61.57620984,63.1456,57.4559
102,1.6985,0.5746,-3.8501,3.0247,61.66563078,63.2373,57.5476
102.24,1.7027,0.5759,-3.8394,3.0354,61.78849923,63.3633,57.6736
102.48,1.7068,0.5771,-3.8288,3.046,61.90532178,63.4831,57.7934
102.72,1.7106,0.578,-3.8194,3.0554,61.99415763,63.5742,57.8845
102.96,1.7147,0.5793,-3.8082,3.0666,62.11956146,63.7028,58.0131
103.2,1.7189,0.5808,-3.7966,3.0782,62.26329806,63.8502,58.1605
103.44,1.7227,0.5817,-3.7871,3.0877,62.35720466,63.9465,58.2568
103.68,1.7267,0.5828,-3.7764,3.0984,62.46047268,64.0524,58.3627
103.92,1.7311,0.5843,-3.7649,3.1099,62.6130831,64.2089,58.5192
104.16,1.735,0.5853,-3.7537,3.1211,62.70913503,64.3074,58.6177
104.4,1.7388,0.5861,-3.7446,3.1302,62.78753681,64.3878,58.6981
104.64,1.7431,0.5877,-3.7326,3.1422,62.94346273,64.5477,58.858
104.88,1.7473,0.5888,-3.7212,3.1536,63.05199653,64.659,58.9693
105.12,1.7507,0.5895,-3.712,3.1628,63.11859904,64.7273,59.0376
105.36,1.7549,0.5909,-3.7006,3.1742,63.25160902,64.8637,59.174
105.6,1.7591,0.5921,-3.6896,3.1852,63.3686266,64.9837,59.294
105.84,1.7627,0.5928,-3.6796,3.1952,63.43961726,65.0565,59.3668
106.08,1.7667,0.5939,-3.6686,3.2062,63.54561568,65.1652,59.4755
106.32,1.7709,0.5952,-3.657,3.2178,63.67365242,65.2965,59.6068
106.56,1.7747,0.5962,-3.6469,3.2279,63.77458008,65.4,59.7103
106.8,1.7785,0.5972,-3.6364,3.2384,63.86380598,65.4915,59.8018
107.04,1.7828,0.5983,-3.6245,3.2503,63.97536274,65.6059,59.9162
107.28,1.7867,0.5994,-3.6131,3.2617,64.08526175,65.7186,60.0289
107.52,1.7905,0.6003,-3.6026,3.2722,64.17000198,65.8055,60.1158
107.76,1.7947,0.6015,-3.591,3.2838,64.28926239,65.9278,60.2381
108,1.7989,0.6028,-3.5784,3.2964,64.41564138,66.0574,60.3677
108.24,1.8026,0.6038,-3.5688,3.306,64.51188833,66.1561,60.4664
108.48,1.8066,0.6048,-3.5562,3.3186,64.61223091,66.259,60.5693
108.72,1.811,0.6063,-3.5443,3.3305,64.75469981,66.4051,60.7154
108.96,1.8149,0.6072,-3.5333,3.3415,64.84792381,66.5007,60.811
109.2,1.8187,0.6082,-3.5221,3.3527,64.93880747,66.5939,60.9042
109.44,1.8232,0.6097,-3.5088,3.366,65.08663967,66.7455,61.0558
109.68,1.8271,0.6107,-3.4971,3.3777,65.18620213,66.8476,61.1579
109.92,1.8307,0.6112,-3.4871,3.3877,65.23827495,66.901,61.2113
110.16,1.8351,0.6126,-3.4739,3.4009,65.3717725,67.0379,61.3482
110.4,1.8392,0.6139,-3.4616,3.4132,65.50244213,67.1719,61.4822
110.64,1.8427,0.6145,-3.4514,3.4234,65.55802548,67.2289,61.5392
110.88,1.8469,0.6157,-3.4392,3.4356,65.67104496,67.3448,61.6551
111.12,1.8511,0.6169,-3.4261,3.4487,65.79459602,67.4715,61.7818
111.36,1.8547,0.6176,-3.4157,3.4591,65.86158858,67.5402,61.8505
111.6,1.8587,0.6185,-3.4035,3.4713,65.94837662,67.6292,61.9395
111.84,1.8629,0.6198,-3.3902,3.4846,66.0720252,67.756,62.0663
112.08,1.8667,0.6207,-3.3793,3.4955,66.16622435,67.8526,62.1629
112.32,1.8706,0.6215,-3.3672,3.5076,66.24140814,67.9297,62.24
112.56,1.8747,0.6227,-3.3548,3.52,66.36193625,68.0533,62.3636
112.8,1.8788,0.6238,-3.3419,3.5329,66.46198627,68.1559,62.4662
113.04,1.8825,0.6245,-3.3306,3.5442,66.53707255,68.2329,62.5432
113.28,1.8867,0.6258,-3.3176,3.5572,66.65730812,68.3562,62.6665
113.52,1.8909,0.6269,-3.3042,3.5706,66.76886487,68.4706,62.7809
113.76,1.8946,0.6278,-3.293,3.5818,66.85672557,68.5607,62.871
114,1.8987,0.6288,-3.2799,3.5949,66.956093,68.6626,62.9729
114.24,1.9031,0.6302,-3.2657,3.6091,67.08715269,68.797,63.1073
114.48,1.9069,0.631,-3.2535,3.6213,67.16984511,68.8818,63.1921
114.72,1.9107,0.6318,-3.2408,3.634,67.25195244,68.966,63.2763
114.96,1.9151,0.6332,-3.2268,3.648,67.38320716,69.1006,63.4109
115.2,1.9192,0.6342,-3.2133,3.6615,67.47828394,69.1981,63.5084
115.44,1.9227,0.6348,-3.2024,3.6724,67.5359151,69.2572,63.5675
115.68,1.927,0.636,-3.1876,3.6872,67.65673575,69.3811,63.6914
115.92,1.9312,0.6372,-3.1742,3.7006,67.77326575,69.5006,63.8109
116.16,1.9347,0.6376,-3.1628,3.712,67.81782995,69.5463,63.8566
116.4,1.9388,0.6388,-3.149,3.7258,67.92753393,69.6588,63.9691
116.64,1.943,0.6399,-3.1354,3.7394,68.04016334,69.7743,64.0846
116.88,1.9467,0.6406,-3.1229,3.7519,68.10423047,69.84,64.1503
117.12,1.9506,0.6416,-3.1098,3.765,68.20301281,69.9413,64.2516
117.36,1.9548,0.6425,-3.095,3.7798,68.29253125,70.0331,64.3434
117.6,1.9587,0.6434,-3.0821,3.7927,68.37649137,70.1192,64.4295
117.84,1.9625,0.6443,-3.0689,3.8059,68.46825265,70.2133,64.5236
118.08,1.9667,0.6453,-3.0543,3.8205,68.5684002,70.316,64.6263
118.32,1.9708,0.6464,-3.0406,3.8342,68.67049803,70.4207,64.731
118.56,1.9746,0.6471,-3.0267,3.8481,68.74090361,70.4929,64.8032
118.8,1.9787,0.648,-3.0129,3.8619,68.83432264,70.5887,64.899
119.04,1.9829,0.6492,-2.9979,3.8769,68.94344153,70.7006,65.0109
119.28,1.9867,0.65,-2.9852,3.8896,69.0237936,70.783,65.0933
119.52,1.9907,0.6508,-2.9703,3.9045,69.10073266,70.8619,65.1722
119.76,1.9951,0.6522,-2.9547,3.9201,69.23842334,71.0031,65.3134
120,1.9991,0.6529,-2.9403,3.9345,69.30824383,71.0747,65.385
120.24,2.0027,0.6535,-2.9274,3.9474,69.36967806,71.1377,65.448
120.48,2.0071,0.6547,-2.9114,3.9634,69.48650061,71.2575,65.5678
120.72,2.0113,0.6559,-2.8963,3.9785,69.59717974,71.371,65.6813
120.96,2.0147,0.6563,-2.8838,3.991,69.64301162,71.418,65.7283
121.2,2.0189,0.6571,-2.8686,4.0062,69.71946311,71.4964,65.8067
121.44,2.0231,0.6582,-2.8524,4.0224,69.82672922,71.6064,65.9167
121.68,2.0267,0.6587,-2.8398,4.035,69.87821695,71.6592,65.9695
121.92,2.0307,0.6596,-2.8252,4.0496,69.96159198,71.7447,66.055
122.16,2.0349,0.6607,-2.8093,4.0655,70.06720034,71.853,66.1633
122.4,2.0387,0.6613,-2.7952,4.0796,70.12561162,71.9129,66.2232
122.64,2.0426,0.662,-2.7804,4.0944,70.20021032,71.9894,66.2997
122.88,2.0468,0.663,-2.7647,4.1101,70.28972877,72.0812,66.3915
123.12,2.0507,0.6638,-2.7491,4.1257,70.37125102,72.1648,66.4751
123.36,2.0545,0.6645,-2.7353,4.1395,70.43892618,72.2342,66.5445
123.6,2.0587,0.6653,-2.7187,4.1561,70.51586524,72.3131,66.6234
123.84,2.0628,0.6663,-2.703,4.1718,70.6214736,72.4214,66.7317
124.08,2.0666,0.667,-2.6888,4.186,70.68476061,72.4863,66.7966
124.32,2.0707,0.6678,-2.6721,4.2027,70.76238227,72.5659,66.8762
124.56,2.075,0.6689,-2.6553,4.2195,70.87120862,72.6775,66.9878
124.8,2.0788,0.6695,-2.6401,4.2347,70.92464665,72.7323,67.0426
125.04,2.0827,0.6701,-2.6247,4.2501,70.98432561,72.7935,67.1038
125.28,2.0871,0.6713,-2.607,4.2678,71.1014407,72.9136,67.2239
125.52,2.0911,0.672,-2.5915,4.2833,71.1726264,72.9866,67.2969
125.76,2.0947,0.6724,-2.5773,4.2975,71.21504527,73.0301,67.3404
126,2.0991,0.6734,-2.5593,4.3155,71.30953696,73.127,67.4373
126.24,2.1032,0.6743,-2.5425,4.3323,71.39788523,73.2176,67.5279
126.48,2.1067,0.6745,-2.5283,4.3465,71.42089869,73.2412,67.5515
126.72,2.1109,0.6754,-2.5117,4.3631,71.50203088,73.3244,67.6347
126.96,2.1151,0.6763,-2.4938,4.381,71.59310956,73.4178,67.7281
127.2,2.1187,0.6766,-2.4792,4.3956,71.625972,73.4515,67.7618
127.44,2.1227,0.6773,-2.4633,4.4115,71.69247699,73.5197,67.83
127.68,2.1269,0.6782,-2.4456,4.4292,71.77965508,73.6091,67.9194
127.92,2.1307,0.6786,-2.4297,4.4451,71.81456533,73.6449,67.9552
128.16,2.1346,0.6791,-2.4135,4.4613,71.86381022,73.6954,68.0057
128.4,2.1387,0.6798,-2.3964,4.4784,71.93831142,73.7718,68.0821
128.64,2.1428,0.6805,-2.3797,4.4951,72.0041338,73.8393,68.1496
128.88,2.1465,0.6809,-2.3638,4.511,72.04411481,73.8803,68.1906
129.12,2.1507,0.6816,-2.3461,4.5287,72.11403281,73.952,68.2623
129.36,2.1548,0.6825,-2.3284,4.5464,72.20150345,74.0417,68.352
129.6,2.1586,0.6829,-2.3122,4.5626,72.241777,74.083,68.3933
129.84,2.1627,0.6835,-2.2941,4.5807,72.30057833,74.1433,68.4536
130.08,2.167,0.6846,-2.2755,4.5993,72.40501652,74.2504,68.5607
130.32,2.1709,0.6852,-2.2582,4.6166,72.46001479,74.3068,68.6171
130.56,2.1747,0.6856,-2.2411,4.6337,72.49687532,74.3446,68.6549
130.8,2.1792,0.6866,-2.2214,4.6534,72.59585269,74.4461,68.7564
131.04,2.1832,0.6873,-2.2036,4.6712,72.66889116,74.521,68.8313
131.28,2.1868,0.6875,-2.1873,4.6875,72.68488356,74.5374,68.8477
131.52,2.191,0.6883,-2.1677,4.7071,72.76689338,74.6215,68.9318
131.76,2.1952,0.689,-2.1489,4.7259,72.83534867,74.6917,69.002
132,2.1987,0.6892,-2.1324,4.7424,72.85251125,74.7093,69.0196
132.24,2.2028,0.6899,-2.1143,4.7605,72.92330688,74.7819,69.0922
132.48,2.207,0.6906,-2.0941,4.7807,72.99459009,74.855,69.1653
132.72,2.2107,0.6909,-2.0771,4.7977,73.02208922,74.8832,69.1935
132.96,2.2146,0.6912,-2.0588,4.816,73.04871072,74.9105,69.2208
133.2,2.2188,0.6919,-2.0395,4.8353,73.11599583,74.9795,69.2898
133.44,2.2227,0.6924,-2.0215,4.8533,73.16290037,75.0276,69.3379
133.68,2.2265,0.6926,-2.0034,4.8714,73.18591383,75.0512,69.3615
133.92,2.2307,0.6933,-1.984,4.8908,73.25280888,75.1198,69.4301
134.16,2.2348,0.6938,-1.9647,4.9101,73.30449164,75.1728,69.4831
134.4,2.2386,0.6941,-1.9472,4.9276,73.32965042,75.1986,69.5089
134.64,2.2427,0.6946,-1.9274,4.9474,73.37850526,75.2487,69.559
134.88,2.2469,0.6953,-1.9074,4.9674,73.44530279,75.3172,69.6275
135.12,2.2507,0.6954,-1.8896,4.9852,73.45846727,75.3307,69.641
135.36,2.2547,0.6957,-1.8707,5.0041,73.49152474,75.3646,69.6749
135.6,2.2591,0.6962,-1.8511,5.0237,73.5405746,75.4149,69.7252
135.84,2.263,0.6956,-1.8368,5.038,73.47972546,75.3525,69.6628
136.08,2.2667,0.6941,-1.8279,5.0469,73.3288703,75.1978,69.5081
136.32,2.2711,0.6948,-1.8099,5.0649,73.39781316,75.2685,69.5788
136.56,2.2753,0.6954,-1.7893,5.0855,73.45895484,75.3312,69.6415
136.8,2.2787,0.6955,-1.7724,5.1024,73.46880382,75.3413,69.6516
137.04,2.2829,0.6965,-1.7505,5.1243,73.56154025,75.4364,69.7467
137.28,2.2872,0.6973,-1.7289,5.1459,73.64472025,75.5217,69.832
137.52,2.2907,0.6976,-1.7094,5.1654,73.67134175,75.549,69.8593
137.76,2.2947,0.6981,-1.6881,5.1867,73.72604747,75.6051,69.9154
138,2.2989,0.6989,-1.6658,5.209,73.80201138,75.683,69.9933
138.24,2.3027,0.6994,-1.6452,5.2296,73.85125627,75.7335,70.0438
138.48,2.3066,0.6999,-1.6238,5.251,73.90011111,75.7836,70.0939
138.72,2.3108,0.7007,-1.6011,5.2737,73.97412473,75.8595,70.1698
138.96,2.3148,0.7013,-1.5794,5.2954,74.03351115,75.9204,70.2307
139.2,2.3185,0.7016,-1.5581,5.3167,74.06120531,75.9488,70.2591
139.44,2.3227,0.7023,-1.5355,5.3393,74.12927054,76.0186,70.3289
139.68,2.3268,0.7031,-1.5121,5.3627,74.21137787,76.1028,70.4131
139.92,2.3306,0.7032,-1.4908,5.384,74.21839893,76.11,70.4203
140.16,2.3346,0.7038,-1.468,5.4068,74.27466488,76.1677,70.478
140.4,2.339,0.7045,-1.4437,5.4311,74.34897104,76.2439,70.5542
140.64,2.3428,0.7051,-1.4215,5.4533,74.4046519,76.301,70.6113
140.88,2.3467,0.7053,-1.3987,5.4761,74.42142442,76.3182,70.6285
141.12,2.3511,0.7062,-1.374,5.5008,74.51386831,76.413,70.7233
141.36,2.3551,0.7066,-1.3506,5.5242,74.55004625,76.4501,70.7604
141.6,2.3588,0.7067,-1.3284,5.5464,74.56428338,76.4647,70.775
141.84,2.3631,0.7075,-1.3036,5.5712,74.64112493,76.5435,70.8538
142.08,2.3673,0.7079,-1.2787,5.5961,74.68276368,76.5862,70.8965
142.32,2.3707,0.7079,-1.2568,5.618,74.68305623,76.5865,70.8968
142.56,2.3749,0.7084,-1.2323,5.6425,74.72323226,76.6277,70.938
142.8,2.3791,0.709,-1.2069,5.6679,74.78495903,76.691,71.0013
143.04,2.3827,0.7091,-1.1847,5.6901,74.79295523,76.6992,71.0095
143.28,2.3867,0.7094,-1.1598,5.715,74.82757293,76.7347,71.045
143.52,2.3909,0.71,-1.1342,5.7406,74.8806209,76.7891,71.0994
143.76,2.3947,0.7101,-1.1104,5.7644,74.89602822,76.8049,71.1152
144,2.3986,0.7103,-1.0857,5.7891,74.91611624,76.8255,71.1358
144.24,2.4027,0.7107,-1.0601,5.8147,74.95122151,76.8615,71.1718
144.48,2.4067,0.711,-1.0345,5.8403,74.98408395,76.8952,71.2055
144.72,2.4105,0.7112,-1.0103,5.8645,75.00027138,76.9118,71.2221
144.96,2.4147,0.7116,-0.9841,5.8907,75.04122753,76.9538,71.2641
145.2,2.4189,0.7122,-0.9575,5.9173,75.0942755,77.0082,71.3185
145.44,2.4226,0.7121,-0.9331,5.9417,75.0876445,77.0014,71.3117
145.68,2.4267,0.7124,-0.9062,5.9686,75.12177463,77.0364,71.3467
145.92,2.431,0.713,-0.8788,5.996,75.17765052,77.0937,71.404
146.16,2.4349,0.7132,-0.8532,6.0216,75.19286281,77.1093,71.4196
146.4,2.4387,0.7132,-0.8275,6.0473,75.20076149,77.1174,71.4277
146.64,2.4432,0.7138,-0.7987,6.0761,75.25692993,77.175,71.4853
146.88,2.4472,0.7141,-0.772,6.1028,75.28686693,77.2057,71.516
147.12,2.4507,0.7139,-0.747,6.1278,75.26024543,77.1784,71.4887
147.36,2.455,0.7144,-0.7185,6.1563,75.31222074,77.2317,71.542
147.6,2.4592,0.7146,-0.6907,6.1841,75.33464911,77.2547,71.565
147.84,2.4627,0.7145,-0.6651,6.2097,75.32304486,77.2428,71.5531
148.08,2.4668,0.7148,-0.6371,6.2377,75.34908127,77.2695,71.5798
148.32,2.471,0.715,-0.6085,6.2663,75.37531271,77.2964,71.6067
148.56,2.4747,0.7148,-0.582,6.2928,75.35220174,77.2727,71.583
148.8,2.4786,0.7151,-0.5542,6.3206,75.383894,77.3052,71.6155
149.04,2.4828,0.7153,-0.5252,6.3496,75.39910629,77.3208,71.6311
149.28,2.4867,0.7153,-0.497,6.3778,75.40349445,77.3253,71.6356
149.52,2.4906,0.7153,-0.4693,6.4055,75.40212924,77.3239,71.6342
149.76,2.4947,0.7155,-0.4402,6.4346,75.42075454,77.343,71.6533
150,2.4988,0.7158,-0.4107,6.4641,75.45186171,77.3749,71.6852
150.24,2.5025,0.7156,-0.3831,6.4917,75.43508919,77.3577,71.668
150.48,2.5067,0.7158,-0.3534,6.5214,75.44640089,77.3693,71.6796
150.72,2.5109,0.7161,-0.3231,6.5517,75.47663043,77.4003,71.7106
150.96,2.5147,0.7159,-0.2944,6.5804,75.46258833,77.3859,71.6962
151.2,2.5187,0.7159,-0.265,6.6098,75.46249081,77.3858,71.6961
151.44,2.5231,0.7163,-0.2332,6.6416,75.49652342,77.4207,71.731
151.68,2.527,0.7163,-0.2038,6.671,75.50422708,77.4286,71.7389
151.92,2.5307,0.7161,-0.1743,6.7005,75.48228628,77.4061,71.7164
152.16,2.5351,0.7164,-0.1425,6.7323,75.51183322,77.4364,71.7467
152.4,2.5393,0.7166,-0.1119,6.7629,75.53172621,77.4568,71.7671
152.64,2.5427,0.7161,-0.0833,6.7915,75.47653292,77.4002,71.7105
152.88,2.547,0.7162,-0.0519,6.8229,75.49057503,77.4146,71.7249
153.12,2.5512,0.7166,-0.0193,6.8555,75.53006846,77.4551,71.7654
153.36,2.5547,0.7162,0.0093,6.8841,75.48628438,77.4102,71.7205
153.6,2.5587,0.716,0.041,6.9158,75.47331494,77.3969,71.7072
153.84,2.563,0.7162,0.073,6.9478,75.49311041,77.4172,71.7275
154.08,2.5667,0.7159,0.1035,6.9783,75.46161318,77.3849,71.6952
154.32,2.5706,0.7158,0.135,7.0098,75.45390952,77.377,71.6873
154.56,2.5748,0.716,0.1674,7.0422,75.47097458,77.3945,71.7048
154.8,2.5787,0.7159,0.1995,7.0743,75.45829768,77.3815,71.6918
155.04,2.5825,0.7156,0.2307,7.1055,75.42933583,77.3518,71.6621
155.28,2.5867,0.7156,0.2639,7.1387,75.43304139,77.3556,71.6659
155.52,2.5908,0.7156,0.2965,7.1713,75.43070104,77.3532,71.6635
155.76,2.5946,0.7154,0.3289,7.2037,75.41305088,77.3351,71.6454
156,2.5987,0.7154,0.3616,7.2364,75.4098329,77.3318,71.6421
156.24,2.6029,0.7155,0.3962,7.271,75.41656141,77.3387,71.649
156.48,2.6068,0.7153,0.4287,7.3035,75.40398202,77.3258,71.6361
156.72,2.6107,0.7151,0.4615,7.3363,75.38243128,77.3037,71.614
156.96,2.6151,0.7153,0.4972,7.372,75.39998392,77.3217,71.632
157.2,2.6191,0.7151,0.5308,7.4056,75.38535672,77.3067,71.617
157.44,2.6227,0.7147,0.563,7.4378,75.34537572,77.2657,71.576
157.68,2.6271,0.7149,0.5985,7.4733,75.35951534,77.2802,71.5905
157.92,2.6312,0.7148,0.6329,7.5077,75.35239677,77.2729,71.5832
158.16,2.6347,0.7142,0.6654,7.5402,75.29476562,77.2138,71.5241
158.4,2.6389,0.7141,0.7004,7.5752,75.28550172,77.2043,71.5146
158.64,2.6431,0.7141,0.7361,7.6109,75.28452658,77.2033,71.5136
158.88,2.6467,0.7136,0.7692,7.644,75.23469659,77.1522,71.4625
159.12,2.6507,0.7134,0.8035,7.6783,75.220752,77.1379,71.4482
159.36,2.6549,0.7133,0.8397,7.7145,75.2028093,77.1195,71.4298
159.6,2.6587,0.713,0.874,7.7488,75.18047845,77.0966,71.4069
159.84,2.6626,0.7126,0.9086,7.7834,75.14030241,77.0554,71.3657
160.08,2.6668,0.7127,0.9453,7.8201,75.1475185,77.0628,71.3731
160.32,2.6708,0.7124,0.9808,7.8556,75.12021439,77.0348,71.3451
160.56,2.6745,0.712,1.0159,7.8907,75.08023339,76.9938,71.3041
160.8,2.6787,0.7118,1.0523,7.9271,75.05878017,76.9718,71.2821
161.04,2.6828,0.7117,1.0892,7.964,75.04561569,76.9583,71.2686
161.28,2.6866,0.7113,1.1239,7.9987,75.00719492,76.9189,71.2292
161.52,2.6907,0.7111,1.1606,8.0354,74.99061743,76.9019,71.2122
161.76,2.695,0.7113,1.1985,8.0733,75.00651231,76.9182,71.2285
162,2.6989,0.7108,1.2346,8.1094,74.95990031,76.8704,71.1807
162.24,2.7027,0.7104,1.2711,8.1459,74.92011434,76.8296,71.1399
162.48,2.7072,0.7105,1.3095,8.1843,74.92957326,76.8393,71.1496
162.72,2.7112,0.7102,1.3471,8.2219,74.907925,76.8171,71.1274
162.96,2.7147,0.7095,1.3816,8.2564,74.83693434,76.7443,71.0546
163.2,2.719,0.7096,1.4209,8.2957,74.84161504,76.7491,71.0594
163.44,2.7232,0.7094,1.459,8.3338,74.82142951,76.7284,71.0387
163.68,2.7267,0.7087,1.4942,8.369,74.75336429,76.6586,70.9689
163.92,2.7308,0.7083,1.5325,8.4073,74.71962422,76.624,70.9343
164.16,2.735,0.7083,1.5712,8.446,74.72206208,76.6265,70.9368
164.4,2.7387,0.7076,1.6075,8.4823,74.65399686,76.5567,70.867
164.64,2.7426,0.7072,1.6459,8.5207,74.61128544,76.5129,70.8232
164.88,2.7468,0.7071,1.6845,8.5593,74.60455693,76.506,70.8163
165.12,2.7507,0.7067,1.7227,8.5975,74.56194303,76.4623,70.7726
165.36,2.7545,0.7062,1.76,8.6348,74.51698878,76.4162,70.7265
165.6,2.7587,0.7061,1.7999,8.6747,74.50187401,76.4007,70.711
165.84,2.7628,0.7058,1.8385,8.7133,74.47349725,76.3716,70.6819
166.08,2.7666,0.7052,1.8762,8.751,74.41225805,76.3088,70.6191
166.32,2.7707,0.705,1.9157,8.7905,74.39217003,76.2882,70.5985
166.56,2.7749,0.7049,1.9554,8.8302,74.39041477,76.2864,70.5967
166.8,2.7787,0.7044,1.9937,8.8685,74.33453887,76.2291,70.5394
167.04,2.7827,0.7039,2.0327,8.9075,74.28675669,76.1801,70.4904
167.28,2.7871,0.704,2.0742,8.949,74.29436284,76.1879,70.4982
167.52,2.7909,0.7034,2.1122,8.987,74.23848694,76.1306,70.4409
167.76,2.7947,0.7028,2.1519,9.0267,74.18436631,76.0751,70.3854
168,2.7991,0.7029,2.1928,9.0676,74.18631661,76.0771,70.3874
168.24,2.8032,0.7026,2.2329,9.1077,74.15911002,76.0492,70.3595
168.48,2.8067,0.7018,2.2707,9.1455,74.07875795,75.9668,70.2771
168.72,2.811,0.7016,2.3113,9.1861,74.06023017,75.9478,70.2581
168.96,2.8152,0.7014,2.3529,9.2277,74.03975209,75.9268,70.2371
169.2,2.8187,0.7006,2.3904,9.2652,73.96837137,75.8536,70.1639
169.44,2.8228,0.7002,2.4309,9.3057,73.93190089,75.8162,70.1265
169.68,2.827,0.6999,2.4728,9.3476,73.90108626,75.7846,70.0949
169.92,2.8307,0.6994,2.5116,9.3864,73.85067119,75.7329,70.0432
170.16,2.8346,0.6988,2.552,9.4268,73.79479529,75.6756,69.9859
170.4,2.8388,0.6986,2.5933,9.4681,73.77080669,75.651,69.9613
170.64,2.8427,0.6982,2.6339,9.5087,73.73355609,75.6128,69.9231
170.88,2.8465,0.6976,2.6739,9.5487,73.67602245,75.5538,69.8641
171.12,2.8507,0.6974,2.7151,9.5899,73.65252142,75.5297,69.84
171.36,2.8548,0.6971,2.7567,9.6315,73.62502229,75.5015,69.8118
171.6,2.8586,0.6964,2.7962,9.671,73.55666452,75.4314,69.7417
171.84,2.8627,0.6961,2.8388,9.7136,73.52584989,75.3998,69.7101
172.08,2.8669,0.696,2.8808,9.7556,73.5172686,75.391,69.7013
172.32,2.8707,0.6954,2.9216,9.7964,73.4600275,75.3323,69.6426
172.56,2.8747,0.695,2.9628,9.8376,73.41790118,75.2891,69.5994
172.8,2.8791,0.6949,3.0061,9.8809,73.40834474,75.2793,69.5896
173.04,2.8831,0.6945,3.0475,9.9223,73.37158172,75.2416,69.5519
173.28,2.8867,0.6938,3.0881,9.9629,73.30605188,75.1744,69.4847
173.52,2.8911,0.6938,3.1313,10.0061,73.29864076,75.1668,69.4771
173.76,2.8953,0.6934,3.1736,10.0484,73.2662659,75.1336,69.4439
174,2.8988,0.6925,3.2139,10.0887,73.17333444,75.0383,69.3486
174.24,2.9029,0.6923,3.2563,10.1311,73.15665943,75.0212,69.3315
174.48,2.9071,0.6921,3.2995,10.1743,73.13676645,75.0008,69.3111
174.72,2.9107,0.6912,3.3394,10.2142,73.05183119,74.9137,69.224
174.96,2.9147,0.6908,3.3822,10.257,73.0133129,74.8742,69.1845
175.2,2.9189,0.6905,3.4254,10.3002,72.98405851,74.8442,69.1545
175.44,2.9227,0.6901,3.4666,10.3414,72.94397999,74.8031,69.1134
175.68,2.9266,0.6895,3.5088,10.3836,72.88020541,74.7377,69.048
175.92,2.9308,0.6894,3.5516,10.4264,72.86947879,74.7267,69.037
176.16,2.9347,0.689,3.5944,10.4692,72.82949779,74.6857,68.996
176.4,2.9385,0.6881,3.6355,10.5103,72.74982832,74.604,68.9143
176.64,2.9427,0.6878,3.6795,10.5543,72.71862363,74.572,68.8823
176.88,2.9468,0.6875,3.7222,10.597,72.69141705,74.5441,68.8544
177.12,2.9506,0.687,3.7643,10.6391,72.63905168,74.4904,68.8007
177.36,2.9547,0.6866,3.807,10.6818,72.59565766,74.4459,68.7562
177.6,2.959,0.6865,3.8514,10.7262,72.59351234,74.4437,68.754
177.84,2.9629,0.686,3.8939,10.7687,72.54114697,74.39,68.7003
178.08,2.9667,0.6853,3.9363,10.8111,72.46986376,74.3169,68.6272
178.32,2.9711,0.6853,3.9814,10.8562,72.4681085,74.3151,68.6254
178.56,2.9752,0.6851,4.0244,10.8992,72.44899563,74.2955,68.6058
178.8,2.9787,0.6842,4.0659,10.9407,72.36015979,74.2044,68.5147
179.04,2.9831,0.684,4.1104,10.9852,72.34689779,74.1908,68.5011
179.28,2.9873,0.6838,4.1546,11.0294,72.3289551,74.1724,68.4827
179.52,2.9907,0.6829,4.1956,11.0704,72.23514601,74.0762,68.3865
179.76,2.9948,0.6826,4.2398,11.1146,72.20969468,74.0501,68.3604
180,2.999,0.6823,4.2842,11.159,72.1791726,74.0188,68.3291
180.24,3.0027,0.6817,4.3262,11.201,72.11803091,73.9561,68.2664
180.48,3.0066,0.6812,4.3695,11.2443,72.07044376,73.9073,68.2176
180.72,3.0108,0.6809,4.4139,11.2887,72.04567504,73.8819,68.1922
180.96,3.0147,0.6805,4.4571,11.3319,72.00803439,73.8433,68.1536
181.2,3.0186,0.6799,4.5003,11.3751,71.94591756,73.7796,68.0899
181.44,3.0227,0.6796,4.545,11.4198,71.91988115,73.7529,68.0632
181.68,3.0268,0.6792,4.5889,11.4637,71.87931505,73.7113,68.0216
181.92,3.0305,0.6787,4.6325,11.5073,71.82343916,73.654,67.9643
182.16,3.0347,0.6784,4.6773,11.5521,71.79633009,73.6262,67.9365
182.4,3.0389,0.6782,4.7227,11.5975,71.78180041,73.6113,67.9216
182.64,3.0427,0.6775,4.7658,11.6406,71.712565,73.5403,67.8506
182.88,3.0467,0.6771,4.8107,11.6855,71.67102376,73.4977,67.808
183.12,3.0511,0.6771,4.8579,11.7327,71.67433926,73.5011,67.8114
183.36,3.0549,0.6765,4.9035,11.7783,71.61368515,73.4389,67.7492
183.438,3.0564,0.7167,8.8329,15.7077,75.54011247,77.4654,71.7757