File: data/ReportRaw/Resin_CSV/V4_Resin_HT/Tensile_Test_01.csv
Time,Displacement,Force,Tensile strain (Strain 1),,,,Tensile stress
(s),(mm),(kN),(%),,,,(MPa)
0,0,0.0001,-5.5368,0,0.008518868,0,0.0086
0.24,0.0015,0.0014,-5.5328,0.004,0.135014151,0.004,0.1363
0.48,0.0068,0.0067,-5.5163,0.0205,0.662391509,0.0205,0.6687
0.72,0.011,0.0107,-5.5031,0.0337,1.051584906,0.0337,1.0616
0.96,0.0145,0.0138,-5.4915,0.0453,1.355490566,0.0453,1.3684
1.2,0.0186,0.0174,-5.479,0.0578,1.708528302,0.0578,1.7248
1.44,0.0228,0.0211,-5.4662,0.0706,2.076820755,0.0706,2.0966
1.68,0.0265,0.0243,-5.4554,0.0814,2.390533019,0.0814,2.4133
1.92,0.0304,0.0276,-5.4434,0.0934,2.711674528,0.0934,2.7375
2.16,0.0346,0.031,-5.4306,0.1062,3.046981132,0.1062,3.076
2.4,0.0385,0.0342,-5.4201,0.1167,3.363665094,0.1167,3.3957
2.64,0.0423,0.0372,-5.4085,0.1283,3.652117925,0.1283,3.6869
2.88,0.0465,0.0403,-5.3969,0.1399,3.960084906,0.1399,3.9978
3.12,0.0506,0.0432,-5.3861,0.1507,4.242099057,0.1507,4.2825
3.36,0.0544,0.0456,-5.3762,0.1606,4.485877358,0.1606,4.5286
3.6,0.0585,0.0482,-5.3668,0.17,4.740948113,0.17,4.7861
3.84,0.0627,0.0507,-5.3572,0.1796,4.986707547,0.1796,5.0342
4.08,0.0665,0.0527,-5.3494,0.1874,5.180561321,0.1874,5.2299
4.32,0.0705,0.0546,-5.3413,0.1955,5.369165094,0.1955,5.4203
4.56,0.0749,0.0572,-5.3315,0.2053,5.621462264,0.2053,5.675
4.8,0.0788,0.0591,-5.3244,0.2124,5.812641509,0.2124,5.868
5.04,0.0825,0.0606,-5.3177,0.2191,5.952212264,0.2191,6.0089
5.28,0.087,0.0627,-5.3088,0.228,6.164787736,0.228,6.2235
5.52,0.0911,0.0646,-5.3012,0.2356,6.351311321,0.2356,6.4118
5.76,0.0946,0.0655,-5.2966,0.2402,6.440660377,0.2402,6.502
6,0.0988,0.0666,-5.2911,0.2457,6.546353774,0.2457,6.6087
6.24,0.103,0.068,-5.2862,0.2506,6.686122642,0.2506,6.7498
6.48,0.1066,0.0687,-5.2817,0.2551,6.753976415,0.2551,6.8183
6.72,0.1105,0.0697,-5.2761,0.2607,6.848476415,0.2607,6.9137
6.96,0.1147,0.0711,-5.2701,0.2667,6.988641509,0.2667,7.0552
7.2,0.1185,0.0723,-5.2649,0.2719,7.105924528,0.2719,7.1736
7.44,0.1224,0.0733,-5.2598,0.277,7.199830189,0.277,7.2684
7.68,0.1266,0.0748,-5.2534,0.2834,7.352278302,0.2834,7.4223
7.92,0.1305,0.0761,-5.2473,0.2895,7.479566038,0.2895,7.5508
8.16,0.1343,0.0772,-5.2428,0.294,7.591103774,0.294,7.6634
8.4,0.1385,0.0784,-5.2371,0.2997,7.709179245,0.2997,7.7826
8.64,0.1426,0.0798,-5.2312,0.3056,7.841221698,0.3056,7.9159
8.88,0.1464,0.0804,-5.2278,0.309,7.898971698,0.309,7.9742
9.12,0.1505,0.0813,-5.2233,0.3135,7.990301887,0.3135,8.0664
9.36,0.1548,0.0825,-5.2182,0.3186,8.108278302,0.3186,8.1855
9.6,0.1586,0.0833,-5.2141,0.3227,8.188018868,0.3227,8.266
9.84,0.1625,0.0841,-5.2102,0.3266,8.263103774,0.3266,8.3418
10.08,0.167,0.0852,-5.2053,0.3315,8.375334906,0.3315,8.4551
10.32,0.171,0.0861,-5.2004,0.3364,8.457948113,0.3364,8.5385
10.56,0.1745,0.0865,-5.1975,0.3393,8.499650943,0.3393,8.5806
10.8,0.1789,0.0878,-5.1927,0.3441,8.62545283,0.3441,8.7076
11.04,0.1831,0.0887,-5.1873,0.3495,8.718665094,0.3495,8.8017
11.28,0.1865,0.0894,-5.1841,0.3527,8.788301887,0.3527,8.872
11.52,0.1906,0.0903,-5.1792,0.3576,8.877551887,0.3576,8.9621
11.76,0.1949,0.0917,-5.173,0.3638,9.00840566,0.3638,9.0942
12,0.1985,0.0928,-5.1679,0.3689,9.122816038,0.3689,9.2097
12.24,0.2025,0.0943,-5.1618,0.375,9.268726415,0.375,9.357
12.48,0.2066,0.096,-5.1544,0.3824,9.434943396,0.3824,9.5248
12.72,0.2105,0.0975,-5.1478,0.389,9.585806604,0.389,9.6771
12.96,0.2144,0.0989,-5.1414,0.3954,9.718740566,0.3954,9.8113
13.2,0.2185,0.1004,-5.1347,0.4021,9.862174528,0.4021,9.9561
13.44,0.2226,0.102,-5.1279,0.4089,10.02007075,0.4089,10.1155
13.68,0.2264,0.1032,-5.122,0.4148,10.14339623,0.4148,10.24
13.92,0.2305,0.1048,-5.1152,0.4216,10.29574528,0.4216,10.3938
14.16,0.2347,0.1064,-5.1078,0.429,10.45601887,0.429,10.5556
14.4,0.2384,0.1076,-5.1021,0.4347,10.57250943,0.4347,10.6732
14.64,0.2425,0.1091,-5.0958,0.441,10.71683491,0.441,10.8189
14.88,0.2469,0.1108,-5.0883,0.4485,10.88513208,0.4485,10.9888
15.12,0.2507,0.1119,-5.0821,0.4547,10.99429245,0.4547,11.099
15.36,0.2545,0.1131,-5.0765,0.4603,11.1165283,0.4603,11.2224
15.6,0.259,0.115,-5.069,0.4678,11.30017925,0.4678,11.4078
15.84,0.2631,0.1163,-5.0625,0.4743,11.43232075,0.4743,11.5412
16.08,0.2665,0.1172,-5.0577,0.4791,11.51602358,0.4791,11.6257
16.32,0.2708,0.1187,-5.0511,0.4857,11.66787736,0.4857,11.779
16.56,0.2751,0.1203,-5.0438,0.493,11.82101887,0.493,11.9336
16.8,0.2785,0.1212,-5.0392,0.4976,11.90917925,0.4976,12.0226
17.04,0.2826,0.1225,-5.0329,0.5039,12.03339623,0.5039,12.148
17.28,0.2869,0.124,-5.0262,0.5106,12.18475472,0.5106,12.3008
17.52,0.2905,0.125,-5.0211,0.5157,12.28698113,0.5157,12.404
17.76,0.2944,0.1264,-5.0148,0.522,12.4221934,0.522,12.5405
18,0.2986,0.1278,-5.0085,0.5283,12.5625566,0.5283,12.6822
18.24,0.3025,0.129,-5.0028,0.534,12.67508491,0.534,12.7958
18.48,0.3063,0.1301,-4.9976,0.5392,12.78414623,0.5392,12.9059
18.72,0.3105,0.1315,-4.9908,0.546,12.91787264,0.546,13.0409
18.96,0.3145,0.133,-4.9845,0.5523,13.0725,0.5523,13.197
19.2,0.3183,0.134,-4.9793,0.5575,13.17225,0.5575,13.2977
19.44,0.3225,0.1355,-4.9727,0.5641,13.31429717,0.5641,13.4411
19.68,0.3267,0.137,-4.9662,0.5706,13.46357547,0.5706,13.5918
19.92,0.3305,0.1382,-4.9605,0.5763,13.57689623,0.5763,13.7062
20.16,0.3345,0.1395,-4.9544,0.5824,13.70725472,0.5824,13.8378
20.4,0.3389,0.1412,-4.947,0.5898,13.87842453,0.5898,14.0106
20.64,0.3428,0.1424,-4.9416,0.5952,13.98926887,0.5952,14.1225
20.88,0.3466,0.1433,-4.9367,0.6001,14.08386792,0.6001,14.218
21.12,0.351,0.1449,-4.9297,0.6071,14.2373066,0.6071,14.3729
21.36,0.3551,0.1464,-4.9234,0.6134,14.38737736,0.6134,14.5244
21.6,0.3585,0.1471,-4.9193,0.6175,14.45275472,0.6175,14.5904
21.84,0.3628,0.1485,-4.9133,0.6235,14.58836321,0.6235,14.7273
22.08,0.367,0.1498,-4.9069,0.6299,14.72496226,0.6299,14.8652
22.32,0.3705,0.1505,-4.9024,0.6344,14.7915283,0.6344,14.9324
22.56,0.3746,0.1518,-4.8971,0.6397,14.91584434,0.6397,15.0579
22.8,0.3788,0.1529,-4.8912,0.6456,15.02401415,0.6456,15.1671
23.04,0.3825,0.1541,-4.8868,0.65,15.14743868,0.65,15.2917
23.28,0.3864,0.155,-4.8813,0.6555,15.23005189,0.6555,15.3751
23.52,0.3906,0.1563,-4.8754,0.6614,15.3637783,0.6614,15.5101
23.76,0.3946,0.1575,-4.8702,0.6666,15.48066509,0.6666,15.6281
24,0.3983,0.1584,-4.8659,0.6709,15.56337736,0.6709,15.7116
24.24,0.4025,0.1597,-4.8601,0.6767,15.69016981,0.6767,15.8396
24.48,0.4066,0.1609,-4.8543,0.6825,15.81210849,0.6825,15.9627
24.72,0.4104,0.1618,-4.8498,0.687,15.90462736,0.687,16.0561
24.96,0.4145,0.1631,-4.8446,0.6922,16.02706132,0.6922,16.1797
25.2,0.4188,0.1646,-4.8387,0.6981,16.17089151,0.6981,16.3249
25.44,0.4226,0.1655,-4.8333,0.7035,16.26142925,0.7035,16.4163
25.68,0.4265,0.1665,-4.8286,0.7082,16.36325943,0.7082,16.5191
25.92,0.4309,0.1681,-4.8224,0.7144,16.52303774,0.7144,16.6804
26.16,0.4349,0.1693,-4.8172,0.7196,16.63685377,0.7196,16.7953
26.4,0.4386,0.17,-4.8129,0.7239,16.70688679,0.7239,16.866
26.64,0.4429,0.1714,-4.8069,0.7299,16.8413066,0.7299,17.0017
26.88,0.4471,0.1727,-4.801,0.7358,16.97612264,0.7358,17.1378
27.12,0.4505,0.1733,-4.7977,0.7391,17.03456604,0.7391,17.1968
27.36,0.4547,0.1745,-4.7921,0.7447,17.15026415,0.7447,17.3136
27.6,0.4589,0.1759,-4.7861,0.7507,17.29013208,0.7507,17.4548
27.84,0.4625,0.1768,-4.7823,0.7545,17.37472642,0.7545,17.5402
28.08,0.4665,0.1778,-4.777,0.7598,17.47091038,0.7598,17.6373
28.32,0.4707,0.1791,-4.7718,0.765,17.60325,0.765,17.7709
28.56,0.4745,0.1801,-4.7667,0.7701,17.69953302,0.7701,17.8681
28.8,0.4783,0.181,-4.7616,0.7752,17.78660377,0.7752,17.956
29.04,0.4825,0.1824,-4.7562,0.7806,17.92666981,0.7806,18.0974
29.28,0.4865,0.1837,-4.7512,0.7856,18.05712736,0.7856,18.2291
29.52,0.4903,0.1847,-4.7462,0.7906,18.15251887,0.7906,18.3254
29.76,0.4945,0.1859,-4.7405,0.7963,18.26881132,0.7963,18.4428
30,0.4987,0.1873,-4.7346,0.8022,18.40451887,0.8022,18.5798
30.24,0.5024,0.1883,-4.7297,0.8071,18.50615094,0.8071,18.6824
30.48,0.5065,0.1894,-4.7248,0.812,18.61362736,0.812,18.7909
30.72,0.5109,0.191,-4.7186,0.8182,18.77112736,0.8182,18.9499
30.96,0.5147,0.192,-4.7135,0.8233,18.86909434,0.8233,19.0488
31.2,0.5185,0.193,-4.7089,0.8279,18.96577358,0.8279,19.1464
31.44,0.523,0.1946,-4.7028,0.834,19.12297642,0.834,19.3051
31.68,0.527,0.1958,-4.697,0.8398,19.24590566,0.8398,19.4292
31.92,0.5305,0.1964,-4.6935,0.8433,19.30028774,0.8433,19.4841
32.16,0.5348,0.1978,-4.6874,0.8494,19.43441038,0.8494,19.6195
32.4,0.5391,0.1991,-4.682,0.8548,19.56892925,0.8548,19.7553
32.64,0.5425,0.1998,-4.6779,0.8589,19.63163208,0.8589,19.8186
32.88,0.5466,0.201,-4.6725,0.8643,19.75238208,0.8643,19.9405
33.12,0.5508,0.2022,-4.6665,0.8703,19.86887264,0.8703,20.0581
33.36,0.5545,0.2032,-4.6629,0.8739,19.97010849,0.8739,20.1603
33.6,0.5584,0.204,-4.6579,0.8789,20.04965094,0.8789,20.2406
33.84,0.5626,0.2055,-4.6521,0.8847,20.1990283,0.8847,20.3914
34.08,0.5665,0.2067,-4.6469,0.8899,20.30799057,0.8899,20.5014
34.32,0.5703,0.2076,-4.6426,0.8942,20.40209434,0.8942,20.5964
34.56,0.5745,0.2089,-4.6369,0.8999,20.5334434,0.8999,20.729
34.8,0.5786,0.2102,-4.6313,0.9055,20.65359906,0.9055,20.8503
35.04,0.5824,0.2112,-4.6274,0.9094,20.74998113,0.9094,20.9476
35.28,0.5865,0.2123,-4.6212,0.9156,20.86726415,0.9156,21.066
35.52,0.5907,0.2139,-4.6149,0.9219,21.01882075,0.9219,21.219
35.76,0.5944,0.2147,-4.611,0.9258,21.09816509,0.9258,21.2991
36,0.5985,0.2159,-4.6059,0.9309,21.21891509,0.9309,21.421
36.24,0.6029,0.2175,-4.599,0.9378,21.37136321,0.9378,21.5749
36.48,0.6068,0.2185,-4.5936,0.9432,21.47368868,0.9432,21.6782
36.72,0.6105,0.2194,-4.5896,0.9472,21.55907547,0.9472,21.7644
36.96,0.6149,0.221,-4.5827,0.9541,21.71925,0.9541,21.9261
37.2,0.6191,0.2223,-4.5774,0.9594,21.84396226,0.9594,22.052
37.44,0.6225,0.2229,-4.574,0.9628,21.90319811,0.9628,22.1118
37.68,0.6268,0.2244,-4.5673,0.9695,22.04811792,0.9695,22.2581
37.92,0.631,0.2256,-4.5615,0.9753,22.17253302,0.9753,22.3837
38.16,0.6345,0.2264,-4.5582,0.9786,22.24831132,0.9786,22.4602
38.4,0.6385,0.2276,-4.5526,0.9842,22.36747642,0.9842,22.5805
38.64,0.6428,0.229,-4.5465,0.9903,22.50387736,0.9903,22.7182
38.88,0.6465,0.23,-4.5417,0.9951,22.60333019,0.9951,22.8186
39.12,0.6504,0.231,-4.5369,0.9999,22.70317925,0.9999,22.9194
39.36,0.6546,0.2323,-4.5312,1.0056,22.83215094,1.0056,23.0496
39.6,0.6585,0.2335,-4.5259,1.0109,22.94527358,1.0109,23.1638
39.84,0.6623,0.2344,-4.521,1.0158,23.0347217,1.0158,23.2541
40.08,0.6665,0.2357,-4.5153,1.0215,23.15992925,1.0215,23.3805
40.32,0.6706,0.2372,-4.5097,1.0271,23.30722642,1.0271,23.5292
40.56,0.6744,0.2381,-4.5052,1.0316,23.40232075,1.0316,23.6252
40.8,0.6785,0.2395,-4.4994,1.0374,23.53168868,1.0374,23.7558
41.04,0.6828,0.2409,-4.4932,1.0436,23.67026887,1.0436,23.8957
41.28,0.6866,0.242,-4.4879,1.0489,23.78349057,1.0489,24.01
41.52,0.6905,0.2429,-4.4831,1.0537,23.8740283,1.0537,24.1014
41.76,0.695,0.2446,-4.4763,1.0605,24.0374717,1.0605,24.2664
42,0.699,0.2459,-4.4709,1.0659,24.16208491,1.0659,24.3922
42.24,0.7026,0.2467,-4.4668,1.07,24.24241981,1.07,24.4733
42.48,0.7069,0.2481,-4.4606,1.0762,24.38109906,1.0762,24.6133
42.72,0.7111,0.2494,-4.4546,1.0822,24.5092783,1.0822,24.7427
42.96,0.7145,0.2502,-4.4509,1.0859,24.58475943,1.0859,24.8189
43.2,0.7187,0.2514,-4.4457,1.0911,24.70283491,1.0911,24.9381
43.44,0.7229,0.253,-4.4397,1.0971,24.85766038,1.0971,25.0944
43.68,0.7265,0.2537,-4.4356,1.1012,24.9292783,1.1012,25.1667
43.92,0.7305,0.2548,-4.4299,1.1069,25.03685377,1.1069,25.2753
44.16,0.7347,0.2563,-4.4238,1.113,25.1872217,1.113,25.4271
44.4,0.7385,0.2574,-4.4192,1.1176,25.29142925,1.1176,25.5323
44.64,0.7424,0.2584,-4.4145,1.1223,25.38999057,1.1223,25.6318
44.88,0.7465,0.2596,-4.4084,1.1284,25.50856132,1.1284,25.7515
45.12,0.7506,0.2609,-4.4022,1.1346,25.63891981,1.1346,25.8831
45.36,0.7543,0.2618,-4.3982,1.1386,25.73153774,1.1386,25.9766
45.6,0.7585,0.2632,-4.3923,1.1445,25.86704717,1.1445,26.1134
45.84,0.7627,0.2645,-4.3869,1.1499,25.99661321,1.1499,26.2442
46.08,0.7664,0.2654,-4.3822,1.1546,26.08536792,1.1546,26.3338
46.32,0.7705,0.2668,-4.3763,1.1605,26.21711321,1.1605,26.4668
46.56,0.7749,0.2682,-4.37,1.1668,26.3579717,1.1668,26.609
46.8,0.7787,0.2694,-4.3651,1.1717,26.47525472,1.1717,26.7274
47.04,0.7825,0.2704,-4.36,1.1768,26.56945755,1.1768,26.8225
47.28,0.787,0.272,-4.3527,1.1841,26.72784906,1.1841,26.9824
47.52,0.791,0.2732,-4.3473,1.1895,26.85206604,1.1895,27.1078
47.76,0.7945,0.2741,-4.3433,1.1935,26.93200472,1.1935,27.1885
48,0.7989,0.2754,-4.3374,1.1994,27.06791038,1.1994,27.3257
48.24,0.8031,0.277,-4.3308,1.206,27.21758491,1.206,27.4768
48.48,0.8065,0.2776,-4.3276,1.2092,27.27751415,1.2092,27.5373
48.72,0.8106,0.2789,-4.3219,1.2149,27.40539623,1.2149,27.6664
48.96,0.8149,0.2802,-4.3153,1.2215,27.53674528,1.2215,27.799
49.2,0.8185,0.2812,-4.3107,1.2261,27.62936321,1.2261,27.8925
49.44,0.8225,0.2824,-4.3054,1.2314,27.75536321,1.2314,28.0197
49.68,0.8266,0.2838,-4.2997,1.2371,27.88740566,1.2371,28.153
49.92,0.8306,0.2851,-4.2942,1.2426,28.01766509,1.2426,28.2845
50.16,0.8343,0.2861,-4.2891,1.2477,28.11890094,1.2477,28.3867
50.4,0.8385,0.2875,-4.2824,1.2544,28.25223113,1.2544,28.5213
50.64,0.8426,0.2888,-4.2772,1.2596,28.38070755,1.2596,28.651
50.88,0.8463,0.2898,-4.2721,1.2647,28.47867453,1.2647,28.7499
51.12,0.8505,0.2913,-4.2661,1.2707,28.62210849,1.2707,28.8947
51.36,0.8547,0.2927,-4.259,1.2778,28.76722642,1.2778,29.0412
51.6,0.8585,0.2939,-4.254,1.2828,28.88223113,1.2828,29.1573
51.84,0.8624,0.2952,-4.2488,1.288,29.0115,1.288,29.2878
52.08,0.8669,0.2969,-4.2413,1.2955,29.18039151,1.2955,29.4583
52.32,0.8708,0.2982,-4.2355,1.3013,29.30629245,1.3013,29.5854
52.56,0.8745,0.2992,-4.2307,1.3061,29.40673585,1.3061,29.6868
52.8,0.879,0.3008,-4.2238,1.313,29.5634434,1.313,29.845
53.04,0.8831,0.3023,-4.2178,1.319,29.70509434,1.319,29.988
53.28,0.8866,0.303,-4.2135,1.3233,29.77116509,1.3233,30.0547
53.52,0.8908,0.3043,-4.2073,1.3295,29.90300943,1.3295,30.1878
53.76,0.895,0.3059,-4.2011,1.3357,30.05842925,1.3357,30.3447
54,0.8985,0.3066,-4.1964,1.3404,30.12776887,1.3404,30.4147
54.24,0.9026,0.3079,-4.1912,1.3456,30.2534717,1.3456,30.5416
54.48,0.9068,0.3093,-4.1844,1.3524,30.39809434,1.3524,30.6876
54.72,0.9105,0.3104,-4.1797,1.3571,30.50458019,1.3571,30.7951
54.96,0.9144,0.3115,-4.1745,1.3623,30.61294811,1.3623,30.9045
55.2,0.9186,0.3129,-4.1683,1.3685,30.75123113,1.3685,31.0441
55.44,0.9225,0.3142,-4.1631,1.3737,30.88059906,1.3737,31.1747
55.68,0.9263,0.3152,-4.1576,1.3792,30.97074057,1.3792,31.2657
55.92,0.9305,0.3166,-4.1513,1.3855,31.11625472,1.3855,31.4126
56.16,0.9346,0.318,-4.1453,1.3915,31.24512736,1.3915,31.5427
56.4,0.9384,0.3189,-4.1408,1.396,31.33417925,1.396,31.6326
56.64,0.9425,0.3204,-4.1347,1.4021,31.48444811,1.4021,31.7843
56.88,0.9468,0.3219,-4.1273,1.4095,31.63669811,1.4095,31.938
57.12,0.9506,0.323,-4.1224,1.4144,31.74466981,1.4144,32.047
57.36,0.9545,0.3241,-4.1172,1.4196,31.85283962,1.4196,32.1562
57.6,0.959,0.3258,-4.1102,1.4266,32.01558962,1.4266,32.3205
57.84,0.9629,0.3272,-4.1045,1.4323,32.15228774,1.4323,32.4585
58.08,0.9666,0.328,-4.0997,1.4371,32.23708019,1.4371,32.5441
58.32,0.9709,0.3296,-4.0927,1.4441,32.3895283,1.4441,32.698
58.56,0.9751,0.331,-4.0866,1.4502,32.53137736,1.4502,32.8412
58.8,0.9785,0.3318,-4.0826,1.4542,32.6025,1.4542,32.913
59.04,0.9827,0.3331,-4.0758,1.461,32.73394811,1.461,33.0457
59.28,0.9869,0.3347,-4.0696,1.4672,32.8905566,1.4672,33.2038
59.52,0.9905,0.3356,-4.0647,1.4721,32.97525,1.4721,33.2893
59.76,0.9945,0.3368,-4.0592,1.4776,33.09590094,1.4776,33.4111
60,0.9987,0.3382,-4.0526,1.4842,33.23903774,1.4842,33.5556
60.24,1.0025,0.3396,-4.0472,1.4896,33.36791038,1.4896,33.6857
60.48,1.0064,0.3405,-4.0416,1.4952,33.46270755,1.4952,33.7814
60.72,1.0106,0.3421,-4.0352,1.5016,33.61931604,1.5016,33.9395
60.96,1.0146,0.3434,-4.0291,1.5077,33.74739623,1.5077,34.0688
61.2,1.0183,0.3444,-4.0236,1.5132,33.84823585,1.5132,34.1706
61.44,1.0225,0.3459,-4.0171,1.5197,33.99503774,1.5197,34.3188
61.68,1.0267,0.3474,-4.0111,1.5257,34.13995755,1.5257,34.4651
61.92,1.0304,0.3485,-4.0059,1.5309,34.24515566,1.5309,34.5713
62.16,1.0345,0.3498,-3.9992,1.5376,34.37640566,1.5376,34.7038
62.4,1.0388,0.3513,-3.9916,1.5452,34.52677358,1.5452,34.8556
62.64,1.0426,0.3524,-3.9868,1.55,34.63385377,1.55,34.9637
62.88,1.0465,0.3536,-3.9815,1.5553,34.74945283,1.5553,35.0804
63.12,1.0509,0.3555,-3.9738,1.563,34.93221226,1.563,35.2649
63.36,1.055,0.3567,-3.9672,1.5696,35.05098113,1.5696,35.3848
63.6,1.0585,0.3576,-3.9628,1.574,35.13924057,1.574,35.4739
63.84,1.0629,0.3591,-3.9556,1.5812,35.29337264,1.5812,35.6295
64.08,1.0671,0.3607,-3.9492,1.5876,35.45047642,1.5876,35.7881
64.32,1.0706,0.3615,-3.9446,1.5922,35.52407547,1.5922,35.8624
64.56,1.0746,0.3628,-3.9379,1.5989,35.65255189,1.5989,35.9921
64.8,1.0789,0.3643,-3.9314,1.6054,35.80024528,1.6054,36.1412
65.04,1.0825,0.3654,-3.9266,1.6102,35.90316509,1.6102,36.2451
65.28,1.0864,0.3666,-3.9208,1.616,36.02738208,1.616,36.3705
65.52,1.0907,0.368,-3.9137,1.6231,36.16209906,1.6231,36.5065
65.76,1.0945,0.3693,-3.9079,1.6289,36.29196226,1.6289,36.6376
66,1.0983,0.3702,-3.9026,1.6342,36.38071698,1.6342,36.7272
66.24,1.1025,0.3717,-3.8961,1.6407,36.52395283,1.6407,36.8718
66.48,1.1066,0.3731,-3.8896,1.6472,36.66114623,1.6472,37.0103
66.72,1.1104,0.3743,-3.8837,1.6531,36.77793396,1.6531,37.1282
66.96,1.1145,0.3756,-3.8775,1.6593,36.91066981,1.6593,37.2622
67.2,1.1187,0.3771,-3.8708,1.666,37.05875943,1.666,37.4117
67.44,1.1225,0.3782,-3.8649,1.6719,37.16583962,1.6719,37.5198
67.68,1.1265,0.3793,-3.8586,1.6782,37.27816981,1.6782,37.6332
67.92,1.1309,0.3812,-3.8509,1.6859,37.46122642,1.6859,37.818
68.16,1.1348,0.3824,-3.8457,1.6911,37.58207547,1.6911,37.94
68.4,1.1385,0.3835,-3.8399,1.6969,37.68776887,1.6969,38.0467
68.64,1.143,0.3851,-3.8325,1.7043,37.84516981,1.7043,38.2056
68.88,1.147,0.3865,-3.8259,1.7109,37.98583019,1.7109,38.3476
69.12,1.1505,0.3873,-3.8212,1.7156,38.05546698,1.7156,38.4179
69.36,1.1548,0.389,-3.8142,1.7226,38.22346698,1.7226,38.5875
69.6,1.159,0.3904,-3.8073,1.7295,38.36184906,1.7295,38.7272
69.84,1.1625,0.3912,-3.8022,1.7346,38.44198585,1.7346,38.8081
70.08,1.1666,0.3924,-3.7959,1.7409,38.56461792,1.7409,38.9319
70.32,1.1708,0.3939,-3.7893,1.7475,38.70676415,1.7475,39.0754
70.56,1.1745,0.3951,-3.7838,1.753,38.82781132,1.753,39.1976
70.8,1.1784,0.3962,-3.7775,1.7593,38.93370283,1.7593,39.3045
71.04,1.1826,0.3976,-3.7708,1.766,39.07030189,1.766,39.4424
71.28,1.1865,0.399,-3.7646,1.7722,39.20600943,1.7722,39.5794
71.52,1.1903,0.4002,-3.7589,1.7779,39.32339151,1.7779,39.6979
71.76,1.1945,0.4015,-3.7519,1.7849,39.45365094,1.7849,39.8294
72,1.1986,0.4029,-3.7451,1.7917,39.59282547,1.7917,39.9699
72.24,1.2024,0.4038,-3.7403,1.7965,39.68623585,1.7965,40.0642
72.48,1.2065,0.4054,-3.7333,1.8035,39.83660377,1.8035,40.216
72.72,1.2108,0.4069,-3.7255,1.8113,39.98231604,1.8113,40.3631
72.96,1.2145,0.4079,-3.7199,1.8169,40.08503774,1.8169,40.4668
73.2,1.2185,0.4092,-3.7139,1.8229,40.21658491,1.8229,40.5996
73.44,1.2229,0.4109,-3.706,1.8308,40.37913679,1.8308,40.7637
73.68,1.2269,0.4122,-3.6995,1.8373,40.50325472,1.8373,40.889
73.92,1.2305,0.4131,-3.6943,1.8425,40.59815094,1.8425,40.9848
74.16,1.2349,0.4148,-3.6867,1.8501,40.76208962,1.8501,41.1503
74.4,1.2391,0.4163,-3.6794,1.8574,40.90750472,1.8574,41.2971
74.64,1.2425,0.4169,-3.675,1.8618,40.96783019,1.8618,41.358
74.88,1.2467,0.4185,-3.6679,1.8689,41.12453774,1.8689,41.5162
75.12,1.251,0.42,-3.6606,1.8762,41.27133962,1.8762,41.6644
75.36,1.2545,0.4209,-3.6556,1.8812,41.35900472,1.8812,41.7529
75.6,1.2585,0.4222,-3.6487,1.8881,41.4855,1.8881,41.8806
75.84,1.2627,0.4237,-3.6415,1.8953,41.64101887,1.8953,42.0376
76.08,1.2665,0.4249,-3.6358,1.901,41.7502783,1.901,42.1479
76.32,1.2704,0.426,-3.6296,1.9072,41.8635,1.9072,42.2622
76.56,1.2746,0.4275,-3.6222,1.9146,42.01040094,1.9146,42.4105
76.8,1.2785,0.4288,-3.6152,1.9216,42.13848113,1.9216,42.5398
77.04,1.2823,0.4299,-3.6092,1.9276,42.2437783,1.9276,42.6461
77.28,1.2865,0.4314,-3.6022,1.9346,42.39256132,1.9346,42.7963
77.52,1.2906,0.4329,-3.5946,1.9422,42.53668868,1.9422,42.9418
77.76,1.2944,0.434,-3.5882,1.9486,42.651,1.9486,43.0572
78,1.2985,0.4354,-3.5814,1.9554,42.78502358,1.9554,43.1925
78.24,1.3028,0.4372,-3.5734,1.9634,42.96263208,1.9634,43.3718
78.48,1.3066,0.4383,-3.5669,1.9699,43.07040566,1.9699,43.4806
78.72,1.3105,0.4394,-3.5601,1.9767,43.18333019,1.9767,43.5946
78.96,1.315,0.4412,-3.5527,1.9841,43.35757075,1.9841,43.7705
79.2,1.3189,0.4425,-3.5452,1.9916,43.48228302,1.9916,43.8964
79.44,1.3225,0.4435,-3.5398,1.997,43.57866509,1.997,43.9937
79.68,1.3269,0.445,-3.532,2.0048,43.73467925,2.0048,44.1512
79.92,1.3311,0.4466,-3.5247,2.0121,43.88891038,2.0121,44.3069
80.16,1.3346,0.4475,-3.5193,2.0175,43.97261321,2.0175,44.3914
80.4,1.3387,0.4489,-3.5117,2.0251,44.11218396,2.0251,44.5323
80.64,1.3429,0.4505,-3.5044,2.0324,44.26839623,2.0324,44.69
80.88,1.3465,0.4514,-3.4987,2.0381,44.35903302,2.0381,44.7815
81.12,1.3505,0.4526,-3.4915,2.0453,44.47324528,2.0453,44.8968
81.36,1.3547,0.4542,-3.4839,2.0529,44.6332217,2.0529,45.0583
81.6,1.3585,0.4553,-3.4775,2.0593,44.74515566,2.0593,45.1713
81.84,1.3623,0.4564,-3.4712,2.0656,44.85342453,2.0656,45.2806
82.08,1.3665,0.4579,-3.4639,2.0729,44.99685849,2.0729,45.4254
82.32,1.3706,0.4592,-3.4566,2.0802,45.12840566,2.0802,45.5582
82.56,1.3743,0.4604,-3.4502,2.0866,45.24856132,2.0866,45.6795
82.8,1.3785,0.4618,-3.4425,2.0943,45.38466509,2.0943,45.8169
83.04,1.3827,0.4633,-3.435,2.1018,45.53325,2.1018,45.9669
83.28,1.3864,0.4644,-3.4288,2.108,45.63468396,2.108,46.0693
83.52,1.3905,0.4659,-3.4211,2.1157,45.78435849,2.1157,46.2204
83.76,1.3949,0.4676,-3.4129,2.1239,45.94948585,2.1239,46.3871
84,1.3988,0.4689,-3.4065,2.1303,46.07508962,2.1303,46.5139
84.24,1.4025,0.4698,-3.3995,2.1373,46.16909434,2.1373,46.6088
84.48,1.407,0.4716,-3.3911,2.1457,46.34571226,2.1457,46.7871
84.72,1.411,0.473,-3.384,2.1528,46.4857783,2.1528,46.9285
84.96,1.4145,0.4738,-3.3785,2.1583,46.56234906,2.1583,47.0058
85.2,1.4188,0.4754,-3.3702,2.1666,46.72123585,2.1666,47.1662
85.44,1.423,0.4769,-3.3616,2.1752,46.8637783,2.1752,47.3101
85.68,1.4265,0.4777,-3.3566,2.1802,46.94114151,2.1802,47.3882
85.92,1.4306,0.479,-3.3492,2.1876,47.07140094,2.1876,47.5197
86.16,1.4348,0.4806,-3.3416,2.1952,47.23038679,2.1952,47.6802
86.4,1.4385,0.4817,-3.3349,2.2019,47.33340566,2.2019,47.7842
86.64,1.4424,0.4829,-3.328,2.2088,47.45395755,2.2088,47.9059
86.88,1.4466,0.4843,-3.3196,2.2172,47.59293396,2.2172,48.0462
87.12,1.4505,0.4856,-3.3127,2.2241,47.72071698,2.2241,48.1752
87.36,1.4543,0.4868,-3.306,2.2308,47.83532547,2.2308,48.2909
87.6,1.4585,0.4883,-3.2979,2.2389,47.98608962,2.2389,48.4431
87.84,1.4626,0.4898,-3.2902,2.2466,48.13051415,2.2466,48.5889
88.08,1.4664,0.4908,-3.2835,2.2533,48.22788679,2.2533,48.6872
88.32,1.4705,0.4921,-3.276,2.2608,48.36329717,2.2608,48.8239
88.56,1.4748,0.4938,-3.267,2.2698,48.5264434,2.2698,48.9886
88.8,1.4786,0.495,-3.2605,2.2763,48.64045755,2.2763,49.1037
89.04,1.4825,0.496,-3.2533,2.2835,48.74605189,2.2835,49.2103
89.28,1.487,0.498,-3.244,2.2928,48.93812264,2.2928,49.4042
89.52,1.4908,0.4992,-3.2365,2.3003,49.05956604,2.3003,49.5268
89.76,1.4945,0.5001,-3.2284,2.3084,49.14772642,2.3084,49.6158
90,1.4989,0.5019,-3.2196,2.3172,49.32166981,2.3172,49.7914
90.24,1.5031,0.5034,-3.2115,2.3253,49.46589623,2.3253,49.937
90.48,1.5065,0.5042,-3.2056,2.3312,49.54514151,2.3312,50.017
90.72,1.5107,0.5057,-3.1969,2.3399,49.69521226,2.3399,50.1685
90.96,1.5149,0.5071,-3.1888,2.348,49.83735849,2.348,50.312
91.2,1.5185,0.508,-3.1828,2.354,49.91838679,2.354,50.3938
91.44,1.5225,0.5094,-3.1748,2.362,50.05587736,2.362,50.5326
91.68,1.5268,0.5109,-3.1663,2.3705,50.20575,2.3705,50.6839
91.92,1.5305,0.512,-3.1592,2.3776,50.31738679,2.3776,50.7966
92.16,1.5344,0.5133,-3.1522,2.3846,50.43764151,2.3846,50.918
92.4,1.5386,0.5147,-3.1438,2.393,50.58355189,2.393,51.0653
92.64,1.5425,0.516,-3.1356,2.4012,50.71153302,2.4012,51.1945
92.88,1.5463,0.5171,-3.1286,2.4082,50.81167925,2.4082,51.2956
93.12,1.5505,0.5185,-3.1208,2.416,50.95739151,2.416,51.4427
93.36,1.5547,0.52,-3.1121,2.4247,51.09854717,2.4247,51.5852
93.6,1.5584,0.5212,-3.1049,2.4319,51.21483962,2.4319,51.7026
93.84,1.5625,0.5224,-3.0966,2.4402,51.33975,2.4402,51.8287
94.08,1.5668,0.5242,-3.0882,2.4486,51.51032547,2.4486,52.0009
94.32,1.5706,0.5251,-3.0804,2.4564,51.60284434,2.4564,52.0943
94.56,1.5745,0.5262,-3.073,2.4638,51.71141038,2.4638,52.2039
94.8,1.5789,0.5281,-3.0636,2.4732,51.9015,2.4732,52.3958
95.04,1.583,0.5295,-3.0553,2.4815,52.03413679,2.4815,52.5297
95.28,1.5865,0.5303,-3.0485,2.4883,52.10961792,2.4883,52.6059
95.52,1.5909,0.532,-3.0395,2.4973,52.27751887,2.4973,52.7754
95.76,1.595,0.5334,-3.0313,2.5055,52.41986321,2.5055,52.9191
96,1.5986,0.5343,-3.0247,2.5121,52.50326887,2.5121,53.0033
96.24,1.6027,0.5356,-3.016,2.5208,52.62986321,2.5208,53.1311
96.48,1.6069,0.5372,-3.0072,2.5296,52.78974057,2.5296,53.2925
96.72,1.6105,0.538,-3.0008,2.536,52.87284906,2.536,53.3764
96.96,1.6145,0.5393,-2.9924,2.5444,52.99686792,2.5444,53.5016
97.2,1.6187,0.5407,-2.9832,2.5536,53.13564623,2.5536,53.6417
97.44,1.6225,0.5419,-2.9757,2.5611,53.25718868,2.5611,53.7644
97.68,1.6264,0.5431,-2.9686,2.5682,53.36704245,2.5682,53.8753
97.92,1.6305,0.5445,-2.9591,2.5777,53.50849528,2.5777,54.0181
98.16,1.6346,0.5458,-2.9507,2.5861,53.63766509,2.5861,54.1485
98.4,1.6383,0.5469,-2.9436,2.5932,53.74850943,2.5932,54.2604
98.64,1.6425,0.5483,-2.9345,2.6023,53.87767925,2.6023,54.3908
98.88,1.6467,0.5498,-2.9255,2.6113,54.03220755,2.6113,54.5468
99.12,1.6505,0.5509,-2.9181,2.6187,54.13265094,2.6187,54.6482
99.36,1.6545,0.5522,-2.9095,2.6273,54.26162264,2.6273,54.7784
99.6,1.6589,0.5537,-2.8999,2.6369,54.40852358,2.6369,54.9267
99.84,1.6628,0.5551,-2.8919,2.6449,54.54551887,2.6449,55.065
100.08,1.6665,0.556,-2.884,2.6528,54.63774057,2.6528,55.1581
100.32,1.671,0.5578,-2.8744,2.6624,54.81376415,2.6624,55.3358
100.56,1.6751,0.5591,-2.8656,2.6712,54.94263679,2.6712,55.4659
100.8,1.6785,0.5599,-2.859,2.6778,55.02099057,2.6778,55.545
101.04,1.6828,0.5615,-2.8489,2.6879,55.17551887,2.6879,55.701
101.28,1.687,0.563,-2.8396,2.6972,55.32350943,2.6972,55.8504
101.52,1.6905,0.5637,-2.8332,2.7036,55.39225472,2.7036,55.9198
101.76,1.6946,0.5649,-2.8242,2.7126,55.51389623,2.7126,56.0426
102,1.6988,0.5664,-2.8149,2.7219,55.65881604,2.7219,56.1889
102.24,1.7025,0.5675,-2.8074,2.7294,55.76688679,2.7294,56.298
102.48,1.7064,0.5686,-2.7991,2.7377,55.87862264,2.7377,56.4108
102.72,1.7106,0.5701,-2.7893,2.7475,56.02284906,2.7475,56.5564
102.96,1.7145,0.5713,-2.7809,2.7559,56.14498585,2.7559,56.6797
103.2,1.7183,0.5724,-2.7726,2.7642,56.25434434,2.7642,56.7901
103.44,1.7225,0.5737,-2.7636,2.7732,56.37866038,2.7732,56.9156
103.68,1.7266,0.5751,-2.7541,2.7827,56.51882547,2.7827,57.0571
103.92,1.7304,0.5761,-2.7465,2.7903,56.61520755,2.7903,57.1544
104.16,1.7345,0.5775,-2.7373,2.7995,56.75279717,2.7995,57.2933
104.4,1.7388,0.5792,-2.7272,2.8096,56.91336792,2.8096,57.4554
104.64,1.7425,0.5801,-2.719,2.8178,57.00935377,2.8178,57.5523
104.88,1.7465,0.5813,-2.71,2.8268,57.12376415,2.8268,57.6678
105.12,1.7509,0.583,-2.6997,2.8371,57.28819811,2.8371,57.8338
105.36,1.7548,0.5841,-2.6911,2.8457,57.39607075,2.8457,57.9427
105.6,1.7585,0.5851,-2.6827,2.8541,57.49770283,2.8541,58.0453
105.84,1.763,0.5868,-2.6722,2.8646,57.66411792,2.8646,58.2133
106.08,1.767,0.5881,-2.663,2.8738,57.79358491,2.8738,58.344
106.32,1.7705,0.589,-2.6554,2.8814,57.8805566,2.8814,58.4318
106.56,1.7748,0.5903,-2.6455,2.8913,58.00447642,2.8913,58.5569
106.8,1.779,0.5918,-2.6353,2.9015,58.15464623,2.9015,58.7085
107.04,1.7825,0.5926,-2.6281,2.9087,58.23537736,2.9087,58.79
107.28,1.7865,0.5938,-2.6187,2.9181,58.35266038,2.9181,58.9084
107.52,1.7908,0.5954,-2.6084,2.9284,58.50847642,2.9284,59.0657
107.76,1.7945,0.5963,-2.5998,2.937,58.59584434,2.937,59.1539
108,1.7984,0.5975,-2.5912,2.9456,58.71847642,2.9456,59.2777
108.24,1.8026,0.5988,-2.5815,2.9553,58.84467453,2.9553,59.4051
108.48,1.8066,0.5999,-2.5718,2.965,58.95343868,2.965,59.5149
108.72,1.8103,0.601,-2.5631,2.9737,59.06448113,2.9737,59.627
108.96,1.8145,0.6025,-2.5531,2.9837,59.20811321,2.9837,59.772
109.2,1.8186,0.6037,-2.5435,2.9933,59.3256934,2.9933,59.8907
109.44,1.8224,0.6048,-2.5344,3.0024,59.43723113,3.0024,60.0033
109.68,1.8265,0.606,-2.5246,3.0122,59.55084906,3.0122,60.118
109.92,1.8308,0.6075,-2.514,3.0228,59.70309906,3.0228,60.2717
110.16,1.8346,0.6086,-2.5051,3.0317,59.80463208,3.0317,60.3742
110.4,1.8385,0.6098,-2.4955,3.0413,59.92825472,3.0413,60.499
110.64,1.843,0.6114,-2.4838,3.053,60.08367453,3.053,60.6559
110.88,1.8469,0.6126,-2.4746,3.0622,60.19778774,3.0622,60.7711
111.12,1.8506,0.6136,-2.4662,3.0706,60.30090566,3.0706,60.8752
111.36,1.8549,0.615,-2.4551,3.0817,60.4357217,3.0817,61.0113
111.6,1.8591,0.6164,-2.4446,3.0922,60.56984434,3.0922,61.1467
111.84,1.8625,0.617,-2.4366,3.1002,60.63333962,3.1002,61.2108
112.08,1.8667,0.6184,-2.4265,3.1103,60.76974057,3.1103,61.3485
112.32,1.8709,0.6197,-2.4157,3.1211,60.90099057,3.1211,61.481
112.56,1.8745,0.6206,-2.4073,3.1295,60.98786321,3.1295,61.5687
112.8,1.8785,0.6217,-2.3971,3.1397,61.09890566,3.1397,61.6808
113.04,1.8827,0.6231,-2.3867,3.1501,61.23590094,3.1501,61.8191
113.28,1.8865,0.6241,-2.3776,3.1592,61.33208491,3.1592,61.9162
113.52,1.8903,0.6251,-2.3676,3.1692,61.42906132,3.1692,62.0141
113.76,1.8945,0.6265,-2.3567,3.1801,61.56635377,3.1801,62.1527
114,1.8985,0.6278,-2.3466,3.1902,61.69185849,3.1902,62.2794
114.24,1.9023,0.6288,-2.3373,3.1995,61.78883491,3.1995,62.3773
114.48,1.9065,0.63,-2.3262,3.2106,61.90829717,3.2106,62.4979
114.72,1.9107,0.6314,-2.3153,3.2215,62.05113679,3.2215,62.6421
114.96,1.9145,0.6324,-2.3057,3.2311,62.14821226,3.2311,62.7401
115.2,1.9185,0.6334,-2.2955,3.2413,62.24895283,3.2413,62.8418
115.44,1.9229,0.6351,-2.2833,3.2535,62.41100943,3.2535,63.0054
115.68,1.9267,0.636,-2.274,3.2628,62.5042217,3.2628,63.0995
115.92,1.9305,0.6371,-2.2636,3.2732,62.60961792,3.2732,63.2059
116.16,1.9349,0.6386,-2.2517,3.2851,62.75899528,3.2851,63.3567
116.4,1.939,0.6398,-2.2413,3.2955,62.87806132,3.2955,63.4769
116.64,1.9425,0.6405,-2.2322,3.3046,62.94274528,3.3046,63.5422
116.88,1.9468,0.642,-2.2203,3.3165,63.09291509,3.3165,63.6938
117.12,1.951,0.6434,-2.2091,3.3277,63.22565094,3.3277,63.8278
117.36,1.9545,0.6439,-2.2001,3.3367,63.2812217,3.3367,63.8839
117.6,1.9586,0.6452,-2.1891,3.3477,63.40405189,3.3477,64.0079
117.84,1.9628,0.6465,-2.1773,3.3595,63.53015094,3.3595,64.1352
118.08,1.9665,0.6475,-2.1679,3.3689,63.62593868,3.3689,64.2319
118.32,1.9704,0.6485,-2.1573,3.3795,63.72895755,3.3795,64.3359
118.56,1.9747,0.6498,-2.1451,3.3917,63.85337264,3.3917,64.4615
118.8,1.9785,0.6509,-2.135,3.4018,63.96243396,3.4018,64.5716
119.04,1.9823,0.6517,-2.1247,3.4121,64.04534434,3.4121,64.6553
119.28,1.9865,0.6531,-2.1125,3.4243,64.17966509,3.4243,64.7909
119.52,1.9906,0.6543,-2.1016,3.4352,64.30289151,3.4352,64.9153
119.76,1.9944,0.6551,-2.0911,3.4457,64.37975943,3.4457,64.9929
120,1.9985,0.6563,-2.0796,3.4572,64.49357547,3.4572,65.1078
120.24,2.0027,0.6577,-2.0676,3.4692,64.63443396,3.4692,65.25
120.48,2.0065,0.6588,-2.0572,3.4796,64.73824528,3.4796,65.3548
120.72,2.0105,0.6597,-2.0455,3.4913,64.82957547,3.4913,65.447
120.96,2.0149,0.6613,-2.0329,3.5039,64.98162736,3.5039,65.6005
121.2,2.0188,0.6623,-2.022,3.5148,65.08850943,3.5148,65.7084
121.44,2.0225,0.6631,-2.0116,3.5252,65.16131604,3.5252,65.7819
121.68,2.027,0.6646,-1.9983,3.5385,65.30782075,3.5385,65.9298
121.92,2.0311,0.6657,-1.9859,3.5509,65.42005189,3.5509,66.0431
122.16,2.0346,0.6664,-1.9762,3.5606,65.48681604,3.5606,66.1105
122.4,2.0388,0.6677,-1.9638,3.573,65.61162736,3.573,66.2365
122.64,2.043,0.6689,-1.9515,3.5853,65.73515094,3.5853,66.3612
122.88,2.0465,0.6696,-1.9415,3.5953,65.8012217,3.5953,66.4279
123.12,2.0505,0.6705,-1.9296,3.6072,65.89096698,3.6072,66.5185
123.36,2.0548,0.6719,-1.917,3.6198,66.02380189,3.6198,66.6526
123.6,2.0585,0.6727,-1.9062,3.6306,66.10522642,3.6306,66.7348
123.84,2.0624,0.6736,-1.8945,3.6423,66.19784434,3.6423,66.8283
124.08,2.0666,0.6748,-1.8819,3.6549,66.31780189,3.6549,66.9494
124.32,2.0705,0.6758,-1.8701,3.6667,66.41517453,3.6667,67.0477
124.56,2.0744,0.6766,-1.8586,3.6782,66.48986321,3.6782,67.1231
124.8,2.0785,0.6779,-1.8462,3.6906,66.6149717,3.6906,67.2494
125.04,2.0826,0.6791,-1.8335,3.7033,66.73106604,3.7033,67.3666
125.28,2.0864,0.6798,-1.8226,3.7142,66.80317925,3.7142,67.4394
125.52,2.0905,0.6809,-1.8091,3.7277,66.91610377,3.7277,67.5534
125.76,2.0948,0.6824,-1.7961,3.7407,67.05616981,3.7407,67.6948
126,2.0986,0.6832,-1.7848,3.752,67.13789151,3.752,67.7773
126.24,2.1025,0.6839,-1.7725,3.7643,67.21069811,3.7643,67.8508
126.48,2.107,0.6854,-1.7576,3.7792,67.35878774,3.7792,68.0003
126.72,2.1109,0.6865,-1.7457,3.7911,67.45863679,3.7911,68.1011
126.96,2.1145,0.6871,-1.7344,3.8024,67.51906132,3.8024,68.1621
127.2,2.1189,0.6885,-1.7202,3.8166,67.66081132,3.8166,68.3052
127.44,2.123,0.6895,-1.7066,3.8302,67.76125472,3.8302,68.4066
127.68,2.1265,0.6901,-1.6955,3.8413,67.81930189,3.8413,68.4652
127.92,2.1307,0.6912,-1.6825,3.8543,67.92440094,3.8543,68.5713
128.16,2.1349,0.6924,-1.6686,3.8682,68.03920755,3.8682,68.6872
128.4,2.1385,0.6932,-1.6569,3.8799,68.12132547,3.8799,68.7701
128.64,2.1425,0.6939,-1.644,3.8928,68.19135849,3.8928,68.8408
128.88,2.1467,0.6951,-1.6301,3.9067,68.30695755,3.9067,68.9575
129.12,2.1505,0.696,-1.6171,3.9197,68.3963066,3.9197,69.0477
129.36,2.1544,0.6969,-1.6045,3.9323,68.48416981,3.9323,69.1364
129.6,2.1586,0.698,-1.5909,3.9459,68.59006132,3.9459,69.2433
129.84,2.1625,0.6992,-1.5771,3.9597,68.70694811,3.9597,69.3613
130.08,2.1663,0.6998,-1.5648,3.972,68.76826415,3.972,69.4232
130.32,2.1705,0.7008,-1.5504,3.9864,68.86464623,3.9864,69.5205
130.56,2.1747,0.702,-1.5362,4.0006,68.98093868,4.0006,69.6379
130.8,2.1784,0.7026,-1.5237,4.0131,69.04918868,4.0131,69.7068
131.04,2.1825,0.7036,-1.5095,4.0273,69.14160849,4.0273,69.8001
131.28,2.1869,0.7049,-1.4942,4.0426,69.27563208,4.0426,69.9354
131.52,2.1907,0.7058,-1.4808,4.056,69.35458019,4.056,70.0151
131.76,2.1945,0.7064,-1.468,4.0688,69.41936321,4.0688,70.0805
132,2.199,0.7077,-1.4524,4.0844,69.55001887,4.0844,70.2124
132.24,2.203,0.7087,-1.4377,4.0991,69.64521226,4.0991,70.3085
132.48,2.2065,0.709,-1.4252,4.1116,69.67651415,4.1116,70.3401
132.72,2.2108,0.7104,-1.4099,4.1269,69.80687264,4.1269,70.4717
132.96,2.2151,0.7114,-1.395,4.1418,69.91335849,4.1418,70.5792
133.2,2.2185,0.7119,-1.3823,4.1545,69.95456604,4.1545,70.6208
133.44,2.2226,0.7129,-1.3673,4.1695,70.05520755,4.1695,70.7224
133.68,2.2269,0.714,-1.3526,4.1842,70.16268396,4.1842,70.8309
133.92,2.2305,0.7145,-1.3392,4.1976,70.21696698,4.1976,70.8857
134.16,2.2344,0.7152,-1.3244,4.2124,70.28442453,4.2124,70.9538
134.4,2.2386,0.7163,-1.3088,4.228,70.39398113,4.228,71.0644
134.64,2.2425,0.717,-1.2948,4.242,70.45916038,4.242,71.1302
134.88,2.2464,0.7179,-1.2809,4.2559,70.54583491,4.2559,71.2177
135.12,2.2505,0.7188,-1.2646,4.2722,70.63657075,4.2722,71.3093
135.36,2.2546,0.7197,-1.2492,4.2876,70.72542453,4.2876,71.399
135.6,2.2583,0.7202,-1.2353,4.3015,70.77683491,4.3015,71.4509
135.84,2.2625,0.7214,-1.2197,4.3171,70.88837264,4.3171,71.5635
136.08,2.2667,0.7224,-1.2034,4.3334,70.98624057,4.3334,71.6623
136.32,2.2705,0.723,-1.1887,4.3481,71.04557547,4.3481,71.7222
136.56,2.2745,0.7238,-1.1739,4.3629,71.12680189,4.3629,71.8042
136.8,2.2789,0.7251,-1.1566,4.3802,71.25834906,4.3802,71.937
137.04,2.2828,0.7257,-1.141,4.3958,71.31164151,4.3958,71.9908
137.28,2.2865,0.7261,-1.1266,4.4102,71.35691038,4.4102,72.0365
137.52,2.2909,0.7275,-1.1093,4.4275,71.49123113,4.4275,72.1721
137.76,2.295,0.7283,-1.0926,4.4442,71.57364623,4.4442,72.2553
138,2.2985,0.7285,-1.0785,4.4583,71.59008962,4.4583,72.2719
138.24,2.3028,0.7297,-1.0615,4.4753,71.7038066,4.4753,72.3867
138.48,2.307,0.7306,-1.0443,4.4925,71.80038679,4.4925,72.4842
138.72,2.3105,0.731,-1.03,4.5068,71.83515566,4.5068,72.5193
138.96,2.3146,0.7318,-1.013,4.5238,71.91142925,4.5238,72.5963
139.2,2.3188,0.7327,-0.9962,4.5406,72.00176887,4.5406,72.6875
139.44,2.3225,0.7333,-0.9806,4.5562,72.0569434,4.5562,72.7432
139.68,2.3264,0.7338,-0.9642,4.5726,72.11142453,4.5726,72.7982
139.92,2.3306,0.7349,-0.9468,4.59,72.21493868,4.59,72.9027
140.16,2.3345,0.7355,-0.9306,4.6062,72.27734434,4.6062,72.9657
140.4,2.3384,0.736,-0.9143,4.6225,72.32944811,4.6225,73.0183
140.64,2.3425,0.737,-0.8961,4.6407,72.42176887,4.6407,73.1115
140.88,2.3466,0.7378,-0.8785,4.6583,72.5070566,4.6583,73.1976
141.12,2.3504,0.7383,-0.8628,4.674,72.54965094,4.674,73.2406
141.36,2.3545,0.739,-0.8452,4.6916,72.61938679,4.6916,73.311
141.6,2.3588,0.74,-0.8266,4.7102,72.71854245,4.7102,73.4111
141.84,2.3626,0.7405,-0.8098,4.727,72.76747642,4.727,73.4605
142.08,2.3666,0.7411,-0.7922,4.7446,72.82393868,4.7446,73.5175
142.32,2.3709,0.7421,-0.7727,4.7641,72.93121698,4.7641,73.6258
142.56,2.375,0.7429,-0.7553,4.7815,73.00669811,4.7815,73.702
142.8,2.3785,0.7432,-0.7385,4.7983,73.03195755,4.7983,73.7275
143.04,2.3829,0.7442,-0.7188,4.818,73.12833962,4.818,73.8248
143.28,2.3871,0.745,-0.7004,4.8364,73.21570755,4.8364,73.913
143.52,2.3905,0.7451,-0.6843,4.8525,73.22412736,4.8525,73.9215
143.76,2.3947,0.746,-0.6653,4.8715,73.30654245,4.8715,74.0047
144,2.3989,0.7467,-0.6455,4.8913,73.37617925,4.8913,74.075
144.24,2.4025,0.7469,-0.629,4.9078,73.40203302,4.9078,74.1011
144.48,2.4065,0.7475,-0.6102,4.9266,73.46156604,4.9266,74.1612
144.72,2.4107,0.7484,-0.5907,4.9461,73.54081132,4.9461,74.2412
144.96,2.4145,0.7488,-0.5725,4.9643,73.58608019,4.9643,74.2869
145.2,2.4184,0.7491,-0.5542,4.9826,73.61827358,4.9826,74.3194
145.44,2.4226,0.7501,-0.5339,5.0029,73.71445755,5.0029,74.4165
145.68,2.4266,0.7508,-0.5143,5.0225,73.77953774,5.0225,74.4822
145.92,2.4303,0.7511,-0.4963,5.0405,73.81371226,5.0405,74.5167
146.16,2.4345,0.7517,-0.476,5.0608,73.87235377,5.0608,74.5759
146.4,2.4387,0.7525,-0.4555,5.0813,73.94961792,5.0813,74.6539
146.64,2.4424,0.753,-0.4362,5.1006,73.99884906,5.1006,74.7036
146.88,2.4465,0.7534,-0.4162,5.1206,74.03629245,5.1206,74.7414
147.12,2.4509,0.7544,-0.3951,5.1417,74.13663679,5.1417,74.8427
147.36,2.4547,0.7547,-0.3759,5.1609,74.16625472,5.1609,74.8726
147.6,2.4585,0.755,-0.356,5.1808,74.19488208,5.1808,74.9015
147.84,2.463,0.756,-0.3343,5.2025,74.29671226,5.2025,75.0043
148.08,2.467,0.7566,-0.3139,5.2229,74.34881604,5.2229,75.0569
148.32,2.4705,0.7567,-0.2946,5.2422,74.35882075,5.2422,75.067
148.56,2.4748,0.7575,-0.2725,5.2643,74.43648113,5.2643,75.1454
148.8,2.479,0.7581,-0.2511,5.2857,74.50156132,5.2857,75.2111
149.04,2.4825,0.7582,-0.2319,5.3049,74.50661321,5.3049,75.2162
149.28,2.4866,0.7587,-0.2103,5.3265,74.55495283,5.3265,75.265
149.52,2.4909,0.7594,-0.1884,5.3484,74.6241934,5.3484,75.3349
149.76,2.4945,0.7596,-0.1687,5.3681,74.64162736,5.3681,75.3525
150,2.4985,0.7599,-0.1472,5.3896,74.67778302,5.3896,75.389
150.24,2.5027,0.7606,-0.1241,5.4127,74.74375472,5.4127,75.4556
150.48,2.5065,0.7609,-0.1036,5.4332,74.77079717,5.4332,75.4829
150.72,2.5104,0.7612,-0.0821,5.4547,74.80289151,5.4547,75.5153
150.96,2.5145,0.7616,-0.0593,5.4775,74.84528774,5.4775,75.5581
151.2,2.5186,0.7622,-0.037,5.4998,74.90125472,5.4998,75.6146
151.44,2.5224,0.7622,-0.0157,5.5211,74.90591038,5.5211,75.6193
151.68,2.5265,0.763,0.0074,5.5442,74.97851887,5.5442,75.6926
151.92,2.5307,0.7635,0.031,5.5678,75.02467925,5.5678,75.7392
152.16,2.5344,0.7636,0.0523,5.5891,75.04042925,5.5891,75.7551
152.4,2.5385,0.764,0.0759,5.6127,75.07708019,5.6127,75.7921
152.64,2.5428,0.7647,0.1005,5.6373,75.14760849,5.6373,75.8633
152.88,2.5468,0.7651,0.1233,5.6601,75.18336792,5.6601,75.8994
153.12,2.5505,0.7651,0.1449,5.6817,75.18614151,5.6817,75.9022
153.36,2.555,0.7659,0.1706,5.7074,75.2617217,5.7074,75.9785
153.6,2.5591,0.7663,0.1944,5.7312,75.30946698,5.7312,76.0267
153.84,2.5626,0.7662,0.2158,5.7526,75.29470755,5.7526,76.0118
154.08,2.5668,0.7667,0.2407,5.7775,75.34819811,5.7775,76.0658
154.32,2.571,0.7671,0.2666,5.8034,75.38732547,5.8034,76.1053
154.56,2.5745,0.7671,0.2883,5.8251,75.38286792,5.8251,76.1008
154.8,2.5786,0.7674,0.3129,5.8497,75.40931604,5.8497,76.1275
155.04,2.5828,0.7679,0.3385,5.8753,75.45983491,5.8753,76.1785
155.28,2.5865,0.7681,0.3621,5.8989,75.47667453,5.8989,76.1955
155.52,2.5904,0.768,0.3861,5.9229,75.46974057,5.9229,76.1885
155.76,2.5946,0.7684,0.4118,5.9486,75.5077783,5.9486,76.2269
156,2.5985,0.7687,0.4367,5.9735,75.53868396,5.9735,76.2581
156.24,2.6023,0.7688,0.461,5.9978,75.54799528,5.9978,76.2675
156.48,2.6065,0.7691,0.4875,6.0243,75.57682075,6.0243,76.2966
156.72,2.6106,0.7694,0.5131,6.0499,75.60881604,6.0499,76.3289
156.96,2.6144,0.7693,0.5377,6.0745,75.60316981,6.0745,76.3232
157.2,2.6185,0.7697,0.5648,6.1016,75.63922642,6.1016,76.3596
157.44,2.6228,0.7702,0.5912,6.128,75.68449528,6.128,76.4053
157.68,2.6266,0.7702,0.6169,6.1537,75.68816038,6.1537,76.409
157.92,2.6305,0.7703,0.6429,6.1797,75.69667925,6.1797,76.4176
158.16,2.6349,0.7709,0.6714,6.2082,75.75710377,6.2082,76.4786
158.4,2.6389,0.771,0.6973,6.2341,75.76383962,6.2341,76.4854
158.64,2.6425,0.7709,0.7226,6.2594,75.75641038,6.2594,76.4779
158.88,2.6469,0.7712,0.7518,6.2886,75.78890094,6.2886,76.5107
159.12,2.6511,0.7716,0.7794,6.3162,75.82456132,6.3162,76.5467
159.36,2.6545,0.7712,0.8042,6.341,75.78751415,6.341,76.5093
159.6,2.6587,0.7714,0.8325,6.3693,75.80980189,6.3693,76.5318
159.84,2.6629,0.7719,0.8611,6.3979,75.85487264,6.3979,76.5773
160.08,2.6665,0.7716,0.8873,6.4241,75.82079717,6.4241,76.5429
160.32,2.6705,0.7715,0.9147,6.4515,75.82010377,6.4515,76.5422
160.56,2.6747,0.7718,0.9437,6.4805,75.84516509,6.4805,76.5675
160.8,2.6785,0.7717,0.971,6.5078,75.83466509,6.5078,76.5569
161.04,2.6824,0.7716,0.9988,6.5356,75.83020755,6.5356,76.5524
161.28,2.6866,0.7718,1.0281,6.5649,75.84952358,6.5649,76.5719
161.52,2.6905,0.7719,1.0566,6.5934,75.85100943,6.5934,76.5734
161.76,2.6943,0.7717,1.085,6.6218,75.83545755,6.6218,76.5577
162,2.6985,0.7719,1.1143,6.6511,75.85824057,6.6511,76.5807
162.24,2.7027,0.7721,1.144,6.6808,75.87250472,6.6808,76.5951
162.48,2.7064,0.772,1.1727,6.7095,75.8654717,6.7095,76.588
162.72,2.7105,0.772,1.2031,6.7399,75.86368868,6.7399,76.5862
162.96,2.7148,0.7725,1.2336,6.7704,75.91183019,6.7704,76.6348
163.2,2.7186,0.7721,1.2624,6.7992,75.87587264,6.7992,76.5985
163.44,2.7225,0.772,1.292,6.8288,75.86150943,6.8288,76.584
163.68,2.727,0.7724,1.3243,6.8611,75.90598585,6.8611,76.6289
163.92,2.7309,0.7724,1.3542,6.891,75.90321226,6.891,76.6261
164.16,2.7345,0.7719,1.3833,6.9201,75.85061321,6.9201,76.573
164.4,2.7389,0.772,1.4157,6.9525,75.86804717,6.9525,76.5906
164.64,2.7431,0.7722,1.4476,6.9844,75.88597642,6.9844,76.6087
164.88,2.7465,0.7717,1.4757,7.0125,75.83615094,7.0125,76.5584
165.12,2.7507,0.7718,1.5074,7.0442,75.84110377,7.0442,76.5634
165.36,2.7549,0.7719,1.54,7.0768,75.85417925,7.0768,76.5766
165.6,2.7585,0.7714,1.5699,7.1067,75.80910849,7.1067,76.5311
165.84,2.7625,0.7712,1.6011,7.1379,75.78434434,7.1379,76.5061
166.08,2.7667,0.7713,1.6338,7.1706,75.79464623,7.1706,76.5165
166.32,2.7705,0.7711,1.6651,7.2019,75.77800472,7.2019,76.4997
166.56,2.7744,0.7707,1.6968,7.2336,75.74115566,7.2336,76.4625
166.8,2.7785,0.7708,1.7295,7.2663,75.747,7.2663,76.4684
167.04,2.7826,0.7707,1.7619,7.2987,75.73917453,7.2987,76.4605
167.28,2.7863,0.7703,1.794,7.3308,75.69816509,7.3308,76.4191
167.52,2.7905,0.7703,1.8273,7.3641,75.69697642,7.3641,76.4179
167.76,2.7947,0.7703,1.8607,7.3975,75.70024528,7.3975,76.4212
168,2.7985,0.77,1.8932,7.43,75.6728066,7.43,76.3935
168.24,2.8025,0.7699,1.9268,7.4636,75.65586792,7.4636,76.3764
168.48,2.8069,0.77,1.9615,7.4983,75.66716038,7.4983,76.3878
168.72,2.8108,0.7698,1.9948,7.5316,75.65190566,7.5316,76.3724
168.96,2.8146,0.7693,2.0277,7.5645,75.59504717,7.5645,76.315
169.2,2.819,0.7696,2.0632,7.6,75.62654717,7.6,76.3468
169.44,2.823,0.7694,2.0976,7.6344,75.60465566,7.6344,76.3247
169.68,2.8265,0.7687,2.1296,7.6664,75.54502358,7.6664,76.2645
169.92,2.8308,0.7687,2.165,7.7018,75.53670283,7.7018,76.2561
170.16,2.835,0.7687,2.201,7.7378,75.53749528,7.7378,76.2569
170.4,2.8385,0.768,2.233,7.7698,75.47429717,7.7698,76.1931
170.64,2.8426,0.7678,2.2679,7.8047,75.45101887,7.8047,76.1696
170.88,2.8468,0.7677,2.3039,7.8407,75.43893396,7.8407,76.1574
171.12,2.8505,0.7672,2.3377,7.8745,75.39148585,7.8745,76.1095
171.36,2.8544,0.767,2.3728,7.9096,75.36870283,7.9096,76.0865
171.6,2.8586,0.7667,2.4087,7.9455,75.34522642,7.9455,76.0628
171.84,2.8625,0.7664,2.4441,7.9809,75.31441981,7.9809,76.0317
172.08,2.8664,0.766,2.4791,8.0159,75.27489623,8.0159,75.9918
172.32,2.8705,0.7659,2.5161,8.0529,75.26300943,8.0529,75.9798
172.56,2.8746,0.7657,2.5521,8.0889,75.24567453,8.0889,75.9623
172.8,2.8784,0.7651,2.5873,8.1241,75.19099528,8.1241,75.9071
173.04,2.8825,0.7649,2.6241,8.1609,75.16395283,8.1609,75.8798
173.28,2.8868,0.765,2.6619,8.1987,75.17861321,8.1987,75.8946
173.52,2.8906,0.7644,2.6973,8.2341,75.11373113,8.2341,75.8291
173.76,2.8945,0.7641,2.7338,8.2706,75.08411321,8.2706,75.7992
174,2.8989,0.7641,2.7726,8.3094,75.0884717,8.3094,75.8036
174.24,2.9029,0.7637,2.8096,8.3464,75.04617453,8.3464,75.7609
174.48,2.9065,0.763,2.8447,8.3815,74.97604245,8.3815,75.6901
174.72,2.9109,0.7629,2.8836,8.4204,74.9729717,8.4204,75.687
174.96,2.9151,0.7628,2.922,8.4588,74.95979717,8.4588,75.6737
175.2,2.9185,0.7619,2.957,8.4938,74.8761934,8.4938,75.5893
175.44,2.9227,0.7617,2.9952,8.532,74.85370755,8.532,75.5666
175.68,2.9269,0.7616,3.034,8.5708,74.83934434,8.5708,75.5521
175.92,2.9305,0.7609,3.0703,8.6071,74.77773113,8.6071,75.4899
176.16,2.9345,0.7605,3.1087,8.6455,74.73166981,8.6455,75.4434
176.4,2.9388,0.7602,3.1474,8.6842,74.70611321,8.6842,75.4176
176.64,2.9425,0.7598,3.1845,8.7213,74.66450943,8.7213,75.3756
176.88,2.9464,0.7591,3.2229,8.7597,74.6018066,8.7597,75.3123
177.12,2.9506,0.759,3.2621,8.7989,74.58932547,8.7989,75.2997
177.36,2.9545,0.7585,3.3003,8.8371,74.5417783,8.8371,75.2517
177.6,2.9583,0.758,3.3387,8.8755,74.49086321,8.8755,75.2003
177.84,2.9625,0.7578,3.3782,8.915,74.47174528,8.915,75.181
178.08,2.9666,0.7574,3.4176,8.9544,74.43360849,8.9544,75.1425
178.32,2.9704,0.7569,3.4558,8.9926,74.38120755,8.9926,75.0896
178.56,2.9745,0.7566,3.4953,9.0321,74.34921226,9.0321,75.0573
178.8,2.9788,0.7565,3.5362,9.073,74.34525,9.073,75.0533
179.04,2.9826,0.7558,3.5743,9.1111,74.27075943,9.1111,74.9781
179.28,2.9865,0.7554,3.6139,9.1507,74.23163208,9.1507,74.9386
179.52,2.991,0.7553,3.6559,9.1927,74.22697642,9.1927,74.9339
179.76,2.9949,0.7548,3.6953,9.2321,74.17903302,9.2321,74.8855
180,2.9986,0.7542,3.7334,9.2702,74.11236792,9.2702,74.8182
180.24,3.0029,0.754,3.775,9.3118,74.09424057,9.3118,74.7999
180.48,3.007,0.7537,3.8161,9.3529,74.06363208,9.3529,74.769
180.72,3.0105,0.7528,3.854,9.3908,73.97933491,9.3908,74.6839
180.96,3.0147,0.7525,3.8953,9.4321,73.94724057,9.4321,74.6515
181.16,3.0184,0.7726,3.9318,9.4686,75.91975472,9.4686,76.6428