File: data/ReportRaw/Resin_CSV/V4_Resin_HT/Tensile_Test_03.csv
Time,Displacement,Force,Tensile strain (Strain 1),,,Tensile stress
(s),(mm),(kN),(%),,,(MPa)
0,0,0.0003,-8.257,0,0.030223408,0.0308
0.2,0.0007,0.0007,-8.2567,0.0003,0.068002668,0.0693
0.4,0.0052,0.0046,-8.2435,0.0135,0.436963753,0.4453
0.6,0.0084,0.0057,-8.2406,0.0164,0.536661748,0.5469
0.8,0.012,0.0069,-8.2387,0.0183,0.649214505,0.6616
1,0.0152,0.0081,-8.2344,0.0226,0.761571005,0.7761
1.2,0.0187,0.0093,-8.2297,0.0273,0.88089459,0.8977
1.4,0.0225,0.0116,-8.2237,0.0333,1.090201504,1.111
1.6,0.0253,0.0128,-8.2201,0.0369,1.205599971,1.2286
1.8,0.0289,0.0145,-8.2142,0.0428,1.372809994,1.399
2,0.0317,0.0155,-8.2106,0.0464,1.463480218,1.4914
2.2,0.0353,0.0173,-8.206,0.051,1.627942659,1.659
2.4,0.0386,0.0186,-8.2009,0.0561,1.752172642,1.7856
2.6,0.0419,0.0202,-8.1961,0.0609,1.901621506,1.9379
2.8,0.0458,0.022,-8.1897,0.0673,2.076878022,2.1165
3,0.0486,0.0231,-8.1857,0.0713,2.176085377,2.2176
3.2,0.0523,0.0248,-8.1799,0.0771,2.340155307,2.3848
3.4,0.0552,0.0258,-8.1763,0.0807,2.431021787,2.4774
3.6,0.0586,0.0271,-8.1727,0.0843,2.56094319,2.6098
3.8,0.0619,0.0282,-8.1686,0.0884,2.664075663,2.7149
4,0.0651,0.0294,-8.1644,0.0926,2.774960245,2.8279
4.2,0.0689,0.0312,-8.1586,0.0984,2.939618942,2.9957
4.4,0.0719,0.0324,-8.1542,0.1028,3.060905085,3.1193
4.6,0.0757,0.0342,-8.1481,0.1089,3.227428213,3.289
4.8,0.0788,0.0354,-8.1434,0.1136,3.343906088,3.4077
5,0.0819,0.0366,-8.1397,0.1173,3.45047304,3.5163
5.2,0.0853,0.0379,-8.1346,0.1224,3.578726268,3.647
5.4,0.0884,0.0389,-8.131,0.126,3.668120828,3.7381
5.6,0.0921,0.0403,-8.1265,0.1305,3.801869222,3.8744
5.8,0.0953,0.0413,-8.1219,0.1351,3.897347715,3.9717
6,0.0989,0.0428,-8.1176,0.1394,4.036591274,4.1136
6.2,0.1024,0.0441,-8.113,0.144,4.165629525,4.2451
6.4,0.1053,0.0447,-8.1097,0.1473,4.215871035,4.2963
6.6,0.1088,0.0461,-8.1053,0.1517,4.351680115,4.4347
6.8,0.1117,0.0468,-8.1024,0.1546,4.416542689,4.5008
7,0.1153,0.048,-8.0976,0.1594,4.529978597,4.6164
7.2,0.1185,0.049,-8.094,0.163,4.627714033,4.716
7.4,0.122,0.0502,-8.0893,0.1677,4.740757429,4.8312
7.6,0.1258,0.0517,-8.0844,0.1726,4.880982267,4.9741
7.8,0.1286,0.0522,-8.0823,0.1747,4.923079157,5.017
8,0.1322,0.0535,-8.0778,0.1792,5.052215537,5.1486
8.2,0.1351,0.0542,-8.0755,0.1815,5.11040541,5.2079
8.4,0.1386,0.0551,-8.0721,0.1849,5.200977506,5.3002
8.6,0.1419,0.0561,-8.068,0.189,5.291549602,5.3925
8.8,0.1452,0.0569,-8.0645,0.1925,5.372112647,5.4746
9,0.1491,0.0585,-8.0598,0.1972,5.51547758,5.6207
9.2,0.1519,0.0589,-8.0577,0.1993,5.558065109,5.6641
9.4,0.1557,0.0601,-8.053,0.204,5.673463576,5.7817
9.6,0.1585,0.0606,-8.0513,0.2057,5.718013665,5.8271
9.8,0.1619,0.0614,-8.0481,0.2089,5.791805881,5.9023
10,0.1653,0.0623,-8.0448,0.2122,5.881396698,5.9936
10.2,0.1685,0.0629,-8.0422,0.2148,5.933110127,6.0463
10.4,0.1723,0.064,-8.0377,0.2193,6.036929496,6.1521
10.6,0.1752,0.0647,-8.0356,0.2214,6.106796595,6.2233
10.8,0.179,0.0659,-8.0319,0.2251,6.217386792,6.336
11,0.1821,0.0665,-8.0296,0.2274,6.272436571,6.3921
11.2,0.1852,0.0668,-8.0279,0.2291,6.299127373,6.4193
11.4,0.1886,0.0675,-8.0252,0.2318,6.373312102,6.4949
11.6,0.1918,0.0677,-8.0245,0.2325,6.383615537,6.5054
11.8,0.1955,0.0679,-8.0219,0.2351,6.410993234,6.5333
12,0.1986,0.0682,-8.0217,0.2353,6.43081508,6.5535
12.2,0.2022,0.0686,-8.0191,0.2379,6.469281235,6.5927
12.4,0.2057,0.0691,-8.017,0.24,6.522466583,6.6469
12.6,0.2086,0.0692,-8.0162,0.2408,6.524919782,6.6494
12.8,0.2121,0.0699,-8.0139,0.2431,6.60008579,6.726
13,0.2151,0.07,-8.0128,0.2442,6.602735245,6.7287
13.2,0.2186,0.0706,-8.0108,0.2462,6.656705616,6.7837
13.4,0.2219,0.0713,-8.0077,0.2493,6.724610156,6.8529
13.6,0.2254,0.0717,-8.0055,0.2515,6.764646359,6.8937
13.8,0.2291,0.0717,-8.0022,0.2548,6.766608918,6.8957
14,0.2319,0.0712,-8.0032,0.2538,6.717152432,6.8453
14.2,0.2356,0.0725,-7.9992,0.2578,6.840008623,6.9705
14.4,0.2384,0.0729,-7.9975,0.2595,6.877787883,7.009
14.6,0.2419,0.0736,-7.9942,0.2628,6.947556854,7.0801
14.8,0.2452,0.0743,-7.9918,0.2652,7.009573718,7.1433
15,0.2486,0.0745,-7.9902,0.2668,7.031554378,7.1657
15.2,0.2524,0.0748,-7.9889,0.2681,7.057558284,7.1922
15.4,0.2553,0.0737,-7.9916,0.2654,6.957173393,7.0899
15.6,0.259,0.0735,-7.9915,0.2655,6.935487117,7.0678
15.8,0.2619,0.0732,-7.9916,0.2654,6.902123614,7.0338
16,0.2652,0.0736,-7.9901,0.2669,6.948636262,7.0812
16.2,0.2686,0.0745,-7.9868,0.2702,7.029591819,7.1637
16.4,0.2718,0.0753,-7.9839,0.2731,7.102795268,7.2383
16.6,0.2756,0.0768,-7.9781,0.2789,7.242038827,7.3802
16.8,0.2786,0.078,-7.9744,0.2826,7.358124189,7.4985
17,0.2824,0.0793,-7.9691,0.2879,7.483727963,7.6265
17.2,0.2854,0.0803,-7.9657,0.2913,7.578028921,7.7226
17.4,0.2886,0.0809,-7.963,0.294,7.636807562,7.7825
17.6,0.292,0.0821,-7.9591,0.2979,7.742295106,7.89
17.8,0.2951,0.0828,-7.9562,0.3008,7.81098467,7.96
18,0.2988,0.084,-7.952,0.305,7.928051312,8.0793
18.2,0.3019,0.0847,-7.9491,0.3079,7.991638222,8.1441
18.4,0.3055,0.0857,-7.9453,0.3117,8.087607356,8.2419
18.6,0.309,0.0868,-7.9413,0.3157,8.187403479,8.3436
18.8,0.3119,0.0873,-7.9393,0.3177,8.239509419,8.3967
19,0.3154,0.0882,-7.9355,0.3215,8.319876209,8.4786
19.2,0.3184,0.0888,-7.9332,0.3238,8.375809139,8.5356
19.4,0.322,0.0897,-7.9298,0.3272,8.466086851,8.6276
19.6,0.3252,0.0906,-7.9266,0.3304,8.547238665,8.7103
19.8,0.3287,0.0914,-7.9232,0.3338,8.620245858,8.7847
20,0.3325,0.0927,-7.9186,0.3384,8.747517807,8.9144
20.2,0.3353,0.093,-7.9169,0.3401,8.772540433,8.9399
20.4,0.3389,0.094,-7.9128,0.3442,8.872434685,9.0417
20.6,0.3418,0.0944,-7.9111,0.3459,8.908742025,9.0787
20.8,0.3452,0.0957,-7.9068,0.3502,9.028261866,9.2005
21,0.3486,0.0973,-7.9017,0.3553,9.17633694,9.3514
21.2,0.3519,0.0988,-7.897,0.36,9.320094384,9.4979
21.4,0.3557,0.1004,-7.8906,0.3664,9.47425339,9.655
21.6,0.3586,0.1012,-7.8868,0.3702,9.552952005,9.7352
21.8,0.3623,0.1026,-7.8817,0.3753,9.678359522,9.863
22,0.3652,0.103,-7.879,0.378,9.722124587,9.9076
22.2,0.3686,0.1039,-7.8753,0.3817,9.807888414,9.995
22.4,0.3719,0.1049,-7.8716,0.3854,9.896399823,10.0852
22.6,0.3751,0.1055,-7.8686,0.3884,9.953314033,10.1432
22.8,0.3789,0.1068,-7.8634,0.3936,10.07744589,10.2697
23,0.3819,0.1074,-7.8603,0.3967,10.13426197,10.3276
23.2,0.3857,0.1087,-7.8553,0.4017,10.25329117,10.4489
23.4,0.3888,0.1095,-7.852,0.405,10.33051787,10.5276
23.6,0.3919,0.1103,-7.8487,0.4083,10.40264191,10.6011
23.8,0.3953,0.1114,-7.8445,0.4125,10.50763881,10.7081
24,0.3984,0.1119,-7.8417,0.4153,10.56003914,10.7615
24.2,0.4021,0.1133,-7.8364,0.4206,10.68897926,10.8929
24.4,0.4052,0.114,-7.8335,0.4235,10.76022015,10.9655
24.6,0.4089,0.1151,-7.8288,0.4282,10.85815184,11.0653
24.8,0.4124,0.1165,-7.8247,0.4323,10.99150772,11.2012
25,0.4152,0.1168,-7.8223,0.4347,11.02516561,11.2355
25.2,0.4188,0.118,-7.8182,0.4388,11.12927936,11.3416
25.4,0.4217,0.1184,-7.8152,0.4418,11.16921744,11.3823
25.6,0.4253,0.1195,-7.8111,0.4459,11.27499937,11.4901
25.8,0.4285,0.1203,-7.8079,0.4491,11.34918409,11.5657
26,0.4321,0.1214,-7.8034,0.4536,11.45094278,11.6694
26.2,0.4358,0.1227,-7.7986,0.4584,11.58096231,11.8019
26.4,0.4386,0.1231,-7.7968,0.4602,11.612167,11.8337
26.6,0.4422,0.1241,-7.7924,0.4646,11.70941179,11.9328
26.8,0.4451,0.1247,-7.7901,0.4669,11.76289152,11.9873
27,0.4486,0.1256,-7.786,0.471,11.84944037,12.0755
27.2,0.4519,0.1264,-7.7826,0.4744,11.92912027,12.1567
27.4,0.4553,0.1272,-7.7793,0.4777,11.99937988,12.2283
27.6,0.4591,0.1286,-7.7742,0.4828,12.13096946,12.3624
27.8,0.462,0.1289,-7.772,0.485,12.16109474,12.3931
28,0.4657,0.1302,-7.7678,0.4892,12.28149773,12.5158
28.2,0.4685,0.1306,-7.7657,0.4913,12.32310398,12.5582
28.4,0.4719,0.1314,-7.7622,0.4948,12.39777935,12.6343
28.6,0.4753,0.1324,-7.7586,0.4984,12.49051026,12.7288
28.8,0.4785,0.1331,-7.7558,0.5012,12.5559616,12.7955
29,0.4822,0.1343,-7.7512,0.5058,12.66861249,12.9103
29.2,0.4853,0.1348,-7.7486,0.5084,12.71453636,12.9571
29.4,0.489,0.1361,-7.7439,0.5131,12.83925699,13.0842
29.6,0.4921,0.1367,-7.741,0.516,12.90088134,13.147
29.8,0.4952,0.1372,-7.7385,0.5185,12.94386138,13.1908
30,0.4987,0.1381,-7.7346,0.5224,13.03001772,13.2786
30.2,0.5017,0.1387,-7.7322,0.5248,13.08418435,13.3338
30.4,0.5054,0.1399,-7.7279,0.5291,13.19869966,13.4505
30.6,0.5086,0.1406,-7.7246,0.5324,13.26954804,13.5227
30.8,0.5122,0.1416,-7.7205,0.5365,13.36149393,13.6164
31,0.5157,0.1429,-7.7163,0.5407,13.480425,13.7376
31.2,0.5186,0.1432,-7.7142,0.5428,13.50741019,13.7651
31.4,0.5221,0.1443,-7.7099,0.5471,13.61230896,13.872
31.6,0.5251,0.1447,-7.7082,0.5488,13.65057886,13.911
31.8,0.5286,0.1457,-7.7038,0.5532,13.7507675,14.0131
32,0.5319,0.1466,-7.701,0.556,13.8290736,14.0929
32.2,0.5354,0.1475,-7.697,0.56,13.91621122,14.1817
32.4,0.5391,0.1487,-7.6926,0.5644,14.03141343,14.2991
32.6,0.5419,0.149,-7.6907,0.5663,14.05839861,14.3266
32.8,0.5456,0.1501,-7.6864,0.5706,14.16251237,14.4327
33,0.5484,0.1504,-7.6847,0.5723,14.19548336,14.4663
33.2,0.5519,0.1512,-7.681,0.576,14.26849055,14.5407
33.4,0.5552,0.1521,-7.6778,0.5792,14.35131054,14.6251
33.6,0.5586,0.1528,-7.6748,0.5822,14.41676188,14.6918
33.8,0.5624,0.1539,-7.6701,0.5869,14.52480075,14.8019
34,0.5653,0.1543,-7.6683,0.5887,14.56081371,14.8386
34.2,0.5691,0.1556,-7.6636,0.5934,14.68455305,14.9647
34.4,0.5719,0.1559,-7.6613,0.5957,14.70604307,14.9866
34.6,0.5752,0.1565,-7.6587,0.5983,14.77080752,15.0526
34.8,0.5786,0.1574,-7.6557,0.6013,14.84999677,15.1333
35,0.5818,0.1581,-7.6526,0.6044,14.91544811,15.2
35.2,0.5855,0.1591,-7.6488,0.6082,15.01573488,15.3022
35.4,0.5886,0.1598,-7.6464,0.6106,15.08138247,15.3691
35.6,0.5923,0.1609,-7.6423,0.6147,15.18098234,15.4706
35.8,0.5955,0.1616,-7.6393,0.6177,15.24888688,15.5398
36,0.5986,0.162,-7.6372,0.6198,15.28254477,15.5741
36.2,0.602,0.1628,-7.6336,0.6234,15.36379471,15.6569
36.4,0.6051,0.1633,-7.631,0.626,15.41217179,15.7062
36.6,0.6087,0.1643,-7.6276,0.6294,15.50303827,15.7988
36.8,0.6119,0.165,-7.6249,0.6321,15.56623267,15.8632
37,0.6155,0.1658,-7.6213,0.6357,15.64601069,15.9445
37.2,0.6191,0.1668,-7.6177,0.6393,15.73736781,16.0376
37.4,0.6219,0.167,-7.6166,0.6404,15.75944659,16.0601
37.6,0.6255,0.168,-7.6134,0.6436,15.84903741,16.1514
37.8,0.6284,0.1679,-7.6117,0.6453,15.84638796,16.1487
38,0.632,0.1689,-7.6083,0.6487,15.93244617,16.2364
38.2,0.6352,0.1694,-7.6063,0.6507,15.98298206,16.2879
38.4,0.6387,0.1703,-7.6027,0.6543,16.07296539,16.3796
38.6,0.6425,0.1716,-7.5981,0.6589,16.19081705,16.4997
38.8,0.6453,0.1719,-7.597,0.66,16.22104046,16.5305
39,0.6489,0.173,-7.5928,0.6642,16.32505609,16.6365
39.2,0.6518,0.1735,-7.5904,0.6666,16.37009682,16.6824
39.4,0.6553,0.1744,-7.5865,0.6705,16.45478124,16.7687
39.6,0.6585,0.1753,-7.5831,0.6739,16.54201698,16.8576
39.8,0.6619,0.1762,-7.5795,0.6775,16.62307067,16.9402
40,0.6657,0.1777,-7.5747,0.6823,16.76977195,17.0897
40.2,0.6686,0.1784,-7.5717,0.6853,16.83306448,17.1542
40.4,0.6724,0.1797,-7.5667,0.6903,16.95906076,17.2826
40.6,0.6752,0.1802,-7.5644,0.6926,17.00213893,17.3265
40.8,0.6786,0.1811,-7.5607,0.6963,17.08358513,17.4095
41,0.6819,0.1821,-7.5568,0.7002,17.18043741,17.5082
41.2,0.6851,0.183,-7.5535,0.7035,17.26237425,17.5917
41.4,0.6889,0.1841,-7.5488,0.7082,17.37110001,17.7025
41.6,0.6919,0.1847,-7.5462,0.7108,17.42497226,17.7574
41.8,0.6957,0.1859,-7.5414,0.7156,17.54390333,17.8786
42,0.6988,0.1868,-7.539,0.718,17.62299446,17.9592
42.2,0.7019,0.1873,-7.5361,0.7209,17.66911459,18.0062
42.4,0.7054,0.1882,-7.5322,0.7248,17.75988295,18.0987
42.6,0.7084,0.1887,-7.5299,0.7271,17.80806377,18.1478
42.8,0.7121,0.1897,-7.5257,0.7313,17.89745833,18.2389
43,0.7152,0.1905,-7.5232,0.7338,17.97056365,18.3134
43.2,0.7189,0.1914,-7.5192,0.7378,18.05681812,18.4013
43.4,0.7224,0.1924,-7.5157,0.7413,18.15003967,18.4963
43.6,0.7252,0.1926,-7.5143,0.7427,18.17300161,18.5197
43.8,0.7288,0.1935,-7.5109,0.7461,18.25346652,18.6017
44,0.7317,0.1939,-7.5087,0.7483,18.29212894,18.6411
44.2,0.7353,0.1947,-7.5054,0.7516,18.3741639,18.7247
44.4,0.7386,0.1954,-7.5025,0.7545,18.43990963,18.7917
44.6,0.742,0.1962,-7.499,0.758,18.51537002,18.8686
44.8,0.7458,0.1974,-7.4948,0.7622,18.62223135,18.9775
45,0.7486,0.1975,-7.4933,0.7637,18.6371468,18.9927
45.2,0.7523,0.1986,-7.4897,0.7673,18.7403774,19.0979
45.4,0.7551,0.1956,-7.4968,0.7602,18.45384379,18.8059
45.6,0.7586,0.1925,-7.5082,0.7488,18.15926369,18.5057
45.8,0.7619,0.1938,-7.5038,0.7532,18.28810569,18.637
46,0.7652,0.1954,-7.4988,0.7582,18.44069465,18.7925
46.2,0.7691,0.1974,-7.4922,0.7648,18.62723588,18.9826
46.4,0.7719,0.1984,-7.4883,0.7687,18.7203593,19.0775
46.6,0.7757,0.2003,-7.4823,0.7747,18.8965971,19.2571
46.8,0.7786,0.2011,-7.4789,0.7781,18.97647325,19.3385
47,0.7819,0.2023,-7.4743,0.7827,19.08843723,19.4526
47.2,0.7853,0.2037,-7.4692,0.7878,19.21835864,19.585
47.4,0.7884,0.2047,-7.4647,0.7923,19.31736974,19.6859
47.6,0.7922,0.2062,-7.459,0.798,19.45808522,19.8293
47.8,0.7952,0.2073,-7.4553,0.8017,19.55905887,19.9322
48,0.799,0.2088,-7.4499,0.8071,19.69997061,20.0758
48.2,0.8022,0.2101,-7.4455,0.8115,19.81978483,20.1979
48.4,0.8052,0.2108,-7.4419,0.8151,19.8871006,20.2665
48.6,0.8087,0.2121,-7.4371,0.8199,20.00976054,20.3915
48.8,0.8117,0.2129,-7.4336,0.8234,20.08767413,20.4709
49,0.8154,0.2144,-7.4281,0.8289,20.22986153,20.6158
49.2,0.8186,0.2156,-7.4239,0.8331,20.34172739,20.7298
49.4,0.8222,0.2169,-7.418,0.839,20.46841057,20.8589
49.6,0.8258,0.2184,-7.413,0.844,20.60667285,20.9998
49.8,0.8286,0.219,-7.4099,0.8471,20.66456834,21.0588
50,0.8322,0.2202,-7.4049,0.8521,20.77937804,21.1758
50.2,0.835,0.2208,-7.4011,0.8559,20.83423156,21.2317
50.4,0.8386,0.2222,-7.3964,0.8606,20.96582114,21.3658
50.6,0.8419,0.223,-7.3924,0.8646,21.04137966,21.4428
50.8,0.8453,0.2241,-7.3883,0.8687,21.14608218,21.5495
51,0.8491,0.2256,-7.3827,0.8743,21.28738642,21.6935
51.2,0.8519,0.226,-7.3809,0.8761,21.32202559,21.7288
51.4,0.8556,0.2273,-7.3762,0.8808,21.44468552,21.8538
51.6,0.8585,0.2276,-7.3736,0.8834,21.47422204,21.8839
51.8,0.8619,0.2286,-7.3699,0.8871,21.56577541,21.9772
52,0.8653,0.2295,-7.3657,0.8913,21.65674002,22.0699
52.2,0.8685,0.2302,-7.3622,0.8948,21.72484082,22.1393
52.4,0.8724,0.2317,-7.3567,0.9003,21.86143492,22.2785
52.6,0.8753,0.2323,-7.3541,0.9029,21.91638657,22.3345
52.8,0.8791,0.2337,-7.3489,0.9081,22.05033122,22.471
53,0.8819,0.2341,-7.3467,0.9103,22.0878161,22.5092
53.2,0.8852,0.2351,-7.3426,0.9144,22.17887883,22.602
53.4,0.8886,0.2359,-7.3383,0.9187,22.2619932,22.6867
53.6,0.8918,0.2367,-7.3345,0.9225,22.33755172,22.7637
53.8,0.8955,0.238,-7.3293,0.9277,22.45540339,22.8838
54,0.8985,0.2387,-7.3264,0.9306,22.52556487,22.9553
54.2,0.9023,0.24,-7.3213,0.9357,22.64420156,23.0762
54.4,0.9055,0.2408,-7.3181,0.9389,22.72142826,23.1549
54.6,0.9085,0.2414,-7.3152,0.9418,22.77304356,23.2075
54.8,0.912,0.2424,-7.3113,0.9457,22.87244717,23.3088
55,0.9151,0.2431,-7.3082,0.9488,22.93554344,23.3731
55.2,0.9187,0.2443,-7.3033,0.9537,23.04603551,23.4857
55.4,0.9219,0.2451,-7.3,0.957,23.12188841,23.563
55.6,0.9255,0.2461,-7.2951,0.9619,23.22188079,23.6649
55.8,0.9291,0.2473,-7.2909,0.9661,23.33050843,23.7756
56,0.9319,0.2476,-7.2886,0.9684,23.36141874,23.8071
56.2,0.9354,0.2488,-7.2841,0.9729,23.47662095,23.9245
56.4,0.9384,0.2493,-7.281,0.976,23.51773656,23.9664
56.6,0.9419,0.2504,-7.2766,0.9804,23.62734547,24.0781
56.8,0.9453,0.2513,-7.2728,0.9842,23.70947857,24.1618
57,0.9487,0.2523,-7.2684,0.9886,23.80446642,24.2586
57.2,0.9525,0.2535,-7.2632,0.9938,23.91731356,24.3736
57.4,0.9553,0.254,-7.2613,0.9957,23.96137301,24.4185
57.6,0.9589,0.2552,-7.2562,1.0008,24.07677148,24.5361
57.8,0.9618,0.2557,-7.2536,1.0034,24.12348038,24.5837
58,0.9653,0.2566,-7.2495,1.0075,24.21542627,24.6774
58.2,0.9685,0.2576,-7.2454,1.0116,24.30413393,24.7678
58.4,0.9719,0.2584,-7.2419,1.0151,24.38479511,24.85
58.6,0.9757,0.2599,-7.2362,1.0208,24.51942665,24.9872
58.8,0.9786,0.2605,-7.2338,1.0232,24.57585022,25.0447
59,0.9824,0.2617,-7.2282,1.0288,24.69595883,25.1671
59.2,0.9853,0.2622,-7.2259,1.0311,24.74168645,25.2137
59.4,0.9885,0.2631,-7.2223,1.0347,24.82538959,25.299
59.6,0.992,0.2641,-7.2179,1.0391,24.91713922,25.3925
59.8,0.9951,0.2648,-7.2145,1.0425,24.98288495,25.4595
60,0.9989,0.2661,-7.2096,1.0474,25.10937188,25.5884
60.2,1.002,0.2667,-7.2065,1.0505,25.16834677,25.6485
60.4,1.0057,0.268,-7.2012,1.0558,25.28335273,25.7657
60.6,1.0089,0.2689,-7.1977,1.0593,25.375593,25.8597
60.8,1.0119,0.2694,-7.1945,1.0625,25.4223019,25.9073
61,1.0153,0.2706,-7.1897,1.0673,25.53004639,26.0171
61.2,1.0184,0.2711,-7.187,1.07,25.58372238,26.0718
61.4,1.022,0.2723,-7.182,1.075,25.69176125,26.1819
61.6,1.0252,0.273,-7.1783,1.0787,25.75888076,26.2503
61.8,1.0288,0.2743,-7.1738,1.0832,25.88095193,26.3747
62,1.0324,0.2754,-7.1695,1.0875,25.98918706,26.485
62.2,1.0353,0.2759,-7.1671,1.0899,26.02922326,26.5258
62.4,1.0388,0.2769,-7.1622,1.0948,26.1262718,26.6247
62.6,1.0417,0.2774,-7.1599,1.0971,26.17425637,26.6736
62.8,1.0453,0.2783,-7.1557,1.1013,26.25658572,26.7575
63,1.0485,0.2793,-7.1525,1.1045,26.35402677,26.8568
63.2,1.052,0.2803,-7.148,1.109,26.44283256,26.9473
63.4,1.0558,0.2816,-7.1427,1.1143,26.56588501,27.0727
63.6,1.0586,0.2819,-7.1407,1.1163,26.60081856,27.1083
63.8,1.0623,0.2831,-7.1357,1.1213,26.7118994,27.2215
64,1.0651,0.2835,-7.1331,1.1239,26.74663669,27.2569
64.2,1.0686,0.2841,-7.1293,1.1277,26.8102236,27.3217
64.4,1.0719,0.2851,-7.1258,1.1312,26.90059944,27.4138
64.6,1.0752,0.2859,-7.1222,1.1348,26.97429353,27.4889
64.8,1.079,0.2873,-7.1172,1.1398,27.1072569,27.6244
65,1.082,0.2877,-7.1142,1.1428,27.14219045,27.66
65.2,1.0857,0.2889,-7.1097,1.1473,27.25650951,27.7765
65.4,1.0886,0.2893,-7.1071,1.1499,27.3010596,27.8219
65.6,1.0919,0.2902,-7.1038,1.1532,27.37681437,27.8991
65.8,1.0953,0.2911,-7.1,1.157,27.4650314,27.989
66,1.0984,0.2917,-7.0965,1.1605,27.52557634,28.0507
66.2,1.1022,0.2931,-7.0917,1.1653,27.65559587,28.1832
66.4,1.1052,0.2937,-7.0883,1.1687,27.71133255,28.24
66.6,1.109,0.295,-7.0833,1.1737,27.83340371,28.3644
66.8,1.1122,0.2958,-7.0797,1.1773,27.91141543,28.4439
67,1.1152,0.2962,-7.077,1.18,27.95223666,28.4855
67.2,1.1187,0.2973,-7.0726,1.1844,28.05478037,28.59
67.4,1.1217,0.2979,-7.0695,1.1875,28.10865261,28.6449
67.6,1.1254,0.2991,-7.0647,1.1923,28.22179413,28.7602
67.8,1.1286,0.2998,-7.0612,1.1958,28.2862642,28.8259
68,1.1322,0.301,-7.0562,1.2008,28.40450837,28.9464
68.2,1.1358,0.3024,-7.0512,1.2058,28.52893461,29.0732
68.4,1.1386,0.3026,-7.0491,1.2079,28.55415349,29.0989
68.6,1.1422,0.3038,-7.0442,1.2128,28.66739315,29.2143
68.8,1.1451,0.3044,-7.0411,1.2159,28.72450361,29.2725
69,1.1486,0.3056,-7.0365,1.2205,28.83430879,29.3844
69.2,1.1519,0.3065,-7.0323,1.2247,28.92174079,29.4735
69.4,1.1553,0.3075,-7.0274,1.2296,29.01672864,29.5703
69.6,1.1591,0.3089,-7.0224,1.2346,29.14920137,29.7053
69.8,1.1619,0.3094,-7.0197,1.2373,29.19326082,29.7502
70,1.1656,0.3107,-7.0146,1.2424,29.31582263,29.8751
70.2,1.1685,0.3112,-7.0117,1.2453,29.36145212,29.9216
70.4,1.1719,0.3122,-7.007,1.25,29.45751938,30.0195
70.6,1.1753,0.3132,-7.0025,1.2545,29.54818961,30.1119
70.8,1.1785,0.3141,-6.999,1.258,29.63866358,30.2041
71,1.1824,0.3157,-6.993,1.264,29.78467796,30.3529
71.2,1.1853,0.316,-6.9903,1.2667,29.82029841,30.3892
71.4,1.189,0.3175,-6.9846,1.2724,29.96081763,30.5324
71.6,1.1919,0.318,-6.9819,1.2751,30.00850781,30.581
71.8,1.1952,0.3188,-6.9777,1.2793,30.08004309,30.6539
72,1.1986,0.3199,-6.9734,1.2836,30.18464748,30.7605
72.2,1.2018,0.3208,-6.9697,1.2873,30.26707496,30.8445
72.4,1.2055,0.3221,-6.9639,1.2931,30.39218809,30.972
72.6,1.2086,0.3228,-6.9604,1.2966,30.45685441,31.0379
72.8,1.2123,0.3242,-6.9551,1.3019,30.58834586,31.1719
73,1.2156,0.3252,-6.9509,1.3061,30.6829412,31.2683
73.2,1.2185,0.3258,-6.9478,1.3092,30.73848162,31.3249
73.4,1.222,0.3268,-6.943,1.314,30.83749272,31.4258
73.6,1.2251,0.3275,-6.9396,1.3174,30.89617323,31.4856
73.8,1.2287,0.3287,-6.9341,1.3229,31.01049229,31.6021
74,1.2319,0.3297,-6.9305,1.3265,31.10862024,31.7021
74.2,1.2355,0.3308,-6.9249,1.3321,31.21096769,31.8064
74.4,1.2391,0.3321,-6.9196,1.3374,31.33254822,31.9303
74.6,1.2419,0.3325,-6.9166,1.3404,31.37562639,31.9742
74.8,1.2455,0.3338,-6.9118,1.3452,31.49514623,32.096
75,1.2484,0.3343,-6.909,1.348,31.5393038,32.141
75.2,1.2519,0.3354,-6.9039,1.3531,31.64704829,32.2508
75.4,1.2552,0.3363,-6.8996,1.3574,31.73055517,32.3359
75.6,1.2587,0.3374,-6.8947,1.3623,31.83447267,32.4418
75.8,1.2625,0.3389,-6.889,1.368,31.97577692,32.5858
76,1.2653,0.3394,-6.8863,1.3707,32.02415399,32.6351
76.2,1.269,0.3407,-6.8804,1.3766,32.14347758,32.7567
76.4,1.2718,0.3413,-6.8774,1.3796,32.20098056,32.8153
76.6,1.2753,0.3422,-6.8728,1.3842,32.2889032,32.9049
76.8,1.2785,0.3433,-6.8689,1.3881,32.38771804,33.0056
77,1.2818,0.3441,-6.8644,1.3926,32.46720168,33.0866
77.2,1.2856,0.3455,-6.8584,1.3986,32.59810436,33.22
77.4,1.2886,0.3461,-6.8554,1.4016,32.65953246,33.2826
77.6,1.2924,0.3476,-6.8494,1.4076,32.79926666,33.425
77.8,1.2954,0.3483,-6.8458,1.4112,32.86147978,33.4884
78,1.2986,0.3491,-6.8416,1.4154,32.94096341,33.5694
78.2,1.302,0.3501,-6.8368,1.4202,33.03693255,33.6672
78.4,1.3051,0.3509,-6.8329,1.4241,33.10738841,33.739
78.6,1.3088,0.3521,-6.8274,1.4296,33.22190373,33.8557
78.8,1.3119,0.353,-6.8235,1.4335,33.30305554,33.9384
79,1.3156,0.3544,-6.8172,1.4398,33.43915901,34.0771
79.2,1.3189,0.3553,-6.8132,1.4438,33.5195258,34.159
79.4,1.3219,0.356,-6.8098,1.4472,33.58635093,34.2271
79.6,1.3254,0.3571,-6.8044,1.4526,33.69232911,34.3351
79.8,1.3284,0.3577,-6.801,1.456,33.75140214,34.3953
80,1.332,0.359,-6.7958,1.4612,33.86876316,34.5149
80.2,1.3352,0.3598,-6.7914,1.4656,33.94383104,34.5914
80.4,1.3388,0.361,-6.786,1.471,34.06040705,34.7102
80.6,1.3424,0.3624,-6.7805,1.4765,34.19327229,34.8456
80.8,1.3452,0.3628,-6.7774,1.4796,34.23311223,34.8862
81,1.3489,0.364,-6.772,1.485,34.34900134,35.0043
81.2,1.3518,0.3647,-6.7687,1.4883,34.40758373,35.064
81.4,1.3553,0.3657,-6.7637,1.4933,34.50571167,35.164
81.6,1.3586,0.3667,-6.7592,1.4978,34.60177894,35.2619
81.8,1.362,0.3677,-6.7547,1.5023,34.69725743,35.3592
82,1.3658,0.3691,-6.7481,1.5089,34.82982829,35.4943
82.2,1.3686,0.3697,-6.7451,1.5119,34.88546683,35.551
82.4,1.3723,0.3711,-6.7394,1.5176,35.01116874,35.6791
82.6,1.3752,0.3715,-6.7361,1.5209,35.05719074,35.726
82.8,1.3786,0.3725,-6.7308,1.5262,35.14992165,35.8205
83,1.3819,0.3735,-6.726,1.531,35.24098439,35.9133
83.2,1.3852,0.3747,-6.7215,1.5355,35.35010267,36.0245
83.4,1.389,0.3759,-6.7154,1.5416,35.47119256,36.1479
83.6,1.3919,0.3765,-6.7117,1.5453,35.52594795,36.2037
83.8,1.3957,0.378,-6.7057,1.5513,35.66244393,36.3428
84,1.3986,0.3786,-6.7024,1.5546,35.72652148,36.4081
84.2,1.4019,0.3794,-6.698,1.559,35.79736986,36.4803
84.4,1.4053,0.3805,-6.6931,1.5639,35.89903041,36.5839
84.6,1.4084,0.3813,-6.689,1.568,35.97350952,36.6598
84.8,1.4122,0.3827,-6.6827,1.5743,36.10617851,36.795
85,1.4153,0.3835,-6.679,1.578,36.18046136,36.8707
85.2,1.419,0.3848,-6.6724,1.5846,36.30949962,37.0022
85.4,1.4222,0.3857,-6.6681,1.5889,36.39428216,37.0886
85.6,1.4252,0.3863,-6.6648,1.5922,36.447075,37.1424
85.8,1.4287,0.3875,-6.6592,1.5978,36.56227721,37.2598
86,1.4317,0.3881,-6.6552,1.6018,36.62056521,37.3192
86.2,1.4354,0.3893,-6.6497,1.6073,36.73527678,37.4361
86.4,1.4386,0.3902,-6.6449,1.6121,36.81858741,37.521
86.6,1.4422,0.3914,-6.6397,1.6173,36.93320085,37.6378
86.8,1.4457,0.3926,-6.6338,1.6232,37.04555736,37.7523
87,1.4485,0.393,-6.6308,1.6262,37.07774332,37.7851
87.2,1.4521,0.3942,-6.6253,1.6317,37.19137549,37.9009
87.4,1.4551,0.3949,-6.622,1.635,37.25770998,37.9685
87.6,1.4586,0.3959,-6.6164,1.6406,37.35367911,38.0663
87.8,1.4619,0.3969,-6.6119,1.6451,37.44905948,38.1635
88,1.4653,0.398,-6.6068,1.6502,37.54856122,38.2649
88.2,1.4691,0.3993,-6.6007,1.6563,37.67838449,38.3972
88.4,1.472,0.3998,-6.5973,1.6597,37.71959823,38.4392
88.6,1.4757,0.4012,-6.5913,1.6657,37.85344475,38.5756
88.8,1.4785,0.4015,-6.5881,1.6689,37.88278501,38.6055
89,1.4819,0.4026,-6.5832,1.6738,37.98974447,38.7145
89.2,1.4853,0.4035,-6.5781,1.6789,38.07109254,38.7974
89.4,1.4885,0.4044,-6.5736,1.6834,38.15283312,38.8807
89.6,1.4923,0.4058,-6.5674,1.6896,38.28560024,39.016
89.8,1.4953,0.4063,-6.5643,1.6927,38.33574362,39.0671
90,1.4991,0.4077,-6.558,1.699,38.46507625,39.1989
90.2,1.502,0.4082,-6.5544,1.7026,38.51786909,39.2527
90.4,1.5052,0.409,-6.5501,1.7069,38.59293697,39.3292
90.6,1.5086,0.41,-6.5451,1.7119,38.68380345,39.4218
90.8,1.5117,0.4107,-6.541,1.716,38.74905853,39.4883
91,1.5155,0.4119,-6.5352,1.7218,38.86543828,39.6069
91.2,1.5186,0.4125,-6.5312,1.7258,38.92539446,39.668
91.4,1.5223,0.4138,-6.5252,1.7318,39.03941913,39.7842
91.6,1.5256,0.4147,-6.5203,1.7367,39.1298931,39.8764
91.8,1.5286,0.4153,-6.5171,1.7399,39.18160653,39.9291
92,1.5321,0.4162,-6.5115,1.7455,39.27129547,40.0205
92.2,1.5351,0.4168,-6.5079,1.7491,39.33056476,40.0809
92.4,1.5387,0.4181,-6.5024,1.7546,39.44625761,40.1988
92.6,1.5419,0.4189,-6.498,1.759,39.52279741,40.2768
92.8,1.5454,0.4201,-6.4926,1.7644,39.63378011,40.3899
93,1.5492,0.4213,-6.4861,1.7709,39.75496813,40.5134
93.2,1.5519,0.4218,-6.4832,1.7738,39.79500433,40.5542
93.4,1.5555,0.4229,-6.4772,1.7798,39.90569266,40.667
93.6,1.5584,0.4234,-6.4739,1.7831,39.95210718,40.7143
93.8,1.5619,0.4245,-6.4683,1.7887,40.05484714,40.819
94,1.5652,0.4254,-6.4634,1.7936,40.14051284,40.9063
94.2,1.5686,0.4265,-6.4586,1.7984,40.24560787,41.0134
94.4,1.5724,0.428,-6.4514,1.8056,40.38514581,41.1556
94.6,1.5753,0.4285,-6.4483,1.8087,40.42596704,41.1972
94.8,1.579,0.4297,-6.4417,1.8153,40.5445056,41.318
95,1.5818,0.4304,-6.4383,1.8187,40.60642434,41.3811
95.2,1.5852,0.4312,-6.4328,1.8242,40.68512295,41.4613
95.4,1.5886,0.4322,-6.4275,1.8295,40.77863889,41.5566
95.6,1.5918,0.433,-6.423,1.834,40.85782814,41.6373
95.8,1.5957,0.4346,-6.4162,1.8408,41.00914144,41.7915
96,1.5986,0.4353,-6.4123,1.8447,41.07174707,41.8553
96.2,1.6024,0.4366,-6.4049,1.8521,41.19097252,41.9768
96.4,1.6053,0.4372,-6.4015,1.8555,41.25446131,42.0415
96.6,1.6086,0.4381,-6.3963,1.8607,41.33188426,42.1204
96.8,1.612,0.4393,-6.3905,1.8665,41.44630144,42.237
97,1.6151,0.4399,-6.386,1.871,41.50625762,42.2981
97.2,1.6188,0.4413,-6.3794,1.8776,41.64010414,42.4345
97.4,1.6219,0.4421,-6.3746,1.8824,41.70967686,42.5054
97.6,1.6256,0.4436,-6.3681,1.8889,41.85196238,42.6504
97.8,1.6289,0.4446,-6.3625,1.8945,41.94802964,42.7483
98,1.6319,0.4453,-6.3579,1.8991,42.01691546,42.8185
98.2,1.6354,0.4464,-6.3517,1.9053,42.12073483,42.9243
98.4,1.6384,0.4473,-6.3469,1.9101,42.20659679,43.0118
98.6,1.642,0.4486,-6.3402,1.9168,42.32611663,43.1336
98.8,1.6453,0.4497,-6.3346,1.9224,42.4267959,43.2362
99,1.6488,0.4509,-6.3283,1.9287,42.54759141,43.3593
99.2,1.6524,0.4522,-6.3214,1.9356,42.67113449,43.4852
99.4,1.6553,0.4529,-6.3172,1.9398,42.73354387,43.5488
99.6,1.6588,0.4542,-6.3108,1.9462,42.85218056,43.6697
99.8,1.6618,0.4548,-6.3064,1.9506,42.91557121,43.7343
100,1.6653,0.4559,-6.2999,1.9571,43.01801679,43.8387
100.2,1.6686,0.457,-6.2945,1.9625,43.12370059,43.9464
100.4,1.672,0.4581,-6.2885,1.9685,43.22506676,44.0497
100.6,1.6758,0.4596,-6.2809,1.9761,43.36637101,44.1937
100.8,1.6786,0.4602,-6.2772,1.9798,43.42505152,44.2535
101,1.6823,0.4617,-6.27,1.987,43.5668464,44.398
101.2,1.6852,0.4621,-6.2655,1.9915,43.60442941,44.4363
101.4,1.6886,0.4634,-6.2593,1.9977,43.72002413,44.5541
101.6,1.6919,0.4645,-6.2536,2.0034,43.82541355,44.6615
101.8,1.6952,0.4654,-6.2477,2.0093,43.91392496,44.7517
102,1.699,0.4668,-6.2399,2.0171,44.04728084,44.8876
102.2,1.7019,0.4677,-6.2357,2.0213,44.12676448,44.9686
102.4,1.7057,0.4691,-6.2277,2.0293,44.26375109,45.1082
102.6,1.7087,0.4699,-6.2231,2.0339,44.34146843,45.1874
102.8,1.7119,0.4707,-6.2176,2.0394,44.40780292,45.255
103,1.7153,0.4719,-6.2116,2.0454,44.52977596,45.3793
103.2,1.7184,0.4727,-6.2064,2.0506,44.59875991,45.4496
103.4,1.7222,0.4741,-6.1994,2.0576,44.72848505,45.5818
103.6,1.7253,0.475,-6.1946,2.0624,44.81385637,45.6688
103.8,1.729,0.4762,-6.187,2.07,44.93288557,45.7901
104,1.7323,0.4774,-6.1816,2.0754,45.04121882,45.9005
104.2,1.7352,0.4779,-6.1769,2.0801,45.08930152,45.9495
104.4,1.7387,0.4792,-6.1702,2.0868,45.21431652,46.0769
104.6,1.7417,0.4799,-6.1654,2.0916,45.27809969,46.1419
104.8,1.7454,0.4811,-6.1582,2.0988,45.39732515,46.2634
105,1.7486,0.482,-6.1522,2.1048,45.48151893,46.3492
105.2,1.7521,0.4834,-6.1454,2.1116,45.60751521,46.4776
105.4,1.7558,0.4846,-6.1385,2.1185,45.72320806,46.5955
105.6,1.7586,0.4853,-6.1342,2.1228,45.78777625,46.6613
105.8,1.7622,0.4865,-6.127,2.13,45.90317472,46.7789
106,1.7651,0.4871,-6.1226,2.1344,45.95802824,46.8348
106.2,1.7686,0.4881,-6.1158,2.1412,46.05576368,46.9344
106.4,1.7719,0.4893,-6.1099,2.1471,46.16399881,47.0447
106.6,1.7753,0.4902,-6.1034,2.1536,46.25672972,47.1392
106.8,1.7791,0.4918,-6.0955,2.1615,46.40735612,47.2927
107,1.7819,0.4923,-6.0912,2.1658,46.45043429,47.3366
107.2,1.7857,0.4937,-6.0838,2.1732,46.57957067,47.4682
107.4,1.7885,0.4944,-6.0792,2.1778,46.64659205,47.5365
107.6,1.7919,0.4953,-6.0729,2.1841,46.73539785,47.627
107.8,1.7952,0.4964,-6.0669,2.1901,46.83735279,47.7309
108,1.7985,0.4972,-6.0613,2.1957,46.91399071,47.809
108.2,1.8023,0.4987,-6.0533,2.2037,47.05362678,47.9513
108.4,1.8053,0.4995,-6.0484,2.2086,47.13006846,48.0292
108.6,1.809,0.5007,-6.0406,2.2164,47.24379875,48.1451
108.8,1.812,0.5015,-6.0358,2.2212,47.31474525,48.2174
109,1.8152,0.5023,-6.03,2.227,47.3921682,48.2963
109.2,1.8187,0.5034,-6.0228,2.2342,47.50050146,48.4067
109.4,1.8218,0.5042,-6.0176,2.2394,47.57066294,48.4782
109.6,1.8255,0.5056,-6.0104,2.2466,47.70558887,48.6157
109.8,1.8286,0.5064,-6.0044,2.2526,47.7804605,48.692
110,1.8322,0.5077,-5.997,2.26,47.9005691,48.8144
110.2,1.8357,0.5089,-5.99,2.267,48.01371063,48.9297
110.4,1.8386,0.5094,-5.9855,2.2715,48.06022328,48.9771
110.6,1.8421,0.5106,-5.9783,2.2787,48.17768243,49.0968
110.8,1.8451,0.5111,-5.9735,2.2835,48.22419508,49.1442
111,1.8487,0.5125,-5.966,2.291,48.35166328,49.2741
111.2,1.8519,0.5133,-5.9601,2.2969,48.43104879,49.355
111.4,1.8554,0.5145,-5.9529,2.3041,48.54281652,49.4689
111.6,1.8591,0.5159,-5.9457,2.3113,48.67313044,49.6017
111.8,1.8619,0.5164,-5.9412,2.3158,48.72199816,49.6515
112,1.8655,0.5176,-5.9337,2.3233,48.83798539,49.7697
112.2,1.8684,0.5183,-5.9288,2.3282,48.90127792,49.8342
112.4,1.8719,0.5193,-5.9215,2.3355,48.9939107,49.9286
112.6,1.8752,0.5204,-5.9155,2.3415,49.09704318,50.0337
112.8,1.8786,0.5213,-5.9084,2.3486,49.1870265,50.1254
113,1.8824,0.5229,-5.9004,2.3566,49.33313902,50.2743
113.2,1.8853,0.5233,-5.8954,2.3616,49.37258645,50.3145
113.4,1.889,0.5246,-5.8874,2.3696,49.50005466,50.4444
113.6,1.8919,0.5253,-5.8827,2.3743,49.56570226,50.5113
113.8,1.8952,0.5262,-5.8758,2.3812,49.644499,50.5916
114,1.8986,0.5271,-5.8687,2.3883,49.73703365,50.6859
114.2,1.9018,0.5281,-5.8627,2.3943,49.82829264,50.7789
114.4,1.9057,0.5296,-5.8544,2.4026,49.96871374,50.922
114.6,1.9086,0.5302,-5.8491,2.4079,50.02690361,50.9813
114.8,1.9123,0.5316,-5.841,2.416,50.15702127,51.1139
115,1.9154,0.5323,-5.8356,2.4214,50.22080444,51.1789
115.2,1.9185,0.5331,-5.8297,2.4273,50.29646108,51.256
115.4,1.922,0.5343,-5.8218,2.4352,50.41284083,51.3746
115.6,1.9251,0.5351,-5.816,2.441,50.48702556,51.4502
115.8,1.9288,0.5364,-5.808,2.449,50.61439564,51.58
116,1.9319,0.5372,-5.8013,2.4557,50.68602904,51.653
116.2,1.9356,0.5384,-5.7938,2.4632,50.80378258,51.773
116.4,1.9389,0.5395,-5.7869,2.4701,50.90200865,51.8731
116.6,1.9419,0.54,-5.7815,2.4755,50.955194,51.9273
116.8,1.9454,0.5413,-5.7737,2.4833,51.06970932,52.044
117,1.9484,0.5419,-5.7676,2.4894,51.13084303,52.1063
117.2,1.952,0.5432,-5.7596,2.4974,51.25055912,52.2283
117.4,1.9553,0.5441,-5.7529,2.5041,51.33946305,52.3189
117.6,1.9588,0.5452,-5.7457,2.5113,51.44436182,52.4258
117.8,1.9625,0.5466,-5.7373,2.5197,51.57310569,52.557
118,1.9653,0.547,-5.7322,2.5248,51.6135344,52.5982
118.2,1.9689,0.5483,-5.7243,2.5327,51.73246548,52.7194
118.4,1.9718,0.549,-5.7189,2.5381,51.79732805,52.7855
118.6,1.9753,0.55,-5.7108,2.5462,51.89270842,52.8827
118.8,1.9786,0.551,-5.704,2.553,51.9860281,52.9778
119,1.982,0.552,-5.6967,2.5603,52.08337102,53.077
119.2,1.9858,0.5534,-5.6879,2.5691,52.21702129,53.2132
119.4,1.9886,0.5539,-5.6826,2.5744,52.2665759,53.2637
119.6,1.9923,0.5553,-5.674,2.583,52.39757671,53.3972
119.8,1.9952,0.5559,-5.6682,2.5888,52.45419654,53.4549
120,1.9986,0.5569,-5.6608,2.5962,52.54496489,53.5474
120.2,2.0019,0.5579,-5.6532,2.6038,52.64103215,53.6453
120.4,2.0051,0.5588,-5.6464,2.6106,52.72483342,53.7307
120.6,2.0089,0.5602,-5.6376,2.6194,52.85563797,53.864
120.8,2.0119,0.5609,-5.6315,2.6255,52.92707512,53.9368
121,2.0157,0.5623,-5.6223,2.6347,53.05454332,54.0667
121.2,2.0188,0.563,-5.6163,2.6407,53.11832649,54.1317
121.4,2.0219,0.5638,-5.6097,2.6473,53.19231496,54.2071
121.6,2.0254,0.5648,-5.6014,2.6556,53.29436803,54.3111
121.8,2.0284,0.5656,-5.5948,2.6622,53.3659033,54.384
122,2.0321,0.5668,-5.5861,2.6709,53.47668976,54.4969
122.2,2.0352,0.5676,-5.5797,2.6773,53.55941162,54.5812
122.4,2.0389,0.5689,-5.5706,2.6864,53.68167904,54.7058
122.6,2.0423,0.5701,-5.5627,2.6943,53.79040481,54.8166
122.8,2.0452,0.5705,-5.557,2.7,53.83142229,54.8584
123,2.0487,0.5718,-5.5485,2.7085,53.94819455,54.9774
123.2,2.0517,0.5724,-5.5421,2.7149,54.00824885,55.0386
123.4,2.0553,0.5735,-5.5337,2.7233,54.11628772,55.1487
123.6,2.0586,0.5746,-5.5267,2.7303,54.21421941,55.2485
123.8,2.0621,0.5756,-5.5181,2.7389,54.30979603,55.3459
124,2.0658,0.5771,-5.5093,2.7477,54.45149279,55.4903
124.2,2.0686,0.5774,-5.5035,2.7535,54.47798734,55.5173
124.4,2.0722,0.5787,-5.4947,2.7623,54.59819407,55.6398
124.6,2.0751,0.5792,-5.4882,2.7688,54.6505944,55.6932
124.8,2.0786,0.5803,-5.4799,2.7771,54.75745573,55.8021
125,2.0819,0.5813,-5.4722,2.7848,54.84321956,55.8895
125.2,2.0853,0.5823,-5.464,2.793,54.94144564,55.9896
125.4,2.0891,0.5837,-5.4541,2.8029,55.07656782,56.1273
125.6,2.0919,0.5843,-5.4482,2.8088,55.12720184,56.1789
125.8,2.0957,0.5855,-5.4389,2.8181,55.24358159,56.2975
126,2.0986,0.5861,-5.4324,2.8246,55.29755196,56.3525
126.2,2.1019,0.587,-5.4245,2.8325,55.38979223,56.4465
126.4,2.1053,0.5881,-5.4162,2.8408,55.48585949,56.5444
126.6,2.1085,0.5889,-5.4082,2.8488,55.56465624,56.6247
126.8,2.1123,0.5902,-5.3991,2.8579,55.69114316,56.7536
127,2.1153,0.5909,-5.3919,2.8651,55.74982367,56.8134
127.2,2.119,0.5924,-5.3823,2.8747,55.89318861,56.9595
127.4,2.122,0.593,-5.3756,2.8814,55.9521635,57.0196
127.6,2.1252,0.5937,-5.3681,2.8889,56.01889051,57.0876
127.8,2.1286,0.5949,-5.3592,2.8978,56.13036386,57.2012
128,2.1318,0.5955,-5.3518,2.9052,56.18482487,57.2567
128.2,2.1355,0.5969,-5.3421,2.9149,56.31916203,57.3936
128.4,2.1386,0.5975,-5.3351,2.9219,56.37499683,57.4505
128.6,2.1423,0.5989,-5.3255,2.9315,56.50737143,57.5854
128.8,2.1456,0.5999,-5.317,2.94,56.59912106,57.6789
129,2.1486,0.6003,-5.3102,2.9468,56.63827412,57.7188
129.2,2.1521,0.6015,-5.3011,2.9559,56.75720519,57.84
129.4,2.1551,0.6021,-5.2937,2.9633,56.81264748,57.8965
129.6,2.1587,0.6033,-5.2845,2.9725,56.92264891,58.0086
129.8,2.1619,0.6041,-5.2766,2.9804,56.99791305,58.0853
130,2.1654,0.6051,-5.2676,2.9894,57.08985893,58.179
130.2,2.1691,0.6066,-5.2576,2.9994,57.23028003,58.3221
130.4,2.1719,0.6068,-5.251,3.006,57.25216256,58.3444
130.6,2.1755,0.6081,-5.2416,3.0154,57.37668693,58.4713
130.8,2.1784,0.6085,-5.2346,3.0224,57.41613436,58.5115
131,2.1819,0.6096,-5.2255,3.0315,57.52122939,58.6186
131.2,2.1852,0.6106,-5.2164,3.0406,57.60866139,58.7077
131.4,2.1886,0.6114,-5.2079,3.0491,57.68441617,58.7849
131.6,2.1924,0.6128,-5.1974,3.0596,57.82081402,58.9239
131.8,2.1953,0.6134,-5.1902,3.0668,57.8758638,58.98
132,2.199,0.6146,-5.1801,3.0769,57.98527646,59.0915
132.2,2.2019,0.615,-5.1731,3.0839,58.02717709,59.1342
132.4,2.2052,0.616,-5.1644,3.0926,58.12196869,59.2308
132.6,2.2086,0.6169,-5.155,3.102,58.21097074,59.3215
132.8,2.2118,0.6177,-5.1467,3.1103,58.28270227,59.3946
133,2.2156,0.6191,-5.1361,3.1209,58.41036673,59.5247
133.2,2.2186,0.6196,-5.1284,3.1286,58.45697751,59.5722
133.4,2.2223,0.6208,-5.1179,3.1391,58.57787114,59.6954
133.6,2.2254,0.6216,-5.1101,3.1469,58.6465607,59.7654
133.8,2.2285,0.6222,-5.1017,3.1553,58.7079888,59.828
134,2.232,0.6232,-5.092,3.165,58.80258414,59.9244
134.2,2.2351,0.624,-5.0842,3.1728,58.87402129,59.9972
134.4,2.2388,0.6251,-5.0733,3.1837,58.98098075,60.1062
134.6,2.2419,0.6257,-5.0651,3.1919,59.0408388,60.1672
134.8,2.2456,0.627,-5.0547,3.2023,59.15653165,60.2851
135,2.249,0.6279,-5.0452,3.2118,59.24602434,60.3763
135.2,2.2519,0.6284,-5.0379,3.2191,59.29037817,60.4215
135.4,2.2554,0.6295,-5.0276,3.2294,59.39135183,60.5244
135.6,2.2584,0.6299,-5.0202,3.2368,59.43050488,60.5643
135.8,2.262,0.631,-5.0098,3.2472,59.53991754,60.6758
136,2.2653,0.6318,-5.0006,3.2564,59.61518168,60.7525
136.2,2.2687,0.6329,-4.9909,3.2661,59.71380027,60.853
136.4,2.2725,0.6342,-4.9801,3.2769,59.84058157,60.9822
136.6,2.2753,0.6345,-4.9728,3.2842,59.8662911,61.0084
136.8,2.2789,0.6356,-4.9618,3.2952,59.97168051,61.1158
137,2.2818,0.636,-4.9545,3.3025,60.00818411,61.153
137.2,2.2853,0.6369,-4.9438,3.3132,60.09541986,61.2419
137.4,2.2886,0.6378,-4.9346,3.3224,60.1833425,61.3315
137.6,2.2919,0.6387,-4.9246,3.3324,60.26312052,61.4128
137.8,2.2957,0.64,-4.9135,3.3435,60.38587858,61.5379
138,2.2986,0.6404,-4.9056,3.3514,60.42198967,61.5747
138.2,2.3023,0.6416,-4.8945,3.3625,60.53758439,61.6925
138.4,2.3052,0.6421,-4.8862,3.3708,60.58576521,61.7416
138.6,2.3085,0.6428,-4.8768,3.3802,60.65180532,61.8089
138.8,2.3119,0.6437,-4.8664,3.3906,60.73962983,61.8984
139,2.3151,0.6444,-4.8568,3.4002,60.79909537,61.959
139.2,2.3189,0.6457,-4.8449,3.4121,60.9231291,62.0854
139.4,2.3219,0.6462,-4.8363,3.4207,60.9740575,62.1373
139.6,2.3257,0.6474,-4.8247,3.4323,61.08837656,62.2538
139.8,2.3287,0.648,-4.8158,3.4412,61.13753866,62.3039
140,2.3319,0.6488,-4.8066,3.4504,61.21643353,62.3843
140.2,2.3353,0.6495,-4.7963,3.4607,61.28708566,62.4563
140.4,2.3384,0.65,-4.7872,3.4698,61.32908442,62.4991
140.6,2.3421,0.6512,-4.7755,3.4815,61.44526791,62.6175
140.8,2.3452,0.6519,-4.7662,3.4908,61.51022861,62.6837
141,2.3489,0.6531,-4.7551,3.5019,61.62248698,62.7981
141.2,2.3523,0.654,-4.7443,3.5127,61.70677889,62.884
141.4,2.3552,0.6543,-4.7356,3.5214,61.74033865,62.9182
141.6,2.3587,0.6553,-4.7243,3.5327,61.83120513,63.0108
141.8,2.3617,0.6558,-4.7148,3.5422,61.8785028,63.059
142,2.3653,0.6568,-4.7038,3.5532,61.96878051,63.151
142.2,2.3686,0.6576,-4.6933,3.5637,62.05140425,63.2352
142.4,2.3721,0.6585,-4.682,3.575,62.13667743,63.3221
142.6,2.3758,0.6598,-4.6698,3.5872,62.25835609,63.4461
142.8,2.3786,0.66,-4.6609,3.5961,62.27199587,63.46
143,2.3822,0.6612,-4.6492,3.6078,62.3826842,63.5728
143.2,2.3851,0.6615,-4.6402,3.6168,62.41202445,63.6027
143.4,2.3886,0.6624,-4.6288,3.6282,62.49661075,63.6889
143.6,2.3919,0.6633,-4.6172,3.6398,62.58149142,63.7754
143.8,2.3953,0.664,-4.6064,3.6506,62.64645212,63.8416
144,2.3991,0.6652,-4.5937,3.6633,62.76616822,63.9636
144.2,2.4019,0.6656,-4.5845,3.6725,62.80316246,64.0013
144.4,2.4057,0.6667,-4.5719,3.6851,62.90344922,64.1035
144.6,2.4085,0.6671,-4.5626,3.6944,62.93887341,64.1396
144.8,2.4119,0.6678,-4.5517,3.7053,63.0069742,64.209
145,2.4153,0.6686,-4.5404,3.7166,63.08606533,64.2896
145.2,2.4185,0.6694,-4.5293,3.7277,63.16240887,64.3674
145.4,2.4223,0.6706,-4.5166,3.7404,63.26927021,64.4763
145.6,2.4253,0.6709,-4.5069,3.7501,63.29890485,64.5065
145.8,2.429,0.672,-4.4939,3.7631,63.40606057,64.6157
146,2.4321,0.6727,-4.4833,3.7737,63.46945122,64.6803
146.2,2.4352,0.6731,-4.4727,3.7843,63.51174437,64.7234
146.4,2.4387,0.674,-4.4604,3.7966,63.59230741,64.8055
146.6,2.4417,0.6744,-4.45,3.807,63.63283426,64.8468
146.8,2.4455,0.6756,-4.4369,3.8201,63.74067687,64.9567
147,2.4486,0.6762,-4.4258,3.8312,63.79837611,65.0155
147.2,2.4522,0.6772,-4.4132,3.8438,63.8956209,65.1146
147.4,2.4557,0.6782,-4.4005,3.8565,63.98697802,65.2077
147.6,2.4586,0.6784,-4.3904,3.8666,64.01052873,65.2317
147.8,2.4621,0.6793,-4.3778,3.8792,64.09521315,65.318
148,2.4651,0.6797,-4.3671,3.8899,64.13230551,65.3558
148.2,2.4687,0.6806,-4.3542,3.9028,64.21473299,65.4398
148.4,2.4719,0.6813,-4.3423,3.9147,64.28646452,65.5129
148.6,2.4754,0.6822,-4.3298,3.9272,64.36653693,65.5945
148.8,2.4791,0.6833,-4.316,3.941,64.46986565,65.6998
149,2.482,0.6835,-4.306,3.951,64.4945939,65.725
149.2,2.4856,0.6844,-4.2928,3.9642,64.5802596,65.8123
149.4,2.4885,0.6847,-4.2817,3.9753,64.60547848,65.838
149.6,2.4919,0.6856,-4.269,3.988,64.68869098,65.9228
149.8,2.4952,0.6861,-4.2565,4.0005,64.73903062,65.9741
150,2.4986,0.687,-4.244,4.013,64.81851425,66.0551
150.2,2.5024,0.688,-4.2297,4.0273,64.91958604,66.1581
150.4,2.5053,0.6883,-4.2185,4.0385,64.94431428,66.1833
150.6,2.509,0.6894,-4.2043,4.0527,65.04391415,66.2848
150.8,2.5119,0.6898,-4.1931,4.0639,65.08228218,66.3239
151,2.5152,0.6903,-4.1803,4.0767,65.1280098,66.3705
151.2,2.5186,0.691,-4.1675,4.0895,65.20052636,66.4444
151.4,2.5218,0.6915,-4.1558,4.1012,65.24880531,66.4936
151.6,2.5256,0.6926,-4.1408,4.1162,65.34977897,66.5965
151.8,2.5286,0.6931,-4.129,4.128,65.39207211,66.6396
152,2.5323,0.694,-4.1143,4.1427,65.48293859,66.7322
152.2,2.5355,0.6945,-4.1022,4.1548,65.53259133,66.7828
152.4,2.5385,0.6949,-4.0897,4.1673,65.56811365,66.819
152.6,2.542,0.6956,-4.0762,4.1808,65.63542942,66.8876
152.8,2.5451,0.6961,-4.0637,4.1933,65.68145143,66.9345
153,2.5487,0.6971,-4.0494,4.2076,65.77153289,67.0263
153.2,2.5519,0.6975,-4.0361,4.2209,65.81647549,67.0721
153.4,2.5555,0.6985,-4.0216,4.2354,65.90420187,67.1615
153.6,2.5591,0.6993,-4.0071,4.2499,65.97966226,67.2384
153.8,2.5619,0.6993,-3.9956,4.2614,65.98584432,67.2447
154,2.5655,0.7003,-3.9806,4.2764,66.07484637,67.3354
154.2,2.5684,0.7004,-3.9682,4.2888,66.0889768,67.3498
154.4,2.572,0.7013,-3.9535,4.3035,66.16963797,67.432
154.6,2.5752,0.7018,-3.94,4.317,66.21438432,67.4776
154.8,2.5787,0.7026,-3.9251,4.3319,66.29102224,67.5557
155,2.5825,0.7036,-3.9096,4.3474,66.38502882,67.6515
155.2,2.5852,0.7036,-3.8977,4.3593,66.39032773,67.6569
155.4,2.5889,0.7046,-3.8821,4.3749,66.48325489,67.7516
155.6,2.5918,0.7047,-3.8696,4.3874,66.4892407,67.7577
155.8,2.5952,0.7054,-3.8548,4.4022,66.55577145,67.8255
156,2.5986,0.7059,-3.8407,4.4163,66.60424665,67.8749
156.2,2.6019,0.7066,-3.8263,4.4307,66.6665579,67.9384
156.4,2.6058,0.7075,-3.8096,4.4474,66.75654123,68.0301
156.6,2.6086,0.7078,-3.797,4.46,66.7820545,68.0561
156.8,2.6123,0.7087,-3.7808,4.4762,66.87184157,68.1476
157,2.6152,0.7089,-3.7674,4.4896,66.88293003,68.1589
157.2,2.6185,0.7093,-3.7529,4.5041,66.92875578,68.2056
157.4,2.6219,0.7099,-3.7379,4.5191,66.98056733,68.2584
157.6,2.6251,0.7102,-3.7231,4.5339,67.01265517,68.2911
157.8,2.6289,0.7113,-3.7061,4.5509,67.11313819,68.3935
158,2.632,0.7117,-3.6919,4.5651,67.14973992,68.4308
158.2,2.6357,0.7124,-3.6753,4.5817,67.2216677,68.5041
158.4,2.6388,0.7128,-3.6608,4.5962,67.25807317,68.5412
158.6,2.6419,0.7132,-3.6464,4.6106,67.29369362,68.5775
158.8,2.6454,0.7139,-3.6302,4.6268,67.35600486,68.641
159,2.6484,0.7141,-3.6163,4.6407,67.37396228,68.6593
159.2,2.6521,0.715,-3.599,4.658,67.46139428,68.7484
159.4,2.6553,0.7153,-3.5843,4.6727,67.49554281,68.7832
159.6,2.6589,0.7161,-3.5673,4.6897,67.56207356,68.851
159.8,2.6624,0.7168,-3.5509,4.7061,67.63184253,68.9221
160,2.6652,0.7168,-3.5369,4.7201,67.63086125,68.9211
160.2,2.6688,0.7174,-3.5203,4.7367,67.69405565,68.9855
160.4,2.6717,0.7176,-3.505,4.752,67.70494785,68.9966
160.6,2.6753,0.7182,-3.4879,4.7691,67.76892727,69.0618
160.8,2.6786,0.7186,-3.4721,4.7849,67.80601963,69.0996
161,2.682,0.7193,-3.4547,4.8023,67.86950842,69.1643
161.2,2.6858,0.7202,-3.4369,4.8201,67.95762731,69.2541
161.4,2.6886,0.7201,-3.4218,4.8352,67.94585196,69.2421
161.6,2.6923,0.7209,-3.4045,4.8525,68.02199925,69.3197
161.8,2.6951,0.721,-3.3893,4.8677,68.03367647,69.3316
162,2.6986,0.7214,-3.3716,4.8854,68.06478303,69.3633
162.2,2.7019,0.722,-3.355,4.902,68.12709428,69.4268
162.4,2.7052,0.7223,-3.3381,4.9189,68.15123376,69.4514
162.6,2.7091,0.7232,-3.3194,4.9376,68.23797886,69.5398
162.8,2.7119,0.7233,-3.3038,4.9532,68.24995047,69.552
163,2.7157,0.724,-3.2851,4.9719,68.3101029,69.6133
163.2,2.7186,0.7243,-3.2691,4.9879,68.34179823,69.6456
163.4,2.7219,0.7245,-3.2518,5.0052,68.36377889,69.668
163.6,2.7253,0.7249,-3.2342,5.0228,68.39812367,69.703
163.8,2.7285,0.7252,-3.2171,5.0399,68.42834708,69.7338
164,2.7322,0.7261,-3.1977,5.0593,68.50586816,69.8128
164.2,2.7353,0.7261,-3.1811,5.0759,68.50734008,69.8143
164.4,2.739,0.7269,-3.1615,5.0955,68.58996381,69.8985
164.6,2.7422,0.7273,-3.144,5.113,68.61930407,69.9284
164.8,2.7452,0.7271,-3.1275,5.1295,68.60801935,69.9169
165,2.7487,0.7277,-3.1092,5.1478,68.66552233,69.9755
165.2,2.7518,0.7279,-3.0919,5.1651,68.67592389,69.9861
165.4,2.7554,0.7285,-3.0724,5.1846,68.73264185,70.0439
165.6,2.7586,0.7286,-3.0545,5.2025,68.74549661,70.057
165.8,2.7622,0.7292,-3.0351,5.2219,68.79819132,70.1107
166,2.7657,0.7297,-3.0158,5.2412,68.85402612,70.1676
166.2,2.7686,0.7297,-2.9994,5.2576,68.84715716,70.1606
166.4,2.7721,0.7302,-2.9796,5.2774,68.8981837,70.2126
166.6,2.7751,0.7301,-2.9617,5.2953,68.88523081,70.1994
166.8,2.7786,0.7307,-2.9419,5.3151,68.94194876,70.2572
167,2.7819,0.7309,-2.9232,5.3338,68.96167248,70.2773
167.2,2.7853,0.7313,-2.9036,5.3534,68.99915736,70.3155
167.4,2.7891,0.732,-2.8821,5.3749,69.06716002,70.3848
167.6,2.7919,0.7318,-2.8654,5.3916,69.04655315,70.3638
167.8,2.7956,0.7324,-2.8443,5.4127,69.10866815,70.4271
168,2.7985,0.7323,-2.827,5.43,69.09846284,70.4167
168.2,2.8019,0.7327,-2.8068,5.4502,69.13408328,70.453
168.4,2.8052,0.7329,-2.7873,5.4697,69.15351262,70.4728
168.6,2.8085,0.7331,-2.7675,5.4895,69.17019437,70.4898
168.8,2.8124,0.7338,-2.7454,5.5116,69.23849142,70.5594
169,2.8153,0.7337,-2.7275,5.5295,69.22357597,70.5442
169.2,2.819,0.7343,-2.706,5.551,69.28637786,70.6082
169.4,2.822,0.7341,-2.6868,5.5702,69.26734104,70.5888
169.6,2.8252,0.7343,-2.6671,5.5899,69.28412092,70.6059
169.8,2.8286,0.7346,-2.6466,5.6104,69.31493309,70.6373
170,2.8318,0.7348,-2.6264,5.6306,69.33053544,70.6532
170.2,2.8356,0.7353,-2.6043,5.6527,69.38018818,70.7038
170.4,2.8386,0.7352,-2.5846,5.6724,69.370081,70.6935
170.6,2.8423,0.7358,-2.562,5.695,69.4223832,70.7468
170.8,2.8454,0.7358,-2.5421,5.7149,69.42778023,70.7523
171,2.8486,0.7357,-2.5215,5.7355,69.42022438,70.7446
171.2,2.852,0.7362,-2.5,5.757,69.46016246,70.7853
171.4,2.8551,0.736,-2.4799,5.7771,69.44308819,70.7679
171.6,2.8588,0.7365,-2.4571,5.7999,69.49607728,70.8219
171.8,2.8619,0.7367,-2.4364,5.8206,69.50638072,70.8324
172,2.8656,0.737,-2.4133,5.8437,69.53817417,70.8648
172.2,2.869,0.7373,-2.3914,5.8656,69.57094891,70.8982
172.4,2.8719,0.737,-2.3714,5.8856,69.54190304,70.8686
172.6,2.8755,0.7374,-2.3484,5.9086,69.57830851,70.9057
172.8,2.8784,0.7372,-2.3281,5.9289,69.55917356,70.8862
173,2.882,0.7375,-2.3052,5.9518,69.58125234,70.9087
173.2,2.8853,0.7376,-2.2829,5.9741,69.5941071,70.9218
173.4,2.8887,0.7379,-2.2602,5.9968,69.62060165,70.9488
173.6,2.8924,0.7383,-2.2361,6.0209,69.66201165,70.991
173.8,2.8952,0.738,-2.2157,6.0413,69.63581148,70.9643
174,2.8989,0.7384,-2.1917,6.0653,69.66976375,70.9989
174.2,2.9018,0.7381,-2.1706,6.0864,69.64415236,70.9728
174.4,2.9052,0.7384,-2.147,6.11,69.67153006,71.0007
174.6,2.9086,0.7385,-2.1239,6.1331,69.67565143,71.0049
174.8,2.9119,0.7386,-2.1009,6.1561,69.68683802,71.0163
175,2.9157,0.739,-2.0758,6.1812,69.72746299,71.0577
175.2,2.9186,0.7387,-2.0543,6.2027,69.69517889,71.0248
175.4,2.9224,0.7392,-2.0293,6.2277,69.74934552,71.08
175.6,2.9253,0.7388,-2.0076,6.2494,69.70930932,71.0392
175.8,2.9286,0.7388,-1.9835,6.2735,69.71274379,71.0427
176,2.932,0.7389,-1.9595,6.2975,69.7204959,71.0506
176.2,2.9351,0.7387,-1.936,6.321,69.70077218,71.0305
176.4,2.9389,0.7392,-1.9104,6.3466,69.74581291,71.0764
176.6,2.9419,0.7391,-1.8871,6.3699,69.7369814,71.0674
176.669,2.9431,0.7395,-0.9425,7.3145,69.77328874,71.1044