File: data/ReportRaw/Resin_CSV/V4_Resin_HT/Tensile_Test_04.csv
Time,Displacement,Force,Tensile strain (Strain 1),,,Tensile stress
(s),(mm),(kN),(%),,,(MPa)
0,0,0.0011,-14.0806,0,0.110884581,0.113
0.22,0.0008,0.0017,-14.079,0.0016,0.17025199,0.1735
0.44,0.0057,0.0068,-14.0655,0.0151,0.669723246,0.6825
0.66,0.0095,0.0102,-14.0547,0.0259,1.003260142,1.0224
0.88,0.0135,0.0139,-14.0439,0.0367,1.370258667,1.3964
1.1,0.0167,0.0168,-14.0347,0.0459,1.649138296,1.6806
1.32,0.0207,0.0204,-14.0245,0.0561,2.001025118,2.0392
1.54,0.0246,0.0237,-14.0136,0.067,2.325436114,2.3698
1.76,0.0277,0.0262,-14.0057,0.0749,2.57576051,2.6249
1.98,0.0318,0.0298,-13.9951,0.0855,2.930885554,2.9868
2.2,0.0353,0.0324,-13.9876,0.093,3.182387485,3.2431
2.42,0.0387,0.0347,-13.9792,0.1014,3.408179894,3.4732
2.64,0.0427,0.0376,-13.9705,0.1101,3.690788384,3.7612
2.86,0.046,0.0397,-13.9631,0.1175,3.904609183,3.9791
3.08,0.0497,0.0421,-13.9551,0.1255,4.139036851,4.218
3.3,0.0535,0.045,-13.9463,0.1343,4.419486527,4.5038
3.52,0.0569,0.0471,-13.9395,0.1411,4.624181427,4.7124
3.74,0.0607,0.0495,-13.931,0.1496,4.866164947,4.959
3.96,0.0644,0.052,-13.9228,0.1578,5.114330528,5.2119
4.18,0.0679,0.0541,-13.9162,0.1644,5.319516067,5.421
4.4,0.0717,0.0565,-13.9088,0.1718,5.54893921,5.6548
4.62,0.0753,0.0587,-13.9016,0.179,5.767077639,5.8771
4.84,0.0789,0.0607,-13.8946,0.186,5.967062397,6.0809
5.06,0.0829,0.0631,-13.8868,0.1938,6.202275088,6.3206
5.28,0.0863,0.065,-13.8803,0.2003,6.383419281,6.5052
5.5,0.09,0.0669,-13.874,0.2066,6.575750059,6.7012
5.72,0.0941,0.0694,-13.8668,0.2138,6.817046683,6.9471
5.94,0.0973,0.0709,-13.8608,0.2198,6.969733771,7.1027
6.16,0.1013,0.0731,-13.8542,0.2264,7.186792792,7.3239
6.38,0.1052,0.0755,-13.8466,0.234,7.423673659,7.5653
6.6,0.1084,0.077,-13.8411,0.2395,7.567332975,7.7117
6.82,0.1125,0.0793,-13.8333,0.2473,7.789200265,7.9378
7.04,0.1161,0.0813,-13.8264,0.2542,7.990068175,8.1425
7.26,0.1194,0.0828,-13.8214,0.2592,8.137848865,8.2931
7.48,0.1234,0.0852,-13.8138,0.2668,8.374435348,8.5342
7.7,0.1268,0.0869,-13.8081,0.2725,8.540958476,8.7039
7.92,0.1303,0.0887,-13.802,0.2786,8.721415772,8.8878
8.14,0.1343,0.0909,-13.7942,0.2864,8.934647804,9.1051
8.36,0.1376,0.0925,-13.7884,0.2922,9.094301975,9.2678
8.58,0.1413,0.0945,-13.7813,0.2993,9.289576592,9.4668
8.8,0.1452,0.0968,-13.7737,0.3069,9.516546536,9.6981
9.02,0.1485,0.0985,-13.7678,0.3128,9.68375656,9.8685
9.24,0.1524,0.1004,-13.7612,0.3194,9.870984685,10.0593
9.46,0.1561,0.102,-13.7558,0.3248,10.02681187,10.2181
9.68,0.1595,0.1023,-13.7532,0.3274,10.05320828,10.245
9.9,0.1634,0.1024,-13.7518,0.3288,10.05968473,10.2516
10.12,0.167,0.1028,-13.7496,0.331,10.09942655,10.2921
10.34,0.1706,0.1031,-13.7472,0.3334,10.13642078,10.3298
10.56,0.1746,0.104,-13.7437,0.3369,10.21619881,10.4111
10.78,0.178,0.1047,-13.7413,0.3393,10.28626216,10.4825
11,0.1818,0.1053,-13.7384,0.3422,10.34876966,10.5462
11.22,0.1858,0.1065,-13.7344,0.3462,10.46465877,10.6643
11.44,0.1891,0.107,-13.7321,0.3485,10.51313398,10.7137
11.66,0.193,0.1079,-13.7281,0.3525,10.60193977,10.8042
11.88,0.197,0.1092,-13.7239,0.3567,10.73284245,10.9376
12.1,0.2001,0.1097,-13.7211,0.3595,10.77552811,10.9811
12.32,0.2041,0.1114,-13.7157,0.3649,10.94352316,11.1523
12.54,0.2077,0.1128,-13.7106,0.37,11.08708435,11.2986
12.76,0.211,0.1144,-13.7053,0.3753,11.2452666,11.4598
12.98,0.2151,0.1167,-13.6978,0.3828,11.46909645,11.6879
13.2,0.2184,0.1183,-13.6926,0.388,11.6265918,11.8484
13.42,0.222,0.1201,-13.686,0.3946,11.80557718,12.0308
13.64,0.2259,0.1224,-13.6791,0.4015,12.02872014,12.2582
13.86,0.2292,0.1239,-13.6726,0.408,12.17277196,12.405
14.08,0.233,0.1261,-13.6652,0.4154,12.3926767,12.6291
14.3,0.2367,0.1283,-13.6575,0.4231,12.60806754,12.8486
14.52,0.2402,0.1301,-13.6508,0.4298,12.78930986,13.0333
14.74,0.2441,0.1323,-13.6433,0.4373,12.99822426,13.2462
14.96,0.2477,0.1343,-13.6364,0.4442,13.19359701,13.4453
15.18,0.2512,0.136,-13.6301,0.4505,13.36777412,13.6228
15.4,0.2551,0.138,-13.6225,0.4581,13.56098805,13.8197
15.62,0.2587,0.1398,-13.6162,0.4644,13.73820712,14.0003
15.84,0.2623,0.1414,-13.6101,0.4705,13.89815568,14.1633
16.06,0.2663,0.1435,-13.6023,0.4783,14.1004955,14.3695
16.28,0.2697,0.1449,-13.5971,0.4835,14.2433698,14.5151
16.5,0.2735,0.1466,-13.5908,0.4898,14.40950041,14.6844
16.72,0.2775,0.1485,-13.5841,0.4965,14.59712105,14.8756
16.94,0.2807,0.1497,-13.579,0.5016,14.71114573,14.9918
17.16,0.2847,0.1515,-13.5731,0.5075,14.88561722,15.1696
17.38,0.2886,0.1534,-13.5663,0.5143,15.07618169,15.3638
17.6,0.2917,0.1543,-13.5615,0.5191,15.1629268,15.4522
17.82,0.2958,0.1562,-13.555,0.5256,15.34730921,15.6401
18.04,0.2993,0.1576,-13.5493,0.5313,15.48920223,15.7847
18.26,0.3027,0.1588,-13.5446,0.536,15.60597448,15.9037
18.48,0.3067,0.1607,-13.538,0.5426,15.79084754,16.0921
18.7,0.31,0.1619,-13.5335,0.5471,15.90850295,16.212
18.92,0.3137,0.1634,-13.5276,0.553,16.05324167,16.3595
19.14,0.3175,0.165,-13.5218,0.5588,16.21760598,16.527
19.36,0.3208,0.1661,-13.5171,0.5635,16.32201412,16.6334
19.58,0.3247,0.1677,-13.5112,0.5694,16.47970573,16.7941
19.8,0.3284,0.1691,-13.505,0.5756,16.61610358,16.9331
20.02,0.3318,0.1702,-13.5005,0.5801,16.7239462,17.043
20.24,0.3358,0.1718,-13.4946,0.586,16.88183407,17.2039
20.46,0.3393,0.1732,-13.4893,0.5913,17.02382521,17.3486
20.68,0.3429,0.1746,-13.4847,0.5959,17.15727922,17.4846
20.9,0.3469,0.1761,-13.4784,0.6022,17.30486365,17.635
21.12,0.3503,0.1773,-13.4739,0.6067,17.41869207,17.751
21.34,0.3541,0.1788,-13.4684,0.6122,17.57069226,17.9059
21.56,0.3581,0.1805,-13.4615,0.6191,17.73417342,18.0725
21.78,0.3614,0.1814,-13.4573,0.6233,17.82278296,18.1628
22,0.3653,0.183,-13.4518,0.6288,17.97929704,18.3223
22.22,0.3693,0.1845,-13.446,0.6346,18.13237664,18.4783
22.44,0.3724,0.1853,-13.4427,0.6379,18.20822954,18.5556
22.66,0.3765,0.1871,-13.4361,0.6445,18.3839767,18.7347
22.88,0.3802,0.1884,-13.4311,0.6495,18.51429061,18.8675
23.1,0.3834,0.1892,-13.4273,0.6533,18.5946574,18.9494
23.32,0.3875,0.1908,-13.4208,0.6598,18.74803138,19.1057
23.54,0.3908,0.1918,-13.417,0.6636,18.84517805,19.2047
23.76,0.3943,0.1929,-13.4126,0.668,18.95547386,19.3171
23.98,0.3983,0.1945,-13.4064,0.6742,19.11375425,19.4784
24.2,0.4016,0.1953,-13.4027,0.6779,19.19186409,19.558
24.42,0.4053,0.1965,-13.3977,0.6829,19.30902886,19.6774
24.64,0.4091,0.198,-13.3924,0.6882,19.45288443,19.824
24.86,0.4125,0.199,-13.388,0.6926,19.55680193,19.9299
25.08,0.4164,0.2003,-13.3832,0.6974,19.67985438,20.0553
25.3,0.4201,0.2015,-13.378,0.7026,19.79662664,20.1743
25.52,0.4235,0.2025,-13.3741,0.7065,19.90407674,20.2838
25.74,0.4275,0.2039,-13.3686,0.712,20.03478317,20.417
25.96,0.431,0.205,-13.3641,0.7165,20.14959287,20.534
26.18,0.4346,0.2061,-13.3596,0.721,20.25635607,20.6428
26.4,0.4386,0.2077,-13.3534,0.7272,20.41316453,20.8026
26.62,0.442,0.2087,-13.349,0.7316,20.50864303,20.8999
26.84,0.4458,0.2099,-13.344,0.7366,20.6226677,21.0161
27.06,0.4499,0.2114,-13.3383,0.7423,20.77437351,21.1707
27.28,0.453,0.2123,-13.3348,0.7458,20.85886167,21.2568
27.5,0.457,0.2136,-13.3294,0.7512,20.99506327,21.3956
27.72,0.4609,0.2151,-13.3239,0.7567,21.1377413,21.541
27.94,0.4641,0.2157,-13.3206,0.76,21.19563679,21.6
28.16,0.4681,0.2172,-13.3148,0.7658,21.34116054,21.7483
28.38,0.4717,0.2184,-13.3099,0.7707,21.46048412,21.8699
28.6,0.4751,0.2191,-13.3066,0.774,21.53506136,21.9459
28.82,0.4791,0.2206,-13.3004,0.7802,21.68068324,22.0943
29.04,0.4825,0.2217,-13.2969,0.7837,21.78538576,22.201
29.26,0.486,0.2225,-13.2926,0.788,21.86771511,22.2849
29.48,0.4899,0.2239,-13.2874,0.7932,22.00744931,22.4273
29.7,0.4932,0.2246,-13.2836,0.797,22.07525572,22.4964
29.92,0.497,0.2258,-13.2788,0.8018,22.18800473,22.6113
30.14,0.5008,0.2272,-13.2733,0.8073,22.32508948,22.751
30.36,0.5042,0.2279,-13.2695,0.8111,22.39829292,22.8256
30.58,0.508,0.2294,-13.2643,0.8163,22.53940091,22.9694
30.8,0.5117,0.2305,-13.2596,0.821,22.65107052,23.0832
31.02,0.5152,0.2314,-13.2556,0.825,22.73673622,23.1705
31.24,0.5191,0.2327,-13.2507,0.8299,22.86871831,23.305
31.46,0.5226,0.2338,-13.2464,0.8342,22.97243955,23.4107
31.68,0.5263,0.235,-13.242,0.8386,23.09038934,23.5309
31.9,0.5303,0.2363,-13.236,0.8446,23.22315646,23.6662
32.12,0.5337,0.2371,-13.2322,0.8484,23.30185507,23.7464
32.34,0.5375,0.2384,-13.2267,0.8539,23.42863638,23.8756
32.56,0.5416,0.2399,-13.2211,0.8595,23.5775946,24.0274
32.78,0.5447,0.2405,-13.2183,0.8623,23.63617699,24.0871
33,0.5487,0.242,-13.2129,0.8677,23.77895315,24.2326
33.22,0.5526,0.2433,-13.2076,0.873,23.9093652,24.3655
33.44,0.5557,0.2438,-13.2043,0.8763,23.95715351,24.4142
33.66,0.5599,0.2455,-13.1989,0.8817,24.12171408,24.5819
33.88,0.5632,0.2462,-13.195,0.8856,24.19560442,24.6572
34.1,0.5667,0.2471,-13.1907,0.8899,24.28097574,24.7442
34.32,0.5707,0.2486,-13.1851,0.8955,24.4346441,24.9008
34.54,0.574,0.2493,-13.1816,0.899,24.50333367,24.9708
34.76,0.5777,0.2503,-13.1773,0.9033,24.59370951,25.0629
34.98,0.5815,0.2517,-13.1723,0.9083,24.73373809,25.2056
35.2,0.5849,0.2525,-13.1685,0.9121,24.81331986,25.2867
35.42,0.5887,0.2538,-13.1636,0.917,24.93784422,25.4136
35.64,0.5924,0.2549,-13.1587,0.9219,25.04647186,25.5243
35.86,0.5958,0.2557,-13.1544,0.9262,25.1308619,25.6103
36.08,0.5998,0.2569,-13.1491,0.9315,25.24890982,25.7306
36.3,0.6034,0.2581,-13.1444,0.9362,25.36725212,25.8512
36.52,0.6069,0.259,-13.1405,0.9401,25.45291782,25.9385
36.74,0.6109,0.2605,-13.1346,0.946,25.59893221,26.0873
36.96,0.6144,0.2614,-13.1306,0.95,25.69176125,26.1819
37.18,0.6181,0.2624,-13.1262,0.9544,25.79067422,26.2827
37.4,0.6221,0.264,-13.1207,0.9599,25.94345943,26.4384
37.62,0.6254,0.2647,-13.117,0.9636,26.01548535,26.5118
37.84,0.6293,0.266,-13.1117,0.9689,26.1445236,26.6433
38.06,0.6333,0.2674,-13.1063,0.9743,26.27591692,26.7772
38.28,0.6364,0.268,-13.1031,0.9775,26.33744315,26.8399
38.5,0.6404,0.2695,-13.0973,0.9833,26.48041557,26.9856
38.72,0.6441,0.2707,-13.0924,0.9882,26.598856,27.1063
38.94,0.6473,0.2713,-13.0891,0.9915,26.66116725,27.1698
39.16,0.6514,0.2728,-13.0835,0.9971,26.81179365,27.3233
39.38,0.6548,0.2737,-13.079,1.0016,26.89480989,27.4079
39.6,0.6583,0.2745,-13.0753,1.0053,26.97645234,27.4911
39.82,0.6623,0.2761,-13.0695,1.0111,27.12982633,27.6474
40.04,0.6656,0.2767,-13.0654,1.0152,27.19311885,27.7119
40.26,0.6693,0.2779,-13.0605,1.0201,27.31430687,27.8354
40.48,0.6731,0.2793,-13.0554,1.0252,27.45129348,27.975
40.7,0.6765,0.2801,-13.0518,1.0288,27.5215531,28.0466
40.92,0.6804,0.2813,-13.047,1.0336,27.64715687,28.1746
41.14,0.684,0.2824,-13.0421,1.0385,27.75097624,28.2804
41.36,0.6875,0.2833,-13.0382,1.0424,27.84154833,28.3727
41.58,0.6915,0.2847,-13.0321,1.0485,27.98138066,28.5152
41.8,0.695,0.2857,-13.028,1.0526,28.0801955,28.6159
42.02,0.6986,0.2869,-13.0231,1.0575,28.19058945,28.7284
42.24,0.7026,0.2883,-13.0172,1.0634,28.32649665,28.8669
42.46,0.706,0.2891,-13.013,1.0676,28.41088669,28.9529
42.68,0.7098,0.2904,-13.0081,1.0725,28.53442978,29.0788
42.9,0.7138,0.2919,-13.0024,1.0782,28.68113106,29.2283
43.12,0.717,0.2927,-12.9988,1.0818,28.76081095,29.3095
43.34,0.721,0.294,-12.9929,1.0877,28.89171364,29.4429
43.56,0.7249,0.2954,-12.9878,1.0928,29.0338029,29.5877
43.78,0.728,0.2959,-12.9846,1.096,29.0776661,29.6324
44,0.7322,0.2975,-12.9785,1.1021,29.23555397,29.7933
44.22,0.7358,0.2987,-12.9739,1.1067,29.34967677,29.9096
44.44,0.739,0.2993,-12.9699,1.1107,29.41414683,29.9753
44.66,0.7431,0.3008,-12.9638,1.1168,29.55662861,30.1205
44.88,0.7464,0.3015,-12.9602,1.1204,29.63051896,30.1958
45.1,0.75,0.3025,-12.9558,1.1248,29.72501617,30.2921
45.32,0.7539,0.3039,-12.9503,1.1303,29.86367096,30.4334
45.54,0.7572,0.3047,-12.9462,1.1344,29.94649095,30.5178
45.76,0.761,0.3059,-12.941,1.1396,30.064637,30.6382
45.98,0.7647,0.3073,-12.9355,1.1451,30.19544155,30.7715
46.2,0.7682,0.3081,-12.9318,1.1488,30.27266825,30.8502
46.42,0.772,0.3093,-12.9261,1.1545,30.39846828,30.9784
46.64,0.7757,0.3106,-12.922,1.1586,30.52662338,31.109
46.86,0.7792,0.3115,-12.9171,1.1635,30.61395725,31.198
47.08,0.7832,0.3129,-12.9113,1.1693,30.74476181,31.3313
47.3,0.7867,0.3139,-12.9069,1.1737,30.84887556,31.4374
47.52,0.7903,0.3149,-12.9021,1.1785,30.9490642,31.5395
47.74,0.7944,0.3163,-12.896,1.1846,31.08644332,31.6795
47.96,0.7977,0.3171,-12.8927,1.1879,31.15925426,31.7537
48.18,0.8015,0.3183,-12.8875,1.1931,31.28161981,31.8784
48.4,0.8056,0.3199,-12.8816,1.199,31.43587695,32.0356
48.62,0.8087,0.3205,-12.8784,1.2022,31.49475371,32.0956
48.84,0.8127,0.3218,-12.8727,1.2079,31.62585265,32.2292
49.06,0.8165,0.3232,-12.8677,1.2129,31.75812913,32.364
49.28,0.8197,0.3237,-12.8641,1.2165,31.80954817,32.4164
49.5,0.8238,0.3252,-12.8579,1.2227,31.95742699,32.5671
49.72,0.8272,0.326,-12.8539,1.2267,32.04063949,32.6519
49.94,0.8306,0.3268,-12.8496,1.231,32.11482422,32.7275
50.16,0.8346,0.3283,-12.8436,1.237,32.26280116,32.8783
50.38,0.838,0.3291,-12.8403,1.2403,32.34306983,32.9601
50.6,0.8417,0.3302,-12.8358,1.2448,32.44639856,33.0654
50.82,0.8455,0.3314,-12.8302,1.2504,32.56994164,33.1913
51.04,0.8489,0.3321,-12.8261,1.2545,32.63549111,33.2581
51.26,0.8527,0.3334,-12.8207,1.2599,32.76354808,33.3886
51.48,0.8564,0.3347,-12.8159,1.2647,32.88620802,33.5136
51.7,0.8599,0.3355,-12.8113,1.2693,32.97305125,33.6021
51.92,0.8638,0.3367,-12.8059,1.2747,33.09090292,33.7222
52.14,0.8674,0.3379,-12.8012,1.2794,33.20718454,33.8407
52.36,0.8709,0.3389,-12.7965,1.2841,33.30197614,33.9373
52.58,0.8749,0.3404,-12.7904,1.2902,33.45054185,34.0887
52.8,0.8784,0.3414,-12.7859,1.2947,33.54700162,34.187
53.02,0.8821,0.3426,-12.7806,1.3,33.6645589,34.3068
53.24,0.8861,0.3441,-12.7742,1.3064,33.81469466,34.4598
53.46,0.8893,0.345,-12.7704,1.3102,33.90055662,34.5473
53.68,0.8933,0.3464,-12.7646,1.316,34.0454916,34.695
53.9,0.8973,0.3479,-12.758,1.3226,34.18365575,34.8358
54.12,0.9004,0.3485,-12.7547,1.3259,34.24930335,34.9027
54.34,0.9045,0.3501,-12.7481,1.3325,34.40208856,35.0584
54.56,0.9081,0.3512,-12.7435,1.3371,34.51709452,35.1756
54.78,0.9114,0.3521,-12.7393,1.3413,34.5981482,35.2582
55,0.9155,0.3536,-12.7324,1.3482,34.7487746,35.4117
55.22,0.9188,0.3546,-12.7282,1.3524,34.84798196,35.5128
55.44,0.9224,0.3556,-12.7235,1.3571,34.94660055,35.6133
55.66,0.9263,0.357,-12.7175,1.3631,35.07936766,35.7486
55.88,0.9296,0.3579,-12.7131,1.3675,35.17200044,35.843
56.1,0.9333,0.359,-12.7078,1.3728,35.27660483,35.9496
56.32,0.9371,0.3603,-12.7019,1.3787,35.41172702,36.0873
56.54,0.9405,0.3612,-12.6975,1.3831,35.49974779,36.177
56.76,0.9444,0.3626,-12.692,1.3886,35.62917855,36.3089
56.98,0.9481,0.3639,-12.6871,1.3935,35.7631232,36.4454
57.2,0.9515,0.3648,-12.6823,1.3983,35.84486378,36.5287
57.42,0.9555,0.3661,-12.6761,1.4045,35.97537395,36.6617
57.64,0.959,0.3672,-12.6714,1.4092,36.08302031,36.7714
57.86,0.9626,0.3682,-12.666,1.4146,36.18487712,36.8752
58.08,0.9666,0.3697,-12.6601,1.4205,36.33128402,37.0244
58.3,0.97,0.3706,-12.6561,1.4245,36.41940292,37.1142
58.52,0.9738,0.3719,-12.6503,1.4303,36.54765615,37.2449
58.74,0.9778,0.3733,-12.6445,1.4361,36.68846975,37.3884
58.96,0.981,0.3741,-12.6403,1.4403,36.75892562,37.4602
59.18,0.985,0.3755,-12.6343,1.4463,36.89767854,37.6016
59.4,0.9889,0.3769,-12.628,1.4526,37.03839402,37.745
59.62,0.9921,0.3775,-12.6245,1.4561,37.09785955,37.8056
59.84,0.9962,0.379,-12.6182,1.4624,37.24652339,37.9571
60.06,0.9997,0.38,-12.6136,1.467,37.34327755,38.0557
60.28,1.003,0.3809,-12.6095,1.4711,37.42747133,38.1415
60.5,1.0071,0.3823,-12.6031,1.4775,37.56691114,38.2836
60.72,1.0104,0.3831,-12.599,1.4816,37.64511912,38.3633
60.94,1.014,0.3841,-12.5936,1.487,37.74187328,38.4619
61.16,1.0179,0.3855,-12.5878,1.4928,37.88366816,38.6064
61.38,1.0212,0.3863,-12.5832,1.4974,37.95804915,38.6822
61.6,1.025,0.3876,-12.5777,1.5029,38.08944247,38.8161
61.82,1.0288,0.3888,-12.5723,1.5083,38.21131738,38.9403
62.04,1.0322,0.3896,-12.568,1.5126,38.2868759,39.0173
62.26,1.0361,0.391,-12.5625,1.5181,38.42160557,39.1546
62.48,1.0397,0.392,-12.5571,1.5235,38.52385489,39.2588
62.7,1.0432,0.3932,-12.5519,1.5287,38.63886085,39.376
62.92,1.0472,0.3945,-12.5455,1.5351,38.77143171,39.5111
63.14,1.0507,0.3955,-12.5407,1.5399,38.86475139,39.6062
63.36,1.0544,0.3968,-12.5354,1.5452,38.99349525,39.7374
63.58,1.0584,0.3983,-12.5288,1.5518,39.13990215,39.8866
63.8,1.0616,0.3991,-12.5247,1.5559,39.21634382,39.9645
64.02,1.0656,0.4004,-12.5185,1.5621,39.34969971,40.1004
64.24,1.0695,0.402,-12.5117,1.5689,39.5041531,40.2578
64.46,1.0727,0.4028,-12.5071,1.5735,39.57951536,40.3346
64.68,1.0768,0.4043,-12.5005,1.5801,39.72670728,40.4846
64.9,1.0805,0.4056,-12.4954,1.5852,39.85358672,40.6139
65.12,1.0837,0.4063,-12.4911,1.5895,39.92914524,40.6909
65.34,1.0878,0.408,-12.4839,1.5967,40.0950796,40.86
65.56,1.0912,0.409,-12.4792,1.6014,40.18977307,40.9565
65.78,1.0947,0.4098,-12.4736,1.607,40.26945296,41.0377
66,1.0986,0.4114,-12.4671,1.6135,40.42596704,41.1972
66.22,1.102,0.4123,-12.4626,1.618,40.51899233,41.292
66.44,1.1056,0.4135,-12.4569,1.6237,40.63340952,41.4086
66.66,1.1095,0.4148,-12.4506,1.63,40.76244777,41.5401
66.88,1.1129,0.4156,-12.4462,1.6344,40.84291269,41.6221
67.1,1.1167,0.417,-12.4402,1.6404,40.97852552,41.7603
67.32,1.1204,0.4183,-12.4344,1.6462,41.10736751,41.8916
67.54,1.1239,0.4193,-12.4291,1.6515,41.20225724,41.9883
67.76,1.1278,0.4206,-12.4228,1.6578,41.33365056,42.1222
67.98,1.1314,0.4217,-12.4173,1.6633,41.44306322,42.2337
68.2,1.1349,0.4227,-12.4119,1.6687,41.53991551,42.3324
68.42,1.1389,0.4242,-12.4055,1.6751,41.68416359,42.4794
68.64,1.1423,0.4252,-12.4006,1.68,41.78042711,42.5775
68.86,1.1461,0.4263,-12.3952,1.6854,41.89258735,42.6918
69.08,1.1501,0.4279,-12.3888,1.6918,42.05273216,42.855
69.3,1.1534,0.4286,-12.3843,1.6963,42.11690784,42.9204
69.52,1.1573,0.43,-12.3778,1.7028,42.25978213,43.066
69.74,1.1612,0.4313,-12.3713,1.7093,42.38813349,43.1968
69.96,1.1644,0.4321,-12.3672,1.7134,42.45947251,43.2695
70.18,1.1685,0.4336,-12.3603,1.7203,42.60843073,43.4213
70.4,1.1721,0.4347,-12.3547,1.7259,42.7164696,43.5314
70.62,1.1754,0.4354,-12.3505,1.7301,42.78358912,43.5998
70.84,1.1794,0.4368,-12.3437,1.7369,42.92930912,43.7483
71.06,1.1828,0.4376,-12.3392,1.7414,43.00673208,43.8272
71.28,1.1863,0.4387,-12.3343,1.7463,43.11418218,43.9367
71.5,1.1903,0.4401,-12.3275,1.7531,43.25038377,44.0755
71.72,1.1936,0.4409,-12.3223,1.7583,43.32770859,44.1543
71.94,1.1973,0.442,-12.3168,1.7638,43.43908381,44.2678
72.16,1.2011,0.4433,-12.3113,1.7693,43.56144937,44.3925
72.38,1.2045,0.4442,-12.3066,1.774,43.64770383,44.4804
72.6,1.2084,0.4454,-12.3003,1.7803,43.76565363,44.6006
72.82,1.212,0.4465,-12.2949,1.7857,43.87398688,44.711
73.04,1.2155,0.4475,-12.2897,1.7909,43.97918004,44.8182
73.26,1.2195,0.4488,-12.2829,1.7977,44.10674637,44.9482
73.48,1.223,0.4498,-12.2776,1.803,44.20271551,45.046
73.7,1.2267,0.4509,-12.2719,1.8087,44.3139926,45.1594
73.92,1.2306,0.4523,-12.2655,1.8151,44.45215675,45.3002
74.14,1.234,0.4532,-12.2608,1.8198,44.53556551,45.3852
74.36,1.2378,0.4543,-12.2546,1.826,44.64232871,45.494
74.58,1.2419,0.4559,-12.248,1.8326,44.80571175,45.6605
74.8,1.2451,0.4567,-12.2432,1.8374,44.8757751,45.7319
75.02,1.249,0.4581,-12.2365,1.8441,45.01403738,45.8728
75.24,1.2529,0.4593,-12.2301,1.8505,45.13659919,45.9977
75.46,1.256,0.4599,-12.2262,1.8544,45.19586847,46.0581
75.68,1.2601,0.4615,-12.2193,1.8613,45.34767241,46.2128
75.9,1.2637,0.4625,-12.2137,1.8669,45.45306182,46.3202
76.12,1.267,0.4632,-12.2088,1.8718,45.52126075,46.3897
76.34,1.2711,0.4649,-12.2014,1.8792,45.68336812,46.5549
76.56,1.2744,0.4656,-12.1964,1.8842,45.75686595,46.6298
76.78,1.278,0.4667,-12.1906,1.89,45.8592134,46.7341
77,1.2819,0.4681,-12.1841,1.8965,45.99973262,46.8773
77.22,1.2852,0.469,-12.1793,1.9013,46.08559458,46.9648
77.44,1.289,0.4702,-12.1734,1.9072,46.20393688,47.0854
77.66,1.2928,0.4714,-12.1667,1.9139,46.32532115,47.2091
77.88,1.2962,0.4723,-12.1615,1.9191,46.41579512,47.3013
78.1,1.3001,0.4735,-12.1547,1.9259,46.53423555,47.422
78.32,1.3037,0.4746,-12.149,1.9316,46.6355036,47.5252
78.54,1.3072,0.4755,-12.1439,1.9367,46.72332811,47.6147
78.76,1.3112,0.477,-12.137,1.9436,46.87915529,47.7735
78.98,1.3147,0.478,-12.132,1.9486,46.96962926,47.8657
79.2,1.3184,0.479,-12.1259,1.9547,47.07119169,47.9692
79.42,1.3224,0.4805,-12.1187,1.9619,47.21691169,48.1177
79.64,1.3257,0.4811,-12.1138,1.9668,47.2787323,48.1807
79.86,1.3296,0.4824,-12.1073,1.9733,47.40786868,48.3123
80.08,1.3336,0.484,-12.1001,1.9805,47.56222394,48.4696
80.3,1.3367,0.4845,-12.096,1.9846,47.6115823,48.5199
80.52,1.3408,0.486,-12.0891,1.9915,47.75690979,48.668
80.74,1.3445,0.487,-12.0831,1.9975,47.86082728,48.7739
80.96,1.3477,0.4876,-12.0788,2.0018,47.91891903,48.8331
81.18,1.3518,0.4889,-12.0722,2.0084,48.04540596,48.962
81.4,1.3552,0.4872,-12.0754,2.0052,47.88143415,48.7949
81.62,1.3587,0.4876,-12.0724,2.0082,47.91833026,48.8325
81.84,1.3626,0.4893,-12.0655,2.0151,48.08141891,48.9987
82.06,1.3659,0.4902,-12.0602,2.0204,48.17621051,49.0953
82.28,1.3697,0.4916,-12.0535,2.0271,48.30564127,49.2272
82.5,1.3734,0.493,-12.0466,2.034,48.44861369,49.3729
82.72,1.3769,0.494,-12.0407,2.0399,48.54742854,49.4736
82.94,1.3807,0.4953,-12.0332,2.0474,48.67224729,49.6008
83.16,1.3844,0.4968,-12.0266,2.054,48.81973359,49.7511
83.38,1.3879,0.4977,-12.0202,2.0604,48.91324953,49.8464
83.6,1.3918,0.4991,-12.013,2.0676,49.04709605,49.9828
83.82,1.3954,0.5004,-12.007,2.0736,49.17309233,50.1112
84.04,1.3989,0.5014,-12.0008,2.0798,49.27288846,50.2129
84.26,1.403,0.5029,-11.9933,2.0873,49.41880472,50.3616
84.48,1.4064,0.5038,-11.9878,2.0928,49.51065248,50.4552
84.7,1.4101,0.5051,-11.9812,2.0994,49.64096639,50.588
84.92,1.4142,0.5067,-11.9736,2.107,49.79551791,50.7455
85.14,1.4174,0.5074,-11.9687,2.1119,49.86204866,50.8133
85.36,1.4213,0.5089,-11.961,2.1196,50.00855369,50.9626
85.58,1.4252,0.5103,-11.9537,2.1269,50.15015231,51.1069
85.8,1.4284,0.5109,-11.9486,2.132,50.20225825,51.16
86.02,1.4324,0.5123,-11.9407,2.1399,50.34827264,51.3088
86.24,1.4361,0.5135,-11.9345,2.1461,50.46396549,51.4267
86.46,1.4394,0.5144,-11.9291,2.1515,50.54688361,51.5112
86.68,1.4434,0.5158,-11.9215,2.1591,50.68436086,51.6513
86.9,1.4468,0.5167,-11.9162,2.1644,50.77238163,51.741
87.12,1.4503,0.5175,-11.9103,2.1703,50.85677167,51.827
87.34,1.4543,0.5188,-11.9024,2.1782,50.98649682,51.9592
87.56,1.4576,0.5197,-11.8968,2.1838,51.07579325,52.0502
87.78,1.4613,0.5208,-11.8903,2.1903,51.17686504,52.1532
88,1.4651,0.5223,-11.8837,2.1969,51.32287942,52.302
88.22,1.4685,0.523,-11.878,2.2026,51.39402218,52.3745
88.44,1.4724,0.5244,-11.8705,2.2101,51.53091067,52.514
88.66,1.4761,0.5255,-11.864,2.2166,51.63894954,52.6241
88.88,1.4795,0.5264,-11.8577,2.2229,51.73432991,52.7213
89.1,1.4835,0.5277,-11.8505,2.2301,51.85944304,52.8488
89.32,1.487,0.5286,-11.8442,2.2364,51.94932824,52.9404
89.54,1.4907,0.5299,-11.8378,2.2428,52.07022188,53.0636
89.76,1.4946,0.5312,-11.8302,2.2504,52.19827885,53.1941
89.98,1.498,0.532,-11.8245,2.2561,52.28041194,53.2778
90.2,1.5018,0.5333,-11.8173,2.2633,52.40591759,53.4057
90.42,1.5059,0.5348,-11.8092,2.2714,52.55929157,53.562
90.64,1.509,0.5355,-11.8042,2.2764,52.62327099,53.6272
90.86,1.513,0.5367,-11.796,2.2846,52.74622531,53.7525
91.08,1.5169,0.538,-11.7886,2.292,52.87192721,53.8806
91.3,1.52,0.5387,-11.7834,2.2972,52.93414033,53.944
91.52,1.5242,0.5403,-11.7755,2.3051,53.0913413,54.1042
91.74,1.5276,0.5412,-11.7697,2.3109,53.18456285,54.1992
91.96,1.531,0.5421,-11.7633,2.3173,53.26944353,54.2857
92.18,1.5351,0.5435,-11.7553,2.3253,53.40701891,54.4259
92.4,1.5383,0.5442,-11.7493,2.3313,53.47462907,54.4948
92.62,1.542,0.5453,-11.7423,2.3383,53.58482675,54.6071
92.84,1.5459,0.5466,-11.7347,2.3459,53.71023427,54.7349
93.06,1.5492,0.5473,-11.7293,2.3513,53.78059201,54.8066
93.28,1.553,0.5486,-11.722,2.3586,53.91110218,54.9396
93.5,1.5567,0.5498,-11.7145,2.3661,54.02522499,55.0559
93.72,1.5602,0.5506,-11.7083,2.3723,54.10716182,55.1394
93.94,1.5641,0.5519,-11.7003,2.3803,54.2320787,55.2667
94.16,1.5677,0.553,-11.6938,2.3868,54.34423894,55.381
94.38,1.5713,0.5538,-11.687,2.3936,54.42568514,55.464
94.6,1.5752,0.5553,-11.6789,2.4017,54.57209204,55.6132
94.82,1.5787,0.5563,-11.6728,2.4078,54.66305665,55.7059
95.04,1.5824,0.5572,-11.6659,2.4147,54.75941829,55.8041
95.26,1.5865,0.5586,-11.6578,2.4228,54.89718993,55.9445
95.48,1.5897,0.5595,-11.6518,2.4288,54.9792249,56.0281
95.7,1.5936,0.5607,-11.6437,2.4369,55.10345488,56.1547
95.92,1.5976,0.5622,-11.6355,2.4451,55.2513337,56.3054
96.14,1.6007,0.5628,-11.6301,2.4505,55.3054022,56.3605
96.36,1.6048,0.5642,-11.6214,2.4592,55.4413094,56.499
96.58,1.6084,0.5654,-11.6144,2.4662,55.56053486,56.6205
96.8,1.6117,0.5659,-11.6083,2.4723,55.60871568,56.6696
97.02,1.6158,0.5674,-11.6001,2.4805,55.76218779,56.826
97.24,1.6192,0.5682,-11.5934,2.4872,55.83951262,56.9048
97.46,1.6227,0.5691,-11.5866,2.494,55.92714088,56.9941
97.68,1.6266,0.5705,-11.5783,2.5023,56.0609874,57.1305
97.9,1.63,0.5712,-11.5719,2.5087,56.1326208,57.2035
98.12,1.6337,0.5723,-11.5643,2.5163,56.23938401,57.3123
98.34,1.6375,0.5736,-11.5569,2.5237,56.3633196,57.4386
98.56,1.6408,0.5744,-11.5504,2.5302,56.44378452,57.5206
98.78,1.6447,0.5755,-11.5427,2.5379,56.55565038,57.6346
99,1.6484,0.5767,-11.5349,2.5457,56.67291328,57.7541
99.22,1.6519,0.5775,-11.5276,2.553,56.75573327,57.8385
99.44,1.6558,0.5789,-11.5193,2.5613,56.88702846,57.9723
99.66,1.6594,0.5797,-11.5121,2.5685,56.96867092,58.0555
99.88,1.663,0.5807,-11.5051,2.5755,57.06787827,58.1566
100.1,1.667,0.582,-11.4965,2.5841,57.19250077,58.2836
100.32,1.6704,0.583,-11.49,2.5906,57.28994182,58.3829
100.54,1.6741,0.584,-11.4823,2.5983,57.39248552,58.4874
100.76,1.6781,0.5854,-11.4735,2.6071,57.52750958,58.625
100.98,1.6814,0.5861,-11.4672,2.6134,57.59315718,58.6919
101.2,1.6853,0.5874,-11.4588,2.6218,57.72003662,58.8212
101.42,1.6893,0.5886,-11.4498,2.6308,57.83985084,58.9433
101.64,1.6924,0.5892,-11.4438,2.6368,57.89912012,59.0037
101.86,1.6965,0.5907,-11.4347,2.6459,58.04856899,59.156
102.08,1.7001,0.5917,-11.427,2.6536,58.14689319,59.2562
102.3,1.7034,0.5923,-11.4207,2.6599,58.20704562,59.3175
102.52,1.7074,0.5938,-11.4118,2.6688,58.35502257,59.4683
102.74,1.7108,0.5946,-11.405,2.6756,58.42999232,59.5447
102.96,1.7143,0.5954,-11.3974,2.6832,58.51104601,59.6273
103.18,1.7183,0.5967,-11.389,2.6916,58.63458909,59.7532
103.4,1.7216,0.5974,-11.3825,2.6981,58.70955884,59.8296
103.62,1.7253,0.5985,-11.3737,2.7069,58.814752,59.9368
103.84,1.7291,0.5996,-11.3655,2.7151,58.92387028,60.048
104.06,1.7325,0.6004,-11.3583,2.7223,59.001882,60.1275
104.28,1.7364,0.6017,-11.3499,2.7307,59.12630824,60.2543
104.5,1.74,0.6026,-11.3419,2.7387,59.21972605,60.3495
104.72,1.7436,0.6035,-11.334,2.7466,59.31039627,60.4419
104.94,1.7475,0.6049,-11.3252,2.7554,59.43953265,60.5735
105.16,1.751,0.6056,-11.3175,2.7631,59.51538555,60.6508
105.38,1.7547,0.6067,-11.3093,2.7713,59.6244057,60.7619
105.6,1.7587,0.6081,-11.3001,2.7805,59.76207922,60.9022
105.82,1.762,0.6087,-11.2929,2.7877,59.81457767,60.9557
106.04,1.7658,0.61,-11.2838,2.7968,59.94106459,61.0846
106.26,1.7699,0.6114,-11.2744,2.8062,60.08246697,61.2287
106.48,1.773,0.6119,-11.2678,2.8128,60.13398414,61.2812
106.7,1.777,0.6132,-11.2583,2.8223,60.25939166,61.409
106.92,1.7809,0.6144,-11.2498,2.8308,60.37773396,61.5296
107.14,1.784,0.615,-11.2431,2.8375,60.43317625,61.5861
107.36,1.7881,0.6164,-11.233,2.8476,60.5695741,61.7251
107.58,1.7916,0.6171,-11.2252,2.8554,60.64258129,61.7995
107.8,1.795,0.6178,-11.2174,2.8632,60.71617726,61.8745
108.02,1.799,0.6193,-11.208,2.8726,60.85434141,62.0153
108.24,1.8023,0.62,-11.201,2.8796,60.92401225,62.0863
108.46,1.806,0.6209,-11.1921,2.8885,61.01556563,62.1796
108.68,1.8098,0.6222,-11.1835,2.8971,61.14705708,62.3136
108.9,1.8132,0.6228,-11.1758,2.9048,61.20760202,62.3753
109.12,1.817,0.6239,-11.1663,2.9143,61.31485587,62.4846
109.34,1.8207,0.625,-11.1573,2.9233,61.42367976,62.5955
109.56,1.8242,0.6258,-11.1489,2.9317,61.50228025,62.6756
109.78,1.8281,0.627,-11.1394,2.9412,61.61689369,62.7924
110,1.8317,0.628,-11.131,2.9496,61.71394223,62.8913
110.22,1.8353,0.6288,-11.1227,2.9579,61.79205208,62.9709
110.44,1.8392,0.6301,-11.1129,2.9677,61.92462294,63.106
110.66,1.8427,0.6309,-11.1045,2.9761,61.99488255,63.1776
110.88,1.8464,0.6318,-11.0957,2.9849,62.09124419,63.2758
111.1,1.8504,0.6332,-11.0849,2.9957,62.22332441,63.4104
111.32,1.8537,0.6339,-11.0778,3.0028,62.29191585,63.4803
111.54,1.8576,0.6349,-11.0678,3.0128,62.39514645,63.5855
111.76,1.8616,0.6363,-11.058,3.0226,62.53056302,63.7235
111.98,1.8647,0.6368,-11.0508,3.0298,62.58276708,63.7767
112.2,1.8688,0.6382,-11.04,3.0406,62.72024434,63.9168
112.42,1.8725,0.6393,-11.0308,3.0498,62.821218,64.0197
112.64,1.8757,0.6397,-11.023,3.0576,62.86223548,64.0615
112.86,1.8798,0.6411,-11.0126,3.068,62.99833894,64.2002
113.08,1.8832,0.6418,-11.0041,3.0765,63.06742102,64.2706
113.3,1.8867,0.6424,-10.9953,3.0853,63.13257798,64.337
113.52,1.8906,0.6437,-10.9854,3.0952,63.25935929,64.4662
113.74,1.8939,0.6444,-10.9774,3.1032,63.32608629,64.5342
113.96,1.8977,0.6453,-10.9678,3.1128,63.4188172,64.6287
114.18,1.9015,0.6464,-10.9582,3.1224,63.52548228,64.7374
114.4,1.9048,0.6471,-10.9496,3.131,63.58671412,64.7998
114.62,1.9087,0.6481,-10.9396,3.141,63.68503833,64.9
114.84,1.9124,0.6487,-10.931,3.1496,63.75107843,64.9673
115.06,1.9159,0.649,-10.9243,3.1563,63.77914303,64.9959
115.28,1.9198,0.6497,-10.9156,3.165,63.84861761,65.0667
115.5,1.9233,0.6503,-10.9082,3.1724,63.90877005,65.128
115.72,1.9269,0.6506,-10.9011,3.1795,63.93742341,65.1572
115.94,1.9309,0.6515,-10.8922,3.1884,64.02112655,65.2425
116.16,1.9344,0.6521,-10.8845,3.1961,64.0778445,65.3003
116.38,1.9381,0.6529,-10.8751,3.2055,64.16508025,65.3892
116.6,1.9421,0.6543,-10.8647,3.2159,64.29598293,65.5226
116.82,1.9454,0.6549,-10.8559,3.2247,64.35574285,65.5835
117.04,1.9493,0.656,-10.8452,3.2354,64.46976753,65.6997
117.26,1.9533,0.6575,-10.8343,3.2463,64.60959985,65.8422
117.48,1.9564,0.6579,-10.8258,3.2548,64.6561125,65.8896
117.7,1.9605,0.6593,-10.8141,3.2665,64.79378601,66.0299
117.92,1.9641,0.6603,-10.804,3.2766,64.88651692,66.1244
118.14,1.9673,0.6609,-10.7952,3.2854,64.94460867,66.1836
118.36,1.9714,0.6622,-10.7835,3.2971,65.07335254,66.3148
118.58,1.9748,0.6629,-10.7737,3.3069,65.14086456,66.3836
118.8,1.9783,0.6638,-10.7635,3.3171,65.23496927,66.4795
119.02,1.9823,0.665,-10.7524,3.3282,65.35223216,66.599
119.24,1.9856,0.6657,-10.743,3.3376,65.41738912,66.6654
119.46,1.9893,0.6666,-10.7321,3.3485,65.50845186,66.7582
119.68,1.9931,0.6677,-10.7212,3.3594,65.61649073,66.8683
119.9,1.9965,0.6684,-10.7122,3.3684,65.6813533,66.9344
120.12,2.0004,0.6695,-10.7003,3.3803,65.79174724,67.0469
120.34,2.004,0.6704,-10.6898,3.3908,65.88192683,67.1388
120.56,2.0075,0.6711,-10.6796,3.401,65.94492497,67.203
120.78,2.0115,0.6724,-10.6675,3.4131,66.07278569,67.3333
121,2.015,0.6732,-10.6578,3.4228,66.15275996,67.4148
121.22,2.0187,0.6739,-10.6471,3.4335,66.22576716,67.4892
121.44,2.0227,0.6752,-10.6351,3.4455,66.34911399,67.6149
121.66,2.026,0.6757,-10.6255,3.4551,66.39650979,67.6632
121.88,2.0299,0.6767,-10.6137,3.4669,66.49679655,67.7654
122.1,2.0339,0.6779,-10.6013,3.4793,66.61435383,67.8852
122.32,2.037,0.6783,-10.5924,3.4882,66.66076835,67.9325
122.54,2.0411,0.6794,-10.5799,3.5007,66.76919973,68.043
122.76,2.0448,0.6805,-10.5684,3.5122,66.87252846,68.1483
122.98,2.048,0.6809,-10.5593,3.5213,66.91070024,68.1872
123.2,2.0521,0.682,-10.5468,3.5338,67.02236984,68.301
123.42,2.0556,0.6828,-10.536,3.5446,67.09822274,68.3783
123.64,2.059,0.6833,-10.5255,3.5551,67.14885677,68.4299
123.86,2.063,0.6846,-10.5129,3.5677,67.27603059,68.5595
124.08,2.0663,0.6851,-10.5023,3.5783,67.32587958,68.6103
124.3,2.07,0.6859,-10.491,3.5896,67.39996619,68.6858
124.52,2.0739,0.6869,-10.4792,3.6014,67.50466871,68.7925
124.74,2.0772,0.6874,-10.4688,3.6118,67.55284953,68.8416
124.96,2.081,0.6883,-10.4568,3.6238,67.64145907,68.9319
125.18,2.0848,0.6893,-10.4447,3.6359,67.73683943,69.0291
125.4,2.0882,0.6898,-10.4339,3.6467,67.7890435,69.0823
125.62,2.0921,0.6908,-10.421,3.6596,67.88305007,69.1781
125.84,2.0957,0.6915,-10.4093,3.6713,67.95399658,69.2504
126.06,2.0993,0.6924,-10.3975,3.6831,68.04339114,69.3415
126.28,2.1032,0.6934,-10.3843,3.6963,68.14093032,69.4409
126.5,2.1067,0.6941,-10.3738,3.7068,68.20726481,69.5085
126.72,2.1104,0.6948,-10.3615,3.7191,68.27654315,69.5791
126.94,2.1144,0.6959,-10.3481,3.7325,68.38252133,69.6871
127.16,2.1177,0.6965,-10.3369,3.7437,68.44424381,69.75
127.38,2.1216,0.6974,-10.324,3.7566,68.53844664,69.846
127.6,2.1256,0.6984,-10.3106,3.77,68.63657459,69.946
127.82,2.1288,0.6988,-10.3001,3.7805,68.67082124,69.9809
128.04,2.1328,0.6997,-10.2864,3.7942,68.76149147,70.0733
128.26,2.1364,0.7005,-10.2746,3.806,68.84038634,70.1537
128.48,2.1397,0.7011,-10.2631,3.8175,68.89357168,70.2079
128.7,2.1438,0.702,-10.2494,3.8312,68.98905018,70.3052
128.92,2.1471,0.7026,-10.2374,3.8432,69.04939886,70.3667
129.14,2.1507,0.7032,-10.2248,3.8558,69.10238796,70.4207
129.36,2.1546,0.7041,-10.2111,3.8695,69.19443197,70.5145
129.58,2.1579,0.7047,-10.1995,3.8811,69.24938362,70.5705
129.8,2.1617,0.7054,-10.1859,3.8947,69.32062451,70.6431
130.02,2.1655,0.7062,-10.173,3.9076,69.39775308,70.7217
130.24,2.1688,0.7068,-10.1613,3.9193,69.45643359,70.7815
130.46,2.1727,0.7076,-10.1473,3.9333,69.53140335,70.8579
130.68,2.1764,0.7084,-10.1341,3.9465,69.61363457,70.9417
130.9,2.1799,0.7089,-10.1216,3.959,69.65946032,70.9884
131.12,2.1838,0.7098,-10.1074,3.9732,69.75130808,71.082
131.34,2.1874,0.7106,-10.0939,3.9867,69.83049733,71.1627
131.56,2.191,0.7111,-10.0808,3.9998,69.88015007,71.2133
131.78,2.1949,0.7121,-10.0658,4.0148,69.97739487,71.3124
132,2.1984,0.7125,-10.0539,4.0267,70.0192955,71.3551
132.22,2.2021,0.7133,-10.0397,4.0409,70.09151767,71.4287
132.44,2.2062,0.7142,-10.0242,4.0564,70.18846809,71.5275
132.66,2.2094,0.7146,-10.0122,4.0684,70.2264436,71.5662
132.88,2.2133,0.7155,-9.9972,4.0834,70.31044113,71.6518
133.1,2.2172,0.7164,-9.9825,4.0981,70.39963943,71.7427
133.32,2.2204,0.7166,-9.9702,4.1104,70.4244658,71.768
133.54,2.2244,0.7176,-9.9543,4.1263,70.52004242,71.8654
133.76,2.228,0.7182,-9.9405,4.1401,70.57793791,71.9244
133.98,2.2313,0.7185,-9.928,4.1526,70.60884822,71.9559
134.2,2.2354,0.7195,-9.9125,4.1681,70.70432671,72.0532
134.42,2.2388,0.72,-9.8986,4.182,70.7506431,72.1004
134.64,2.2423,0.7205,-9.8845,4.1961,70.79960895,72.1503
134.86,2.2462,0.7213,-9.8689,4.2117,70.87889633,72.2311
135.08,2.2496,0.7216,-9.8558,4.2248,70.90931599,72.2621
135.3,2.2534,0.7222,-9.8406,4.24,70.97437482,72.3284
135.52,2.2571,0.7229,-9.8258,4.2548,71.04021868,72.3955
135.74,2.2605,0.7234,-9.8119,4.2687,71.08506315,72.4412
135.96,2.2644,0.7242,-9.7962,4.2844,71.16336925,72.521
136.18,2.268,0.7247,-9.7812,4.2994,71.21243323,72.571
136.4,2.2716,0.7251,-9.7658,4.3148,71.25992715,72.6194
136.62,2.2755,0.7259,-9.7499,4.3307,71.33685946,72.6978
136.84,2.279,0.7263,-9.7354,4.3452,71.37601251,72.7377
137.06,2.2827,0.727,-9.7198,4.3608,71.43930504,72.8022
137.28,2.2867,0.728,-9.7034,4.3772,71.53831614,72.9031
137.5,2.29,0.7281,-9.6889,4.3917,71.554311,72.9194
137.72,2.2939,0.7288,-9.6725,4.4081,71.61622973,72.9825
137.94,2.2979,0.7297,-9.6557,4.4249,71.70768498,73.0757
138.16,2.301,0.7297,-9.6413,4.4393,71.71131571,73.0794
138.38,2.3051,0.7307,-9.6243,4.4563,71.80561667,73.1755
138.6,2.3088,0.7313,-9.6082,4.4724,71.86733915,73.2384
138.82,2.312,0.7314,-9.5939,4.4867,71.87921263,73.2505
139.04,2.3161,0.7324,-9.5761,4.5045,71.97341546,73.3465
139.26,2.3195,0.7327,-9.5615,4.5191,72.0012838,73.3749
139.48,2.323,0.7329,-9.5451,4.5355,72.01973185,73.3937
139.7,2.327,0.7338,-9.5269,4.5537,72.11020582,73.4859
139.92,2.3303,0.734,-9.512,4.5686,72.13306963,73.5092
140.14,2.334,0.7345,-9.4953,4.5853,72.17958228,73.5566
140.36,2.3378,0.7351,-9.4773,4.6033,72.23600585,73.6141
140.58,2.3412,0.7354,-9.4617,4.6189,72.26436483,73.643
140.8,2.345,0.7359,-9.4443,4.6363,72.32088653,73.7006
141.02,2.3487,0.7365,-9.4273,4.6533,72.3783895,73.7592
141.24,2.3522,0.7368,-9.4108,4.6698,72.40949606,73.7909
141.46,2.3561,0.7376,-9.3929,4.6877,72.48152198,73.8643
141.68,2.3597,0.738,-9.3752,4.7054,72.52087129,73.9044
141.9,2.3633,0.7383,-9.3579,4.7227,72.55197784,73.9361
142.12,2.3673,0.739,-9.339,4.7416,72.62577006,74.0113
142.34,2.3707,0.7394,-9.3218,4.7588,72.65717101,74.0433
142.56,2.3744,0.7399,-9.3043,4.7763,72.70721626,74.0943
142.78,2.3785,0.7407,-9.2857,4.7949,72.78571862,74.1743
143,2.3817,0.7407,-9.2687,4.8119,72.78748492,74.1761
143.22,2.3856,0.7413,-9.2497,4.8309,72.85254375,74.2424
143.44,2.3896,0.742,-9.2304,4.8502,72.91564002,74.3067
143.66,2.3927,0.7419,-9.2138,4.8668,72.90366841,74.2945
143.88,2.3968,0.7427,-9.1935,4.8871,72.98913785,74.3816
144.1,2.4004,0.7432,-9.1757,4.9049,73.03574863,74.4291
144.32,2.4037,0.7431,-9.1584,4.9222,73.02603396,74.4192
144.54,2.4077,0.7439,-9.1385,4.9421,73.1048307,74.4995
144.76,2.4112,0.744,-9.1205,4.9601,73.11572291,74.5106
144.98,2.4147,0.7443,-9.1012,4.9794,73.13897923,74.5343
145.2,2.4186,0.7449,-9.0817,4.9989,73.20138861,74.5979
145.42,2.422,0.745,-9.0641,5.0165,73.2094351,74.6061
145.64,2.4257,0.7452,-9.0443,5.0363,73.23426147,74.6314
145.86,2.4295,0.7458,-9.0248,5.0558,73.28901686,74.6872
146.08,2.4329,0.7459,-9.0063,5.0743,73.29853527,74.6969
146.3,2.4367,0.7463,-8.986,5.0946,73.3344501,74.7335
146.52,2.4404,0.7467,-8.9664,5.1142,73.3793927,74.7793
146.74,2.4439,0.7467,-8.9468,5.1338,73.38312157,74.7831
146.96,2.4478,0.7472,-8.9259,5.1547,73.4323818,74.8333
147.18,2.4513,0.7475,-8.9061,5.1745,73.4523999,74.8537
147.4,2.455,0.7477,-8.8864,5.1942,73.47467494,74.8764
147.62,2.459,0.7483,-8.8652,5.2154,73.54022441,74.9432
147.84,2.4623,0.7483,-8.8458,5.2348,73.54071505,74.9437
148.06,2.4661,0.7486,-8.825,5.2556,73.56770024,74.9712
148.28,2.4702,0.7493,-8.8027,5.2779,73.6357029,75.0405
148.5,2.4734,0.7492,-8.7838,5.2968,73.6230444,75.0276
148.72,2.4774,0.7497,-8.7615,5.3191,73.66965517,75.0751
148.94,2.4812,0.7502,-8.7398,5.3408,73.7269619,75.1335
149.16,2.4844,0.7499,-8.7211,5.3595,73.69752351,75.1035
149.38,2.4885,0.7506,-8.6984,5.3822,73.76101229,75.1682
149.6,2.492,0.7506,-8.6779,5.4027,73.76503554,75.1723
149.82,2.4954,0.7506,-8.6574,5.4232,73.76621307,75.1735
150.04,2.4994,0.7511,-8.6347,5.4459,73.80605302,75.2141
150.26,2.5027,0.7511,-8.6139,5.4667,73.81066504,75.2188
150.48,2.5063,0.7511,-8.592,5.4886,73.80978188,75.2179
150.7,2.5102,0.7515,-8.5694,5.5112,73.85187877,75.2608
150.92,2.5136,0.7514,-8.5489,5.5317,73.83706145,75.2457
151.14,2.5173,0.7516,-8.5269,5.5537,73.86365413,75.2728
151.36,2.5211,0.752,-8.504,5.5766,73.8944663,75.3042
151.58,2.5245,0.7519,-8.4828,5.5978,73.8877936,75.2974
151.8,2.5284,0.7523,-8.4596,5.621,73.92586725,75.3362
152.02,2.532,0.7523,-8.4371,5.6435,73.92871296,75.3391
152.24,2.5356,0.7524,-8.4147,5.6659,73.94029205,75.3509
152.46,2.5396,0.7527,-8.3899,5.6907,73.97267428,75.3839
152.68,2.543,0.7528,-8.3682,5.7124,73.97434245,75.3856
152.9,2.5467,0.7529,-8.3449,5.7357,73.98729534,75.3988
153.12,2.5507,0.7533,-8.3205,5.7601,74.02321017,75.4354
153.34,2.5541,0.7531,-8.2985,5.7821,74.01074792,75.4227
153.56,2.5579,0.7533,-8.2744,5.8062,74.02792031,75.4402
153.78,2.5619,0.7538,-8.2493,5.8313,74.07188163,75.485
154,2.5651,0.7535,-8.2275,5.8531,74.04352266,75.4561
154.22,2.5691,0.7538,-8.2024,5.8782,74.07698429,75.4902
154.44,2.5728,0.754,-8.1783,5.9023,74.09189973,75.5054
154.66,2.576,0.7536,-8.1559,5.9247,74.05323732,75.466
154.88,2.5801,0.754,-8.1303,5.9503,74.09523608,75.5088
155.1,2.5836,0.7539,-8.1068,5.9738,74.08660083,75.5
155.32,2.587,0.7536,-8.0833,5.9973,74.06049879,75.4734
155.54,2.591,0.7541,-8.0575,6.0231,74.10779646,75.5216
155.76,2.5943,0.7538,-8.034,6.0466,74.0756105,75.4888
155.98,2.598,0.7539,-8.0089,6.0717,74.09082033,75.5043
156.2,2.6018,0.7541,-7.9834,6.0972,74.10102563,75.5147
156.42,2.6052,0.7537,-7.9592,6.1214,74.0700172,75.4831
156.64,2.609,0.7539,-7.9331,6.1475,74.08267571,75.496
156.86,2.6127,0.7539,-7.9082,6.1724,74.08316635,75.4965
157.08,2.6162,0.7537,-7.8833,6.1973,74.06795652,75.481
157.3,2.6201,0.754,-7.8571,6.2235,74.10024061,75.5139
157.52,2.6237,0.754,-7.8312,6.2494,74.09268476,75.5062
157.74,2.6273,0.7538,-7.8059,6.2747,74.07374606,75.4869
157.96,2.6312,0.7541,-7.7786,6.302,74.10151627,75.5152
158.18,2.6347,0.7538,-7.7535,6.3271,74.07727867,75.4905
158.4,2.6384,0.7537,-7.727,6.3536,74.06844716,75.4815
158.62,2.6425,0.7541,-7.6994,6.3812,74.10524514,75.519
158.84,2.6457,0.7538,-7.6745,6.4061,74.07384419,75.487
159.06,2.6496,0.7537,-7.6471,6.4335,74.06893779,75.482
159.28,2.6536,0.7539,-7.619,6.4616,74.08611019,75.4995
159.5,2.6567,0.7534,-7.5941,6.4865,74.03900877,75.4515
159.72,2.6608,0.7537,-7.5655,6.5151,74.067564,75.4806
159.94,2.6645,0.7535,-7.539,6.5416,74.04970472,75.4624
160.16,2.6677,0.7531,-7.5135,6.5671,74.00780408,75.4197
160.38,2.6717,0.7533,-7.4846,6.596,74.0317473,75.4441
160.6,2.6751,0.753,-7.4587,6.6219,74.00122951,75.413
160.82,2.6787,0.7528,-7.4316,6.649,73.97993575,75.3913
161.04,2.6826,0.753,-7.4025,6.6781,73.99367366,75.4053
161.26,2.6859,0.7524,-7.3765,6.7041,73.94225461,75.3529
161.48,2.6897,0.7524,-7.348,6.7326,73.93715196,75.3477
161.7,2.6935,0.7524,-7.3197,6.7609,73.93656319,75.3471
161.92,2.6968,0.7519,-7.2929,6.7877,73.88710671,75.2967
162.14,2.7007,0.7519,-7.2642,6.8164,73.88465351,75.2942
162.36,2.7044,0.7518,-7.2357,6.8449,73.88416287,75.2937
162.58,2.7079,0.7514,-7.2082,6.8724,73.84324351,75.252
162.8,2.7118,0.7515,-7.1783,6.9023,73.84805178,75.2569
163.02,2.7153,0.7513,-7.1498,6.9308,73.83176254,75.2403
163.24,2.719,0.751,-7.1213,6.9593,73.79820279,75.2061
163.46,2.723,0.7512,-7.091,6.9896,73.82057596,75.2289
163.68,2.7264,0.7507,-7.0636,7.017,73.77622213,75.1837
163.9,2.7302,0.7506,-7.0337,7.0469,73.75914786,75.1663
164.12,2.7342,0.7509,-7.003,7.0776,73.78848812,75.1962
164.34,2.7374,0.7501,-6.9751,7.1055,73.71420526,75.1205
164.56,2.7414,0.7502,-6.9442,7.1364,73.71989668,75.1263
164.78,2.7452,0.7501,-6.9145,7.1661,73.71744348,75.1238
165,2.7484,0.7495,-6.8866,7.194,73.65572101,75.0609
165.22,2.7525,0.7495,-6.8556,7.225,73.65199214,75.0571
165.44,2.756,0.7492,-6.8262,7.2544,73.62147435,75.026
165.66,2.7593,0.7488,-6.7973,7.2833,73.58310632,74.9869
165.88,2.7633,0.7489,-6.7657,7.3149,73.59056405,74.9945
166.1,2.7666,0.7482,-6.7369,7.3437,73.52285576,74.9255
166.32,2.7703,0.748,-6.7064,7.3742,73.50175825,74.904
166.54,2.7742,0.7478,-6.6753,7.4053,73.49086605,74.8929
166.76,2.7775,0.7474,-6.6459,7.4347,73.44337213,74.8445
166.98,2.7813,0.7472,-6.6151,7.4655,73.42894732,74.8298
167.2,2.7851,0.747,-6.5842,7.4964,73.41148054,74.812
167.42,2.7885,0.7465,-6.5537,7.5269,73.35770643,74.7572
167.64,2.7924,0.7465,-6.5217,7.5589,73.36310346,74.7627
167.86,2.7961,0.7461,-6.4907,7.5899,73.32316539,74.722
168.08,2.7996,0.7458,-6.4604,7.6202,73.29166632,74.6899
168.3,2.8035,0.7457,-6.4278,7.6528,73.2817554,74.6798
168.52,2.807,0.7453,-6.3975,7.6831,73.2378922,74.6351
168.74,2.8107,0.745,-6.366,7.7146,73.21267332,74.6094
168.96,2.8147,0.745,-6.333,7.7476,73.21100514,74.6077
169.18,2.818,0.7444,-6.3029,7.7777,73.15340404,74.549
169.4,2.8219,0.7442,-6.2697,7.8109,73.13279717,74.528
169.62,2.8259,0.7443,-6.2361,7.8445,73.14751636,74.543
169.84,2.829,0.7435,-6.2067,7.8739,73.06136002,74.4552
170.06,2.8331,0.7437,-6.1733,7.9073,73.08216315,74.4764
170.28,2.8369,0.7434,-6.141,7.9396,73.05046782,74.4441
170.5,2.8401,0.7426,-6.1104,7.9702,72.97873629,74.371
170.72,2.8441,0.7427,-6.077,8.0036,72.98521274,74.3776
170.94,2.8475,0.742,-6.0452,8.0354,72.9141681,74.3052
171.16,2.851,0.7415,-6.0136,8.067,72.86343595,74.2535
171.38,2.855,0.7415,-5.9795,8.1011,72.8632397,74.2533
171.6,2.8583,0.7408,-5.9483,8.1323,72.80318539,74.1921
171.82,2.862,0.7406,-5.9152,8.1654,72.77472829,74.1631
172.04,2.8658,0.7404,-5.8818,8.1988,72.75912594,74.1472
172.26,2.8692,0.7397,-5.8502,8.2304,72.68602062,74.0727
172.48,2.873,0.7397,-5.8164,8.2642,72.68660939,74.0733
172.7,2.8767,0.7392,-5.7832,8.2974,72.640293,74.0261
172.92,2.8802,0.7386,-5.751,8.3296,72.58720578,73.972
173.14,2.8841,0.7385,-5.7163,8.3643,72.57503791,73.9596
173.36,2.8877,0.7381,-5.6834,8.3972,72.53784742,73.9217
173.58,2.8913,0.7378,-5.65,8.4306,72.5079184,73.8912
173.8,2.8952,0.7377,-5.6152,8.4654,72.49094226,73.8739
174.02,2.8987,0.7371,-5.5826,8.498,72.43118234,73.813
174.24,2.9024,0.7368,-5.5485,8.5321,72.40694474,73.7883
174.46,2.9064,0.7368,-5.5133,8.5673,72.40665035,73.788
174.68,2.9097,0.736,-5.4805,8.6001,72.32942366,73.7093
174.9,2.9136,0.7359,-5.4453,8.6353,72.31725579,73.6969
175.12,2.9176,0.7358,-5.4101,8.6705,72.30852241,73.688
175.34,2.9207,0.7349,-5.3781,8.7025,72.22010912,73.5979
175.56,2.9248,0.735,-5.3426,8.738,72.2291369,73.6071
175.78,2.9284,0.7345,-5.3086,8.772,72.18389991,73.561
176,2.9317,0.7338,-5.2757,8.8049,72.11344404,73.4892
176.22,2.9358,0.7339,-5.2394,8.8412,72.12149054,73.4974
176.44,2.9391,0.7332,-5.2062,8.8744,72.05378225,73.4284
176.66,2.9427,0.7326,-5.1717,8.9089,71.99186352,73.3653
176.88,2.9466,0.7324,-5.1358,8.9448,71.97616305,73.3493
177.1,2.9499,0.7318,-5.1026,8.978,71.91120234,73.2831
177.32,2.9537,0.7315,-5.0676,9.013,71.88088081,73.2522
177.54,2.9575,0.7311,-5.0321,9.0485,71.84987238,73.2206
177.76,2.9609,0.7306,-4.9981,9.0825,71.79855146,73.1683
177.98,2.9647,0.7303,-4.9622,9.1184,71.76234225,73.1314
178.2,2.9684,0.7299,-4.9273,9.1533,71.729175,73.0976
178.42,2.9719,0.7294,-4.8929,9.1877,71.67667655,73.0441
178.64,2.9759,0.7293,-4.8564,9.2242,71.66627499,73.0335
178.86,2.9794,0.7288,-4.8219,9.2587,71.61995859,72.9863
179.08,2.983,0.7283,-4.7863,9.2943,71.5687358,72.9341
179.3,2.987,0.7283,-4.7492,9.3314,71.57275905,72.9382
179.52,2.9903,0.7276,-4.715,9.3656,71.50191067,72.866
179.74,2.9942,0.7272,-4.6785,9.4021,71.46462205,72.828
179.96,2.9982,0.7272,-4.6418,9.4388,71.46511269,72.8285
180.18,3.0014,0.7264,-4.608,9.4726,71.38768974,72.7496
180.4,3.0054,0.7264,-4.5706,9.51,71.38602157,72.7479
180.62,3.0092,0.7262,-4.5344,9.5462,71.35913451,72.7205
180.84,3.0124,0.7253,-4.5003,9.5803,71.2741557,72.6339
181.06,3.0164,0.7253,-4.4628,9.6178,71.27121187,72.6309
181.28,3.0199,0.7247,-4.4277,9.6529,71.21351263,72.5721
181.5,3.0234,0.724,-4.3925,9.6881,71.15228079,72.5097
181.72,3.0273,0.724,-4.3557,9.7249,71.14315489,72.5004
181.94,3.0307,0.7234,-4.3206,9.76,71.08408187,72.4402
182.16,3.0343,0.7228,-4.2843,9.7963,71.03285908,72.388
182.38,3.0382,0.7227,-4.2473,9.8333,71.02186875,72.3768
182.6,3.0416,0.7221,-4.2119,9.8687,70.96524892,72.3191
182.82,3.0453,0.7218,-4.1751,9.9055,70.93502552,72.2883
183.04,3.0491,0.7213,-4.1384,9.9422,70.88635405,72.2387
183.26,3.0525,0.721,-4.1032,9.9774,70.85014484,72.2018
183.48,3.0564,0.7207,-4.0657,10.0149,70.82129522,72.1724
183.7,3.06,0.7202,-4.0296,10.051,70.77370317,72.1239
183.92,3.0636,0.7198,-3.9929,10.0877,70.73327445,72.0827
184.14,3.0676,0.7197,-3.9551,10.1255,70.72277476,72.072
184.36,3.071,0.7191,-3.9195,10.1611,70.66419238,72.0123
184.58,3.0747,0.7187,-3.8824,10.1982,70.62513746,71.9725
184.8,3.0787,0.7187,-3.844,10.2366,70.62876819,71.9762
185.02,3.0821,0.7179,-3.8092,10.2714,70.54938268,71.8953
185.24,3.0859,0.7177,-3.7708,10.3098,70.5276964,71.8732
185.46,3.0899,0.7177,-3.7322,10.3484,70.52897207,71.8745
185.68,3.0931,0.717,-3.6971,10.3835,70.45753492,71.8017
185.9,3.0971,0.7168,-3.6581,10.4225,70.4420307,71.7859
186.12,3.1008,0.7165,-3.6214,10.4592,70.40601775,71.7492
186.34,3.104,0.7156,-3.5859,10.4947,70.32015579,71.6617
186.56,3.1081,0.7156,-3.5466,10.534,70.31789885,71.6594
186.78,3.1115,0.7151,-3.5105,10.5701,70.27069931,71.6113
187,3.115,0.7145,-3.4734,10.6072,70.21417761,71.5537
187.22,3.1189,0.7144,-3.4341,10.6465,70.20250038,71.5418
187.44,3.1223,0.7137,-3.3972,10.6834,70.13371269,71.4717
187.66,3.126,0.7135,-3.3574,10.7232,70.11418523,71.4518
187.871,3.1297,0.7544,12.4832,26.5638,74.13801987,75.5524