File: data/ReportRaw/Resin_CSV/V4_Resin_HT/Tensile_Test_02.csv
Time,Displacement,Force,Tensile strain (Strain 1),,,Tensile stress
(s),(mm),(kN),(%),,,(MPa)
0,0,-0.0002,0.8514,0,-0.014822227,-0.0152
0.18,0.0006,0.0007,0.8537,0.0023,0.066212446,0.0679
0.36,0.0035,0.0037,0.863,0.0116,0.359829053,0.369
0.54,0.0072,0.0079,0.8757,0.0243,0.769195547,0.7888
0.72,0.0103,0.0108,0.8862,0.0348,1.052768145,1.0796
0.9,0.0129,0.0133,0.8947,0.0433,1.301040439,1.3342
1.08,0.016,0.0164,0.9052,0.0538,1.604213481,1.6451
1.26,0.019,0.0194,0.9152,0.0638,1.892954355,1.9412
1.44,0.0225,0.0231,0.9262,0.0748,2.256098906,2.3136
1.62,0.0249,0.0251,0.9346,0.0832,2.450445601,2.5129
1.8,0.028,0.028,0.9451,0.0937,2.731190273,2.8008
1.98,0.0308,0.0306,0.9539,0.1025,2.987653799,3.0638
2.16,0.0344,0.0338,0.9652,0.1138,3.305161494,3.3894
2.34,0.037,0.0364,0.9736,0.1222,3.55031332,3.6408
2.52,0.0402,0.0392,0.9837,0.1323,3.827059893,3.9246
2.7,0.0428,0.0413,0.9914,0.14,4.031450596,4.1342
2.88,0.0462,0.0445,1.0018,0.1504,4.34242481,4.4531
3.06,0.0489,0.0466,1.0105,0.1591,4.552178818,4.6682
3.24,0.0524,0.0498,1.0215,0.1701,4.862567944,4.9865
3.42,0.0548,0.0517,1.0278,0.1764,5.045992998,5.1746
3.6,0.058,0.0541,1.0373,0.1859,5.285196431,5.4199
3.78,0.0609,0.0562,1.0452,0.1938,5.492707603,5.6327
3.96,0.0643,0.059,1.0546,0.2032,5.7569723,5.9037
4.14,0.0671,0.061,1.0614,0.21,5.954536978,6.1063
4.32,0.07,0.0629,1.0689,0.2175,6.145178115,6.3018
4.5,0.0729,0.0651,1.0772,0.2258,6.356589873,6.5186
4.68,0.0761,0.0673,1.0854,0.234,6.574145054,6.7417
4.86,0.0794,0.0698,1.0938,0.2424,6.813446001,6.9871
5.04,0.0819,0.0711,1.0991,0.2477,6.94138522,7.1183
5.22,0.085,0.073,1.1064,0.255,7.128418315,7.3101
5.4,0.0879,0.0748,1.1128,0.2614,7.303749653,7.4899
5.58,0.0915,0.0771,1.1211,0.2697,7.529691094,7.7216
5.76,0.094,0.0781,1.1257,0.2743,7.625645508,7.82
5.94,0.0971,0.0799,1.1319,0.2805,7.804097314,8.003
6.12,0.0998,0.0807,1.1363,0.2849,7.882109033,8.083
6.3,0.1033,0.0823,1.142,0.2906,8.040082764,8.245
6.48,0.106,0.0826,1.144,0.2926,8.064461426,8.27
6.66,0.1093,0.083,1.1462,0.2948,8.105320063,8.3119
6.84,0.1118,0.0813,1.1423,0.2909,7.937497354,8.1398
7.02,0.1151,0.081,1.1419,0.2905,7.914288867,8.116
7.2,0.118,0.0812,1.143,0.2916,7.927940918,8.13
7.38,0.1214,0.0819,1.1461,0.2947,8.000589331,8.2045
7.56,0.1239,0.0818,1.1464,0.295,7.987619883,8.1912
7.74,0.127,0.0817,1.1468,0.2954,7.982159063,8.1856
7.92,0.1299,0.0822,1.1483,0.2969,8.027015801,8.2316
8.1,0.1333,0.0836,1.1534,0.302,8.166656777,8.3748
8.28,0.1361,0.0852,1.1588,0.3074,8.317804482,8.5298
8.46,0.1389,0.0866,1.164,0.3126,8.458908179,8.6745
8.64,0.142,0.0885,1.1705,0.3191,8.638822705,8.859
8.82,0.1451,0.0903,1.1769,0.3255,8.819322319,9.0441
9,0.1485,0.0925,1.1846,0.3332,9.035024722,9.2653
9.18,0.1509,0.0938,1.1893,0.3379,9.159258384,9.3927
9.36,0.154,0.0956,1.196,0.3446,9.33771019,9.5757
9.54,0.1569,0.0975,1.2025,0.3511,9.518794893,9.7614
9.72,0.1605,0.1,1.2116,0.3602,9.761021279,10.0098
9.9,0.163,0.1014,1.2165,0.3651,9.899394565,10.1517
10.08,0.1661,0.1033,1.2235,0.3721,10.08447737,10.3415
10.26,0.1688,0.1046,1.229,0.3776,10.21885255,10.4793
10.44,0.1723,0.1071,1.2371,0.3857,10.45600818,10.7225
10.62,0.175,0.1085,1.2428,0.3914,10.60032986,10.8705
10.8,0.1783,0.1107,1.2502,0.3988,10.80715843,11.0826
10.98,0.1808,0.1118,1.2541,0.4027,10.9154972,11.1937
11.16,0.1841,0.1137,1.2616,0.4102,11.09892226,11.3818
11.34,0.1869,0.1152,1.2671,0.4157,11.25026499,11.537
11.52,0.1904,0.1172,1.2745,0.4231,11.44236885,11.734
11.7,0.1929,0.1183,1.2785,0.4271,11.5485623,11.8429
11.88,0.196,0.1199,1.2839,0.4325,11.70604846,12.0044
12.06,0.1989,0.1213,1.2897,0.4383,11.84929748,12.1513
12.24,0.2023,0.123,1.2965,0.4451,12.00931901,12.3154
12.42,0.2052,0.1243,1.3014,0.45,12.13930604,12.4487
12.6,0.2079,0.1255,1.3055,0.4541,12.25525096,12.5676
12.78,0.211,0.127,1.3111,0.4597,12.39908506,12.7151
12.96,0.2141,0.1285,1.3166,0.4652,12.54408935,12.8638
13.14,0.2175,0.1304,1.3231,0.4717,12.73239013,13.0569
13.32,0.2199,0.131,1.3264,0.475,12.78963123,13.1156
13.5,0.223,0.1327,1.3321,0.4807,12.9571614,13.2874
13.68,0.2259,0.1337,1.3366,0.4852,13.05555368,13.3883
13.86,0.2295,0.1357,1.3436,0.4922,13.25126558,13.589
14.04,0.232,0.1364,1.3469,0.4955,13.32323139,13.6628
14.22,0.2352,0.1381,1.3528,0.5014,13.48900629,13.8328
14.4,0.2378,0.1389,1.3561,0.5047,13.56194725,13.9076
14.58,0.2412,0.1407,1.3622,0.5108,13.7380587,14.0882
14.76,0.244,0.1417,1.3661,0.5147,13.83908388,14.1918
14.94,0.2473,0.1432,1.3726,0.5212,13.98906141,14.3456
15.12,0.2498,0.144,1.3755,0.5241,14.06200236,14.4204
15.3,0.253,0.1454,1.3803,0.5289,14.20037565,14.5623
15.48,0.2559,0.1465,1.3853,0.5339,14.31076223,14.6755
15.66,0.2594,0.1481,1.3914,0.54,14.46200745,14.8306
15.84,0.262,0.149,1.3942,0.5428,14.54616259,14.9169
16.02,0.2649,0.1501,1.3985,0.5471,14.65401379,15.0275
16.2,0.2679,0.1512,1.4033,0.5519,14.77025125,15.1467
16.38,0.2712,0.1526,1.4085,0.5571,14.89789793,15.2776
16.56,0.2743,0.1539,1.4131,0.5617,15.02798247,15.411
16.74,0.2769,0.1546,1.4155,0.5641,15.09429243,15.479
16.92,0.28,0.1557,1.4201,0.5687,15.20974978,15.5974
17.1,0.283,0.1567,1.4248,0.5734,15.30453401,15.6946
17.28,0.2865,0.1584,1.4309,0.5795,15.46670087,15.8609
17.46,0.289,0.1589,1.433,0.5816,15.51906624,15.9146
17.64,0.292,0.1602,1.4373,0.5859,15.64047198,16.0391
17.82,0.2948,0.161,1.4417,0.5903,15.72501718,16.1258
18,0.2984,0.1628,1.4478,0.5964,15.90142118,16.3067
18.18,0.301,0.1635,1.4511,0.5997,15.96997397,16.377
18.36,0.3042,0.1648,1.4557,0.6043,16.09254989,16.5027
18.54,0.3068,0.1655,1.4591,0.6077,16.16636848,16.5784
18.72,0.3102,0.167,1.4645,0.6131,16.31147027,16.7272
18.9,0.313,0.168,1.4678,0.6164,16.40440173,16.8225
19.08,0.3164,0.1693,1.4733,0.6219,16.53780177,16.9593
19.26,0.3188,0.17,1.476,0.6246,16.59835837,17.0214
19.44,0.322,0.1711,1.4808,0.6294,16.71079276,17.1367
19.62,0.3249,0.1723,1.4844,0.633,16.82137437,17.2501
19.8,0.3284,0.1737,1.4901,0.6387,16.96569605,17.3981
19.98,0.3311,0.1745,1.4935,0.6421,17.0372718,17.4715
20.16,0.334,0.1754,1.4972,0.6458,17.13264113,17.5693
20.34,0.3369,0.1765,1.5013,0.6499,17.23542157,17.6747
20.52,0.3401,0.1777,1.5059,0.6545,17.35243915,17.7947
20.7,0.3434,0.1792,1.5109,0.6595,17.50095396,17.947
20.88,0.3459,0.1796,1.5139,0.6625,17.54210514,17.9892
21.06,0.3489,0.1808,1.5175,0.6661,17.65766,18.1077
21.24,0.3519,0.1816,1.5217,0.6703,17.73801207,18.1901
21.42,0.3555,0.1833,1.5278,0.6764,17.89959384,18.3558
21.6,0.358,0.1837,1.5302,0.6788,17.94376797,18.4011
21.78,0.3611,0.185,1.5344,0.683,18.06517371,18.5256
21.96,0.3638,0.1855,1.5372,0.6858,18.11919683,18.581
22.14,0.3673,0.1871,1.5433,0.6919,18.27005199,18.7357
22.32,0.37,0.1879,1.5461,0.6947,18.34923388,18.8169
22.5,0.3733,0.1893,1.5513,0.6999,18.48195132,18.953
22.68,0.3758,0.1897,1.5535,0.7021,18.52875835,19.001
22.86,0.3791,0.191,1.5587,0.7073,18.65513733,19.1306
23.04,0.3819,0.1919,1.5623,0.7109,18.74455827,19.2223
23.22,0.3854,0.1934,1.5677,0.7163,18.88497936,19.3663
23.4,0.3879,0.194,1.57,0.7186,18.9418304,19.4246
23.58,0.391,0.195,1.5744,0.723,19.04626859,19.5317
23.76,0.3939,0.1958,1.5783,0.7269,19.12457285,19.612
23.94,0.3973,0.1974,1.5838,0.7324,19.27260009,19.7638
24.12,0.4001,0.1981,1.5866,0.7352,19.34271312,19.8357
24.3,0.403,0.1989,1.5903,0.7389,19.41945715,19.9144
24.48,0.4059,0.1998,1.5942,0.7428,19.51375381,20.0111
24.66,0.4091,0.2009,1.5985,0.7471,19.61458396,20.1145
24.84,0.4124,0.2024,1.6034,0.752,19.76134351,20.265
25.02,0.4149,0.2027,1.6056,0.7542,19.79186559,20.2963
25.2,0.418,0.2038,1.6095,0.7581,19.89874165,20.4059
25.38,0.4209,0.2045,1.6133,0.7619,19.97090249,20.4799
25.56,0.4245,0.2061,1.619,0.7676,20.12292782,20.6358
25.74,0.427,0.2064,1.6207,0.7693,20.15978836,20.6736
25.92,0.4301,0.2076,1.6247,0.7733,20.26861471,20.7852
26.1,0.4328,0.208,1.6274,0.776,20.317177,20.835
26.28,0.4363,0.2096,1.6329,0.7815,20.46393655,20.9855
26.46,0.439,0.21,1.6358,0.7844,20.50850074,21.0312
26.64,0.4423,0.2113,1.6403,0.7889,20.63195429,21.1578
26.82,0.4448,0.2117,1.6425,0.7911,20.67242287,21.1993
27,0.4481,0.2128,1.6469,0.7955,20.7851498,21.3149
27.18,0.451,0.2138,1.6502,0.7988,20.87535085,21.4074
27.36,0.4544,0.215,1.6556,0.8042,20.9914908,21.5265
27.54,0.4569,0.2155,1.6578,0.8064,21.04054066,21.5768
27.72,0.46,0.2163,1.6613,0.8099,21.12479332,21.6632
27.9,0.463,0.2173,1.6652,0.8138,21.21635958,21.7571
28.08,0.4663,0.2183,1.6695,0.8181,21.31914001,21.8625
28.26,0.4692,0.2191,1.6729,0.8215,21.39617659,21.9415
28.44,0.4719,0.2199,1.6759,0.8245,21.47584605,22.0232
28.62,0.475,0.2208,1.6795,0.8281,21.55775836,22.1072
28.8,0.478,0.2216,1.683,0.8316,21.64171847,22.1933
28.98,0.4814,0.223,1.6887,0.8373,21.78184702,22.337
29.16,0.4839,0.2233,1.6903,0.8389,21.80642071,22.3622
29.34,0.487,0.2244,1.6943,0.8429,21.91222411,22.4707
29.52,0.4899,0.225,1.6972,0.8458,21.97551111,22.5356
29.7,0.4935,0.2265,1.703,0.8516,22.12334332,22.6872
29.88,0.4959,0.2268,1.7049,0.8535,22.14469903,22.7091
30.06,0.4992,0.228,1.7091,0.8577,22.267665,22.8352
30.24,0.5018,0.2283,1.7113,0.8599,22.29847963,22.8668
30.42,0.5052,0.2296,1.7164,0.865,22.42056797,22.992
30.6,0.508,0.2303,1.7194,0.868,22.48756053,23.0607
30.78,0.5114,0.2315,1.7241,0.8727,22.60760106,23.1838
30.96,0.5138,0.2318,1.7257,0.8743,22.63919581,23.2162
31.14,0.5171,0.2329,1.7303,0.8789,22.74577932,23.3255
31.32,0.52,0.2338,1.7335,0.8821,22.83178724,23.4137
31.5,0.5234,0.2351,1.7394,0.888,22.96352953,23.5488
31.68,0.5259,0.2356,1.7411,0.8897,23.00555834,23.5919
31.86,0.5289,0.2364,1.7447,0.8933,23.08591042,23.6743
32.04,0.5319,0.2371,1.7482,0.8968,23.15319552,23.7433
32.22,0.5352,0.2383,1.7528,0.9014,23.27362611,23.8668
32.4,0.5382,0.2392,1.7565,0.9051,23.35817131,23.9535
32.58,0.5409,0.2396,1.7584,0.907,23.40117527,23.9976
32.76,0.544,0.2405,1.7624,0.911,23.49088875,24.0896
32.94,0.547,0.2414,1.7657,0.9143,23.57055822,24.1713
33.12,0.5505,0.2427,1.771,0.9196,23.6976198,24.3016
33.3,0.553,0.243,1.7723,0.9209,23.72862946,24.3334
33.48,0.556,0.2439,1.7763,0.9249,23.81853797,24.4256
33.66,0.5588,0.2445,1.7791,0.9277,23.87314617,24.4816
33.84,0.5624,0.2458,1.785,0.9336,24.00352326,24.6153
34.02,0.565,0.2463,1.7869,0.9355,24.0504278,24.6634
34.2,0.5682,0.2474,1.7914,0.94,24.16052184,24.7763
34.38,0.5708,0.2478,1.7935,0.9421,24.20294071,24.8198
34.56,0.5741,0.249,1.7985,0.9471,24.31898314,24.9388
34.74,0.577,0.2498,1.8013,0.9499,24.39718989,25.019
34.92,0.5804,0.2511,1.8063,0.9549,24.51713291,25.142
35.1,0.5828,0.2515,1.8082,0.9568,24.55584623,25.1817
35.28,0.586,0.2523,1.8126,0.9612,24.63727096,25.2652
35.46,0.5889,0.253,1.8159,0.9645,24.71030943,25.3401
35.64,0.5924,0.2544,1.8207,0.9693,24.8419542,25.4751
35.82,0.595,0.2549,1.8232,0.9718,24.89636738,25.5309
36,0.5979,0.2556,1.8267,0.9753,24.96384751,25.6001
36.18,0.6009,0.2564,1.8304,0.979,25.03737356,25.6755
36.36,0.6041,0.2573,1.8344,0.983,25.1295249,25.77
36.54,0.6073,0.2587,1.8386,0.9872,25.26233985,25.9062
36.72,0.6099,0.259,1.8409,0.9895,25.29256939,25.9372
36.9,0.613,0.26,1.8448,0.9934,25.38901138,26.0361
37.08,0.6159,0.2608,1.8487,0.9973,25.46946097,26.1186
37.26,0.6195,0.2624,1.8544,1.003,25.62255896,26.2756
37.44,0.6219,0.2627,1.8564,1.005,25.6521059,26.3059
37.62,0.6251,0.2638,1.8611,1.0097,25.76073722,26.4173
37.8,0.6278,0.2645,1.8637,1.0123,25.82558446,26.4838
37.98,0.6314,0.2659,1.8695,1.0181,25.96337266,26.6251
38.16,0.634,0.2665,1.8724,1.021,26.02373423,26.687
38.34,0.6373,0.2677,1.8777,1.0263,26.14435985,26.8107
38.52,0.6398,0.2681,1.8795,1.0281,26.18356074,26.8509
38.7,0.6432,0.2694,1.885,1.0336,26.30993972,26.9805
38.88,0.646,0.2702,1.8886,1.0372,26.38307571,27.0555
39.06,0.6494,0.2715,1.8941,1.0427,26.5181335,27.194
39.24,0.6518,0.2719,1.8959,1.0445,26.55119096,27.2279
39.42,0.655,0.273,1.9001,1.0487,26.66138251,27.3409
39.6,0.6579,0.2738,1.9043,1.0529,26.74153956,27.4231
39.78,0.6613,0.2753,1.9096,1.0582,26.88371591,27.5689
39.96,0.6641,0.276,1.9125,1.0611,26.95314634,27.6401
40.14,0.6669,0.2767,1.916,1.0646,27.02501464,27.7138
40.32,0.6699,0.2777,1.9199,1.0685,27.12311438,27.8144
40.5,0.6731,0.2789,1.925,1.0736,27.23730403,27.9315
40.68,0.6763,0.2801,1.9298,1.0784,27.35588184,28.0531
40.86,0.6789,0.2806,1.932,1.0806,27.40083609,28.0992
41.04,0.682,0.2817,1.9369,1.0855,27.50566434,28.2067
41.22,0.6849,0.2824,1.9407,1.0893,27.58094565,28.2839
41.4,0.6885,0.2841,1.9467,1.0953,27.74330754,28.4504
41.58,0.6909,0.2845,1.9492,1.0978,27.78133825,28.4894
41.76,0.6941,0.2856,1.954,1.1026,27.8934801,28.6044
41.94,0.6968,0.2863,1.9573,1.1059,27.95803479,28.6706
42.12,0.7003,0.2878,1.9633,1.1119,28.10713469,28.8235
42.3,0.703,0.2885,1.9664,1.115,28.16964158,28.8876
42.48,0.7063,0.2898,1.9717,1.1203,28.30372422,29.0251
42.66,0.7088,0.2903,1.9737,1.1223,28.34507043,29.0675
42.84,0.7121,0.2916,1.9791,1.1277,28.47359474,29.1993
43.02,0.715,0.2925,1.9828,1.1314,28.56311319,29.2911
43.2,0.7184,0.2937,1.9885,1.1371,28.68061834,29.4116
43.38,0.7208,0.2941,1.9909,1.1395,28.72196455,29.454
43.56,0.724,0.2952,1.9955,1.1441,28.83176604,29.5666
43.74,0.727,0.296,1.999,1.1476,28.91055788,29.6474
43.92,0.7303,0.2974,2.004,1.1526,29.04522561,29.7855
44.1,0.7332,0.2981,2.0078,1.1564,29.11455853,29.8566
44.28,0.7359,0.2986,2.0106,1.1592,29.16331585,29.9066
44.46,0.739,0.2998,2.0145,1.1631,29.27379995,30.0199
44.64,0.7421,0.3006,2.019,1.1676,29.35512716,30.1033
44.82,0.7455,0.302,2.0243,1.1729,29.49545074,30.2472
45,0.7479,0.3023,2.026,1.1746,29.52324242,30.2757
45.18,0.751,0.3034,2.0305,1.1791,29.62875327,30.3839
45.36,0.7539,0.304,2.0337,1.1823,29.68306893,30.4396
45.54,0.7575,0.3056,2.0402,1.1888,29.84192029,30.6025
45.72,0.76,0.3059,2.0421,1.1907,29.87351503,30.6349
45.9,0.7631,0.3071,2.0468,1.1954,29.98624197,30.7505
46.08,0.7658,0.3075,2.0497,1.1983,30.03080616,30.7962
46.26,0.7693,0.3089,2.0554,1.204,30.16527886,30.9341
46.44,0.772,0.3095,2.0577,1.2063,30.22895593,30.9994
46.62,0.7754,0.3107,2.0633,1.2119,30.34636356,31.1198
46.8,0.7778,0.3111,2.0653,1.2139,30.37951854,31.1538
46.98,0.7811,0.3121,2.0699,1.2185,30.48025118,31.2571
47.16,0.7839,0.313,2.0733,1.2219,30.56391875,31.3429
47.34,0.7874,0.3143,2.0788,1.2274,30.69088282,31.4731
47.52,0.7899,0.3147,2.0813,1.2299,30.73174146,31.515
47.7,0.793,0.3157,2.0856,1.2342,30.825258,31.6109
47.88,0.7959,0.3165,2.0891,1.2377,30.9051225,31.6928
48.06,0.7992,0.3177,2.0938,1.2424,31.02135996,31.812
48.24,0.8023,0.3187,2.098,1.2466,31.12180005,31.915
48.42,0.8049,0.3192,2.1009,1.2495,31.16870459,31.9631
48.6,0.808,0.32,2.1046,1.2532,31.25285974,32.0494
48.78,0.811,0.3208,2.109,1.2576,31.33243169,32.131
48.96,0.8145,0.3224,2.1148,1.2634,31.48816258,32.2907
49.14,0.817,0.3227,2.1165,1.2651,31.51419899,32.3174
49.32,0.8201,0.3236,2.1212,1.2698,31.60381496,32.4093
49.5,0.8229,0.3243,2.1245,1.2731,31.67178267,32.479
49.68,0.8264,0.3258,2.1301,1.2787,31.81737204,32.6283
49.86,0.829,0.3262,2.1326,1.2812,31.85803564,32.67
50.04,0.8322,0.3274,2.1372,1.2858,31.97563831,32.7906
50.22,0.8347,0.3277,2.1399,1.2885,32.00225981,32.8179
50.4,0.8382,0.329,2.145,1.2936,32.12629844,32.9451
50.58,0.841,0.3297,2.1481,1.2967,32.20011703,33.0208
50.76,0.8444,0.3311,2.1538,1.3024,32.33536985,33.1595
50.94,0.8468,0.3313,2.1558,1.3044,32.35428769,33.1789
51.12,0.85,0.3322,2.16,1.3086,32.44468377,33.2716
51.3,0.8529,0.3331,2.1644,1.313,32.5334221,33.3626
51.48,0.8563,0.3344,2.1699,1.3185,32.66048369,33.4929
51.66,0.859,0.335,2.1725,1.3211,32.71567698,33.5495
51.84,0.8619,0.3358,2.1756,1.3242,32.7936887,33.6295
52.02,0.865,0.3368,2.1805,1.3291,32.89208098,33.7304
52.2,0.8682,0.3378,2.1851,1.3337,32.98374475,33.8244
52.38,0.8714,0.3389,2.1894,1.338,33.098617,33.9422
52.56,0.8739,0.3394,2.1923,1.3409,33.14639918,33.9912
52.74,0.877,0.3403,2.1966,1.3452,33.23201704,34.079
52.92,0.8799,0.3411,2.2008,1.3494,33.31178402,34.1608
53.1,0.8835,0.3427,2.2069,1.3555,33.46839255,34.3214
53.28,0.886,0.3431,2.209,1.3576,33.50525309,34.3592
53.46,0.8891,0.344,2.2135,1.3621,33.5905784,34.4467
53.64,0.8918,0.3446,2.2167,1.3653,33.65435298,34.5121
53.82,0.8954,0.3461,2.2225,1.3711,33.7962368,34.6576
54,0.898,0.3467,2.2254,1.374,33.85464807,34.7175
54.18,0.9013,0.3479,2.2305,1.3791,33.96981287,34.8356
54.36,0.9038,0.3482,2.2332,1.3818,34.00599081,34.8727
54.54,0.9071,0.3495,2.2383,1.3869,34.12700648,34.9968
54.72,0.91,0.3503,2.2417,1.3903,34.20628589,35.0781
54.9,0.9134,0.3516,2.2477,1.3963,34.33539529,35.2105
55.08,0.9158,0.3519,2.25,1.3986,34.36494223,35.2408
55.26,0.919,0.3529,2.2548,1.4034,34.46508977,35.3435
55.44,0.922,0.3538,2.2584,1.407,34.55363307,35.4343
55.62,0.9253,0.3551,2.2645,1.4131,34.6776717,35.5615
55.8,0.9281,0.3559,2.2679,1.4165,34.75314804,35.6389
55.98,0.9309,0.3566,2.2714,1.42,34.82394368,35.7115
56.16,0.934,0.3576,2.2756,1.4242,34.91882543,35.8088
56.34,0.9371,0.3586,2.2806,1.4292,35.01790031,35.9104
56.52,0.9404,0.3598,2.2859,1.4345,35.13335766,36.0288
56.7,0.9429,0.3602,2.2883,1.4369,35.17665416,36.0732
56.88,0.946,0.3613,2.293,1.4416,35.2820675,36.1813
57.06,0.9489,0.3621,2.2968,1.4454,35.36241957,36.2637
57.24,0.9525,0.3637,2.3035,1.4521,35.5151275,36.4203
57.42,0.955,0.364,2.3059,1.4545,35.54321172,36.4491
57.6,0.9581,0.3651,2.3105,1.4591,35.65642623,36.5652
57.78,0.9608,0.3657,2.3139,1.4625,35.71054686,36.6207
57.96,0.9644,0.3671,2.3201,1.4687,35.85428345,36.7681
58.14,0.9669,0.3678,2.3233,1.4719,35.91562017,36.831
58.32,0.9702,0.3691,2.3288,1.4774,36.04609477,36.9648
58.5,0.9728,0.3696,2.3321,1.4807,36.09368191,37.0136
58.68,0.9761,0.371,2.3384,1.487,36.23108005,37.1545
58.86,0.9789,0.372,2.3426,1.4912,36.32800961,37.2539
59.04,0.9824,0.3735,2.3494,1.498,36.47584182,37.4055
59.22,0.9849,0.3741,2.3529,1.5015,36.53386304,37.465
59.4,0.988,0.3752,2.3582,1.5068,36.64190927,37.5758
59.58,0.991,0.3764,2.3629,1.5115,36.75629395,37.6931
59.76,0.9943,0.3777,2.3689,1.5175,36.88715861,37.8273
59.94,0.9971,0.3787,2.3737,1.5223,36.97970001,37.9222
60.12,1,0.3795,2.3778,1.5264,37.0648303,38.0095
60.3,1.0029,0.3806,2.3826,1.5312,37.1646853,38.1119
60.48,1.0061,0.3818,2.3881,1.5367,37.28209293,38.2323
60.66,1.0095,0.3832,2.3943,1.5429,37.4236842,38.3775
60.84,1.0119,0.3836,2.3967,1.5453,37.46317764,38.418
61.02,1.015,0.3846,2.4022,1.5508,37.56186246,38.5192
61.2,1.0179,0.3856,2.4068,1.5554,37.66044977,38.6203
61.38,1.0215,0.3873,2.4138,1.5624,37.82251912,38.7865
61.56,1.024,0.3877,2.4166,1.5652,37.86591313,38.831
61.74,1.0271,0.389,2.4218,1.5704,37.98800147,38.9562
61.92,1.0298,0.3896,2.4252,1.5738,38.05021582,39.02
62.1,1.0333,0.3912,2.4321,1.5807,38.20038838,39.174
62.28,1.036,0.3918,2.4357,1.5843,38.26562568,39.2409
62.46,1.0393,0.3931,2.4414,1.59,38.38946928,39.3679
62.64,1.0418,0.3937,2.4443,1.5929,38.44466257,39.4245
62.82,1.0451,0.3948,2.4499,1.5985,38.55378146,39.5364
63,1.0479,0.3956,2.454,1.6026,38.63735152,39.6221
63.18,1.0514,0.3972,2.4606,1.6092,38.79044952,39.7791
63.36,1.054,0.3977,2.4636,1.6122,38.83569631,39.8255
63.54,1.057,0.3986,2.4683,1.6169,38.92404458,39.9161
63.72,1.0599,0.3995,2.4731,1.6217,39.01112517,40.0054
63.9,1.0632,0.4008,2.479,1.6276,39.14140474,40.139
64.08,1.0662,0.4017,2.484,1.6326,39.23121573,40.2311
64.26,1.0689,0.4023,2.4877,1.6363,39.29128475,40.2927
64.44,1.0719,0.4034,2.4927,1.6413,39.39123727,40.3952
64.62,1.075,0.4043,2.4972,1.6458,39.48641156,40.4928
64.8,1.0785,0.4059,2.5036,1.6522,39.63999713,40.6503
64.98,1.0809,0.4061,2.506,1.6546,39.65969509,40.6705
65.16,1.0841,0.4072,2.5113,1.6599,39.76939907,40.783
65.34,1.0868,0.4079,2.5154,1.664,39.83473389,40.85
65.52,1.0904,0.4095,2.5217,1.6703,39.99026975,41.0095
65.7,1.093,0.4099,2.5241,1.6727,40.03278614,41.0531
65.88,1.0962,0.4111,2.53,1.6786,40.14395284,41.1671
66.06,1.0988,0.4117,2.5335,1.6821,40.20450943,41.2292
66.24,1.1022,0.4129,2.5394,1.688,40.32445245,41.3522
66.42,1.105,0.4137,2.5428,1.6914,40.40392689,41.4337
66.6,1.1084,0.415,2.549,1.6976,40.52279725,41.5556
66.78,1.1108,0.4153,2.5519,1.7005,40.55985281,41.5936
66.96,1.114,0.4166,2.5571,1.7057,40.6796008,41.7164
67.14,1.1169,0.4175,2.5611,1.7097,40.76785156,41.8069
67.32,1.1204,0.4187,2.5674,1.716,40.8932554,41.9355
67.5,1.123,0.4194,2.5705,1.7191,40.95439708,41.9982
67.68,1.126,0.4202,2.5755,1.7241,41.03591933,42.0818
67.86,1.1289,0.4211,2.5803,1.7289,41.12475517,42.1729
68.04,1.1322,0.4223,2.5855,1.7341,41.23631193,42.2873
68.22,1.1353,0.4235,2.5908,1.7394,41.35615743,42.4102
68.4,1.1379,0.4239,2.594,1.7426,41.39750364,42.4526
68.58,1.1409,0.4248,2.5988,1.7474,41.48516931,42.5425
68.76,1.144,0.4258,2.6037,1.7523,41.58073367,42.6405
68.94,1.1475,0.4273,2.6102,1.7588,41.73061368,42.7942
69.12,1.1499,0.4275,2.6124,1.761,41.74689863,42.8109
69.3,1.153,0.4287,2.6181,1.7667,41.86040568,42.9273
69.48,1.1558,0.4294,2.6222,1.7708,41.93792982,43.0068
69.66,1.1594,0.4309,2.6288,1.7774,42.08117884,43.1537
69.84,1.162,0.4314,2.6319,1.7805,42.12866848,43.2024
70.02,1.1652,0.4326,2.6373,1.7859,42.24636866,43.3231
70.2,1.1678,0.433,2.6408,1.7894,42.28303417,43.3607
70.38,1.1712,0.4343,2.6466,1.7952,42.41633669,43.4974
70.56,1.174,0.4351,2.6504,1.799,42.49347078,43.5765
70.74,1.1774,0.4364,2.657,1.8056,42.61780195,43.704
70.92,1.1798,0.4368,2.6602,1.8088,42.65729539,43.7445
71.1,1.183,0.4378,2.6649,1.8135,42.754615,43.8443
71.28,1.186,0.4388,2.6694,1.818,42.85173959,43.9439
71.46,1.1894,0.4399,2.6756,1.8242,42.95929825,44.0542
71.64,1.192,0.4405,2.6793,1.8279,43.01614929,44.1125
71.82,1.1949,0.4414,2.6836,1.8322,43.1060578,44.2047
72,1.198,0.4423,2.6885,1.8371,43.19479613,44.2957
72.18,1.2011,0.4434,2.6937,1.8423,43.30157467,44.4052
72.36,1.2043,0.4446,2.6995,1.8481,43.41712953,44.5237
72.54,1.2069,0.4449,2.7027,1.8513,43.44989445,44.5573
72.72,1.21,0.446,2.7078,1.8564,43.5567705,44.6669
72.9,1.2129,0.447,2.7119,1.8605,43.65321249,44.7658
73.08,1.2165,0.4484,2.7192,1.8678,43.78583241,44.9018
73.26,1.2189,0.4486,2.7217,1.8703,43.81216137,44.9288
73.44,1.2221,0.4496,2.7269,1.8755,43.90977353,45.0289
73.62,1.2248,0.4502,2.7302,1.8788,43.96886741,45.0895
73.8,1.2283,0.4517,2.7377,1.8863,44.112604,45.2369
73.98,1.231,0.4523,2.7411,1.8897,44.17325811,45.2991
74.16,1.2343,0.4536,2.7469,1.8955,44.29485888,45.4238
74.34,1.2367,0.454,2.7499,1.8985,44.33259705,45.4625
74.52,1.2401,0.4551,2.7556,1.9042,44.44395877,45.5767
74.7,1.243,0.456,2.7605,1.9091,44.53367225,45.6687
74.88,1.2464,0.4572,2.7665,1.9151,44.65000723,45.788
75.06,1.2488,0.4577,2.7693,1.9179,44.69954467,45.8388
75.24,1.252,0.4586,2.7746,1.9232,44.78545507,45.9269
75.42,1.2549,0.4596,2.7797,1.9283,44.88335978,46.0273
75.6,1.2583,0.4608,2.7857,1.9343,45.0006699,46.1476
75.78,1.2611,0.4616,2.7899,1.9385,45.08082694,46.2298
75.96,1.2639,0.4622,2.7939,1.9425,45.13494757,46.2853
76.14,1.2669,0.4632,2.7989,1.9475,45.23138956,46.3842
76.32,1.2701,0.4642,2.8043,1.9529,45.32812409,46.4834
76.5,1.2734,0.4656,2.8106,1.9592,45.46571726,46.6245
76.68,1.2759,0.4659,2.8136,1.9622,45.4945816,46.6541
76.86,1.279,0.4669,2.8188,1.9674,45.59521671,46.7573
77.04,1.2819,0.4676,2.8235,1.9721,45.66581732,46.8297
77.22,1.2855,0.4692,2.8305,1.9791,45.82223082,46.9901
77.4,1.288,0.4697,2.8342,1.9828,45.86572235,47.0347
77.58,1.2911,0.4708,2.8394,1.988,45.9759139,47.1477
77.76,1.2938,0.4712,2.843,1.9916,46.01911289,47.192
77.94,1.2972,0.4726,2.8493,1.9979,46.14958749,47.3258
78.12,1.3,0.4734,2.8538,2.0024,46.22935447,47.4076
78.3,1.3033,0.4746,2.8605,2.0091,46.34286152,47.524
78.48,1.3058,0.475,2.8633,2.0119,46.38625554,47.5685
78.66,1.3091,0.4762,2.8693,2.0179,46.50220046,47.6874
78.84,1.3119,0.4772,2.8745,2.0231,46.60147037,47.7892
79.02,1.3154,0.4786,2.8819,2.0305,46.73350521,47.9246
79.2,1.3179,0.4791,2.8857,2.0343,46.78752832,47.98
79.38,1.321,0.4801,2.8907,2.0393,46.88484794,48.0798
79.56,1.3239,0.4812,2.8961,2.0447,46.99123642,48.1889
79.74,1.3272,0.4823,2.9024,2.051,47.10367081,48.3042
79.92,1.3302,0.4833,2.9083,2.0569,47.20206309,48.4051
80.1,1.3329,0.484,2.9123,2.0609,47.26564264,48.4703
80.28,1.336,0.4851,2.9184,2.067,47.37203112,48.5794
80.46,1.339,0.486,2.9235,2.0721,47.46115951,48.6708
80.64,1.3425,0.4875,2.9308,2.0794,47.60908923,48.8225
80.82,1.3449,0.4879,2.9342,2.0828,47.64594977,48.8603
81,1.348,0.4889,2.9397,2.0883,47.7433669,48.9602
81.18,1.3509,0.4896,2.9447,2.0933,47.8126023,49.0312
81.36,1.3544,0.4911,2.9518,2.1004,47.96257983,49.185
81.54,1.357,0.4916,2.9555,2.1041,48.00938687,49.233
81.72,1.3602,0.4928,2.9613,2.1099,48.12698953,49.3536
81.9,1.3628,0.4932,2.9652,2.1138,48.16833574,49.396
82.08,1.3663,0.4946,2.9727,2.1213,48.30290596,49.534
82.26,1.369,0.4953,2.9766,2.1252,48.36960598,49.6024
82.44,1.3724,0.4967,2.9831,2.1317,48.50593146,49.7422
82.62,1.3748,0.4971,2.9866,2.1352,48.54054916,49.7777
82.8,1.3781,0.4982,2.9925,2.1411,48.65083822,49.8908
82.98,1.3809,0.4989,2.9979,2.1465,48.72553444,49.9674
83.16,1.3844,0.5004,3.0048,2.1534,48.87131884,50.1169
83.34,1.387,0.5009,3.0089,2.1575,48.92066125,50.1675
83.52,1.3899,0.5018,3.0136,2.1622,49.00374374,50.2527
83.7,1.3929,0.5028,3.0195,2.1681,49.10194099,50.3534
83.88,1.3962,0.5039,3.0258,2.1744,49.20793941,50.4621
84.06,1.3992,0.505,3.0309,2.1795,49.31530304,50.5722
84.24,1.4019,0.5055,3.0354,2.184,49.36142747,50.6195
84.42,1.405,0.5064,3.041,2.1896,49.45094591,50.7113
84.6,1.408,0.5073,3.0467,2.1953,49.54573015,50.8085
84.78,1.4115,0.5089,3.0539,2.2025,49.69443999,50.961
84.96,1.4139,0.5091,3.0572,2.2058,49.7164783,50.9836
85.14,1.417,0.5103,3.0631,2.2117,49.8309605,51.101
85.32,1.4198,0.511,3.068,2.2166,49.90507163,51.177
85.5,1.4234,0.5124,3.0757,2.2243,50.04012942,51.3155
85.68,1.426,0.513,3.0797,2.2283,50.09434756,51.3711
85.86,1.4292,0.5141,3.0861,2.2347,50.20824467,51.4879
86.04,1.4318,0.5147,3.0902,2.2388,50.26490068,51.546
86.22,1.4352,0.516,3.0972,2.2458,50.39225481,51.6766
86.4,1.438,0.5168,3.1022,2.2508,50.46675601,51.753
86.58,1.4414,0.5182,3.1095,2.2581,50.60971248,51.8996
86.76,1.4438,0.5186,3.1135,2.2621,50.64462272,51.9354
86.94,1.447,0.5197,3.1196,2.2682,50.75198635,52.0455
87.12,1.45,0.5208,3.1255,2.2741,50.85564442,52.1518
87.3,1.4534,0.5221,3.1331,2.2817,50.99001961,52.2896
87.48,1.456,0.5228,3.1382,2.2868,51.05925501,52.3606
87.66,1.4589,0.5238,3.1435,2.2921,51.15130884,52.455
87.84,1.4619,0.5248,3.1496,2.2982,51.25272407,52.559
88.02,1.4652,0.5261,3.1569,2.3055,51.37998069,52.6895
88.2,1.4683,0.5274,3.1635,2.3121,51.50528701,52.818
88.38,1.4709,0.5281,3.1687,2.3173,51.56886656,52.8832
88.56,1.474,0.5293,3.1755,2.3241,51.68500651,53.0023
88.74,1.4769,0.5302,3.1814,2.33,51.78018081,53.0999
88.92,1.4805,0.532,3.1903,2.3389,51.95580469,53.28
89.1,1.483,0.5324,3.195,2.3436,51.99198262,53.3171
89.28,1.4861,0.5338,3.2018,2.3504,52.13172111,53.4604
89.46,1.4888,0.5345,3.2074,2.356,52.19939628,53.5298
89.64,1.4924,0.5363,3.2159,2.3645,52.37014443,53.7049
89.82,1.495,0.5369,3.221,2.3696,52.42914079,53.7654
90,1.4983,0.5383,3.2288,2.3774,52.5649787,53.9047
90.18,1.5008,0.5388,3.2336,2.3822,52.62036702,53.9615
90.36,1.5041,0.5403,3.241,2.3896,52.76225083,54.107
90.54,1.5069,0.5412,3.2471,2.3957,52.84903887,54.196
90.72,1.5104,0.5427,3.2553,2.4039,52.99560338,54.3463
90.9,1.5129,0.5432,3.2601,2.4087,53.04728615,54.3993
91.08,1.516,0.5444,3.2669,2.4155,53.16254846,54.5175
91.26,1.5189,0.5454,3.2731,2.4217,53.26035565,54.6178
91.44,1.5223,0.5467,3.281,2.4296,53.38995262,54.7507
91.62,1.5252,0.5477,3.2875,2.4361,53.49049022,54.8538
91.8,1.5279,0.5486,3.2926,2.4412,53.57015969,54.9355
91.98,1.531,0.5496,3.2991,2.4477,53.66699174,55.0348
92.16,1.5341,0.5506,3.3064,2.455,53.76684674,55.1372
92.34,1.5375,0.5522,3.3142,2.4628,53.92677076,55.3012
92.52,1.54,0.5527,3.3191,2.4677,53.97923364,55.355
92.7,1.543,0.5538,3.3258,2.4744,54.07743089,55.4557
92.88,1.5459,0.5546,3.332,2.4806,54.16480402,55.5453
93.06,1.5495,0.5563,3.3411,2.4897,54.32570319,55.7103
93.24,1.552,0.5568,3.3461,2.4947,54.37582572,55.7617
93.42,1.5551,0.558,3.3531,2.5017,54.49255075,55.8814
93.6,1.5578,0.5587,3.3583,2.5069,54.55720296,55.9477
93.78,1.5613,0.5602,3.3668,2.5154,54.70552274,56.0998
93.96,1.564,0.561,3.3727,2.5213,54.78236429,56.1786
94.14,1.5674,0.5622,3.3803,2.5289,54.90611038,56.3055
94.32,1.5698,0.5627,3.3848,2.5334,54.95340498,56.354
94.5,1.5731,0.564,3.3927,2.5413,55.07715107,56.4809
94.68,1.576,0.5649,3.3995,2.5481,55.16198881,56.5679
94.86,1.5794,0.5664,3.4076,2.5562,55.31615947,56.726
95.04,1.5819,0.567,3.4125,2.5611,55.36862235,56.7798
95.22,1.585,0.5679,3.4194,2.568,55.46184636,56.8754
95.4,1.5879,0.5689,3.4263,2.5749,55.55419273,56.9701
95.58,1.5912,0.5702,3.4341,2.5827,55.68652011,57.1058
95.76,1.5942,0.5713,3.4409,2.5895,55.78666765,57.2085
95.94,1.5969,0.5718,3.4462,2.5948,55.84000816,57.2632
96.12,1.6,0.573,3.4533,2.6019,55.96043875,57.3867
96.3,1.603,0.5741,3.4603,2.6089,56.06214653,57.491
96.48,1.6064,0.5756,3.4691,2.6177,56.20832099,57.6409
96.66,1.6089,0.5759,3.4735,2.6221,56.24352378,57.677
96.84,1.6121,0.5771,3.4807,2.6293,56.35303273,57.7893
97.02,1.6148,0.5778,3.487,2.6356,56.42451097,57.8626
97.2,1.6184,0.5794,3.4962,2.6448,56.58433748,58.0265
97.38,1.621,0.58,3.5016,2.6502,56.63953077,58.0831
97.56,1.6241,0.5812,3.5089,2.6575,56.75479308,58.2013
97.74,1.6268,0.5817,3.5143,2.6629,56.80491561,58.2527
97.92,1.6302,0.5831,3.5231,2.6717,56.94553173,58.3969
98.1,1.633,0.5839,3.5291,2.6777,57.02578629,58.4792
98.28,1.6363,0.5853,3.5373,2.6859,57.15440811,58.6111
98.46,1.6388,0.5856,3.5422,2.6908,57.18463765,58.6421
98.64,1.642,0.5869,3.5503,2.6989,57.31394208,58.7747
98.82,1.645,0.5879,3.5572,2.7058,57.41233436,58.8756
99,1.6484,0.5892,3.5654,2.714,57.5431015,59.0097
99.18,1.6509,0.5897,3.5707,2.7193,57.59000604,59.0578
99.36,1.654,0.5908,3.5784,2.727,57.6982473,59.1688
99.54,1.6569,0.5917,3.5854,2.734,57.78435274,59.2571
99.72,1.6602,0.593,3.5939,2.7425,57.91199941,59.388
99.9,1.6633,0.5942,3.6004,2.749,58.02258103,59.5014
100.08,1.6659,0.5946,3.606,2.7546,58.06441481,59.5443
100.26,1.669,0.5957,3.6138,2.7624,58.17840943,59.6612
100.44,1.672,0.5967,3.6208,2.7694,58.27416882,59.7594
100.62,1.6755,0.598,3.6297,2.7783,58.40064532,59.8891
100.8,1.6779,0.5986,3.6349,2.7835,58.45583861,59.9457
100.98,1.6811,0.5996,3.6428,2.7914,58.55559609,60.048
101.16,1.6838,0.6003,3.6497,2.7983,58.62736688,60.1216
101.34,1.6874,0.602,3.6589,2.8075,58.784658,60.2829
101.52,1.69,0.6024,3.6638,2.8124,58.83166006,60.3311
101.7,1.6931,0.6037,3.6725,2.8211,58.95891668,60.4616
101.88,1.6958,0.6043,3.6783,2.8269,59.00972181,60.5137
102.06,1.6992,0.6057,3.6871,2.8357,59.14585226,60.6533
102.24,1.702,0.6064,3.6936,2.8422,59.2166479,60.7259
102.42,1.7054,0.6078,3.7024,2.851,59.35346095,60.8662
102.6,1.7078,0.6081,3.708,2.8566,59.38612835,60.8997
102.78,1.711,0.6092,3.7159,2.8645,59.49251684,61.0088
102.96,1.714,0.6102,3.7231,2.8717,59.590129,61.1089
103.14,1.7174,0.6115,3.7324,2.881,59.71689804,61.2389
103.32,1.72,0.6122,3.7381,2.8867,59.78291546,61.3066
103.5,1.723,0.6131,3.7453,2.8939,59.87194633,61.3979
103.68,1.7259,0.614,3.7532,2.9018,59.96370762,61.492
103.86,1.7292,0.6151,3.7611,2.9097,60.07185136,61.6029
104.04,1.7323,0.6163,3.7694,2.918,60.18760125,61.7216
104.22,1.7349,0.6168,3.7752,2.9238,60.23830887,61.7736
104.4,1.738,0.6178,3.7833,2.9319,60.33231299,61.87
104.58,1.7409,0.6187,3.7904,2.939,60.41705322,61.9569
104.76,1.7445,0.6203,3.8002,2.9488,60.57678221,62.1207
104.94,1.747,0.6206,3.8053,2.9539,60.60944962,62.1542
105.12,1.7501,0.6216,3.8137,2.9623,60.70628167,62.2535
105.3,1.7528,0.6224,3.8202,2.9688,60.77854002,62.3276
105.48,1.7563,0.6239,3.8301,2.9787,60.92393436,62.4767
105.66,1.759,0.6244,3.8363,2.9849,60.97961522,62.5338
105.84,1.7622,0.6256,3.8449,2.9935,61.09321979,62.6503
106.02,1.7648,0.6261,3.8508,2.9994,61.14100197,62.6993
106.2,1.7681,0.6273,3.86,3.0086,61.2563618,62.8176
106.38,1.771,0.6281,3.8669,3.0155,61.34129706,62.9047
106.56,1.7744,0.6295,3.8765,3.0251,61.47635484,63.0432
106.74,1.7769,0.6299,3.8822,3.0308,61.51604331,63.0839
106.92,1.78,0.6309,3.8906,3.0392,61.61043749,63.1807
107.1,1.783,0.6318,3.8984,3.047,61.703759,63.2764
107.28,1.7863,0.633,3.9074,3.056,61.81268287,63.3881
107.46,1.7891,0.6338,3.9143,3.0629,61.89137719,63.4688
107.64,1.7919,0.6346,3.9217,3.0703,61.97153423,63.551
107.82,1.7949,0.6355,3.9299,3.0785,62.05900487,63.6407
108,1.7981,0.6365,3.9379,3.0865,62.15583691,63.74
108.18,1.8014,0.6378,3.9473,3.0959,62.28874938,63.8763
108.36,1.8039,0.6381,3.9528,3.1014,62.31829632,63.9066
108.54,1.807,0.6391,3.9614,3.11,62.41522588,64.006
108.72,1.8099,0.6399,3.9688,3.1174,62.48914198,64.0818
108.9,1.8135,0.6413,3.9792,3.1278,62.63044071,64.2267
109.08,1.8159,0.6418,3.9851,3.1337,62.67510242,64.2725
109.26,1.8191,0.6429,3.9937,3.1423,62.78402628,64.3842
109.44,1.8218,0.6435,4.0004,3.149,62.84351021,64.4452
109.62,1.8253,0.6448,4.0103,3.1589,62.9658911,64.5707
109.8,1.828,0.6454,4.0173,3.1659,63.03132343,64.6378
109.98,1.8313,0.6467,4.0267,3.1753,63.15467946,64.7643
110.16,1.8338,0.6471,4.0329,3.1815,63.19427041,64.8049
110.34,1.8371,0.6482,4.0421,3.1907,63.3040719,64.9175
110.52,1.84,0.6489,4.0494,3.198,63.37145452,64.9866
110.7,1.8434,0.6504,4.0597,3.2083,63.51129053,65.13
110.88,1.8459,0.6505,4.0657,3.2143,63.52903819,65.1482
111.06,1.849,0.6516,4.0741,3.2227,63.63035591,65.2521
111.24,1.8519,0.6524,4.0821,3.2307,63.71207319,65.3359
111.42,1.8553,0.6536,4.0917,3.2403,63.82957834,65.4564
111.6,1.8582,0.6544,4.0999,3.2485,63.90563977,65.5344
111.78,1.8609,0.655,4.1069,3.2555,63.96541625,65.5957
111.96,1.8639,0.6558,4.1146,3.2632,64.04264785,65.6749
112.14,1.867,0.6567,4.124,3.2726,64.13080109,65.7653
112.32,1.8705,0.658,4.1341,3.2827,64.26156823,65.8994
112.5,1.8729,0.6583,4.1398,3.2884,64.28575187,65.9242
112.68,1.876,0.6593,4.1485,3.2971,64.38433917,66.0253
112.86,1.8789,0.6599,4.1563,3.3049,64.44752867,66.0901
113.04,1.8825,0.6615,4.1674,3.316,64.59633602,66.2427
113.22,1.885,0.6617,4.1734,3.322,64.62373764,66.2708
113.4,1.8881,0.6627,4.1821,3.3307,64.72095974,66.3705
113.58,1.8908,0.6633,4.1894,3.338,64.77098476,66.4218
113.76,1.8943,0.6645,4.2001,3.3487,64.89083026,66.5447
113.94,1.897,0.6651,4.2072,3.3558,64.95577501,66.6113
114.12,1.9003,0.6662,4.217,3.3656,65.0602132,66.7184
114.3,1.9028,0.6667,4.2238,3.3724,65.10370474,66.763
114.48,1.9061,0.6677,4.2333,3.3819,65.20190199,66.8637
114.66,1.909,0.6684,4.2417,3.3903,65.27659821,66.9403
114.84,1.9124,0.6697,4.2517,3.4003,65.39810146,67.0649
115.02,1.9149,0.67,4.2583,3.4069,65.43145147,67.0991
115.2,1.9179,0.6707,4.2674,3.416,65.50078438,67.1702
115.38,1.9209,0.6717,4.276,3.4246,65.59946921,67.2714
115.56,1.9243,0.6729,4.2859,3.4345,65.71365886,67.3885
115.74,1.9272,0.6735,4.2943,3.4429,65.77577569,67.4522
115.92,1.9299,0.6741,4.3017,3.4503,65.83233419,67.5102
116.1,1.933,0.6749,4.3107,3.4593,65.91034591,67.5902
116.28,1.936,0.6757,4.3198,3.4684,65.99089301,67.6728
116.46,1.9395,0.6772,4.3305,3.4791,66.13102156,67.8165
116.64,1.9419,0.6773,4.337,3.4856,66.14584378,67.8317
116.82,1.945,0.6782,4.3464,3.495,66.23409454,67.9222
117,1.9478,0.6788,4.3548,3.5034,66.29211576,67.9817
117.18,1.9514,0.6802,4.3656,3.5142,66.42405308,68.117
117.36,1.954,0.6807,4.373,3.5216,66.46998248,68.1641
117.54,1.9572,0.6815,4.3832,3.5318,66.55511276,68.2514
117.72,1.9598,0.682,4.3901,3.5387,66.59918938,68.2966
117.9,1.9632,0.6831,4.4006,3.5492,66.70704059,68.4072
118.08,1.966,0.6838,4.4094,3.558,66.7763735,68.4783
118.26,1.9694,0.6854,4.4198,3.5684,66.9294715,68.6353
118.44,1.9718,0.6851,4.4267,3.5753,66.89963202,68.6047
118.62,1.975,0.686,4.4357,3.5843,66.99383117,68.7013
118.8,1.978,0.6867,4.4453,3.5939,67.06072622,68.7699
118.98,1.9814,0.688,4.4564,3.605,67.18398473,68.8963
119.16,1.984,0.6886,4.4641,3.6127,67.24122583,68.955
119.34,1.9869,0.6891,4.4732,3.6218,67.29866196,69.0139
119.52,1.99,0.69,4.4827,3.6313,67.37872148,69.096
119.7,1.9931,0.6908,4.4924,3.641,67.4640468,69.1835
119.88,1.9963,0.6919,4.5025,3.6511,67.56936262,69.2915
120.06,1.9989,0.6922,4.5108,3.6594,67.59881205,69.3217
120.24,2.002,0.6929,4.5199,3.6685,67.66716981,69.3918
120.42,2.0049,0.6938,4.5293,3.6779,67.75386034,69.4807
120.6,2.0085,0.6951,4.5412,3.6898,67.88355482,69.6137
120.78,2.011,0.6953,4.5485,3.6971,67.90120497,69.6318
120.96,2.0141,0.6962,4.5584,3.707,67.99296625,69.7259
121.14,2.0168,0.6966,4.5667,3.7153,68.03158206,69.7655
121.32,2.0203,0.698,4.5788,3.7274,68.1656647,69.903
121.5,2.023,0.6984,4.5865,3.7351,68.20730345,69.9457
121.68,2.0263,0.6994,4.5976,3.7462,68.3001374,70.0409
121.86,2.0288,0.6997,4.6052,3.7538,68.33338989,70.075
122.04,2.0321,0.7006,4.6164,3.765,68.42017793,70.164
122.22,2.035,0.7014,4.6253,3.7739,68.49731202,70.2431
122.4,2.0384,0.7025,4.6368,3.7854,68.60555328,70.3541
122.58,2.0408,0.7027,4.644,3.7926,68.62174071,70.3707
122.76,2.044,0.7036,4.655,3.8036,68.71174673,70.463
122.94,2.0469,0.7042,4.6645,3.8131,68.77425362,70.5271
123.12,2.0503,0.7052,4.676,3.8246,68.86952543,70.6248
123.3,2.0531,0.706,4.6847,3.8333,68.94236887,70.6995
123.48,2.0559,0.7063,4.6942,3.8428,68.97552385,70.7335
123.66,2.0589,0.7072,4.7046,3.8532,69.06211686,70.8223
123.84,2.0621,0.708,4.7152,3.8638,69.13778823,70.8999
124.02,2.0654,0.709,4.7263,3.8749,69.24310405,71.0079
124.2,2.0679,0.7094,4.7344,3.883,69.27411371,71.0397
124.38,2.071,0.71,4.7448,3.8934,69.33944852,71.1067
124.56,2.0739,0.7106,4.7549,3.9035,69.39230146,71.1609
124.74,2.0775,0.7118,4.7667,3.9153,69.5137072,71.2854
124.92,2.0799,0.7121,4.7747,3.9233,69.53720823,71.3095
125.1,2.0831,0.713,4.7859,3.9345,69.63130986,71.406
125.28,2.0858,0.7134,4.7952,3.9438,69.668853,71.4445
125.46,2.0893,0.7146,4.8079,3.9565,69.78489543,71.5635
125.64,2.092,0.7149,4.816,3.9646,69.81171196,71.591
125.82,2.0953,0.7159,4.8279,3.9765,69.9104943,71.6923
126,2.0978,0.7161,4.8364,3.985,69.92872954,71.711
126.18,2.1011,0.7172,4.8487,3.9973,70.03424039,71.8192
126.36,2.1039,0.7177,4.8585,4.0071,70.08338777,71.8696
126.54,2.1074,0.7188,4.8705,4.0191,70.19777246,71.9869
126.72,2.1099,0.7189,4.8791,4.0277,70.20664629,71.996
126.9,2.113,0.7197,4.8898,4.0384,70.28446298,72.0758
127.08,2.1159,0.7202,4.9005,4.0491,70.33595071,72.1286
127.26,2.1193,0.7213,4.9125,4.0611,70.44116902,72.2365
127.44,2.1221,0.7218,4.9225,4.0711,70.49158409,72.2882
127.62,2.1249,0.7223,4.9332,4.0818,70.53878118,72.3366
127.8,2.128,0.7229,4.9438,4.0924,70.60041044,72.3998
127.98,2.1311,0.7237,4.9549,4.1035,70.67676441,72.4781
128.16,2.1344,0.7248,4.9674,4.116,70.78364046,72.5877
128.34,2.1369,0.725,4.9764,4.125,70.79963287,72.6041
128.52,2.14,0.7258,4.9876,4.1362,70.87481666,72.6812
128.7,2.1429,0.7263,4.9983,4.1469,70.92396404,72.7316
128.88,2.1465,0.7274,5.0115,4.1601,71.03844624,72.849
129.06,2.149,0.7277,5.021,4.1696,71.05980195,72.8709
129.24,2.1521,0.7284,5.0327,4.1813,71.13518077,72.9482
129.42,2.1548,0.7286,5.0423,4.1909,71.15604891,72.9696
129.6,2.1583,0.7297,5.0554,4.204,71.26282745,73.0791
129.78,2.161,0.7301,5.0656,4.2142,71.30290597,73.1202
129.96,2.1643,0.7311,5.0786,4.2272,71.39603246,73.2157
130.14,2.1668,0.7313,5.0876,4.2362,71.4149503,73.2351
130.32,2.1701,0.7321,5.0997,4.2483,71.49247444,73.3146
130.5,2.173,0.7327,5.1108,4.2594,71.55507885,73.3788
130.68,2.1764,0.7337,5.1247,4.2733,71.65337361,73.4796
130.86,2.1789,0.7339,5.1339,4.2825,71.67102376,73.4977
131.04,2.1819,0.7345,5.1454,4.294,71.72689966,73.555
131.22,2.1849,0.7351,5.1572,4.3058,71.78891897,73.6186
131.4,2.1882,0.736,5.1703,4.3189,71.87375672,73.7056
131.58,2.1912,0.7366,5.1822,4.3308,71.93441083,73.7678
131.76,2.1939,0.7369,5.1924,4.341,71.96542049,73.7996
131.94,2.197,0.7376,5.2045,4.3531,72.03504595,73.871
132.12,2.2,0.7381,5.2163,4.3649,72.07892754,73.916
132.3,2.2035,0.7392,5.23,4.3786,72.18814395,74.028
132.48,2.206,0.7393,5.2399,4.3885,72.19935813,74.0395
132.66,2.209,0.74,5.2521,4.4007,72.26479046,74.1066
132.84,2.2119,0.7404,5.2632,4.4118,72.30184603,74.1446
133.02,2.2154,0.7415,5.2783,4.4269,72.41115995,74.2567
133.2,2.2179,0.7416,5.2879,4.4365,72.42422691,74.2701
133.38,2.2212,0.7424,5.3016,4.4502,72.4973629,74.3451
133.56,2.2238,0.7426,5.312,4.4606,72.51920618,74.3675
133.74,2.2272,0.7435,5.3261,4.4747,72.61047989,74.4611
133.92,2.23,0.7438,5.337,4.4856,72.63807653,74.4894
134.1,2.2333,0.7448,5.351,4.4996,72.73578621,74.5896
134.28,2.2358,0.7448,5.3615,4.5101,72.73490858,74.5887
134.46,2.239,0.7455,5.3746,4.5232,72.80658185,74.6622
134.64,2.2419,0.7462,5.3871,4.5357,72.86743099,74.7246
134.82,2.2454,0.7471,5.4008,4.5494,72.95665689,74.8161
135,2.248,0.7472,5.4124,4.561,72.97216172,74.832
135.18,2.2509,0.7477,5.4255,4.5741,73.01643337,74.8774
135.36,2.2539,0.7483,5.4381,4.5867,73.07581979,74.9383
135.54,2.2572,0.749,5.4518,4.6004,73.14476265,75.009
135.72,2.2604,0.7497,5.4649,4.6135,73.21146267,75.0774
135.9,2.2629,0.7498,5.4768,4.6254,73.22131165,75.0875
136.08,2.266,0.7505,5.4897,4.6383,73.29200977,75.16
136.26,2.269,0.751,5.5024,4.651,73.3355013,75.2046
136.44,2.2725,0.7519,5.5175,4.6661,73.4280427,75.2995
136.62,2.2749,0.7519,5.529,4.6776,73.42609241,75.2975
136.8,2.2781,0.7526,5.5426,4.6912,73.49601041,75.3692
136.98,2.2808,0.7529,5.5544,4.703,73.52107167,75.3949
137.16,2.2844,0.7539,5.5696,4.7182,73.62102419,75.4974
137.34,2.287,0.7539,5.5816,4.7302,73.62346206,75.4999
137.52,2.2902,0.7547,5.5961,4.7447,73.69737816,75.5757
137.7,2.2928,0.7548,5.6077,4.7563,73.70634951,75.5849
137.88,2.2961,0.7556,5.6225,4.7711,73.79264997,75.6734
138.06,2.299,0.756,5.6349,4.7835,73.82668258,75.7083
138.24,2.3024,0.7566,5.6505,4.7991,73.88509386,75.7682
138.42,2.3048,0.7568,5.6618,4.8104,73.90615702,75.7898
138.6,2.308,0.7574,5.6761,4.8247,73.96554344,75.8507
138.78,2.3109,0.7577,5.6895,4.8381,73.99713819,75.8831
138.96,2.3143,0.7586,5.7049,4.8535,74.08538895,75.9736
139.14,2.3171,0.7589,5.718,4.8666,74.109085,75.9979
139.32,2.3199,0.7591,5.731,4.8796,74.13092829,76.0203
139.5,2.3229,0.7597,5.7449,4.8935,74.19138737,76.0823
139.68,2.3261,0.7601,5.7598,4.9084,74.2275653,76.1194
139.86,2.3294,0.761,5.7747,4.9233,74.31191547,76.2059
140.04,2.3319,0.7609,5.7871,4.9357,74.30518696,76.199
140.22,2.335,0.7614,5.8017,4.9503,74.35482192,76.2499
140.4,2.3379,0.7618,5.816,4.9646,74.39655819,76.2927
140.58,2.3415,0.7628,5.8324,4.981,74.49319521,76.3918
140.76,2.3439,0.7628,5.8441,4.9927,74.48880705,76.3873
140.94,2.3471,0.7634,5.8591,5.0077,74.54877855,76.4488
141.12,2.3498,0.7634,5.8732,5.0218,74.5530692,76.4532
141.3,2.3533,0.7644,5.8898,5.0384,74.64405037,76.5465
141.48,2.356,0.7645,5.9027,5.0513,74.65848253,76.5613
141.66,2.3592,0.7652,5.9182,5.0668,74.72186706,76.6263
141.84,2.3618,0.7651,5.9317,5.0803,74.71270068,76.6169
142.02,2.3651,0.7658,5.9483,5.0969,74.78222862,76.6882
142.2,2.368,0.7662,5.9622,5.1108,74.82006431,76.727
142.38,2.3714,0.7669,5.9788,5.1274,74.88988479,76.7986
142.56,2.3738,0.7666,5.9918,5.1404,74.86667631,76.7748
142.74,2.377,0.7673,6.0077,5.1563,74.93240118,76.8422
142.92,2.38,0.7677,6.0225,5.1711,74.97023687,76.881
143.1,2.3833,0.7683,6.0392,5.1878,75.02786802,76.9401
143.28,2.3861,0.7686,6.0535,5.2021,75.06336335,76.9765
143.46,2.3889,0.7687,6.0679,5.2165,75.07204216,76.9854
143.64,2.392,0.7691,6.0841,5.2327,75.10939027,77.0237
143.82,2.3951,0.7696,6.0997,5.2483,75.15444204,77.0699
144,2.3984,0.7703,6.1166,5.2652,75.22065448,77.1378
144.18,2.4009,0.7703,6.1305,5.2791,75.22572524,77.143
144.36,2.404,0.7707,6.1462,5.2948,75.25946531,77.1776
144.54,2.4069,0.7709,6.1614,5.31,75.27965084,77.1983
144.72,2.4105,0.7719,6.1797,5.3283,75.37892076,77.3001
144.9,2.413,0.7717,6.1937,5.3423,75.36507368,77.2859
145.08,2.4161,0.7723,6.2102,5.3588,75.41587881,77.338
145.26,2.4188,0.7723,6.2255,5.3741,75.41734153,77.3395
145.44,2.4223,0.773,6.2435,5.3921,75.48755208,77.4115
145.62,2.425,0.7731,6.2582,5.4068,75.49642591,77.4206
145.8,2.4283,0.7737,6.2765,5.4251,75.56146818,77.4873
145.98,2.4308,0.7737,6.2903,5.4389,75.55191174,77.4775
146.16,2.4341,0.7741,6.3077,5.4563,75.59784114,77.5246
146.34,2.437,0.7743,6.3243,5.4729,75.61939188,77.5467
146.52,2.4404,0.7752,6.3424,5.491,75.70198679,77.6314
146.7,2.4429,0.7748,6.3569,5.5055,75.66541879,77.5939
146.88,2.446,0.7752,6.3739,5.5225,75.70774015,77.6373
147.06,2.4489,0.7756,6.3911,5.5397,75.74284542,77.6733
147.24,2.4523,0.7762,6.4095,5.5581,75.8019393,77.7339
147.42,2.4552,0.7764,6.4258,5.5744,75.82514779,77.7577
147.6,2.4579,0.7764,6.4418,5.5904,75.82368507,77.7562
147.78,2.461,0.7767,6.4589,5.6075,75.85176929,77.785
147.96,2.464,0.7771,6.4768,5.6254,75.88804474,77.8222
148.14,2.4675,0.7778,6.4958,5.6444,75.95581742,77.8917
148.32,2.4699,0.7776,6.5107,5.6593,75.9370946,77.8725
148.5,2.473,0.7779,6.5288,5.6774,75.96215587,77.8982
148.68,2.4758,0.778,6.5459,5.6945,75.98009856,77.9166
148.86,2.4794,0.7789,6.5653,5.7139,76.05976803,77.9983
149.04,2.482,0.7787,6.5815,5.7301,76.04611598,77.9843
149.22,2.4852,0.7791,6.6003,5.7489,76.08180634,78.0209
149.4,2.4878,0.7789,6.6165,5.7651,76.06873938,78.0075
149.58,2.4912,0.7796,6.6359,5.7845,76.12978355,78.0701
149.76,2.494,0.7796,6.653,5.8016,76.1281258,78.0684
149.94,2.4974,0.7802,6.6728,5.8214,76.1886824,78.1305
150.12,2.4998,0.78,6.6888,5.8374,76.1740552,78.1155
150.3,2.503,0.7804,6.708,5.8566,76.20701515,78.1493
150.48,2.506,0.7805,6.7258,5.8744,76.22008211,78.1627
150.66,2.5094,0.7811,6.7457,5.8943,76.27927351,78.2234
150.84,2.512,0.781,6.7633,5.9119,76.27000961,78.2139
151.02,2.5149,0.7812,6.7818,5.9304,76.29029266,78.2347
151.2,2.518,0.7815,6.7999,5.9485,76.31759676,78.2627
151.38,2.5212,0.7817,6.8203,5.9689,76.34158537,78.2873
151.56,2.5243,0.7822,6.8394,5.988,76.38312661,78.3299
151.74,2.5269,0.7819,6.8569,6.0055,76.35904049,78.3052
151.92,2.53,0.7822,6.876,6.0246,76.3864421,78.3333
152.1,2.533,0.7823,6.8951,6.0437,76.40058173,78.3478
152.28,2.5365,0.783,6.9165,6.0651,76.46191844,78.4107
152.46,2.5389,0.7826,6.9336,6.0822,76.42925104,78.3772
152.64,2.5421,0.7829,6.9534,6.102,76.45792034,78.4066
152.82,2.5448,0.783,6.9718,6.1204,76.46104081,78.4098
153,2.5484,0.7836,6.994,6.1426,76.51964711,78.4699
153.18,2.551,0.7834,7.0121,6.1607,76.50648264,78.4564
153.36,2.5542,0.7838,7.0327,6.1813,76.54246554,78.4933
153.54,2.5568,0.7835,7.0505,6.1991,76.51457635,78.4647
153.72,2.5602,0.7838,7.0724,6.221,76.54724376,78.4982
153.9,2.563,0.7839,7.0916,6.2402,76.55172943,78.5028
154.08,2.5664,0.7845,7.1136,6.2622,76.61023822,78.5628
154.26,2.5688,0.7841,7.1311,6.2797,76.57074479,78.5223
154.44,2.572,0.7843,7.1526,6.3012,76.59434333,78.5465
154.62,2.5749,0.7845,7.1725,6.3211,76.60643515,78.5589
154.8,2.5783,0.7849,7.1947,6.3433,76.6547049,78.6084
154.98,2.5811,0.7847,7.2134,6.362,76.63549452,78.5887
155.16,2.5839,0.7849,7.2342,6.3828,76.64631864,78.5998
155.34,2.5869,0.7849,7.255,6.4036,76.65392479,78.6076
155.52,2.5901,0.7851,7.2767,6.4253,76.67206251,78.6262
155.7,2.5933,0.7855,7.298,6.4466,76.70707027,78.6621
155.88,2.5959,0.7852,7.3174,6.466,76.6766457,78.6309
156.06,2.599,0.7853,7.3391,6.4877,76.69059029,78.6452
156.24,2.6019,0.7853,7.3602,6.5088,76.68815243,78.6427
156.42,2.6055,0.7859,7.3837,6.5323,76.74695376,78.703
156.6,2.608,0.7855,7.4023,6.5509,76.70755784,78.6626
156.78,2.6111,0.7856,7.4243,6.5729,76.71389629,78.6691
156.96,2.6138,0.7854,7.445,6.5936,76.70209702,78.657
157.14,2.6174,0.7861,7.469,6.6176,76.76343374,78.7199
157.32,2.62,0.7857,7.4889,6.6375,76.72842598,78.684
157.5,2.6232,0.7861,7.512,6.6606,76.76275113,78.7192
157.68,2.6258,0.7855,7.532,6.6806,76.71136091,78.6665
157.86,2.6291,0.7858,7.5552,6.7038,76.74207803,78.698
158.04,2.632,0.7859,7.5769,6.7255,76.74822145,78.7043
158.22,2.6354,0.7863,7.6009,6.7495,76.79054281,78.7477
158.4,2.6378,0.7857,7.6208,6.7694,76.72901106,78.6846
158.58,2.641,0.7861,7.6432,6.7918,76.76314119,78.7196
158.76,2.644,0.7859,7.666,6.8146,76.7491966,78.7053
158.94,2.6473,0.7862,7.69,6.8386,76.77357526,78.7303
159.12,2.6501,0.786,7.7115,6.8601,76.75592511,78.7122
159.3,2.6529,0.7859,7.7336,6.8822,76.74900157,78.7051
159.48,2.6559,0.7858,7.7563,6.9049,76.74012773,78.696
159.66,2.6591,0.786,7.78,6.9286,76.75953315,78.7159
159.84,2.6624,0.7863,7.8045,6.9531,76.79161547,78.7488
160.02,2.6649,0.7858,7.825,6.9736,76.74178548,78.6977
160.2,2.668,0.7857,7.8487,6.9973,76.72979118,78.6854
160.38,2.6709,0.7857,7.8715,7.0201,76.72901106,78.6846
160.56,2.6744,0.7862,7.8973,7.0459,76.77435538,78.7311
160.74,2.677,0.7857,7.9187,7.0673,76.73144893,78.6871
160.92,2.6801,0.786,7.9425,7.0911,76.76206853,78.7185
161.1,2.6828,0.7855,7.9652,7.1138,76.70921559,78.6643
161.28,2.6863,0.7859,7.991,7.1396,76.74529601,78.7013
161.46,2.689,0.7856,8.0138,7.1624,76.71974717,78.6751
161.64,2.6923,0.7858,8.0385,7.1871,76.73622715,78.692
161.82,2.6948,0.7854,8.0602,7.2088,76.69858649,78.6534
162,2.6981,0.7854,8.0856,7.2342,76.70112188,78.656
162.18,2.701,0.7853,8.109,7.2576,76.68561705,78.6401
162.36,2.7044,0.7855,8.1355,7.2841,76.70521749,78.6602
162.54,2.7069,0.7851,8.1576,7.3062,76.66611412,78.6201
162.72,2.7099,0.7849,8.182,7.3306,76.6513894,78.605
162.9,2.7129,0.7849,8.2064,7.355,76.65197449,78.6056
163.08,2.7162,0.7851,8.2327,7.3813,76.67206251,78.6262
163.26,2.7192,0.785,8.2567,7.4053,76.6627011,78.6166
163.44,2.7219,0.7846,8.2805,7.4291,76.61784437,78.5706
163.62,2.7249,0.7845,8.3048,7.4534,76.61228603,78.5649
163.8,2.728,0.7845,8.3306,7.4792,76.60848296,78.561
163.98,2.7315,0.7848,8.3575,7.5061,76.63763984,78.5909
164.16,2.734,0.7841,8.3802,7.5288,76.57571804,78.5274
164.34,2.737,0.7841,8.4052,7.5538,76.56859947,78.5201
164.52,2.7399,0.7838,8.4303,7.5789,76.54451335,78.4954
164.7,2.7434,0.7842,8.458,7.6066,76.57727827,78.529
164.88,2.746,0.7836,8.4814,7.63,76.52276758,78.4731
165.06,2.7492,0.7837,8.5075,7.6561,76.52852095,78.479
165.24,2.7518,0.7832,8.5317,7.6803,76.48103131,78.4303
165.42,2.7552,0.7834,8.5591,7.7077,76.5049224,78.4548
165.6,2.758,0.7831,8.5837,7.7323,76.47001216,78.419
165.78,2.7614,0.7834,8.6105,7.7591,76.5002417,78.45
165.9,2.7628,0.7865,9.3736,8.5222,76.81063083,78.7683